[2022-06-01T01:02:36.012] sched: Allocate JobId=42802 NodeList=gpu05 #CPUs=32 Partition=gpu-v100s
[2022-06-01T07:14:56.632] sched: Allocate JobId=42803 NodeList=gpu05 #CPUs=32 Partition=gpu-v100s
[2022-06-01T07:15:39.684] sched: Allocate JobId=42804 NodeList=gpu05 #CPUs=32 Partition=gpu-v100s
[2022-06-01T08:55:12.868] sched: Allocate JobId=42805 NodeList=cpu04 #CPUs=64 Partition=cpu-opteron
[2022-06-01T09:10:34.641] sched: Allocate JobId=42806 NodeList=cpu01 #CPUs=1 Partition=cpu-opteron
[2022-06-01T09:11:17.689] sched: Allocate JobId=42807 NodeList=cpu01 #CPUs=1 Partition=cpu-opteron
[2022-06-01T09:16:23.309] sched: Allocate JobId=42808 NodeList=cpu01 #CPUs=1 Partition=cpu-opteron
[2022-06-01T09:16:56.360] sched: Allocate JobId=42809 NodeList=cpu01 #CPUs=1 Partition=cpu-opteron
[2022-06-01T10:01:26.899] sched: Allocate JobId=42812 NodeList=cpu01 #CPUs=1 Partition=cpu-opteron
[2022-06-01T10:01:56.938] sched: Allocate JobId=42813 NodeList=cpu01 #CPUs=1 Partition=cpu-opteron
[2022-06-01T10:02:31.275] sched: Allocate JobId=42814 NodeList=cpu01 #CPUs=1 Partition=cpu-opteron
[2022-06-01T10:02:47.298] sched: Allocate JobId=42815 NodeList=cpu01 #CPUs=1 Partition=cpu-opteron
[2022-06-01T10:38:04.154] sched: Allocate JobId=42816 NodeList=cpu01 #CPUs=1 Partition=cpu-opteron
[2022-06-01T10:38:46.210] sched: Allocate JobId=42817 NodeList=cpu01 #CPUs=1 Partition=cpu-opteron
[2022-06-01T10:39:01.232] sched: Allocate JobId=42818 NodeList=cpu01 #CPUs=1 Partition=cpu-opteron
[2022-06-01T10:39:15.254] sched: Allocate JobId=42819 NodeList=cpu01 #CPUs=4 Partition=cpu-opteron
[2022-06-01T10:39:45.296] sched: Allocate JobId=42820 NodeList=cpu01 #CPUs=3 Partition=cpu-opteron
[2022-06-01T10:39:58.316] sched: Allocate JobId=42821 NodeList=cpu01 #CPUs=1 Partition=cpu-opteron
[2022-06-01T10:53:15.257] sched: _slurm_rpc_allocate_resources JobId=42822 NodeList=(null) usec=54752
[2022-06-01T10:53:15.868] sched: Allocate JobId=42822 NodeList=cpu03 #CPUs=1 Partition=cpu-opteron
[2022-06-01T12:36:25.308] sched: Allocate JobId=42823 NodeList=cpu01 #CPUs=1 Partition=cpu-opteron
[2022-06-01T13:01:00.020] sched: Allocate JobId=42824 NodeList=cpu01 #CPUs=1 Partition=cpu-opteron
[2022-06-01T13:23:58.920] sched: _slurm_rpc_allocate_resources JobId=42825 NodeList=(null) usec=28647
[2022-06-01T13:23:59.707] sched: Allocate JobId=42825 NodeList=cpu03 #CPUs=1 Partition=cpu-opteron
[2022-06-01T13:37:19.158] sched: Allocate JobId=42827 NodeList=gpu01 #CPUs=4 Partition=gpu-k10
[2022-06-01T13:40:42.494] sched: Allocate JobId=42828 NodeList=gpu03 #CPUs=16 Partition=gpu-k10
[2022-06-01T13:44:35.944] sched: _slurm_rpc_allocate_resources JobId=42830 NodeList=(null) usec=641
[2022-06-01T13:44:35.989] sched: Allocate JobId=42830 NodeList=cpu03 #CPUs=1 Partition=cpu-opteron
[2022-06-01T13:45:39.624] sched: Allocate JobId=42829 NodeList=gpu03 #CPUs=16 Partition=gpu-k10
[2022-06-01T13:57:12.599] sched: Allocate JobId=42831 NodeList=gpu01 #CPUs=16 Partition=gpu-k10
[2022-06-01T13:57:50.129] sched: Allocate JobId=42832 NodeList=gpu01 #CPUs=4 Partition=gpu-k10
[2022-06-01T13:58:14.591] sched: Allocate JobId=42833 NodeList=gpu01 #CPUs=4 Partition=gpu-k10
[2022-06-01T15:15:32.260] sched: Allocate JobId=42834 NodeList=cpu03 #CPUs=4 Partition=cpu-opteron
[2022-06-01T15:15:47.280] sched: Allocate JobId=42835 NodeList=cpu03 #CPUs=4 Partition=cpu-opteron
[2022-06-01T15:16:04.307] sched: Allocate JobId=42836 NodeList=cpu03 #CPUs=4 Partition=cpu-opteron
[2022-06-01T15:16:09.266] sched: Allocate JobId=42837 NodeList=cpu01 #CPUs=16 Partition=cpu-opteron
[2022-06-01T15:16:19.374] sched: Allocate JobId=42838 NodeList=cpu10 #CPUs=16 Partition=cpu-opteron
[2022-06-01T15:17:19.529] sched: Allocate JobId=42839 NodeList=cpu03 #CPUs=4 Partition=cpu-opteron
[2022-06-01T15:18:13.554] sched: Allocate JobId=42840 NodeList=cpu03 #CPUs=4 Partition=cpu-opteron
[2022-06-01T15:18:16.604] sched: Allocate JobId=42841 NodeList=cpu03 #CPUs=4 Partition=cpu-opteron
[2022-06-01T15:18:44.601] sched: Allocate JobId=42842 NodeList=gpu02 #CPUs=4 Partition=gpu-titan
[2022-06-01T15:18:53.601] sched: Allocate JobId=42843 NodeList=cpu03 #CPUs=4 Partition=cpu-opteron
[2022-06-01T15:18:56.605] sched: Allocate JobId=42844 NodeList=cpu01 #CPUs=16 Partition=cpu-opteron
[2022-06-01T15:20:35.752] sched: Allocate JobId=42845 NodeList=cpu03 #CPUs=4 Partition=cpu-opteron
[2022-06-01T15:20:35.819] sched: Allocate JobId=42846 NodeList=cpu03 #CPUs=4 Partition=cpu-opteron
[2022-06-01T15:20:41.821] sched: Allocate JobId=42847 NodeList=cpu03 #CPUs=4 Partition=cpu-opteron
[2022-06-01T15:21:26.828] sched: Allocate JobId=42848 NodeList=cpu03 #CPUs=4 Partition=cpu-opteron
[2022-06-01T15:21:33.837] sched: Allocate JobId=42849 NodeList=cpu03 #CPUs=4 Partition=cpu-opteron
[2022-06-01T15:21:37.844] sched: Allocate JobId=42850 NodeList=cpu03 #CPUs=4 Partition=cpu-opteron
[2022-06-01T15:21:50.864] sched: Allocate JobId=42851 NodeList=cpu10 #CPUs=16 Partition=cpu-opteron
[2022-06-01T15:22:48.089] sched: Allocate JobId=42852 NodeList=gpu02 #CPUs=4 Partition=gpu-titan
[2022-06-01T15:24:34.311] sched: Allocate JobId=42853 NodeList=cpu03 #CPUs=4 Partition=cpu-opteron
[2022-06-01T15:25:01.275] sched: Allocate JobId=42854 NodeList=cpu10 #CPUs=16 Partition=cpu-opteron
[2022-06-01T15:25:35.426] sched: Allocate JobId=42855 NodeList=cpu03 #CPUs=4 Partition=cpu-opteron
[2022-06-01T15:26:06.367] sched: Allocate JobId=42856 NodeList=cpu03 #CPUs=4 Partition=cpu-opteron
[2022-06-01T15:26:11.447] sched: Allocate JobId=42857 NodeList=cpu04 #CPUs=4 Partition=cpu-opteron
[2022-06-01T15:26:31.404] sched: Allocate JobId=42858 NodeList=cpu03 #CPUs=4 Partition=cpu-opteron
[2022-06-01T15:27:32.596] sched: Allocate JobId=42859 NodeList=cpu03 #CPUs=4 Partition=cpu-opteron
[2022-06-01T15:27:59.641] sched: Allocate JobId=42860 NodeList=cpu04 #CPUs=16 Partition=cpu-opteron
[2022-06-01T15:28:06.737] sched: Allocate JobId=42861 NodeList=cpu03 #CPUs=4 Partition=cpu-opteron
[2022-06-01T15:28:32.685] sched: Allocate JobId=42862 NodeList=cpu03 #CPUs=4 Partition=cpu-opteron
[2022-06-01T15:29:47.791] sched: Allocate JobId=42863 NodeList=cpu04 #CPUs=4 Partition=cpu-opteron
[2022-06-01T15:30:48.878] sched: Allocate JobId=42864 NodeList=gpu02 #CPUs=4 Partition=gpu-titan
[2022-06-01T15:30:53.889] sched: Allocate JobId=42865 NodeList=gpu02 #CPUs=4 Partition=gpu-titan
[2022-06-01T15:31:03.902] sched: Allocate JobId=42866 NodeList=cpu03 #CPUs=4 Partition=cpu-opteron
[2022-06-01T15:32:35.215] sched: Allocate JobId=42867 NodeList=cpu04 #CPUs=16 Partition=cpu-opteron
[2022-06-01T15:32:40.185] sched: Allocate JobId=42868 NodeList=cpu03 #CPUs=4 Partition=cpu-opteron
[2022-06-01T15:34:07.308] sched: Allocate JobId=42869 NodeList=cpu04 #CPUs=16 Partition=cpu-opteron
[2022-06-01T15:34:56.378] sched: Allocate JobId=42870 NodeList=cpu04 #CPUs=4 Partition=cpu-opteron
[2022-06-01T15:40:48.024] sched: Allocate JobId=42871 NodeList=cpu04 #CPUs=1 Partition=cpu-opteron
[2022-06-01T15:42:44.264] sched: Allocate JobId=42872 NodeList=cpu12 #CPUs=48 Partition=cpu-epyc
[2022-06-01T15:43:59.357] sched: Allocate JobId=42873 NodeList=cpu07 #CPUs=64 Partition=cpu-opteron
[2022-06-01T15:59:32.537] sched: Updated reservation=AI_Training users=jitkang,wktang,zati,f4ww4z,lobbeytan,xinpeng,loojh666,jamesong22,roland,nerv_zmg,rayedbw,tingweijing,shahreeza,aznul,huiszeli,nuruljpr,jackmin,ayhamalomari,jasonyang429,stephen.khor,hass,sawsn nodes=cpu03,gpu[02,04] cores=96 licenses=(null) tres=cpu=128 watts=4294967294 start=2022-06-01T10:00:00 end=2022-06-01T18:00:00 MaxStartDelay=
[2022-06-01T15:59:33.003] sched: Allocate JobId=42874 NodeList=gpu04 #CPUs=8 Partition=gpu-k40c
[2022-06-01T16:00:09.044] sched: Allocate JobId=42875 NodeList=gpu04 #CPUs=4 Partition=gpu-k40c
[2022-06-01T16:10:53.160] sched: Allocate JobId=42878 NodeList=gpu04 #CPUs=4 Partition=gpu-k40c
[2022-06-01T16:15:53.712] sched: Allocate JobId=42879 NodeList=cpu13 #CPUs=32 Partition=cpu-epyc
[2022-06-01T18:00:29.810] sched/backfill: _start_job: Started JobId=42876 in gpu-k40c on gpu04
[2022-06-01T18:00:29.811] sched/backfill: _start_job: Started JobId=42877 in gpu-titan on gpu02
[2022-06-01T18:00:29.827] sched/backfill: _start_job: Started JobId=42810 in gpu-k40c on gpu04
[2022-06-01T18:00:32.413] sched: Allocate JobId=42811 NodeList=gpu04 #CPUs=16 Partition=gpu-k40c
[2022-06-01T19:18:36.400] sched: Allocate JobId=42880 NodeList=cpu12 #CPUs=48 Partition=cpu-epyc
[2022-06-01T19:22:41.876] sched: Allocate JobId=42881 NodeList=gpu04 #CPUs=4 Partition=gpu-k40c
[2022-06-01T19:32:37.907] sched: Allocate JobId=42882 NodeList=gpu02 #CPUs=4 Partition=gpu-titan
[2022-06-01T20:11:02.073] sched: Allocate JobId=42884 NodeList=gpu01 #CPUs=4 Partition=gpu-k10
[2022-06-02T00:12:05.706] sched: _slurm_rpc_allocate_resources JobId=42885 NodeList=cpu10 usec=12892
[2022-06-02T00:39:32.454] sched: Allocate JobId=42886 NodeList=cpu01 #CPUs=16 Partition=cpu-opteron
[2022-06-02T00:40:37.531] sched: Allocate JobId=42887 NodeList=cpu01 #CPUs=16 Partition=cpu-opteron
[2022-06-02T00:41:52.638] sched: Allocate JobId=42888 NodeList=cpu01 #CPUs=16 Partition=cpu-opteron
[2022-06-02T00:42:55.829] sched: Allocate JobId=42889 NodeList=cpu01 #CPUs=16 Partition=cpu-opteron
[2022-06-02T00:51:45.687] sched: Allocate JobId=42890 NodeList=cpu10 #CPUs=16 Partition=cpu-opteron
[2022-06-02T00:54:14.014] sched: Allocate JobId=42891 NodeList=cpu04 #CPUs=16 Partition=cpu-opteron
[2022-06-02T00:59:22.555] sched: Allocate JobId=42892 NodeList=cpu01 #CPUs=16 Partition=cpu-opteron
[2022-06-02T01:01:10.700] sched: Allocate JobId=42893 NodeList=cpu10 #CPUs=16 Partition=cpu-opteron
[2022-06-02T01:10:55.210] sched: Allocate JobId=42894 NodeList=cpu01 #CPUs=4 Partition=cpu-opteron
[2022-06-02T01:16:02.738] sched: Allocate JobId=42895 NodeList=cpu01 #CPUs=4 Partition=cpu-opteron
[2022-06-02T01:29:25.212] sched: Allocate JobId=42896 NodeList=cpu01 #CPUs=4 Partition=cpu-opteron
[2022-06-02T01:30:12.278] sched: Allocate JobId=42897 NodeList=cpu01 #CPUs=4 Partition=cpu-opteron
[2022-06-02T01:35:35.454] sched: _slurm_rpc_allocate_resources JobId=42898 NodeList=cpu01 usec=1208
[2022-06-02T03:05:48.033] sched: _slurm_rpc_allocate_resources JobId=42899 NodeList=cpu01 usec=12814
[2022-06-02T03:24:21.837] sched: _slurm_rpc_allocate_resources JobId=42900 NodeList=cpu01 usec=4880
[2022-06-02T03:31:40.564] sched: _slurm_rpc_allocate_resources JobId=42901 NodeList=cpu01 usec=1298
[2022-06-02T04:15:50.381] sched: Allocate JobId=42902 NodeList=gpu02 #CPUs=8 Partition=gpu-titan
[2022-06-02T04:37:19.771] sched: _slurm_rpc_allocate_resources JobId=42903 NodeList=cpu10 usec=14630
[2022-06-02T04:48:33.193] sched: _slurm_rpc_allocate_resources JobId=42904 NodeList=cpu10 usec=3982
[2022-06-02T09:18:49.558] sched: Allocate JobId=42905 NodeList=gpu02 #CPUs=8 Partition=gpu-titan
[2022-06-02T09:23:40.188] sched: Allocate JobId=42906 NodeList=cpu07 #CPUs=64 Partition=cpu-opteron
[2022-06-02T09:53:04.194] sched: _slurm_rpc_allocate_resources JobId=42907 NodeList=cpu10 usec=25365
[2022-06-02T09:53:06.659] sched: _slurm_rpc_allocate_resources JobId=42908 NodeList=cpu10 usec=1192
[2022-06-02T10:17:26.488] sched: _slurm_rpc_allocate_resources JobId=42909 NodeList=cpu10 usec=70438
[2022-06-02T10:32:00.130] sched: Allocate JobId=42910 NodeList=cpu13 #CPUs=16 Partition=cpu-epyc
[2022-06-02T11:07:45.108] sched: Allocate JobId=42911 NodeList=cpu12 #CPUs=48 Partition=cpu-epyc
[2022-06-02T11:13:00.705] sched: Allocate JobId=42912 NodeList=cpu14 #CPUs=48 Partition=cpu-epyc
[2022-06-02T11:59:09.908] sched: Allocate JobId=42913 NodeList=gpu05 #CPUs=32 Partition=gpu-v100s
[2022-06-02T12:53:02.312] sched: Allocate JobId=42914 NodeList=cpu10 #CPUs=4 Partition=cpu-opteron
[2022-06-02T13:52:40.920] sched: Allocate JobId=42915 NodeList=cpu10 #CPUs=4 Partition=cpu-opteron
[2022-06-02T14:21:24.000] sched: Allocate JobId=42916 NodeList=cpu10 #CPUs=16 Partition=cpu-opteron
[2022-06-02T14:25:43.492] sched: Allocate JobId=42917 NodeList=gpu02 #CPUs=24 Partition=gpu-titan
[2022-06-02T14:28:18.836] sched: Allocate JobId=42918 NodeList=cpu13 #CPUs=32 Partition=cpu-epyc
[2022-06-02T14:46:33.846] sched: Allocate JobId=42919 NodeList=cpu14 #CPUs=16 Partition=cpu-epyc
[2022-06-02T14:49:34.247] sched: Allocate JobId=42920 NodeList=cpu07 #CPUs=64 Partition=cpu-opteron
[2022-06-02T14:54:32.979] sched: Allocate JobId=42921 NodeList=cpu07 #CPUs=64 Partition=cpu-opteron
[2022-06-02T15:05:21.205] sched: Allocate JobId=42922 NodeList=cpu07 #CPUs=64 Partition=cpu-opteron
[2022-06-02T15:31:46.174] sched: Allocate JobId=42923 NodeList=gpu04 #CPUs=8 Partition=gpu-k40c
[2022-06-02T15:50:11.616] sched: Allocate JobId=42924 NodeList=cpu01 #CPUs=32 Partition=cpu-opteron
[2022-06-02T15:53:38.981] sched: Allocate JobId=42925 NodeList=cpu01 #CPUs=32 Partition=cpu-opteron
[2022-06-02T16:44:16.504] sched: Allocate JobId=42927 NodeList=cpu03 #CPUs=64 Partition=cpu-opteron
[2022-06-02T16:58:13.232] sched: Allocate JobId=42928 NodeList=cpu01 #CPUs=32 Partition=cpu-opteron
[2022-06-02T17:02:32.832] sched: Allocate JobId=42929 NodeList=cpu01 #CPUs=32 Partition=cpu-opteron
[2022-06-02T17:07:29.390] sched: Allocate JobId=42930 NodeList=cpu01 #CPUs=32 Partition=cpu-opteron
[2022-06-02T17:10:17.632] sched: Allocate JobId=42931 NodeList=cpu01 #CPUs=32 Partition=cpu-opteron
[2022-06-02T17:12:33.902] sched: Allocate JobId=42932 NodeList=cpu13 #CPUs=16 Partition=cpu-epyc
[2022-06-02T17:23:58.163] sched: Allocate JobId=42933 NodeList=cpu13 #CPUs=16 Partition=cpu-epyc
[2022-06-02T17:48:44.807] sched: Allocate JobId=42934 NodeList=cpu13 #CPUs=16 Partition=cpu-epyc
[2022-06-02T17:51:18.023] sched: Allocate JobId=42935 NodeList=cpu13 #CPUs=16 Partition=cpu-epyc
[2022-06-02T17:53:49.355] sched: Allocate JobId=42936 NodeList=cpu13 #CPUs=16 Partition=cpu-epyc
[2022-06-02T20:40:14.451] sched: Allocate JobId=42937 NodeList=cpu13 #CPUs=16 Partition=cpu-epyc
[2022-06-02T20:44:14.909] sched: Allocate JobId=42938 NodeList=cpu13 #CPUs=32 Partition=cpu-epyc
[2022-06-02T20:45:38.033] sched: Allocate JobId=42939 NodeList=cpu14 #CPUs=16 Partition=cpu-epyc
[2022-06-02T22:28:36.287] sched: _slurm_rpc_allocate_resources JobId=42940 NodeList=cpu10 usec=16331
[2022-06-03T00:01:42.152] sched: Allocate JobId=42941 NodeList=cpu14 #CPUs=16 Partition=cpu-epyc
[2022-06-03T00:24:13.797] sched: Allocate JobId=42942 NodeList=cpu14 #CPUs=16 Partition=cpu-epyc
[2022-06-03T00:37:49.459] sched: Allocate JobId=42943 NodeList=cpu14 #CPUs=48 Partition=cpu-epyc
[2022-06-03T00:47:49.563] sched: Allocate JobId=42944 NodeList=cpu10 #CPUs=1 Partition=cpu-opteron
[2022-06-03T00:49:19.675] sched: Allocate JobId=42945 NodeList=cpu10 #CPUs=1 Partition=cpu-opteron
[2022-06-03T00:51:02.821] sched: Allocate JobId=42946 NodeList=cpu10 #CPUs=1 Partition=cpu-opteron
[2022-06-03T03:39:42.800] sched: Allocate JobId=42947 NodeList=gpu02 #CPUs=8 Partition=gpu-titan
[2022-06-03T03:40:35.859] sched: Allocate JobId=42948 NodeList=gpu02 #CPUs=8 Partition=gpu-titan
[2022-06-03T03:43:10.228] sched: Allocate JobId=42949 NodeList=gpu02 #CPUs=8 Partition=gpu-titan
[2022-06-03T03:44:08.310] sched: Allocate JobId=42950 NodeList=gpu02 #CPUs=8 Partition=gpu-titan
[2022-06-03T03:45:44.446] sched: Allocate JobId=42951 NodeList=gpu02 #CPUs=8 Partition=gpu-titan
[2022-06-03T03:46:34.516] sched: Allocate JobId=42952 NodeList=gpu02 #CPUs=8 Partition=gpu-titan
[2022-06-03T03:50:49.993] sched: Allocate JobId=42953 NodeList=gpu02 #CPUs=8 Partition=gpu-titan
[2022-06-03T05:51:05.266] sched: Allocate JobId=42954 NodeList=gpu05 #CPUs=8 Partition=gpu-v100s
[2022-06-03T05:51:05.267] sched: Allocate JobId=42955 NodeList=gpu05 #CPUs=8 Partition=gpu-v100s
[2022-06-03T08:29:14.026] sched: Allocate JobId=42958 NodeList=cpu14 #CPUs=16 Partition=cpu-epyc
[2022-06-03T13:39:52.615] sched: Allocate JobId=42959 NodeList=gpu03 #CPUs=32 Partition=gpu-k10
[2022-06-03T13:42:36.939] sched: Allocate JobId=42960 NodeList=cpu07 #CPUs=64 Partition=cpu-opteron
[2022-06-03T15:02:22.819] sched: Allocate JobId=42961 NodeList=cpu10 #CPUs=16 Partition=cpu-opteron
[2022-06-03T15:02:41.874] sched: Allocate JobId=42962 NodeList=cpu13 #CPUs=16 Partition=cpu-epyc
[2022-06-03T15:02:54.892] sched: Allocate JobId=42963 NodeList=cpu13 #CPUs=16 Partition=cpu-epyc
[2022-06-03T15:03:06.907] sched: Allocate JobId=42964 NodeList=cpu14 #CPUs=16 Partition=cpu-epyc
[2022-06-03T15:03:18.923] sched: Allocate JobId=42965 NodeList=cpu14 #CPUs=16 Partition=cpu-epyc
[2022-06-03T15:03:24.931] sched: Allocate JobId=42966 NodeList=cpu14 #CPUs=16 Partition=cpu-epyc
[2022-06-03T15:03:31.942] sched: Allocate JobId=42967 NodeList=cpu14 #CPUs=16 Partition=cpu-epyc
[2022-06-03T15:03:39.953] sched: Allocate JobId=42968 NodeList=cpu14 #CPUs=16 Partition=cpu-epyc
[2022-06-03T15:03:45.962] sched: Allocate JobId=42969 NodeList=cpu14 #CPUs=16 Partition=cpu-epyc
[2022-06-03T15:33:32.296] sched: Allocate JobId=42972 NodeList=gpu03 #CPUs=32 Partition=gpu-k10
[2022-06-03T15:42:35.842] sched: Allocate JobId=42970 NodeList=cpu15 #CPUs=16 Partition=cpu-epyc
[2022-06-03T15:42:35.842] sched: Allocate JobId=42971 NodeList=cpu15 #CPUs=16 Partition=cpu-epyc
[2022-06-03T15:43:39.328] sched: Allocate JobId=42973 NodeList=gpu01 #CPUs=32 Partition=gpu-k10
[2022-06-03T15:50:18.012] sched: Allocate JobId=42974 NodeList=cpu10 #CPUs=16 Partition=cpu-opteron
[2022-06-03T17:02:54.075] sched: Allocate JobId=42975 NodeList=cpu10 #CPUs=8 Partition=cpu-opteron
[2022-06-03T17:26:20.570] sched: Allocate JobId=42976 NodeList=cpu10 #CPUs=32 Partition=cpu-opteron
[2022-06-03T20:51:14.038] sched: Allocate JobId=42977 NodeList=cpu10 #CPUs=32 Partition=cpu-opteron
[2022-06-03T21:05:32.585] sched: Allocate JobId=42978 NodeList=cpu11 #CPUs=32 Partition=cpu-opteron
[2022-06-04T02:40:45.094] sched: Allocate JobId=42979 NodeList=cpu01 #CPUs=2 Partition=cpu-opteron
[2022-06-04T05:12:52.031] sched: Allocate JobId=42980 NodeList=cpu10 #CPUs=32 Partition=cpu-opteron
[2022-06-04T05:14:10.127] sched: Allocate JobId=42981 NodeList=cpu11 #CPUs=32 Partition=cpu-opteron
[2022-06-04T05:17:23.505] sched: Allocate JobId=42982 NodeList=cpu11 #CPUs=32 Partition=cpu-opteron
[2022-06-04T05:20:33.781] sched: Allocate JobId=42983 NodeList=cpu01 #CPUs=32 Partition=cpu-opteron
[2022-06-04T11:08:27.147] sched: Allocate JobId=42988 NodeList=gpu01 #CPUs=16 Partition=gpu-k10
[2022-06-04T11:12:22.574] sched: Allocate JobId=42989 NodeList=gpu03 #CPUs=16 Partition=gpu-k10
[2022-06-04T11:27:10.165] sched: Allocate JobId=42990 NodeList=gpu01 #CPUs=16 Partition=gpu-k10
[2022-06-04T11:27:50.338] sched: Allocate JobId=42991 NodeList=gpu03 #CPUs=16 Partition=gpu-k10
[2022-06-04T11:36:47.309] sched: _slurm_rpc_allocate_resources JobId=42992 NodeList=cpu11 usec=13199
[2022-06-04T11:49:46.731] sched: _slurm_rpc_allocate_resources JobId=42993 NodeList=cpu11 usec=4135
[2022-06-04T11:53:29.065] sched: _slurm_rpc_allocate_resources JobId=42994 NodeList=cpu11 usec=1102
[2022-06-04T11:54:29.187] sched: _slurm_rpc_allocate_resources JobId=42995 NodeList=cpu11 usec=1369
[2022-06-04T11:55:50.483] sched: _slurm_rpc_allocate_resources JobId=42996 NodeList=cpu11 usec=1196
[2022-06-04T11:56:47.403] sched: _slurm_rpc_allocate_resources JobId=42997 NodeList=cpu11 usec=1105
[2022-06-04T14:39:26.571] sched: Allocate JobId=43001 NodeList=cpu11 #CPUs=4 Partition=cpu-opteron
[2022-06-04T14:41:59.774] sched: Allocate JobId=43003 NodeList=cpu11 #CPUs=4 Partition=cpu-opteron
[2022-06-04T14:45:09.208] sched: Allocate JobId=43004 NodeList=cpu13 #CPUs=4 Partition=cpu-epyc
[2022-06-04T16:15:54.001] sched: Allocate JobId=43005 NodeList=cpu11 #CPUs=8 Partition=cpu-opteron
[2022-06-04T18:10:36.040] sched: Allocate JobId=43006 NodeList=gpu03 #CPUs=16 Partition=gpu-k10
[2022-06-04T19:01:39.970] sched: Allocate JobId=43007 NodeList=cpu12 #CPUs=48 Partition=cpu-epyc
[2022-06-04T19:01:57.786] sched: _slurm_rpc_allocate_resources JobId=43008 NodeList=cpu11 usec=12433
[2022-06-04T19:09:41.270] sched: _slurm_rpc_allocate_resources JobId=43009 NodeList=cpu11 usec=1131
[2022-06-04T19:45:26.984] sched: Allocate JobId=43010 NodeList=gpu05 #CPUs=8 Partition=gpu-v100s
[2022-06-04T19:46:37.816] sched: Allocate JobId=43011 NodeList=gpu05 #CPUs=8 Partition=gpu-v100s
[2022-06-04T19:48:19.071] sched: Allocate JobId=43012 NodeList=gpu05 #CPUs=8 Partition=gpu-v100s
[2022-06-04T19:57:25.192] sched: Allocate JobId=43013 NodeList=gpu05 #CPUs=8 Partition=gpu-v100s
[2022-06-04T20:01:41.460] sched: Allocate JobId=43014 NodeList=gpu05 #CPUs=8 Partition=gpu-v100s
[2022-06-04T20:04:47.858] sched: Allocate JobId=43015 NodeList=gpu05 #CPUs=8 Partition=gpu-v100s
[2022-06-04T20:13:05.050] sched: Allocate JobId=43016 NodeList=gpu05 #CPUs=8 Partition=gpu-v100s
[2022-06-04T20:14:30.966] sched/backfill: _start_job: Started JobId=42956 in gpu-titan on gpu02
[2022-06-05T00:52:49.725] sched: Allocate JobId=43017 NodeList=cpu11 #CPUs=1 Partition=cpu-opteron
[2022-06-05T01:17:45.073] sched: Allocate JobId=43018 NodeList=cpu14 #CPUs=48 Partition=cpu-epyc
[2022-06-05T01:21:30.389] sched: Allocate JobId=43019 NodeList=cpu11 #CPUs=16 Partition=cpu-opteron
[2022-06-05T08:48:42.899] sched: Allocate JobId=43020 NodeList=cpu11 #CPUs=1 Partition=cpu-opteron
[2022-06-05T08:54:06.570] sched: Allocate JobId=43021 NodeList=cpu11 #CPUs=1 Partition=cpu-opteron
[2022-06-05T12:53:28.379] sched: Allocate JobId=43022 NodeList=cpu11 #CPUs=5 Partition=cpu-opteron
[2022-06-05T12:58:20.871] sched: Allocate JobId=43023 NodeList=cpu11 #CPUs=12 Partition=cpu-opteron
[2022-06-05T16:29:36.604] sched: _slurm_rpc_allocate_resources JobId=43024 NodeList=cpu11 usec=15589
[2022-06-05T23:39:29.368] sched: Allocate JobId=42957 NodeList=gpu02 #CPUs=8 Partition=gpu-titan
[2022-06-06T00:25:20.146] sched: _slurm_rpc_allocate_resources JobId=43028 NodeList=cpu11 usec=17099
[2022-06-06T01:13:52.008] sched: Allocate JobId=43029 NodeList=cpu12 #CPUs=32 Partition=cpu-epyc
[2022-06-06T02:08:56.464] sched: Allocate JobId=43026 NodeList=gpu05 #CPUs=8 Partition=gpu-v100s
[2022-06-06T02:09:17.038] sched: Allocate JobId=43027 NodeList=gpu05 #CPUs=8 Partition=gpu-v100s
[2022-06-06T02:42:35.330] sched: Allocate JobId=43030 NodeList=cpu13 #CPUs=32 Partition=cpu-epyc
[2022-06-06T03:40:24.750] sched: Allocate JobId=43031 NodeList=gpu05 #CPUs=8 Partition=gpu-v100s
[2022-06-06T03:41:36.424] sched: _slurm_rpc_allocate_resources JobId=43032 NodeList=cpu11 usec=1119
[2022-06-06T03:42:25.054] sched: Allocate JobId=43033 NodeList=gpu05 #CPUs=8 Partition=gpu-v100s
[2022-06-06T03:43:24.071] sched: _slurm_rpc_allocate_resources JobId=43034 NodeList=cpu11 usec=1032
[2022-06-06T03:49:08.759] sched: Allocate JobId=43035 NodeList=gpu05 #CPUs=8 Partition=gpu-v100s
[2022-06-06T03:49:36.800] sched: Allocate JobId=43036 NodeList=gpu05 #CPUs=8 Partition=gpu-v100s
[2022-06-06T05:03:38.025] sched: Allocate JobId=43037 NodeList=cpu13 #CPUs=32 Partition=cpu-epyc
[2022-06-06T05:07:19.333] sched: Allocate JobId=43038 NodeList=cpu13 #CPUs=32 Partition=cpu-epyc
[2022-06-06T05:08:48.588] sched: Allocate JobId=43039 NodeList=cpu13 #CPUs=32 Partition=cpu-epyc
[2022-06-06T05:10:43.754] sched: Allocate JobId=43040 NodeList=cpu13 #CPUs=32 Partition=cpu-epyc
[2022-06-06T05:13:15.117] sched: Allocate JobId=43041 NodeList=cpu13 #CPUs=32 Partition=cpu-epyc
[2022-06-06T05:14:57.272] sched: Allocate JobId=43042 NodeList=cpu13 #CPUs=32 Partition=cpu-epyc
[2022-06-06T05:26:22.552] sched: Allocate JobId=43043 NodeList=cpu13 #CPUs=32 Partition=cpu-epyc
[2022-06-06T05:27:12.621] sched: Allocate JobId=43044 NodeList=cpu14 #CPUs=32 Partition=cpu-epyc
[2022-06-06T05:29:55.935] sched: Allocate JobId=43045 NodeList=cpu12 #CPUs=32 Partition=cpu-epyc
[2022-06-06T05:37:44.964] sched: Allocate JobId=43046 NodeList=cpu13 #CPUs=32 Partition=cpu-epyc
[2022-06-06T05:40:06.169] sched: Allocate JobId=43047 NodeList=cpu14 #CPUs=32 Partition=cpu-epyc
[2022-06-06T05:43:22.586] sched: Allocate JobId=43048 NodeList=cpu13 #CPUs=32 Partition=cpu-epyc
[2022-06-06T05:44:28.685] sched: Allocate JobId=43049 NodeList=cpu13 #CPUs=32 Partition=cpu-epyc
[2022-06-06T05:45:20.084] sched: _slurm_rpc_allocate_resources JobId=43050 NodeList=cpu11 usec=14419
[2022-06-06T05:47:41.150] sched: Allocate JobId=43051 NodeList=cpu13 #CPUs=32 Partition=cpu-epyc
[2022-06-06T05:50:09.375] sched: Allocate JobId=43052 NodeList=cpu14 #CPUs=32 Partition=cpu-epyc
[2022-06-06T05:55:25.936] sched: Allocate JobId=43053 NodeList=cpu13 #CPUs=32 Partition=cpu-epyc
[2022-06-06T05:57:18.103] sched: Allocate JobId=43054 NodeList=cpu13 #CPUs=32 Partition=cpu-epyc
[2022-06-06T05:58:12.269] sched: Allocate JobId=43055 NodeList=cpu15 #CPUs=32 Partition=cpu-epyc
[2022-06-06T06:05:44.126] sched: Allocate JobId=43056 NodeList=cpu13 #CPUs=32 Partition=cpu-epyc
[2022-06-06T06:08:47.486] sched: Allocate JobId=43057 NodeList=cpu13 #CPUs=32 Partition=cpu-epyc
[2022-06-06T06:11:14.696] sched: Allocate JobId=43058 NodeList=cpu13 #CPUs=32 Partition=cpu-epyc
[2022-06-06T06:14:17.575] sched: Allocate JobId=43059 NodeList=cpu13 #CPUs=32 Partition=cpu-epyc
[2022-06-06T06:21:42.920] sched: _slurm_rpc_allocate_resources JobId=43060 NodeList=cpu11 usec=4534
[2022-06-06T06:36:16.119] sched: Allocate JobId=43061 NodeList=gpu02 #CPUs=8 Partition=gpu-titan
[2022-06-06T06:40:01.450] sched: _slurm_rpc_allocate_resources JobId=43063 NodeList=cpu11 usec=1287
[2022-06-06T08:03:55.034] sched: Allocate JobId=43062 NodeList=gpu02 #CPUs=8 Partition=gpu-titan
[2022-06-06T10:02:02.270] sched: _slurm_rpc_allocate_resources JobId=43064 NodeList=cpu11 usec=16444
[2022-06-06T10:06:44.775] sched: Allocate JobId=43065 NodeList=cpu11 #CPUs=1 Partition=cpu-opteron
[2022-06-06T10:07:54.012] sched: Allocate JobId=43066 NodeList=cpu11 #CPUs=1 Partition=cpu-opteron
[2022-06-06T10:08:50.097] sched: Allocate JobId=43067 NodeList=cpu11 #CPUs=1 Partition=cpu-opteron
[2022-06-06T10:11:57.372] sched: Allocate JobId=43068 NodeList=cpu11 #CPUs=1 Partition=cpu-opteron
[2022-06-06T10:13:37.822] sched: Allocate JobId=43069 NodeList=cpu11 #CPUs=4 Partition=cpu-opteron
[2022-06-06T10:14:35.903] sched: Allocate JobId=43070 NodeList=cpu11 #CPUs=4 Partition=cpu-opteron
[2022-06-06T10:32:20.324] sched: Allocate JobId=43071 NodeList=cpu11 #CPUs=8 Partition=cpu-opteron
[2022-06-06T10:34:02.508] sched: Allocate JobId=43072 NodeList=cpu12 #CPUs=8 Partition=cpu-epyc
[2022-06-06T10:35:32.516] sched/backfill: _start_job: Started JobId=43073 in cpu-opteron on cpu01
[2022-06-06T10:46:46.851] sched: Allocate JobId=43074 NodeList=cpu01 #CPUs=32 Partition=cpu-opteron
[2022-06-06T10:54:44.724] sched: Allocate JobId=43075 NodeList=cpu01 #CPUs=32 Partition=cpu-opteron
[2022-06-06T10:55:15.768] sched: Allocate JobId=43076 NodeList=cpu03 #CPUs=32 Partition=cpu-opteron
[2022-06-06T10:56:54.915] sched: Allocate JobId=43077 NodeList=cpu01 #CPUs=32 Partition=cpu-opteron
[2022-06-06T10:57:48.100] sched: Allocate JobId=43078 NodeList=cpu01 #CPUs=32 Partition=cpu-opteron
[2022-06-06T13:58:54.297] sched: Allocate JobId=43080 NodeList=cpu13 #CPUs=48 Partition=cpu-epyc
[2022-06-06T14:06:27.043] sched: Allocate JobId=43081 NodeList=cpu13 #CPUs=48 Partition=cpu-epyc
[2022-06-06T14:06:54.082] sched: Allocate JobId=43082 NodeList=cpu14 #CPUs=48 Partition=cpu-epyc
[2022-06-06T14:08:15.292] sched: Allocate JobId=43083 NodeList=cpu13 #CPUs=48 Partition=cpu-epyc
[2022-06-06T14:20:01.602] sched: Allocate JobId=43084 NodeList=cpu15 #CPUs=48 Partition=cpu-epyc
[2022-06-06T14:41:56.020] sched: Allocate JobId=43085 NodeList=cpu01 #CPUs=32 Partition=cpu-opteron
[2022-06-06T14:58:14.909] sched: Allocate JobId=43087 NodeList=cpu13 #CPUs=64 Partition=cpu-epyc
[2022-06-06T14:59:57.057] sched: Allocate JobId=43088 NodeList=cpu15 #CPUs=64 Partition=cpu-epyc
[2022-06-06T15:02:40.406] sched: Allocate JobId=43089 NodeList=cpu03 #CPUs=64 Partition=cpu-opteron
[2022-06-06T15:23:09.733] sched: Allocate JobId=43090 NodeList=cpu04 #CPUs=32 Partition=cpu-opteron
[2022-06-06T15:25:14.898] sched: Allocate JobId=43092 NodeList=cpu05 #CPUs=32 Partition=cpu-opteron
[2022-06-06T15:27:33.189] sched: Allocate JobId=43094 NodeList=cpu07 #CPUs=32 Partition=cpu-opteron
[2022-06-06T15:29:40.377] sched: Allocate JobId=43096 NodeList=cpu08 #CPUs=32 Partition=cpu-opteron
[2022-06-06T15:53:59.173] sched: Allocate JobId=43098 NodeList=gpu02 #CPUs=8 Partition=gpu-titan
[2022-06-06T15:54:03.159] sched: Allocate JobId=43099 NodeList=gpu02 #CPUs=8 Partition=gpu-titan
[2022-06-06T16:03:51.332] sched: Allocate JobId=43100 NodeList=cpu11 #CPUs=4 Partition=cpu-opteron
[2022-06-06T16:04:27.381] sched: Allocate JobId=43101 NodeList=cpu11 #CPUs=4 Partition=cpu-opteron
[2022-06-06T16:10:15.024] sched: Allocate JobId=43102 NodeList=cpu11 #CPUs=16 Partition=cpu-opteron
[2022-06-06T16:11:35.143] sched: Allocate JobId=43103 NodeList=gpu04 #CPUs=1 Partition=gpu-k40c
[2022-06-06T16:12:45.392] sched: Allocate JobId=43104 NodeList=cpu11 #CPUs=4 Partition=cpu-opteron
[2022-06-06T16:14:46.567] sched: Allocate JobId=43105 NodeList=cpu11 #CPUs=4 Partition=cpu-opteron
[2022-06-06T16:24:50.838] sched: Allocate JobId=43108 NodeList=gpu02 #CPUs=10 Partition=gpu-titan
[2022-06-06T16:24:53.916] sched: Allocate JobId=43106 NodeList=gpu02 #CPUs=8 Partition=gpu-titan
[2022-06-06T16:27:30.173] sched: Allocate JobId=43109 NodeList=gpu02 #CPUs=8 Partition=gpu-titan
[2022-06-06T17:41:26.617] sched: Allocate JobId=43110 NodeList=cpu01 #CPUs=4 Partition=cpu-opteron
[2022-06-06T17:42:17.669] sched: Allocate JobId=43111 NodeList=cpu01 #CPUs=16 Partition=cpu-opteron
[2022-06-06T17:43:51.896] sched: Allocate JobId=43112 NodeList=gpu04 #CPUs=1 Partition=gpu-k40c
[2022-06-06T17:44:41.971] sched: Allocate JobId=43113 NodeList=cpu01 #CPUs=4 Partition=cpu-opteron
[2022-06-06T17:45:48.067] sched: Allocate JobId=43114 NodeList=cpu01 #CPUs=16 Partition=cpu-opteron
[2022-06-06T19:00:39.392] sched: Allocate JobId=43116 NodeList=cpu01 #CPUs=32 Partition=cpu-opteron
[2022-06-06T19:01:52.477] sched: Allocate JobId=43117 NodeList=cpu11 #CPUs=32 Partition=cpu-opteron
[2022-06-06T19:02:56.693] sched: Allocate JobId=43118 NodeList=cpu04 #CPUs=32 Partition=cpu-opteron
[2022-06-06T19:09:51.391] sched: Allocate JobId=43119 NodeList=cpu04 #CPUs=32 Partition=cpu-opteron
[2022-06-06T19:11:09.504] sched: Allocate JobId=43120 NodeList=cpu04 #CPUs=32 Partition=cpu-opteron
[2022-06-06T19:11:34.538] sched: Allocate JobId=43121 NodeList=cpu04 #CPUs=32 Partition=cpu-opteron
[2022-06-06T19:12:11.591] sched: Allocate JobId=43122 NodeList=cpu04 #CPUs=32 Partition=cpu-opteron
[2022-06-06T19:14:14.867] sched: Allocate JobId=43123 NodeList=cpu04 #CPUs=32 Partition=cpu-opteron
[2022-06-06T19:23:00.837] sched: Allocate JobId=43124 NodeList=cpu04 #CPUs=32 Partition=cpu-opteron
[2022-06-06T21:59:56.475] sched: Allocate JobId=43115 NodeList=gpu02 #CPUs=10 Partition=gpu-titan
[2022-06-06T22:46:16.289] sched: Allocate JobId=43125 NodeList=cpu14 #CPUs=64 Partition=cpu-epyc
[2022-06-07T01:19:10.136] sched: Allocate JobId=43126 NodeList=gpu02 #CPUs=8 Partition=gpu-titan
[2022-06-07T01:21:32.810] sched/backfill: _start_job: Started JobId=43128 in cpu-opteron on cpu01
[2022-06-07T01:27:13.939] sched: Allocate JobId=43129 NodeList=cpu01 #CPUs=16 Partition=cpu-opteron
[2022-06-07T01:28:43.143] sched: Allocate JobId=43130 NodeList=gpu04 #CPUs=1 Partition=gpu-k40c
[2022-06-07T01:29:18.193] sched: Allocate JobId=43131 NodeList=cpu01 #CPUs=4 Partition=cpu-opteron
[2022-06-07T01:31:12.359] sched: Allocate JobId=43132 NodeList=cpu01 #CPUs=4 Partition=cpu-opteron
[2022-06-07T01:35:43.887] sched: Allocate JobId=43134 NodeList=gpu03 #CPUs=16 Partition=gpu-k10
[2022-06-07T01:37:20.101] sched: Allocate JobId=43135 NodeList=cpu01 #CPUs=32 Partition=cpu-opteron
[2022-06-07T01:38:51.277] sched: Allocate JobId=43136 NodeList=cpu11 #CPUs=32 Partition=cpu-opteron
[2022-06-07T01:40:09.390] sched: Allocate JobId=43137 NodeList=cpu04 #CPUs=32 Partition=cpu-opteron
[2022-06-07T07:58:48.392] sched: Allocate JobId=43133 NodeList=gpu02 #CPUs=10 Partition=gpu-titan
[2022-06-07T09:38:32.215] sched: Allocate JobId=43138 NodeList=cpu13 #CPUs=16 Partition=cpu-epyc
[2022-06-07T09:39:13.251] sched: Allocate JobId=43139 NodeList=cpu13 #CPUs=16 Partition=cpu-epyc
[2022-06-07T09:39:43.314] sched: Allocate JobId=43140 NodeList=cpu04 #CPUs=64 Partition=cpu-opteron
[2022-06-07T09:40:09.285] sched: Allocate JobId=43079 NodeList=gpu05 #CPUs=32 Partition=gpu-v100s
[2022-06-07T09:41:37.458] sched: Allocate JobId=43143 NodeList=cpu12 #CPUs=24 Partition=cpu-epyc
[2022-06-07T09:42:16.514] sched: Allocate JobId=43144 NodeList=cpu13 #CPUs=16 Partition=cpu-epyc
[2022-06-07T09:42:48.700] sched: Allocate JobId=43145 NodeList=cpu01 #CPUs=16 Partition=cpu-opteron
[2022-06-07T09:44:27.842] sched: Allocate JobId=43146 NodeList=cpu13 #CPUs=16 Partition=cpu-epyc
[2022-06-07T09:48:28.286] sched: Allocate JobId=43147 NodeList=cpu13 #CPUs=16 Partition=cpu-epyc
[2022-06-07T09:49:05.390] sched: Allocate JobId=43148 NodeList=cpu13 #CPUs=16 Partition=cpu-epyc
[2022-06-07T09:50:26.458] sched: Allocate JobId=43149 NodeList=cpu13 #CPUs=16 Partition=cpu-epyc
[2022-06-07T09:52:51.742] sched: Allocate JobId=43150 NodeList=cpu01 #CPUs=1 Partition=cpu-opteron
[2022-06-07T09:53:23.788] sched: Allocate JobId=43151 NodeList=cpu13 #CPUs=16 Partition=cpu-epyc
[2022-06-07T10:05:53.229] sched: Allocate JobId=43152 NodeList=cpu13 #CPUs=16 Partition=cpu-epyc
[2022-06-07T10:06:08.072] sched: Allocate JobId=43107 NodeList=gpu05 #CPUs=32 Partition=gpu-v100s
[2022-06-07T10:08:32.615] sched: Allocate JobId=43153 NodeList=cpu13 #CPUs=16 Partition=cpu-epyc
[2022-06-07T10:19:18.823] sched: Allocate JobId=43154 NodeList=gpu04 #CPUs=16 Partition=gpu-k40c
[2022-06-07T10:27:04.620] sched: Allocate JobId=43155 NodeList=gpu01 #CPUs=32 Partition=gpu-k10
[2022-06-07T10:33:18.467] sched: Allocate JobId=43156 NodeList=gpu01 #CPUs=32 Partition=gpu-k10
[2022-06-07T10:38:59.550] sched: Allocate JobId=43157 NodeList=gpu01 #CPUs=32 Partition=gpu-k10
[2022-06-07T11:20:29.791] sched: Allocate JobId=43159 NodeList=gpu01 #CPUs=32 Partition=gpu-k10
[2022-06-07T11:29:40.146] sched: Allocate JobId=43160 NodeList=gpu01 #CPUs=32 Partition=gpu-k10
[2022-06-07T11:36:32.617] sched: Allocate JobId=43161 NodeList=gpu01 #CPUs=32 Partition=gpu-k10
[2022-06-07T12:08:00.187] sched: Allocate JobId=43164 NodeList=gpu01 #CPUs=32 Partition=gpu-k10
[2022-06-07T12:08:55.266] sched: Allocate JobId=43165 NodeList=gpu01 #CPUs=32 Partition=gpu-k10
[2022-06-07T12:09:52.348] sched: Allocate JobId=43166 NodeList=gpu01 #CPUs=32 Partition=gpu-k10
[2022-06-07T12:10:58.448] sched: Allocate JobId=43167 NodeList=gpu01 #CPUs=32 Partition=gpu-k10
[2022-06-07T12:14:26.839] sched: Allocate JobId=43168 NodeList=gpu01 #CPUs=32 Partition=gpu-k10
[2022-06-07T12:15:47.975] sched: Allocate JobId=43169 NodeList=cpu12 #CPUs=24 Partition=cpu-epyc
[2022-06-07T12:22:59.823] sched: Allocate JobId=43170 NodeList=gpu01 #CPUs=32 Partition=gpu-k10
[2022-06-07T12:28:31.450] sched: Allocate JobId=43171 NodeList=cpu12 #CPUs=24 Partition=cpu-epyc
[2022-06-07T12:30:01.575] sched: Allocate JobId=43172 NodeList=gpu01 #CPUs=32 Partition=gpu-k10
[2022-06-07T12:37:33.472] sched: Allocate JobId=43173 NodeList=cpu12 #CPUs=24 Partition=cpu-epyc
[2022-06-07T12:45:34.061] sched/backfill: _start_job: Started JobId=43174 in cpu-opteron on cpu01
[2022-06-07T12:49:03.539] sched: Allocate JobId=43175 NodeList=cpu01 #CPUs=8 Partition=cpu-opteron
[2022-06-07T12:50:36.677] sched: Allocate JobId=43176 NodeList=cpu01 #CPUs=8 Partition=cpu-opteron
[2022-06-07T12:52:00.798] sched: Allocate JobId=43177 NodeList=cpu01 #CPUs=8 Partition=cpu-opteron
[2022-06-07T12:53:56.082] sched: Allocate JobId=43178 NodeList=cpu01 #CPUs=8 Partition=cpu-opteron
[2022-06-07T12:57:25.431] sched: Allocate JobId=43179 NodeList=cpu01 #CPUs=8 Partition=cpu-opteron
[2022-06-07T13:00:08.705] sched: Allocate JobId=43180 NodeList=cpu01 #CPUs=8 Partition=cpu-opteron
[2022-06-07T13:00:46.766] sched: Allocate JobId=43181 NodeList=cpu13 #CPUs=32 Partition=cpu-epyc
[2022-06-07T13:01:14.803] sched: Allocate JobId=43182 NodeList=cpu14 #CPUs=32 Partition=cpu-epyc
[2022-06-07T13:01:33.830] sched: Allocate JobId=43183 NodeList=cpu15 #CPUs=32 Partition=cpu-epyc
[2022-06-07T13:02:37.028] sched: Allocate JobId=43185 NodeList=cpu01 #CPUs=8 Partition=cpu-opteron
[2022-06-07T13:27:57.404] sched: Allocate JobId=43184 NodeList=cpu14 #CPUs=32 Partition=cpu-epyc
[2022-06-07T13:58:21.703] sched: _slurm_rpc_allocate_resources JobId=43186 NodeList=cpu13 usec=4682
[2022-06-07T13:58:32.030] sched: _slurm_rpc_allocate_resources JobId=43187 NodeList=cpu13 usec=980
[2022-06-07T14:02:47.803] sched: Allocate JobId=43188 NodeList=cpu01 #CPUs=8 Partition=cpu-opteron
[2022-06-07T14:24:28.206] sched: Allocate JobId=43192 NodeList=cpu01 #CPUs=32 Partition=cpu-opteron
[2022-06-07T14:24:58.236] sched: Allocate JobId=43193 NodeList=cpu01 #CPUs=32 Partition=cpu-opteron
[2022-06-07T14:25:22.272] sched: Allocate JobId=43194 NodeList=cpu01 #CPUs=32 Partition=cpu-opteron
[2022-06-07T14:25:59.325] sched: Allocate JobId=43195 NodeList=cpu01 #CPUs=32 Partition=cpu-opteron
[2022-06-07T14:26:50.907] sched: Allocate JobId=43191 NodeList=gpu01 #CPUs=16 Partition=gpu-k10
[2022-06-07T14:27:25.570] sched: Allocate JobId=43196 NodeList=cpu01 #CPUs=32 Partition=cpu-opteron
[2022-06-07T14:27:39.630] sched: Allocate JobId=43197 NodeList=cpu01 #CPUs=32 Partition=cpu-opteron
[2022-06-07T14:30:25.876] sched: Allocate JobId=43198 NodeList=cpu01 #CPUs=32 Partition=cpu-opteron
[2022-06-07T14:35:29.443] sched: Allocate JobId=43199 NodeList=cpu01 #CPUs=32 Partition=cpu-opteron
[2022-06-07T14:35:57.481] sched: Allocate JobId=43200 NodeList=cpu11 #CPUs=32 Partition=cpu-opteron
[2022-06-07T14:38:05.772] sched: Allocate JobId=43201 NodeList=cpu01 #CPUs=32 Partition=cpu-opteron
[2022-06-07T15:02:18.431] sched: Allocate JobId=43202 NodeList=cpu13 #CPUs=64 Partition=cpu-epyc
[2022-06-07T15:53:23.190] sched: Allocate JobId=43203 NodeList=cpu15 #CPUs=64 Partition=cpu-epyc
[2022-06-07T16:01:54.044] sched: Allocate JobId=43204 NodeList=cpu12 #CPUs=32 Partition=cpu-epyc
[2022-06-07T16:03:05.262] sched: Allocate JobId=43205 NodeList=cpu11 #CPUs=32 Partition=cpu-opteron
[2022-06-07T16:04:03.349] sched: Allocate JobId=43206 NodeList=cpu14 #CPUs=32 Partition=cpu-epyc
[2022-06-07T16:04:54.424] sched: Allocate JobId=43207 NodeList=cpu15 #CPUs=32 Partition=cpu-epyc
[2022-06-07T16:50:17.470] sched: Allocate JobId=43209 NodeList=cpu03 #CPUs=64 Partition=cpu-opteron
[2022-06-07T18:21:32.378] sched: _slurm_rpc_allocate_resources JobId=43210 NodeList=cpu01 usec=15013
[2022-06-07T18:22:05.074] sched: _slurm_rpc_allocate_resources JobId=43211 NodeList=cpu01 usec=1336
[2022-06-07T20:57:25.510] sched: Allocate JobId=43212 NodeList=cpu01 #CPUs=8 Partition=cpu-opteron
[2022-06-07T21:08:22.762] sched: Allocate JobId=43213 NodeList=cpu01 #CPUs=8 Partition=cpu-opteron
[2022-06-07T21:36:41.893] sched: Allocate JobId=43214 NodeList=cpu01 #CPUs=8 Partition=cpu-opteron
[2022-06-07T21:57:43.395] sched: Allocate JobId=43216 NodeList=cpu13 #CPUs=16 Partition=cpu-epyc
[2022-06-07T23:30:51.807] sched: Allocate JobId=43217 NodeList=cpu01 #CPUs=32 Partition=cpu-opteron
[2022-06-07T23:41:31.000] sched: Allocate JobId=43218 NodeList=cpu13 #CPUs=32 Partition=cpu-epyc
[2022-06-08T00:04:14.097] sched: Allocate JobId=43219 NodeList=cpu01 #CPUs=12 Partition=cpu-opteron
[2022-06-08T00:11:35.824] sched: Allocate JobId=43220 NodeList=cpu01 #CPUs=12 Partition=cpu-opteron
[2022-06-08T00:30:27.933] sched: Allocate JobId=43221 NodeList=cpu04 #CPUs=64 Partition=cpu-opteron
[2022-06-08T00:52:24.189] sched: _slurm_rpc_allocate_resources JobId=43222 NodeList=cpu01 usec=4719
[2022-06-08T01:39:52.365] sched: Allocate JobId=43223 NodeList=cpu01 #CPUs=12 Partition=cpu-opteron
[2022-06-08T01:55:28.042] sched: Allocate JobId=43224 NodeList=gpu04 #CPUs=8 Partition=gpu-k40c
[2022-06-08T01:59:40.465] sched: Allocate JobId=43225 NodeList=cpu01 #CPUs=12 Partition=cpu-opteron
[2022-06-08T09:23:25.405] sched: Allocate JobId=43226 NodeList=cpu13 #CPUs=32 Partition=cpu-epyc
[2022-06-08T10:10:47.735] sched: Allocate JobId=43230 NodeList=cpu14 #CPUs=64 Partition=cpu-epyc
[2022-06-08T10:22:54.297] sched: Allocate JobId=43231 NodeList=cpu05 #CPUs=64 Partition=cpu-opteron
[2022-06-08T10:29:05.921] sched: Allocate JobId=43232 NodeList=cpu07 #CPUs=64 Partition=cpu-opteron
[2022-06-08T10:31:52.165] sched: Allocate JobId=43233 NodeList=cpu15 #CPUs=32 Partition=cpu-epyc
[2022-06-08T10:39:00.995] sched: Allocate JobId=43234 NodeList=cpu13 #CPUs=32 Partition=cpu-epyc
[2022-06-08T10:41:02.166] sched: Allocate JobId=43235 NodeList=cpu08 #CPUs=64 Partition=cpu-opteron
[2022-06-08T10:46:13.767] sched: Allocate JobId=43236 NodeList=cpu09 #CPUs=64 Partition=cpu-opteron
[2022-06-08T10:52:49.603] sched: Allocate JobId=43237 NodeList=cpu15 #CPUs=32 Partition=cpu-epyc
[2022-06-08T12:00:18.312] sched: Allocate JobId=43238 NodeList=gpu01 #CPUs=16 Partition=gpu-k10
[2022-06-08T13:02:06.991] sched: Allocate JobId=43240 NodeList=cpu01 #CPUs=1 Partition=cpu-opteron
[2022-06-08T13:03:44.231] sched: Allocate JobId=43241 NodeList=gpu01 #CPUs=16 Partition=gpu-k10
[2022-06-08T13:05:48.409] sched: Allocate JobId=43242 NodeList=gpu01 #CPUs=16 Partition=gpu-k10
[2022-06-08T13:12:09.159] sched: Allocate JobId=43244 NodeList=cpu01 #CPUs=16 Partition=cpu-opteron
[2022-06-08T13:59:51.652] sched: Allocate JobId=43245 NodeList=cpu01 #CPUs=16 Partition=cpu-opteron
[2022-06-08T14:02:01.807] sched: Allocate JobId=43246 NodeList=cpu01 #CPUs=16 Partition=cpu-opteron
[2022-06-08T14:53:38.736] sched: _slurm_rpc_allocate_resources JobId=43247 NodeList=cpu11 usec=14732
[2022-06-08T15:29:19.332] sched: Allocate JobId=43248 NodeList=cpu13 #CPUs=64 Partition=cpu-epyc
[2022-06-08T16:07:38.854] sched: Allocate JobId=43162 NodeList=gpu05 #CPUs=32 Partition=gpu-v100s
[2022-06-08T17:00:14.487] sched: Allocate JobId=43250 NodeList=cpu03 #CPUs=64 Partition=cpu-opteron
[2022-06-08T17:27:44.571] sched: Allocate JobId=43251 NodeList=cpu01 #CPUs=16 Partition=cpu-opteron
[2022-06-08T17:28:00.581] sched: Allocate JobId=43252 NodeList=cpu11 #CPUs=16 Partition=cpu-opteron
[2022-06-08T18:30:10.196] sched: Allocate JobId=43229 NodeList=gpu05 #CPUs=1 Partition=gpu-v100s
[2022-06-08T19:45:06.986] sched: Allocate JobId=43253 NodeList=cpu01 #CPUs=4 Partition=cpu-opteron
[2022-06-08T22:41:20.502] sched: Allocate JobId=43254 NodeList=gpu01 #CPUs=32 Partition=gpu-k10
[2022-06-08T22:45:00.931] sched: Allocate JobId=43256 NodeList=gpu03 #CPUs=32 Partition=gpu-k10
[2022-06-09T00:33:20.246] sched: Allocate JobId=43257 NodeList=cpu01 #CPUs=8 Partition=cpu-opteron
[2022-06-09T00:35:21.418] sched: Allocate JobId=43258 NodeList=cpu12 #CPUs=32 Partition=cpu-epyc
[2022-06-09T00:51:22.141] sched: Allocate JobId=43091 NodeList=gpu05 #CPUs=32 Partition=gpu-v100s
[2022-06-09T00:52:55.394] sched: Allocate JobId=43259 NodeList=cpu01 #CPUs=16 Partition=cpu-opteron
[2022-06-09T00:53:13.421] sched: Allocate JobId=43260 NodeList=cpu01 #CPUs=16 Partition=cpu-opteron
[2022-06-09T00:59:51.126] sched: Allocate JobId=43261 NodeList=cpu14 #CPUs=32 Partition=cpu-epyc
[2022-06-09T08:59:28.435] sched: Allocate JobId=43262 NodeList=gpu04 #CPUs=16 Partition=gpu-k40c
[2022-06-09T10:26:22.434] sched: Allocate JobId=43263 NodeList=cpu01 #CPUs=4 Partition=cpu-opteron
[2022-06-09T11:09:01.336] sched: Allocate JobId=43264 NodeList=cpu04 #CPUs=64 Partition=cpu-opteron
[2022-06-09T11:32:07.892] sched: Allocate JobId=43265 NodeList=cpu13 #CPUs=32 Partition=cpu-epyc
[2022-06-09T11:36:16.407] sched: Allocate JobId=43266 NodeList=cpu15 #CPUs=48 Partition=cpu-epyc
[2022-06-09T11:48:32.975] sched: Allocate JobId=43268 NodeList=cpu15 #CPUs=24 Partition=cpu-epyc
[2022-06-09T11:57:06.799] sched: Allocate JobId=43269 NodeList=gpu01 #CPUs=16 Partition=gpu-k10
[2022-06-09T11:58:47.057] sched: Allocate JobId=43270 NodeList=gpu03 #CPUs=16 Partition=gpu-k10
[2022-06-09T12:05:59.820] sched: Allocate JobId=43271 NodeList=cpu14 #CPUs=32 Partition=cpu-epyc
[2022-06-09T12:08:00.086] sched: Allocate JobId=43272 NodeList=cpu01 #CPUs=32 Partition=cpu-opteron
[2022-06-09T12:09:46.234] sched: Allocate JobId=43273 NodeList=cpu07 #CPUs=64 Partition=cpu-opteron
[2022-06-09T12:57:25.611] sched: Allocate JobId=43276 NodeList=cpu01 #CPUs=16 Partition=cpu-opteron
[2022-06-09T13:28:48.831] sched: Allocate JobId=43278 NodeList=cpu01 #CPUs=32 Partition=cpu-opteron
[2022-06-09T13:32:34.983] sched/backfill: _start_job: Started JobId=43280 in cpu-opteron on cpu01
[2022-06-09T13:32:58.366] sched: Allocate JobId=43281 NodeList=cpu01 #CPUs=32 Partition=cpu-opteron
[2022-06-09T13:33:16.393] sched: Allocate JobId=43282 NodeList=cpu01 #CPUs=32 Partition=cpu-opteron
[2022-06-09T13:35:21.573] sched: Allocate JobId=43283 NodeList=cpu01 #CPUs=32 Partition=cpu-opteron
[2022-06-09T13:39:32.038] sched: Allocate JobId=43284 NodeList=cpu01 #CPUs=16 Partition=cpu-opteron
[2022-06-09T13:47:56.047] sched: Allocate JobId=43288 NodeList=cpu01 #CPUs=32 Partition=cpu-opteron
[2022-06-09T13:48:26.090] sched: Allocate JobId=43289 NodeList=cpu11 #CPUs=32 Partition=cpu-opteron
[2022-06-09T13:50:08.239] sched: Allocate JobId=43290 NodeList=cpu01 #CPUs=32 Partition=cpu-opteron
[2022-06-09T14:20:19.177] sched: _slurm_rpc_allocate_resources JobId=43291 NodeList=cpu12 usec=19391
[2022-06-09T14:29:43.150] sched: Allocate JobId=43274 NodeList=cpu05 #CPUs=32 Partition=cpu-opteron
[2022-06-09T15:40:17.861] sched: Allocate JobId=43295 NodeList=cpu01 #CPUs=16 Partition=cpu-opteron
[2022-06-09T15:41:49.992] sched: Allocate JobId=43296 NodeList=cpu01 #CPUs=4 Partition=cpu-opteron
[2022-06-09T15:48:08.800] sched: Allocate JobId=43297 NodeList=cpu14 #CPUs=32 Partition=cpu-epyc
[2022-06-09T15:49:36.928] sched: Allocate JobId=43299 NodeList=cpu14 #CPUs=32 Partition=cpu-epyc
[2022-06-09T15:51:51.129] sched: Allocate JobId=43300 NodeList=cpu14 #CPUs=32 Partition=cpu-epyc
[2022-06-09T15:54:18.511] sched: Allocate JobId=43301 NodeList=cpu13 #CPUs=64 Partition=cpu-epyc
[2022-06-09T16:00:08.103] sched: Allocate JobId=43303 NodeList=cpu12 #CPUs=56 Partition=cpu-epyc
[2022-06-09T17:06:20.441] sched: Allocate JobId=43305 NodeList=cpu13 #CPUs=64 Partition=cpu-epyc
[2022-06-09T17:21:35.394] sched: Allocate JobId=43307 NodeList=cpu03 #CPUs=32 Partition=cpu-opteron
[2022-06-09T18:11:25.977] sched: Allocate JobId=43308 NodeList=cpu07 #CPUs=64 Partition=cpu-opteron
[2022-06-09T18:19:12.625] sched: Allocate JobId=43306 NodeList=cpu13 #CPUs=32 Partition=cpu-epyc
[2022-06-09T18:24:49.500] sched: Allocate JobId=43309 NodeList=cpu08 #CPUs=64 Partition=cpu-opteron
[2022-06-09T18:27:58.919] sched: Allocate JobId=43310 NodeList=cpu14 #CPUs=32 Partition=cpu-epyc
[2022-06-09T19:07:18.507] sched: Allocate JobId=43311 NodeList=gpu05 #CPUs=32 Partition=gpu-v100s
[2022-06-09T19:12:49.188] sched: Allocate JobId=43312 NodeList=gpu05 #CPUs=32 Partition=gpu-v100s
[2022-06-09T19:15:37.431] sched: Allocate JobId=43313 NodeList=gpu05 #CPUs=32 Partition=gpu-v100s
[2022-06-09T19:17:56.781] sched: Allocate JobId=43314 NodeList=gpu05 #CPUs=32 Partition=gpu-v100s
[2022-06-09T20:13:06.724] sched: Allocate JobId=43127 NodeList=gpu02 #CPUs=8 Partition=gpu-titan
[2022-06-09T21:05:42.303] sched: Allocate JobId=43315 NodeList=gpu05 #CPUs=32 Partition=gpu-v100s
[2022-06-09T21:07:31.526] sched: Allocate JobId=43316 NodeList=gpu05 #CPUs=32 Partition=gpu-v100s
[2022-06-09T21:53:00.577] sched: Allocate JobId=43318 NodeList=cpu05 #CPUs=32 Partition=cpu-opteron
[2022-06-09T21:57:47.083] sched: Allocate JobId=43319 NodeList=cpu05 #CPUs=32 Partition=cpu-opteron
[2022-06-09T22:04:31.827] sched: Allocate JobId=43321 NodeList=cpu13 #CPUs=32 Partition=cpu-epyc
[2022-06-09T22:05:33.905] sched: Allocate JobId=43322 NodeList=cpu13 #CPUs=32 Partition=cpu-epyc
[2022-06-09T22:07:21.184] sched: Allocate JobId=43323 NodeList=cpu08 #CPUs=64 Partition=cpu-opteron
[2022-06-09T22:58:51.894] sched: Allocate JobId=43324 NodeList=cpu05 #CPUs=16 Partition=cpu-opteron
[2022-06-09T23:00:37.028] sched: Allocate JobId=43325 NodeList=cpu05 #CPUs=16 Partition=cpu-opteron
[2022-06-09T23:02:04.157] sched: Allocate JobId=43326 NodeList=cpu14 #CPUs=32 Partition=cpu-epyc
[2022-06-09T23:02:38.295] sched: Allocate JobId=43327 NodeList=cpu05 #CPUs=8 Partition=cpu-opteron
[2022-06-09T23:03:28.364] sched: Allocate JobId=43328 NodeList=cpu14 #CPUs=32 Partition=cpu-epyc
[2022-06-09T23:04:12.432] sched: Allocate JobId=43329 NodeList=cpu05 #CPUs=16 Partition=cpu-opteron
[2022-06-09T23:04:49.484] sched: Allocate JobId=43330 NodeList=cpu11 #CPUs=16 Partition=cpu-opteron
[2022-06-09T23:35:14.153] sched: Allocate JobId=43331 NodeList=gpu04 #CPUs=16 Partition=gpu-k40c
[2022-06-10T00:39:22.526] sched: Allocate JobId=43277 NodeList=gpu01 #CPUs=32 Partition=gpu-k10
[2022-06-10T01:06:40.488] sched: Allocate JobId=43332 NodeList=gpu05 #CPUs=32 Partition=gpu-v100s
[2022-06-10T01:07:48.746] sched: Allocate JobId=43333 NodeList=cpu05 #CPUs=4 Partition=cpu-opteron
[2022-06-10T01:08:27.779] sched: Allocate JobId=43334 NodeList=cpu05 #CPUs=16 Partition=cpu-opteron
[2022-06-10T01:10:54.982] sched: Allocate JobId=43335 NodeList=gpu04 #CPUs=1 Partition=gpu-k40c
[2022-06-10T01:12:55.257] sched: Allocate JobId=43336 NodeList=cpu05 #CPUs=4 Partition=cpu-opteron
[2022-06-10T01:14:35.403] sched: Allocate JobId=43337 NodeList=cpu05 #CPUs=4 Partition=cpu-opteron
[2022-06-10T01:15:04.445] sched: Allocate JobId=43338 NodeList=gpu02 #CPUs=10 Partition=gpu-titan
[2022-06-10T01:16:43.585] sched: Allocate JobId=43339 NodeList=cpu05 #CPUs=4 Partition=cpu-opteron
[2022-06-10T01:17:04.609] sched: Allocate JobId=43340 NodeList=cpu05 #CPUs=16 Partition=cpu-opteron
[2022-06-10T01:17:38.749] sched: Allocate JobId=43341 NodeList=gpu04 #CPUs=1 Partition=gpu-k40c
[2022-06-10T01:18:13.799] sched: Allocate JobId=43342 NodeList=cpu05 #CPUs=4 Partition=cpu-opteron
[2022-06-10T01:18:49.851] sched: Allocate JobId=43343 NodeList=cpu05 #CPUs=4 Partition=cpu-opteron
[2022-06-10T01:20:12.971] sched: Allocate JobId=43344 NodeList=cpu05 #CPUs=4 Partition=cpu-opteron
[2022-06-10T01:20:39.007] sched: Allocate JobId=43345 NodeList=gpu02 #CPUs=10 Partition=gpu-titan
[2022-06-10T01:22:17.148] sched: Allocate JobId=43346 NodeList=cpu12 #CPUs=32 Partition=cpu-epyc
[2022-06-10T01:23:23.319] sched: Allocate JobId=43347 NodeList=cpu05 #CPUs=8 Partition=cpu-opteron
[2022-06-10T01:25:02.462] sched: Allocate JobId=43348 NodeList=cpu12 #CPUs=32 Partition=cpu-epyc
[2022-06-10T01:26:07.556] sched: Allocate JobId=43349 NodeList=cpu12 #CPUs=32 Partition=cpu-epyc
[2022-06-10T01:41:21.229] sched: Allocate JobId=43353 NodeList=cpu01 #CPUs=32 Partition=cpu-opteron
[2022-06-10T01:42:31.500] sched: Allocate JobId=43354 NodeList=cpu01 #CPUs=32 Partition=cpu-opteron
[2022-06-10T09:31:13.637] sched: Allocate JobId=43356 NodeList=gpu05 #CPUs=16 Partition=gpu-v100s
[2022-06-10T09:36:52.770] sched: Allocate JobId=43357 NodeList=gpu05 #CPUs=16 Partition=gpu-v100s
[2022-06-10T09:52:25.556] sched: Allocate JobId=43093 NodeList=gpu05 #CPUs=32 Partition=gpu-v100s
[2022-06-10T10:15:03.466] sched: Allocate JobId=43358 NodeList=cpu15 #CPUs=64 Partition=cpu-epyc
[2022-06-10T10:19:27.928] sched: Allocate JobId=43359 NodeList=cpu11 #CPUs=1 Partition=cpu-opteron
[2022-06-10T10:33:13.466] sched: Allocate JobId=43360 NodeList=cpu11 #CPUs=16 Partition=cpu-opteron
[2022-06-10T10:37:04.790] sched: Allocate JobId=43361 NodeList=gpu05 #CPUs=30 Partition=gpu-v100s
[2022-06-10T10:55:53.888] sched: Allocate JobId=43362 NodeList=gpu01 #CPUs=16 Partition=gpu-k10
[2022-06-10T10:58:31.181] sched: Allocate JobId=43363 NodeList=gpu01 #CPUs=16 Partition=gpu-k10
[2022-06-10T10:58:47.202] sched: Allocate JobId=43364 NodeList=gpu01 #CPUs=16 Partition=gpu-k10
[2022-06-10T10:59:12.241] sched: Allocate JobId=43365 NodeList=cpu01 #CPUs=16 Partition=cpu-opteron
[2022-06-10T11:17:32.344] sched: Allocate JobId=43366 NodeList=gpu01 #CPUs=16 Partition=gpu-k10
[2022-06-10T11:47:53.695] sched: Allocate JobId=43367 NodeList=gpu01 #CPUs=4 Partition=gpu-k10
[2022-06-10T12:50:10.700] sched: Allocate JobId=43369 NodeList=cpu14 #CPUs=32 Partition=cpu-epyc
[2022-06-10T12:51:06.768] sched: Allocate JobId=43370 NodeList=cpu13 #CPUs=64 Partition=cpu-epyc
[2022-06-10T12:52:25.983] sched: Allocate JobId=43371 NodeList=cpu15 #CPUs=32 Partition=cpu-epyc
[2022-06-10T13:00:22.835] sched: Allocate JobId=43372 NodeList=cpu01 #CPUs=16 Partition=cpu-opteron
[2022-06-10T13:15:12.474] sched: Allocate JobId=43373 NodeList=cpu04 #CPUs=64 Partition=cpu-opteron
[2022-06-10T13:19:11.952] sched: Allocate JobId=43374 NodeList=cpu12 #CPUs=40 Partition=cpu-epyc
[2022-06-10T14:27:05.174] sched: Allocate JobId=43375 NodeList=cpu01 #CPUs=16 Partition=cpu-opteron
[2022-06-10T14:29:39.551] sched: Allocate JobId=43376 NodeList=gpu01 #CPUs=16 Partition=gpu-k10
[2022-06-10T14:30:08.604] sched: Allocate JobId=43377 NodeList=cpu05 #CPUs=16 Partition=cpu-opteron
[2022-06-10T14:30:13.599] sched: Allocate JobId=43378 NodeList=cpu11 #CPUs=16 Partition=cpu-opteron
[2022-06-10T14:30:18.606] sched: Allocate JobId=43379 NodeList=cpu11 #CPUs=16 Partition=cpu-opteron
[2022-06-10T14:30:22.612] sched: Allocate JobId=43380 NodeList=cpu01 #CPUs=16 Partition=cpu-opteron
[2022-06-10T14:30:29.622] sched: Allocate JobId=43381 NodeList=cpu01 #CPUs=16 Partition=cpu-opteron
[2022-06-10T14:30:33.628] sched: Allocate JobId=43382 NodeList=cpu03 #CPUs=16 Partition=cpu-opteron
[2022-06-10T14:30:38.635] sched: Allocate JobId=43383 NodeList=cpu09 #CPUs=16 Partition=cpu-opteron
[2022-06-10T14:30:42.641] sched: Allocate JobId=43384 NodeList=cpu09 #CPUs=16 Partition=cpu-opteron
[2022-06-10T14:30:48.650] sched: Allocate JobId=43385 NodeList=cpu09 #CPUs=16 Partition=cpu-opteron
[2022-06-10T14:30:53.657] sched: Allocate JobId=43386 NodeList=cpu09 #CPUs=16 Partition=cpu-opteron
[2022-06-10T16:19:28.489] sched: Allocate JobId=43395 NodeList=gpu01 #CPUs=16 Partition=gpu-k10
[2022-06-10T16:20:30.562] sched: Allocate JobId=43396 NodeList=gpu03 #CPUs=16 Partition=gpu-k10
[2022-06-10T16:28:34.324] sched: Allocate JobId=43397 NodeList=gpu04 #CPUs=8 Partition=gpu-k40c
[2022-06-10T19:20:51.628] sched: Allocate JobId=43400 NodeList=gpu02 #CPUs=12 Partition=gpu-titan
[2022-06-10T19:23:38.993] sched: Allocate JobId=43401 NodeList=gpu02 #CPUs=12 Partition=gpu-titan
[2022-06-10T19:48:37.809] sched: Allocate JobId=43402 NodeList=gpu02 #CPUs=12 Partition=gpu-titan
[2022-06-10T19:51:13.029] sched: Allocate JobId=43403 NodeList=gpu02 #CPUs=12 Partition=gpu-titan
[2022-06-10T20:09:58.244] sched: Allocate JobId=43404 NodeList=gpu02 #CPUs=12 Partition=gpu-titan
[2022-06-10T20:10:28.806] sched: Allocate JobId=43405 NodeList=gpu02 #CPUs=12 Partition=gpu-titan
[2022-06-10T20:47:23.419] sched: Allocate JobId=43406 NodeList=gpu02 #CPUs=12 Partition=gpu-titan
[2022-06-10T21:11:49.047] sched: Allocate JobId=43408 NodeList=cpu12 #CPUs=56 Partition=cpu-epyc
[2022-06-10T21:14:53.387] sched: Allocate JobId=43409 NodeList=cpu12 #CPUs=56 Partition=cpu-epyc
[2022-06-10T21:29:59.208] sched: Allocate JobId=43410 NodeList=cpu12 #CPUs=48 Partition=cpu-epyc
[2022-06-10T22:58:57.971] sched: Allocate JobId=43387 NodeList=cpu09 #CPUs=16 Partition=cpu-opteron
[2022-06-10T23:01:25.294] sched: Allocate JobId=43388 NodeList=cpu09 #CPUs=16 Partition=cpu-opteron
[2022-06-10T23:07:21.159] sched: Allocate JobId=43389 NodeList=cpu11 #CPUs=16 Partition=cpu-opteron
[2022-06-10T23:12:19.744] sched: Allocate JobId=43390 NodeList=cpu09 #CPUs=16 Partition=cpu-opteron
[2022-06-10T23:18:42.970] sched: Allocate JobId=43391 NodeList=cpu01 #CPUs=16 Partition=cpu-opteron
[2022-06-10T23:30:49.688] sched: Allocate JobId=43411 NodeList=cpu15 #CPUs=64 Partition=cpu-epyc
[2022-06-11T00:43:00.710] sched: Allocate JobId=43412 NodeList=cpu13 #CPUs=32 Partition=cpu-epyc
[2022-06-11T00:46:21.986] sched: Allocate JobId=43413 NodeList=cpu13 #CPUs=32 Partition=cpu-epyc
[2022-06-11T00:48:10.251] sched: Allocate JobId=43414 NodeList=cpu15 #CPUs=32 Partition=cpu-epyc
[2022-06-11T00:57:25.282] sched: Allocate JobId=43415 NodeList=cpu13 #CPUs=32 Partition=cpu-epyc
[2022-06-11T00:59:07.232] sched: Allocate JobId=43407 NodeList=gpu02 #CPUs=12 Partition=gpu-titan
[2022-06-11T01:01:12.637] sched: Allocate JobId=43416 NodeList=cpu13 #CPUs=32 Partition=cpu-epyc
[2022-06-11T01:02:44.146] sched: Allocate JobId=43417 NodeList=cpu13 #CPUs=32 Partition=cpu-epyc
[2022-06-11T01:04:55.315] sched: Allocate JobId=43418 NodeList=cpu13 #CPUs=32 Partition=cpu-epyc
[2022-06-11T01:09:34.174] sched: Allocate JobId=43419 NodeList=cpu13 #CPUs=32 Partition=cpu-epyc
[2022-06-11T01:11:20.319] sched: Allocate JobId=43420 NodeList=cpu15 #CPUs=32 Partition=cpu-epyc
[2022-06-11T01:16:14.275] sched: Allocate JobId=43421 NodeList=cpu13 #CPUs=32 Partition=cpu-epyc
[2022-06-11T01:18:11.483] sched: Allocate JobId=43095 NodeList=gpu05 #CPUs=32 Partition=gpu-v100s
[2022-06-11T01:20:00.478] sched: Allocate JobId=43097 NodeList=gpu05 #CPUs=32 Partition=gpu-v100s
[2022-06-11T01:20:31.012] sched: Allocate JobId=43422 NodeList=gpu05 #CPUs=32 Partition=gpu-v100s
[2022-06-11T01:25:40.845] sched: Allocate JobId=43426 NodeList=cpu13 #CPUs=32 Partition=cpu-epyc
[2022-06-11T01:32:39.727] sched: Allocate JobId=43427 NodeList=gpu02 #CPUs=6 Partition=gpu-titan
[2022-06-11T10:08:11.269] sched: Allocate JobId=43429 NodeList=gpu02 #CPUs=12 Partition=gpu-titan
[2022-06-11T11:09:19.984] sched: Allocate JobId=43431 NodeList=cpu13 #CPUs=32 Partition=cpu-epyc
[2022-06-11T11:09:26.972] sched: Allocate JobId=43432 NodeList=cpu15 #CPUs=32 Partition=cpu-epyc
[2022-06-11T11:09:35.985] sched: Allocate JobId=43433 NodeList=cpu15 #CPUs=32 Partition=cpu-epyc
[2022-06-11T11:09:43.997] sched: Allocate JobId=43434 NodeList=cpu09 #CPUs=48 Partition=cpu-opteron
[2022-06-11T11:09:52.009] sched: Allocate JobId=43435 NodeList=cpu08 #CPUs=64 Partition=cpu-opteron
[2022-06-11T11:26:15.759] sched: Allocate JobId=43436 NodeList=cpu11 #CPUs=32 Partition=cpu-opteron
[2022-06-11T13:15:33.765] sched: Allocate JobId=43437 NodeList=cpu04 #CPUs=32 Partition=cpu-opteron
[2022-06-11T13:38:01.187] sched: Allocate JobId=43440 NodeList=cpu14 #CPUs=32 Partition=cpu-epyc
[2022-06-11T13:40:31.165] sched: Allocate JobId=43394 NodeList=cpu13 #CPUs=48 Partition=cpu-epyc
[2022-06-11T13:42:53.725] sched: Allocate JobId=43441 NodeList=cpu12 #CPUs=32 Partition=cpu-epyc
[2022-06-11T13:43:28.535] sched: Allocate JobId=43398 NodeList=cpu15 #CPUs=48 Partition=cpu-epyc
[2022-06-11T13:45:47.996] sched: Allocate JobId=43443 NodeList=cpu09 #CPUs=48 Partition=cpu-opteron
[2022-06-11T13:46:48.923] sched: Allocate JobId=43444 NodeList=cpu08 #CPUs=48 Partition=cpu-opteron
[2022-06-11T13:47:01.088] sched: Allocate JobId=43445 NodeList=cpu03 #CPUs=32 Partition=cpu-opteron
[2022-06-11T13:48:25.302] sched: Allocate JobId=43447 NodeList=cpu04 #CPUs=32 Partition=cpu-opteron
[2022-06-11T13:48:36.321] sched: Allocate JobId=43448 NodeList=cpu12 #CPUs=16 Partition=cpu-epyc
[2022-06-11T13:50:21.470] sched: Allocate JobId=43449 NodeList=cpu11 #CPUs=32 Partition=cpu-opteron
[2022-06-11T13:51:06.533] sched: Allocate JobId=43450 NodeList=cpu05 #CPUs=32 Partition=cpu-opteron
[2022-06-11T13:51:59.610] sched: Allocate JobId=43451 NodeList=cpu04 #CPUs=32 Partition=cpu-opteron
[2022-06-11T13:55:23.711] sched: Allocate JobId=43453 NodeList=cpu05 #CPUs=32 Partition=cpu-opteron
[2022-06-11T13:56:16.080] sched: Allocate JobId=43455 NodeList=cpu01 #CPUs=16 Partition=cpu-opteron
[2022-06-11T14:03:27.881] sched: Allocate JobId=43457 NodeList=cpu08 #CPUs=16 Partition=cpu-opteron
[2022-06-11T14:09:19.726] sched: Allocate JobId=43459 NodeList=cpu08 #CPUs=16 Partition=cpu-opteron
[2022-06-11T14:26:36.389] sched/backfill: _start_job: Started JobId=43439 in gpu-titan on gpu02
[2022-06-11T15:11:11.636] sched: Allocate JobId=43462 NodeList=cpu09 #CPUs=16 Partition=cpu-opteron
[2022-06-11T16:35:28.201] sched: Allocate JobId=43456 NodeList=cpu13 #CPUs=48 Partition=cpu-epyc
[2022-06-11T18:25:08.190] sched: Allocate JobId=43463 NodeList=gpu04 #CPUs=16 Partition=gpu-k40c
[2022-06-11T18:28:35.591] sched: Allocate JobId=43464 NodeList=gpu04 #CPUs=16 Partition=gpu-k40c
[2022-06-11T20:48:33.332] sched: Allocate JobId=43469 NodeList=cpu04 #CPUs=32 Partition=cpu-opteron
[2022-06-11T20:48:49.665] sched: Allocate JobId=43470 NodeList=cpu04 #CPUs=32 Partition=cpu-opteron
[2022-06-11T21:12:31.032] sched: Allocate JobId=43471 NodeList=cpu04 #CPUs=32 Partition=cpu-opteron
[2022-06-11T21:15:13.489] sched: Allocate JobId=43472 NodeList=cpu04 #CPUs=32 Partition=cpu-opteron
[2022-06-11T21:15:43.308] sched: Allocate JobId=43473 NodeList=cpu04 #CPUs=32 Partition=cpu-opteron
[2022-06-11T21:18:58.315] sched: Allocate JobId=43474 NodeList=cpu04 #CPUs=32 Partition=cpu-opteron
[2022-06-11T21:35:19.872] sched: Allocate JobId=43458 NodeList=cpu03 #CPUs=32 Partition=cpu-opteron
[2022-06-11T22:10:01.483] sched: Allocate JobId=43475 NodeList=cpu04 #CPUs=32 Partition=cpu-opteron
[2022-06-11T22:13:18.160] sched: Allocate JobId=43476 NodeList=cpu04 #CPUs=32 Partition=cpu-opteron
[2022-06-11T22:34:20.171] sched: Allocate JobId=43477 NodeList=cpu04 #CPUs=32 Partition=cpu-opteron
[2022-06-11T22:46:15.118] sched: _slurm_rpc_allocate_resources JobId=43478 NodeList=gpu04 usec=16293
[2022-06-11T22:46:29.471] sched: Allocate JobId=43479 NodeList=cpu01 #CPUs=16 Partition=cpu-opteron
[2022-06-11T22:51:52.908] sched: Allocate JobId=43480 NodeList=cpu01 #CPUs=16 Partition=cpu-opteron
[2022-06-12T01:37:51.795] sched: Allocate JobId=43428 NodeList=gpu05 #CPUs=16 Partition=gpu-v100s
[2022-06-12T01:38:37.427] sched: Allocate JobId=43430 NodeList=gpu05 #CPUs=16 Partition=gpu-v100s
[2022-06-12T04:31:03.131] sched: Allocate JobId=43481 NodeList=gpu02 #CPUs=8 Partition=gpu-titan
[2022-06-12T04:32:53.410] sched: Allocate JobId=43482 NodeList=gpu02 #CPUs=2 Partition=gpu-titan
[2022-06-12T04:53:44.121] sched: Allocate JobId=43461 NodeList=cpu13 #CPUs=48 Partition=cpu-epyc
[2022-06-12T07:12:00.047] sched: Allocate JobId=43483 NodeList=gpu05 #CPUs=16 Partition=gpu-v100s
[2022-06-12T07:14:49.347] sched: Allocate JobId=43484 NodeList=gpu05 #CPUs=16 Partition=gpu-v100s
[2022-06-12T08:14:06.173] sched: Allocate JobId=43485 NodeList=gpu05 #CPUs=16 Partition=gpu-v100s
[2022-06-12T08:58:18.864] sched: Allocate JobId=43486 NodeList=gpu05 #CPUs=16 Partition=gpu-v100s
[2022-06-12T09:18:23.165] sched: Allocate JobId=43487 NodeList=gpu05 #CPUs=16 Partition=gpu-v100s
[2022-06-12T09:30:17.390] sched: Allocate JobId=43423 NodeList=gpu05 #CPUs=32 Partition=gpu-v100s
[2022-06-12T10:28:03.791] sched: Allocate JobId=43488 NodeList=gpu05 #CPUs=16 Partition=gpu-v100s
[2022-06-12T11:31:04.573] sched: Allocate JobId=43489 NodeList=gpu05 #CPUs=16 Partition=gpu-v100s
[2022-06-12T12:05:07.002] sched: Allocate JobId=43496 NodeList=gpu02 #CPUs=6 Partition=gpu-titan
[2022-06-12T12:07:48.369] sched: Allocate JobId=43497 NodeList=gpu02 #CPUs=6 Partition=gpu-titan
[2022-06-12T12:36:15.754] sched: Allocate JobId=43492 NodeList=gpu05 #CPUs=16 Partition=gpu-v100s
[2022-06-12T13:06:33.270] sched: Allocate JobId=43493 NodeList=gpu05 #CPUs=16 Partition=gpu-v100s
[2022-06-12T13:52:52.760] sched: Allocate JobId=43399 NodeList=cpu13 #CPUs=48 Partition=cpu-epyc
[2022-06-12T13:59:49.186] sched: Allocate JobId=43498 NodeList=gpu04 #CPUs=8 Partition=gpu-k40c
[2022-06-12T14:04:57.700] sched: Allocate JobId=43499 NodeList=gpu04 #CPUs=8 Partition=gpu-k40c
[2022-06-12T14:05:52.795] sched: Allocate JobId=43500 NodeList=gpu05 #CPUs=16 Partition=gpu-v100s
[2022-06-12T14:44:09.154] sched: Allocate JobId=43505 NodeList=gpu04 #CPUs=8 Partition=gpu-k40c
[2022-06-12T14:46:09.263] sched: Allocate JobId=43506 NodeList=gpu04 #CPUs=8 Partition=gpu-k40c
[2022-06-12T14:48:23.578] sched: Allocate JobId=43507 NodeList=gpu04 #CPUs=8 Partition=gpu-k40c
[2022-06-12T14:50:42.780] sched: Allocate JobId=43508 NodeList=gpu04 #CPUs=8 Partition=gpu-k40c
[2022-06-12T14:54:56.253] sched: Allocate JobId=43509 NodeList=gpu04 #CPUs=8 Partition=gpu-k40c
[2022-06-12T14:56:25.380] sched: Allocate JobId=43510 NodeList=gpu04 #CPUs=8 Partition=gpu-k40c
[2022-06-12T15:03:33.223] sched: Allocate JobId=43511 NodeList=gpu04 #CPUs=8 Partition=gpu-k40c
[2022-06-12T15:05:07.364] sched: Allocate JobId=43512 NodeList=gpu04 #CPUs=8 Partition=gpu-k40c
[2022-06-12T15:09:06.246] sched: Allocate JobId=43501 NodeList=gpu05 #CPUs=16 Partition=gpu-v100s
[2022-06-12T15:09:42.861] sched: Allocate JobId=43513 NodeList=gpu04 #CPUs=8 Partition=gpu-k40c
[2022-06-12T15:11:16.997] sched: Allocate JobId=43514 NodeList=gpu04 #CPUs=8 Partition=gpu-k40c
[2022-06-12T15:27:21.873] sched: Allocate JobId=43515 NodeList=gpu04 #CPUs=8 Partition=gpu-k40c
[2022-06-12T15:43:07.972] sched: Allocate JobId=43516 NodeList=gpu04 #CPUs=8 Partition=gpu-k40c
[2022-06-12T15:44:17.068] sched: Allocate JobId=43517 NodeList=gpu04 #CPUs=8 Partition=gpu-k40c
[2022-06-12T15:46:52.312] sched: Allocate JobId=43518 NodeList=cpu07 #CPUs=64 Partition=cpu-opteron
[2022-06-12T15:48:35.660] sched: Allocate JobId=43521 NodeList=cpu05 #CPUs=32 Partition=cpu-opteron
[2022-06-12T15:48:49.681] sched: Allocate JobId=43522 NodeList=gpu04 #CPUs=8 Partition=gpu-k40c
[2022-06-12T15:50:16.806] sched: Allocate JobId=43523 NodeList=cpu09 #CPUs=64 Partition=cpu-opteron
[2022-06-12T15:51:21.899] sched: Allocate JobId=43524 NodeList=cpu01 #CPUs=32 Partition=cpu-opteron
[2022-06-12T15:58:28.061] sched: Allocate JobId=43531 NodeList=gpu04 #CPUs=4 Partition=gpu-k40c
[2022-06-12T15:59:33.152] sched: Allocate JobId=43532 NodeList=gpu04 #CPUs=12 Partition=gpu-k40c
[2022-06-12T16:00:47.258] sched: Allocate JobId=43533 NodeList=gpu04 #CPUs=12 Partition=gpu-k40c
[2022-06-12T16:18:29.382] sched: Allocate JobId=43535 NodeList=cpu14 #CPUs=32 Partition=cpu-epyc
[2022-06-12T16:40:28.848] sched: Allocate JobId=43536 NodeList=gpu04 #CPUs=12 Partition=gpu-k40c
[2022-06-12T16:41:32.937] sched: Allocate JobId=43537 NodeList=gpu04 #CPUs=12 Partition=gpu-k40c
[2022-06-12T16:41:48.858] sched: Allocate JobId=43454 NodeList=cpu13 #CPUs=64 Partition=cpu-epyc
[2022-06-12T17:17:59.197] sched: Allocate JobId=43538 NodeList=gpu02 #CPUs=6 Partition=gpu-titan
[2022-06-12T17:21:25.480] sched: Allocate JobId=43539 NodeList=gpu02 #CPUs=6 Partition=gpu-titan
[2022-06-12T17:26:37.035] sched: Allocate JobId=43540 NodeList=gpu02 #CPUs=6 Partition=gpu-titan
[2022-06-12T17:33:05.843] sched: Allocate JobId=43541 NodeList=gpu02 #CPUs=6 Partition=gpu-titan
[2022-06-12T17:37:17.205] sched: Allocate JobId=43542 NodeList=gpu02 #CPUs=6 Partition=gpu-titan
[2022-06-12T17:37:59.390] sched: Allocate JobId=43543 NodeList=gpu04 #CPUs=12 Partition=gpu-k40c
[2022-06-12T17:41:26.679] sched: Allocate JobId=43544 NodeList=gpu02 #CPUs=6 Partition=gpu-titan
[2022-06-12T17:43:57.374] sched: _slurm_rpc_allocate_resources JobId=43545 NodeList=cpu13 usec=16772
[2022-06-12T17:57:41.618] sched: Allocate JobId=43546 NodeList=gpu04 #CPUs=12 Partition=gpu-k40c
[2022-06-12T18:01:58.996] sched: Allocate JobId=43547 NodeList=gpu04 #CPUs=12 Partition=gpu-k40c
[2022-06-12T18:02:47.012] sched: Allocate JobId=43534 NodeList=gpu05 #CPUs=16 Partition=gpu-v100s
[2022-06-12T18:03:25.216] sched: Allocate JobId=43548 NodeList=gpu04 #CPUs=12 Partition=gpu-k40c
[2022-06-12T18:05:32.397] sched: Allocate JobId=43549 NodeList=gpu04 #CPUs=12 Partition=gpu-k40c
[2022-06-12T20:39:50.088] sched: Allocate JobId=43502 NodeList=gpu05 #CPUs=16 Partition=gpu-v100s
[2022-06-12T22:56:28.737] sched: Allocate JobId=43551 NodeList=cpu13 #CPUs=32 Partition=cpu-epyc
[2022-06-12T23:12:26.937] sched: Allocate JobId=43550 NodeList=gpu05 #CPUs=16 Partition=gpu-v100s
[2022-06-12T23:23:08.788] sched: Allocate JobId=43552 NodeList=gpu02 #CPUs=12 Partition=gpu-titan
[2022-06-12T23:24:58.929] sched: Allocate JobId=43553 NodeList=gpu02 #CPUs=12 Partition=gpu-titan
[2022-06-12T23:28:10.290] sched: Allocate JobId=43554 NodeList=gpu02 #CPUs=12 Partition=gpu-titan
[2022-06-12T23:35:18.035] sched: Allocate JobId=43555 NodeList=gpu02 #CPUs=6 Partition=gpu-titan
[2022-06-12T23:37:02.183] sched: Allocate JobId=43556 NodeList=gpu02 #CPUs=6 Partition=gpu-titan
[2022-06-12T23:50:35.931] sched: Allocate JobId=43557 NodeList=gpu05 #CPUs=16 Partition=gpu-v100s
[2022-06-12T23:55:07.628] sched: Allocate JobId=43558 NodeList=gpu05 #CPUs=16 Partition=gpu-v100s
[2022-06-13T01:54:27.944] sched: Allocate JobId=43491 NodeList=gpu03 #CPUs=16 Partition=gpu-k10
[2022-06-13T02:08:00.344] sched: Allocate JobId=43504 NodeList=gpu05 #CPUs=16 Partition=gpu-v100s
[2022-06-13T08:28:06.835] sched: Allocate JobId=43559 NodeList=cpu15 #CPUs=48 Partition=cpu-epyc
[2022-06-13T08:58:34.319] sched: Allocate JobId=43560 NodeList=cpu15 #CPUs=24 Partition=cpu-epyc
[2022-06-13T09:15:10.247] sched: Allocate JobId=43561 NodeList=gpu05 #CPUs=16 Partition=gpu-v100s
[2022-06-13T09:18:10.758] sched: Allocate JobId=43562 NodeList=gpu05 #CPUs=16 Partition=gpu-v100s
[2022-06-13T09:19:22.756] sched: Allocate JobId=43563 NodeList=cpu04 #CPUs=32 Partition=cpu-opteron
[2022-06-13T09:38:13.795] sched: Allocate JobId=43564 NodeList=gpu02 #CPUs=8 Partition=gpu-titan
[2022-06-13T09:45:25.512] sched: Allocate JobId=43565 NodeList=cpu03 #CPUs=16 Partition=cpu-opteron
[2022-06-13T09:45:55.539] sched: Allocate JobId=43566 NodeList=cpu03 #CPUs=8 Partition=cpu-opteron
[2022-06-13T09:47:31.832] sched: Allocate JobId=43567 NodeList=cpu03 #CPUs=16 Partition=cpu-opteron
[2022-06-13T09:53:09.434] sched: Allocate JobId=43568 NodeList=cpu15 #CPUs=48 Partition=cpu-epyc
[2022-06-13T09:54:22.545] sched: Allocate JobId=43569 NodeList=cpu15 #CPUs=48 Partition=cpu-epyc
[2022-06-13T09:55:34.654] sched: Allocate JobId=43570 NodeList=cpu03 #CPUs=16 Partition=cpu-opteron
[2022-06-13T09:56:32.739] sched: Allocate JobId=43571 NodeList=cpu04 #CPUs=16 Partition=cpu-opteron
[2022-06-13T09:57:16.803] sched: Allocate JobId=43572 NodeList=cpu04 #CPUs=8 Partition=cpu-opteron
[2022-06-13T10:04:45.860] sched: Allocate JobId=43573 NodeList=cpu03 #CPUs=16 Partition=cpu-opteron
[2022-06-13T10:09:46.987] sched: Allocate JobId=43574 NodeList=cpu15 #CPUs=48 Partition=cpu-epyc
[2022-06-13T10:21:51.818] sched: Allocate JobId=43575 NodeList=cpu04 #CPUs=16 Partition=cpu-opteron
[2022-06-13T10:22:18.854] sched: Allocate JobId=43576 NodeList=cpu04 #CPUs=8 Partition=cpu-opteron
[2022-06-13T10:32:57.872] sched: Allocate JobId=43577 NodeList=cpu15 #CPUs=48 Partition=cpu-epyc
[2022-06-13T10:34:52.266] sched: Allocate JobId=43578 NodeList=gpu04 #CPUs=12 Partition=gpu-k40c
[2022-06-13T10:51:22.039] sched: Allocate JobId=43579 NodeList=gpu04 #CPUs=12 Partition=gpu-k40c
[2022-06-13T10:51:57.086] sched: Allocate JobId=43580 NodeList=gpu04 #CPUs=12 Partition=gpu-k40c
[2022-06-13T10:53:14.323] sched: Allocate JobId=43581 NodeList=gpu03 #CPUs=12 Partition=gpu-k10
[2022-06-13T11:36:13.961] sched: Allocate JobId=43584 NodeList=cpu03 #CPUs=1 Partition=cpu-opteron
[2022-06-13T11:46:22.049] sched: Allocate JobId=43587 NodeList=cpu15 #CPUs=24 Partition=cpu-epyc
[2022-06-13T11:48:29.350] sched: Allocate JobId=43588 NodeList=cpu08 #CPUs=32 Partition=cpu-opteron
[2022-06-13T11:50:40.534] sched: Allocate JobId=43589 NodeList=cpu04 #CPUs=32 Partition=cpu-opteron
[2022-06-13T11:52:55.860] sched: Allocate JobId=43590 NodeList=cpu08 #CPUs=32 Partition=cpu-opteron
[2022-06-13T12:36:19.743] sched: Allocate JobId=43593 NodeList=gpu05 #CPUs=16 Partition=gpu-v100s
[2022-06-13T12:54:22.030] sched: Allocate JobId=43594 NodeList=cpu08 #CPUs=8 Partition=cpu-opteron
[2022-06-13T12:55:03.081] sched: Allocate JobId=43595 NodeList=cpu08 #CPUs=8 Partition=cpu-opteron
[2022-06-13T12:56:46.225] sched: Allocate JobId=43596 NodeList=cpu08 #CPUs=8 Partition=cpu-opteron
[2022-06-13T12:57:26.342] sched: Allocate JobId=43597 NodeList=cpu03 #CPUs=32 Partition=cpu-opteron
[2022-06-13T13:01:28.718] sched: Allocate JobId=43598 NodeList=gpu03 #CPUs=16 Partition=gpu-k10
[2022-06-13T13:25:05.338] sched: Allocate JobId=43602 NodeList=cpu08 #CPUs=8 Partition=cpu-opteron
[2022-06-13T13:29:50.887] sched: Allocate JobId=43603 NodeList=cpu08 #CPUs=8 Partition=cpu-opteron
[2022-06-13T13:31:16.001] sched: Allocate JobId=43604 NodeList=cpu08 #CPUs=8 Partition=cpu-opteron
[2022-06-13T13:59:58.257] sched: Allocate JobId=43605 NodeList=cpu08 #CPUs=8 Partition=cpu-opteron
[2022-06-13T14:01:35.387] sched: Allocate JobId=43606 NodeList=cpu08 #CPUs=8 Partition=cpu-opteron
[2022-06-13T14:02:37.548] sched/backfill: _start_job: Started JobId=43608 in gpu-titan on gpu02
[2022-06-13T14:05:19.021] sched: Allocate JobId=43609 NodeList=cpu03 #CPUs=16 Partition=cpu-opteron
[2022-06-13T14:05:23.007] sched: Allocate JobId=43610 NodeList=cpu03 #CPUs=16 Partition=cpu-opteron
[2022-06-13T14:05:26.011] sched: Allocate JobId=43611 NodeList=cpu08 #CPUs=16 Partition=cpu-opteron
[2022-06-13T14:05:29.015] sched: Allocate JobId=43612 NodeList=cpu08 #CPUs=16 Partition=cpu-opteron
[2022-06-13T14:20:02.575] sched: Allocate JobId=43613 NodeList=cpu08 #CPUs=8 Partition=cpu-opteron
[2022-06-13T14:21:09.665] sched: Allocate JobId=43614 NodeList=cpu08 #CPUs=8 Partition=cpu-opteron
[2022-06-13T14:23:38.982] sched: Allocate JobId=43615 NodeList=cpu08 #CPUs=8 Partition=cpu-opteron
[2022-06-13T14:27:11.284] sched: Allocate JobId=43616 NodeList=cpu08 #CPUs=8 Partition=cpu-opteron
[2022-06-13T14:33:57.045] sched: Allocate JobId=43617 NodeList=cpu12 #CPUs=32 Partition=cpu-epyc
[2022-06-13T14:34:07.060] sched: Allocate JobId=43618 NodeList=cpu03 #CPUs=32 Partition=cpu-opteron
[2022-06-13T14:34:44.092] sched: Allocate JobId=43619 NodeList=cpu03 #CPUs=32 Partition=cpu-opteron
[2022-06-13T14:37:28.443] sched: Allocate JobId=43620 NodeList=cpu03 #CPUs=32 Partition=cpu-opteron
[2022-06-13T14:39:16.598] sched: Allocate JobId=43621 NodeList=cpu08 #CPUs=8 Partition=cpu-opteron
[2022-06-13T14:40:17.676] sched: Allocate JobId=43622 NodeList=cpu08 #CPUs=8 Partition=cpu-opteron
[2022-06-13T14:46:16.261] sched: Allocate JobId=43624 NodeList=cpu08 #CPUs=32 Partition=cpu-opteron
[2022-06-13T15:04:09.185] sched: Allocate JobId=43630 NodeList=cpu03 #CPUs=1 Partition=cpu-opteron
[2022-06-13T15:11:42.927] sched: Allocate JobId=43635 NodeList=gpu02 #CPUs=24 Partition=gpu-titan
[2022-06-13T15:26:08.477] sched: Allocate JobId=43638 NodeList=gpu01 #CPUs=1 Partition=gpu-k10
[2022-06-13T15:31:59.087] sched: Allocate JobId=43639 NodeList=gpu02 #CPUs=24 Partition=gpu-titan
[2022-06-13T15:34:30.390] sched: Allocate JobId=43640 NodeList=gpu02 #CPUs=24 Partition=gpu-titan
[2022-06-13T15:35:29.472] sched: Allocate JobId=43641 NodeList=gpu02 #CPUs=24 Partition=gpu-titan
[2022-06-13T15:36:23.543] sched: Allocate JobId=43642 NodeList=gpu02 #CPUs=24 Partition=gpu-titan
[2022-06-13T15:39:49.955] sched: Allocate JobId=43643 NodeList=gpu01 #CPUs=1 Partition=gpu-k10
[2022-06-13T15:42:35.297] sched: Allocate JobId=43644 NodeList=gpu01 #CPUs=16 Partition=gpu-k10
[2022-06-13T15:46:16.602] sched: Allocate JobId=43646 NodeList=cpu03 #CPUs=16 Partition=cpu-opteron
[2022-06-13T15:47:06.671] sched: Allocate JobId=43647 NodeList=gpu01 #CPUs=16 Partition=gpu-k10
[2022-06-13T15:51:06.094] sched: Allocate JobId=43648 NodeList=gpu01 #CPUs=16 Partition=gpu-k10
[2022-06-13T15:52:45.323] sched: Allocate JobId=43649 NodeList=cpu01 #CPUs=1 Partition=cpu-opteron
[2022-06-13T15:54:18.450] sched: Allocate JobId=43651 NodeList=cpu01 #CPUs=1 Partition=cpu-opteron
[2022-06-13T15:55:17.569] sched: Allocate JobId=43631 NodeList=gpu05 #CPUs=16 Partition=gpu-v100s
[2022-06-13T15:56:46.652] sched: Allocate JobId=43652 NodeList=cpu01 #CPUs=1 Partition=cpu-opteron
[2022-06-13T16:23:19.472] sched: Allocate JobId=43655 NodeList=cpu01 #CPUs=32 Partition=cpu-opteron
[2022-06-13T17:02:43.850] sched: Allocate JobId=43656 NodeList=cpu12 #CPUs=32 Partition=cpu-epyc
[2022-06-13T17:02:53.845] sched: Allocate JobId=43657 NodeList=cpu07 #CPUs=64 Partition=cpu-opteron
[2022-06-13T17:05:51.402] sched: Allocate JobId=43592 NodeList=cpu15 #CPUs=24 Partition=cpu-epyc
[2022-06-13T17:20:09.649] sched: Allocate JobId=43658 NodeList=cpu05 #CPUs=32 Partition=cpu-opteron
[2022-06-13T17:29:09.568] sched: Allocate JobId=43659 NodeList=cpu05 #CPUs=32 Partition=cpu-opteron
[2022-06-13T17:31:35.756] sched: Allocate JobId=43660 NodeList=cpu01 #CPUs=32 Partition=cpu-opteron
[2022-06-13T17:32:30.955] sched: Allocate JobId=43661 NodeList=cpu03 #CPUs=32 Partition=cpu-opteron
[2022-06-13T17:34:45.143] sched: Allocate JobId=43662 NodeList=cpu09 #CPUs=32 Partition=cpu-opteron
[2022-06-13T17:36:25.280] sched: Allocate JobId=43663 NodeList=cpu09 #CPUs=32 Partition=cpu-opteron
[2022-06-13T18:22:49.997] sched: Allocate JobId=43632 NodeList=gpu05 #CPUs=16 Partition=gpu-v100s
[2022-06-13T18:35:09.804] sched: Allocate JobId=43633 NodeList=gpu05 #CPUs=16 Partition=gpu-v100s
[2022-06-13T19:31:45.901] sched: Allocate JobId=43634 NodeList=gpu05 #CPUs=16 Partition=gpu-v100s
[2022-06-13T19:31:46.468] sched: Allocate JobId=43637 NodeList=gpu05 #CPUs=16 Partition=gpu-v100s
[2022-06-13T19:32:37.999] sched: Allocate JobId=43667 NodeList=cpu03 #CPUs=32 Partition=cpu-opteron
[2022-06-13T19:32:40.922] sched: Allocate JobId=43664 NodeList=cpu03 #CPUs=32 Partition=cpu-opteron
[2022-06-13T19:33:50.263] sched: Allocate JobId=43665 NodeList=cpu15 #CPUs=48 Partition=cpu-epyc
[2022-06-13T19:53:36.494] sched: Allocate JobId=43669 NodeList=gpu01 #CPUs=32 Partition=gpu-k10
[2022-06-13T20:15:28.313] sched: Allocate JobId=43424 NodeList=gpu05 #CPUs=32 Partition=gpu-v100s
[2022-06-13T20:18:36.365] sched: Allocate JobId=43673 NodeList=gpu02 #CPUs=12 Partition=gpu-titan
[2022-06-13T20:29:01.508] sched: Allocate JobId=43677 NodeList=gpu02 #CPUs=16 Partition=gpu-titan
[2022-06-13T20:46:07.457] sched: Allocate JobId=43666 NodeList=cpu15 #CPUs=48 Partition=cpu-epyc
[2022-06-13T20:56:37.551] sched: Allocate JobId=43679 NodeList=gpu01 #CPUs=8 Partition=gpu-k10
[2022-06-13T20:57:29.686] sched: Allocate JobId=43680 NodeList=gpu01 #CPUs=8 Partition=gpu-k10
[2022-06-13T20:59:18.857] sched: Allocate JobId=43681 NodeList=cpu03 #CPUs=32 Partition=cpu-opteron
[2022-06-13T21:51:00.073] sched: _slurm_rpc_allocate_resources JobId=43683 NodeList=cpu05 usec=4476
[2022-06-13T23:09:09.004] sched: Allocate JobId=43674 NodeList=gpu05 #CPUs=16 Partition=gpu-v100s
[2022-06-14T00:07:06.318] sched: Allocate JobId=43685 NodeList=cpu15 #CPUs=48 Partition=cpu-epyc
[2022-06-14T00:12:53.012] sched: Allocate JobId=43686 NodeList=cpu05 #CPUs=32 Partition=cpu-opteron
[2022-06-14T00:13:43.085] sched: Allocate JobId=43687 NodeList=cpu05 #CPUs=32 Partition=cpu-opteron
[2022-06-14T00:16:46.352] sched: Allocate JobId=43688 NodeList=cpu08 #CPUs=32 Partition=cpu-opteron
[2022-06-14T00:25:22.295] sched: Allocate JobId=43692 NodeList=gpu01 #CPUs=8 Partition=gpu-k10
[2022-06-14T00:27:12.452] sched: Allocate JobId=43694 NodeList=gpu01 #CPUs=8 Partition=gpu-k10
[2022-06-14T00:28:39.685] sched: Allocate JobId=43695 NodeList=gpu01 #CPUs=8 Partition=gpu-k10
[2022-06-14T00:29:18.738] sched: Allocate JobId=43696 NodeList=gpu01 #CPUs=8 Partition=gpu-k10
[2022-06-14T00:31:32.932] sched: Allocate JobId=43697 NodeList=gpu01 #CPUs=16 Partition=gpu-k10
[2022-06-14T00:38:00.809] sched: Allocate JobId=43699 NodeList=gpu01 #CPUs=8 Partition=gpu-k10
[2022-06-14T00:42:46.366] sched: Allocate JobId=43701 NodeList=gpu01 #CPUs=8 Partition=gpu-k10
[2022-06-14T00:43:27.436] sched: Allocate JobId=43702 NodeList=cpu12 #CPUs=4 Partition=cpu-epyc
[2022-06-14T00:47:06.742] sched: Allocate JobId=43703 NodeList=gpu01 #CPUs=8 Partition=gpu-k10
[2022-06-14T00:50:56.228] sched: Allocate JobId=43690 NodeList=cpu08 #CPUs=1 Partition=cpu-opteron
[2022-06-14T00:50:56.228] sched: Allocate JobId=43693 NodeList=cpu08 #CPUs=4 Partition=cpu-opteron
[2022-06-14T00:53:45.541] sched: Allocate JobId=43705 NodeList=cpu05 #CPUs=1 Partition=cpu-opteron
[2022-06-14T01:03:42.503] sched: Allocate JobId=43706 NodeList=cpu05 #CPUs=1 Partition=cpu-opteron
[2022-06-14T01:05:22.642] sched: Allocate JobId=43707 NodeList=cpu12 #CPUs=4 Partition=cpu-epyc
[2022-06-14T01:11:13.622] sched: Allocate JobId=43708 NodeList=cpu12 #CPUs=4 Partition=cpu-epyc
[2022-06-14T01:13:04.555] sched: Allocate JobId=43709 NodeList=gpu05 #CPUs=16 Partition=gpu-v100s
[2022-06-14T01:15:06.702] sched: Allocate JobId=43698 NodeList=cpu15 #CPUs=48 Partition=cpu-epyc
[2022-06-14T01:20:22.126] sched: Allocate JobId=43700 NodeList=cpu15 #CPUs=48 Partition=cpu-epyc
[2022-06-14T01:49:30.915] sched: Allocate JobId=43712 NodeList=cpu12 #CPUs=4 Partition=cpu-epyc
[2022-06-14T02:24:59.724] sched: Allocate JobId=43710 NodeList=gpu05 #CPUs=16 Partition=gpu-v100s
[2022-06-14T03:00:10.925] sched: Allocate JobId=43713 NodeList=cpu12 #CPUs=4 Partition=cpu-epyc
[2022-06-14T03:00:10.925] sched: Allocate JobId=43714 NodeList=cpu12 #CPUs=4 Partition=cpu-epyc
[2022-06-14T03:00:10.926] sched: Allocate JobId=43715 NodeList=cpu12 #CPUs=4 Partition=cpu-epyc
[2022-06-14T03:36:12.468] sched: Allocate JobId=43682 NodeList=gpu05 #CPUs=16 Partition=gpu-v100s
[2022-06-14T05:32:55.591] sched: Allocate JobId=43529 NodeList=gpu04 #CPUs=8 Partition=gpu-k40c
[2022-06-14T05:33:13.791] sched: Allocate JobId=43530 NodeList=gpu04 #CPUs=8 Partition=gpu-k40c
[2022-06-14T06:58:04.620] sched: Allocate JobId=43711 NodeList=gpu05 #CPUs=16 Partition=gpu-v100s
[2022-06-14T08:08:24.516] sched: Allocate JobId=43716 NodeList=gpu05 #CPUs=16 Partition=gpu-v100s
[2022-06-14T08:28:29.452] sched: Allocate JobId=43717 NodeList=cpu13 #CPUs=32 Partition=cpu-epyc
[2022-06-14T08:29:40.539] sched: Allocate JobId=43718 NodeList=cpu14 #CPUs=32 Partition=cpu-epyc
[2022-06-14T08:31:00.655] sched: Allocate JobId=43719 NodeList=cpu05 #CPUs=64 Partition=cpu-opteron
[2022-06-14T08:32:11.756] sched: Allocate JobId=43720 NodeList=cpu01 #CPUs=32 Partition=cpu-opteron
[2022-06-14T08:33:32.047] sched: Allocate JobId=43721 NodeList=cpu11 #CPUs=32 Partition=cpu-opteron
[2022-06-14T08:34:33.135] sched: Allocate JobId=43722 NodeList=cpu09 #CPUs=64 Partition=cpu-opteron
[2022-06-14T08:41:23.917] sched: Allocate JobId=43723 NodeList=cpu08 #CPUs=32 Partition=cpu-opteron
[2022-06-14T08:50:43.101] sched: Allocate JobId=43727 NodeList=cpu12 #CPUs=1 Partition=cpu-epyc
[2022-06-14T08:52:00.190] sched: Allocate JobId=43728 NodeList=gpu01 #CPUs=16 Partition=gpu-k10
[2022-06-14T08:54:43.574] sched: Allocate JobId=43730 NodeList=cpu12 #CPUs=8 Partition=cpu-epyc
[2022-06-14T09:07:27.042] sched: Allocate JobId=43731 NodeList=gpu01 #CPUs=16 Partition=gpu-k10
[2022-06-14T09:41:10.979] sched: Allocate JobId=43733 NodeList=cpu12 #CPUs=8 Partition=cpu-epyc
[2022-06-14T10:02:18.648] sched: Allocate JobId=43735 NodeList=cpu12 #CPUs=1 Partition=cpu-epyc
[2022-06-14T10:04:02.888] sched: Allocate JobId=43737 NodeList=cpu12 #CPUs=1 Partition=cpu-epyc
[2022-06-14T10:05:30.013] sched: Allocate JobId=43738 NodeList=cpu12 #CPUs=1 Partition=cpu-epyc
[2022-06-14T10:06:02.122] sched: Allocate JobId=43739 NodeList=gpu04 #CPUs=16 Partition=gpu-k40c
[2022-06-14T10:06:05.064] sched: Allocate JobId=43740 NodeList=cpu12 #CPUs=1 Partition=cpu-epyc
[2022-06-14T10:08:08.391] sched: Allocate JobId=43741 NodeList=cpu12 #CPUs=1 Partition=cpu-epyc
[2022-06-14T10:08:32.427] sched: Allocate JobId=43742 NodeList=cpu12 #CPUs=1 Partition=cpu-epyc
[2022-06-14T10:19:48.735] sched: Allocate JobId=43734 NodeList=cpu01 #CPUs=32 Partition=cpu-opteron
[2022-06-14T10:20:25.736] sched: Allocate JobId=43743 NodeList=cpu12 #CPUs=1 Partition=cpu-epyc
[2022-06-14T10:20:32.215] sched: Allocate JobId=43736 NodeList=cpu01 #CPUs=32 Partition=cpu-opteron
[2022-06-14T10:21:28.823] sched: Allocate JobId=43744 NodeList=cpu12 #CPUs=1 Partition=cpu-epyc
[2022-06-14T10:47:15.587] sched: Allocate JobId=43746 NodeList=cpu12 #CPUs=1 Partition=cpu-epyc
[2022-06-14T11:36:50.501] sched: Allocate JobId=43747 NodeList=cpu01 #CPUs=32 Partition=cpu-opteron
[2022-06-14T11:53:37.804] sched: Allocate JobId=43745 NodeList=gpu05 #CPUs=16 Partition=gpu-v100s
[2022-06-14T12:04:11.061] sched: Allocate JobId=43425 NodeList=gpu05 #CPUs=32 Partition=gpu-v100s
[2022-06-14T12:07:04.699] sched: Allocate JobId=43748 NodeList=cpu01 #CPUs=32 Partition=cpu-opteron
[2022-06-14T12:28:14.153] sched: Allocate JobId=43749 NodeList=gpu05 #CPUs=16 Partition=gpu-v100s
[2022-06-14T12:34:52.845] sched: Allocate JobId=43750 NodeList=gpu03 #CPUs=32 Partition=gpu-k10
[2022-06-14T12:35:34.889] sched: Allocate JobId=43751 NodeList=gpu03 #CPUs=32 Partition=gpu-k10
[2022-06-14T12:51:30.583] sched: Allocate JobId=43755 NodeList=cpu01 #CPUs=32 Partition=cpu-opteron
[2022-06-14T13:25:23.397] sched: Allocate JobId=43757 NodeList=cpu12 #CPUs=1 Partition=cpu-epyc
[2022-06-14T14:22:04.515] sched: Allocate JobId=43758 NodeList=cpu01 #CPUs=32 Partition=cpu-opteron
[2022-06-14T14:27:26.265] sched: Allocate JobId=43762 NodeList=cpu12 #CPUs=16 Partition=cpu-epyc
[2022-06-14T14:40:29.424] sched: _slurm_rpc_allocate_resources JobId=43764 NodeList=(null) usec=1002
[2022-06-14T14:40:49.077] sched: Allocate JobId=43765 NodeList=gpu04 #CPUs=2 Partition=gpu-k40c
[2022-06-14T14:48:34.033] sched: Allocate JobId=43766 NodeList=gpu03 #CPUs=16 Partition=gpu-k10
[2022-06-14T14:58:18.971] sched: Allocate JobId=43678 NodeList=gpu05 #CPUs=16 Partition=gpu-v100s
[2022-06-14T15:11:41.495] sched: Allocate JobId=43759 NodeList=cpu04 #CPUs=32 Partition=cpu-opteron
[2022-06-14T15:17:50.854] sched: Allocate JobId=43760 NodeList=cpu01 #CPUs=32 Partition=cpu-opteron
[2022-06-14T15:34:53.152] sched: Allocate JobId=43768 NodeList=gpu03 #CPUs=32 Partition=gpu-k10
[2022-06-14T15:37:15.338] sched: Allocate JobId=43769 NodeList=gpu03 #CPUs=32 Partition=gpu-k10
[2022-06-14T15:37:35.349] sched: Allocate JobId=43770 NodeList=gpu03 #CPUs=32 Partition=gpu-k10
[2022-06-14T15:37:44.580] sched: Allocate JobId=43771 NodeList=cpu12 #CPUs=16 Partition=cpu-epyc
[2022-06-14T15:38:53.111] sched: Allocate JobId=43754 NodeList=cpu13 #CPUs=32 Partition=cpu-epyc
[2022-06-14T15:40:44.827] sched: Allocate JobId=43773 NodeList=cpu13 #CPUs=32 Partition=cpu-epyc
[2022-06-14T15:42:36.249] sched: Allocate JobId=43774 NodeList=gpu02 #CPUs=16 Partition=gpu-titan
[2022-06-14T15:44:09.365] sched: Allocate JobId=43775 NodeList=gpu04 #CPUs=8 Partition=gpu-k40c
[2022-06-14T15:44:40.410] sched: Allocate JobId=43776 NodeList=gpu04 #CPUs=16 Partition=gpu-k40c
[2022-06-14T15:52:12.310] sched: Allocate JobId=43777 NodeList=gpu04 #CPUs=16 Partition=gpu-k40c
[2022-06-14T16:10:38.246] sched/backfill: _start_job: Started JobId=43779 in gpu-titan on gpu02
[2022-06-14T17:04:59.831] sched: Allocate JobId=43781 NodeList=cpu13 #CPUs=32 Partition=cpu-epyc
[2022-06-14T17:06:44.971] sched: Allocate JobId=43782 NodeList=cpu01 #CPUs=32 Partition=cpu-opteron
[2022-06-14T19:39:17.823] sched: Allocate JobId=43783 NodeList=cpu12 #CPUs=48 Partition=cpu-epyc
[2022-06-14T20:35:26.955] sched: Allocate JobId=43784 NodeList=cpu08 #CPUs=32 Partition=cpu-opteron
[2022-06-14T20:40:41.493] sched: Allocate JobId=43785 NodeList=cpu05 #CPUs=64 Partition=cpu-opteron
[2022-06-14T20:46:39.136] sched: Allocate JobId=43786 NodeList=cpu09 #CPUs=64 Partition=cpu-opteron
[2022-06-14T20:47:48.320] sched: Allocate JobId=43787 NodeList=cpu08 #CPUs=32 Partition=cpu-opteron
[2022-06-14T20:49:58.507] sched: Allocate JobId=43788 NodeList=cpu13 #CPUs=32 Partition=cpu-epyc
[2022-06-14T22:38:41.127] sched: _slurm_rpc_allocate_resources JobId=43789 NodeList=cpu03 usec=15604
[2022-06-14T23:53:31.024] sched: Allocate JobId=43790 NodeList=cpu10 #CPUs=32 Partition=cpu-opteron
[2022-06-15T00:05:23.152] sched: Allocate JobId=43780 NodeList=gpu02 #CPUs=32 Partition=gpu-titan
[2022-06-15T00:11:26.997] sched: Allocate JobId=43791 NodeList=gpu02 #CPUs=32 Partition=gpu-titan
[2022-06-15T00:11:36.010] sched: Allocate JobId=43792 NodeList=gpu02 #CPUs=32 Partition=gpu-titan
[2022-06-15T00:15:03.888] sched: Allocate JobId=43793 NodeList=gpu02 #CPUs=32 Partition=gpu-titan
[2022-06-15T00:18:14.731] sched: Allocate JobId=43794 NodeList=cpu11 #CPUs=32 Partition=cpu-opteron
[2022-06-15T00:30:59.030] sched: Allocate JobId=43795 NodeList=gpu02 #CPUs=32 Partition=gpu-titan
[2022-06-15T00:31:08.026] sched: Allocate JobId=43796 NodeList=gpu02 #CPUs=32 Partition=gpu-titan
[2022-06-15T00:33:10.321] sched: Allocate JobId=43797 NodeList=gpu02 #CPUs=32 Partition=gpu-titan
[2022-06-15T01:16:28.711] sched: Allocate JobId=43798 NodeList=gpu02 #CPUs=32 Partition=gpu-titan
[2022-06-15T01:20:48.364] sched: Allocate JobId=43591 NodeList=cpu15 #CPUs=48 Partition=cpu-epyc
[2022-06-15T08:29:47.905] sched: Allocate JobId=43799 NodeList=cpu14 #CPUs=32 Partition=cpu-epyc
[2022-06-15T09:47:10.543] sched: Allocate JobId=43802 NodeList=gpu02 #CPUs=32 Partition=gpu-titan
[2022-06-15T09:52:48.425] sched: Allocate JobId=43804 NodeList=cpu10 #CPUs=32 Partition=cpu-opteron
[2022-06-15T09:57:40.109] sched: Allocate JobId=43803 NodeList=gpu02 #CPUs=32 Partition=gpu-titan
[2022-06-15T10:32:55.892] sched: Allocate JobId=43805 NodeList=cpu10 #CPUs=32 Partition=cpu-opteron
[2022-06-15T10:33:05.903] sched: Allocate JobId=43806 NodeList=gpu02 #CPUs=8 Partition=gpu-titan
[2022-06-15T10:35:52.128] sched: Allocate JobId=43807 NodeList=gpu02 #CPUs=8 Partition=gpu-titan
[2022-06-15T10:46:15.270] sched: Allocate JobId=43808 NodeList=cpu03 #CPUs=16 Partition=cpu-opteron
[2022-06-15T10:49:36.632] sched: Allocate JobId=43809 NodeList=cpu03 #CPUs=32 Partition=cpu-opteron
[2022-06-15T11:12:54.269] sched: Allocate JobId=43811 NodeList=gpu03 #CPUs=32 Partition=gpu-k10
[2022-06-15T11:20:18.051] sched: Allocate JobId=43812 NodeList=gpu03 #CPUs=32 Partition=gpu-k10
[2022-06-15T11:23:17.439] sched: Allocate JobId=43813 NodeList=gpu03 #CPUs=32 Partition=gpu-k10
[2022-06-15T11:27:09.778] sched: Allocate JobId=43814 NodeList=gpu03 #CPUs=32 Partition=gpu-k10
[2022-06-15T11:38:01.154] sched: Allocate JobId=43815 NodeList=cpu03 #CPUs=1 Partition=cpu-opteron
[2022-06-15T11:39:37.294] sched: Allocate JobId=43816 NodeList=cpu11 #CPUs=32 Partition=cpu-opteron
[2022-06-15T11:40:50.402] sched: Allocate JobId=43817 NodeList=cpu03 #CPUs=1 Partition=cpu-opteron
[2022-06-15T11:41:03.421] sched: Allocate JobId=43818 NodeList=cpu11 #CPUs=32 Partition=cpu-opteron
[2022-06-15T11:44:36.845] sched: Allocate JobId=43819 NodeList=cpu03 #CPUs=1 Partition=cpu-opteron
[2022-06-15T11:44:50.864] sched: Allocate JobId=43820 NodeList=cpu11 #CPUs=32 Partition=cpu-opteron
[2022-06-15T11:58:28.374] sched: Allocate JobId=43824 NodeList=gpu03 #CPUs=32 Partition=gpu-k10
[2022-06-15T11:59:52.821] sched: _slurm_rpc_allocate_resources JobId=43825 NodeList=cpu03 usec=1186
[2022-06-15T12:20:42.785] sched: Allocate JobId=43827 NodeList=cpu04 #CPUs=32 Partition=cpu-opteron
[2022-06-15T12:37:34.413] sched: Allocate JobId=43800 NodeList=cpu14 #CPUs=32 Partition=cpu-epyc
[2022-06-15T12:39:50.636] sched: Allocate JobId=43801 NodeList=cpu14 #CPUs=32 Partition=cpu-epyc
[2022-06-15T12:39:52.877] sched: _hold_job_rec: hold on JobId=43801 by uid 548200003
[2022-06-15T12:39:52.877] sched: _update_job: set priority to 0 for JobId=43801
[2022-06-15T13:14:12.692] sched: Allocate JobId=43828 NodeList=gpu03 #CPUs=32 Partition=gpu-k10
[2022-06-15T13:58:37.726] sched: Allocate JobId=43829 NodeList=cpu10 #CPUs=32 Partition=cpu-opteron
[2022-06-15T15:05:20.717] sched: Allocate JobId=43830 NodeList=cpu04 #CPUs=32 Partition=cpu-opteron
[2022-06-15T15:19:15.291] sched: Allocate JobId=43831 NodeList=cpu04 #CPUs=32 Partition=cpu-opteron
[2022-06-15T15:26:44.062] sched: Allocate JobId=43832 NodeList=cpu14 #CPUs=32 Partition=cpu-epyc
[2022-06-15T15:46:34.261] sched: Allocate JobId=43833 NodeList=cpu04 #CPUs=32 Partition=cpu-opteron
[2022-06-15T15:46:50.294] sched: Allocate JobId=43834 NodeList=cpu03 #CPUs=16 Partition=cpu-opteron
[2022-06-15T15:51:01.761] sched: Allocate JobId=43835 NodeList=cpu03 #CPUs=1 Partition=cpu-opteron
[2022-06-15T15:51:38.804] sched: Allocate JobId=43836 NodeList=cpu11 #CPUs=32 Partition=cpu-opteron
[2022-06-15T15:52:18.866] sched: Allocate JobId=43837 NodeList=cpu10 #CPUs=32 Partition=cpu-opteron
[2022-06-15T15:52:59.026] sched: Allocate JobId=43838 NodeList=cpu10 #CPUs=32 Partition=cpu-opteron
[2022-06-15T15:54:28.155] sched: Allocate JobId=43840 NodeList=cpu14 #CPUs=32 Partition=cpu-epyc
[2022-06-15T15:54:54.625] sched: Allocate JobId=43839 NodeList=cpu10 #CPUs=32 Partition=cpu-opteron
[2022-06-15T16:15:02.623] sched: Allocate JobId=43841 NodeList=cpu11 #CPUs=32 Partition=cpu-opteron
[2022-06-15T16:20:26.974] sched: Allocate JobId=43842 NodeList=cpu11 #CPUs=32 Partition=cpu-opteron
[2022-06-15T16:35:25.572] sched: Allocate JobId=43843 NodeList=cpu11 #CPUs=32 Partition=cpu-opteron
[2022-06-15T16:52:42.626] sched: Allocate JobId=43844 NodeList=cpu11 #CPUs=32 Partition=cpu-opteron
[2022-06-15T16:56:41.984] sched: Allocate JobId=43845 NodeList=cpu13 #CPUs=32 Partition=cpu-epyc
[2022-06-15T17:41:41.885] sched: Allocate JobId=43846 NodeList=cpu11 #CPUs=32 Partition=cpu-opteron
[2022-06-15T18:51:13.704] sched: Allocate JobId=43847 NodeList=cpu11 #CPUs=32 Partition=cpu-opteron
[2022-06-15T19:20:18.099] sched: Allocate JobId=43848 NodeList=cpu11 #CPUs=32 Partition=cpu-opteron
[2022-06-15T19:35:52.920] sched: Allocate JobId=43849 NodeList=cpu11 #CPUs=32 Partition=cpu-opteron
[2022-06-15T19:46:06.274] sched: Allocate JobId=43850 NodeList=cpu11 #CPUs=32 Partition=cpu-opteron
[2022-06-15T20:09:48.855] sched: Allocate JobId=43851 NodeList=cpu11 #CPUs=32 Partition=cpu-opteron
[2022-06-15T20:21:56.104] sched: Allocate JobId=43852 NodeList=cpu11 #CPUs=32 Partition=cpu-opteron
[2022-06-15T20:50:39.332] sched: Allocate JobId=43853 NodeList=cpu15 #CPUs=48 Partition=cpu-epyc
[2022-06-15T20:54:56.833] sched: Allocate JobId=43854 NodeList=cpu15 #CPUs=48 Partition=cpu-epyc
[2022-06-15T20:55:12.865] sched: Allocate JobId=43855 NodeList=cpu13 #CPUs=32 Partition=cpu-epyc
[2022-06-15T20:56:50.998] sched: Allocate JobId=43857 NodeList=cpu14 #CPUs=32 Partition=cpu-epyc
[2022-06-15T20:58:36.232] sched: Allocate JobId=43858 NodeList=cpu05 #CPUs=64 Partition=cpu-opteron
[2022-06-15T20:59:44.329] sched: Allocate JobId=43859 NodeList=cpu08 #CPUs=64 Partition=cpu-opteron
[2022-06-15T21:00:39.413] sched: Allocate JobId=43860 NodeList=cpu11 #CPUs=32 Partition=cpu-opteron
[2022-06-15T21:01:55.518] sched: Allocate JobId=43861 NodeList=cpu09 #CPUs=32 Partition=cpu-opteron
[2022-06-15T21:04:00.794] sched: Allocate JobId=43863 NodeList=cpu09 #CPUs=32 Partition=cpu-opteron
[2022-06-15T21:05:20.908] sched: Allocate JobId=43865 NodeList=cpu15 #CPUs=48 Partition=cpu-epyc
[2022-06-15T21:20:20.673] sched: Allocate JobId=43866 NodeList=gpu03 #CPUs=32 Partition=gpu-k10
[2022-06-15T21:50:41.890] sched: Allocate JobId=43864 NodeList=cpu11 #CPUs=32 Partition=cpu-opteron
[2022-06-15T22:52:09.025] sched: Allocate JobId=43867 NodeList=cpu15 #CPUs=1 Partition=cpu-epyc
[2022-06-15T22:53:45.282] sched: Allocate JobId=43868 NodeList=cpu15 #CPUs=1 Partition=cpu-epyc
[2022-06-15T22:54:30.345] sched: Allocate JobId=43869 NodeList=cpu15 #CPUs=1 Partition=cpu-epyc
[2022-06-15T23:56:09.307] sched: Allocate JobId=43871 NodeList=cpu15 #CPUs=48 Partition=cpu-epyc
[2022-06-16T00:05:16.601] sched: Allocate JobId=43872 NodeList=cpu15 #CPUs=48 Partition=cpu-epyc
[2022-06-16T00:05:16.602] sched: Allocate JobId=43873 NodeList=cpu15 #CPUs=48 Partition=cpu-epyc
[2022-06-16T00:19:13.944] sched: Allocate JobId=43874 NodeList=cpu15 #CPUs=48 Partition=cpu-epyc
[2022-06-16T00:21:46.293] sched: Allocate JobId=43875 NodeList=gpu03 #CPUs=32 Partition=gpu-k10
[2022-06-16T00:21:54.304] sched: Allocate JobId=43876 NodeList=cpu09 #CPUs=32 Partition=cpu-opteron
[2022-06-16T00:33:31.566] sched: Allocate JobId=43877 NodeList=gpu03 #CPUs=32 Partition=gpu-k10
[2022-06-16T09:08:05.325] sched: Allocate JobId=43878 NodeList=cpu09 #CPUs=32 Partition=cpu-opteron
[2022-06-16T09:10:12.511] sched: Allocate JobId=43879 NodeList=gpu04 #CPUs=16 Partition=gpu-k40c
[2022-06-16T09:17:28.532] sched: Allocate JobId=43880 NodeList=cpu11 #CPUs=32 Partition=cpu-opteron
[2022-06-16T10:06:14.472] sched: Allocate JobId=43881 NodeList=gpu03 #CPUs=32 Partition=gpu-k10
[2022-06-16T10:22:48.753] sched: _slurm_rpc_allocate_resources JobId=43882 NodeList=cpu03 usec=4651
[2022-06-16T10:34:40.873] sched: Allocate JobId=43883 NodeList=cpu04 #CPUs=16 Partition=cpu-opteron
[2022-06-16T10:34:43.859] sched: Allocate JobId=43884 NodeList=cpu04 #CPUs=16 Partition=cpu-opteron
[2022-06-16T10:48:46.616] sched: Allocate JobId=43885 NodeList=gpu02 #CPUs=8 Partition=gpu-titan
[2022-06-16T10:49:28.663] sched: Allocate JobId=43886 NodeList=gpu02 #CPUs=8 Partition=gpu-titan
[2022-06-16T11:07:45.725] sched: Allocate JobId=43887 NodeList=cpu15 #CPUs=64 Partition=cpu-epyc
[2022-06-16T11:10:04.918] sched: Allocate JobId=43888 NodeList=cpu12 #CPUs=48 Partition=cpu-epyc
[2022-06-16T11:11:59.090] sched: Allocate JobId=43889 NodeList=cpu04 #CPUs=32 Partition=cpu-opteron
[2022-06-16T11:12:07.099] sched: Allocate JobId=43890 NodeList=cpu09 #CPUs=32 Partition=cpu-opteron
[2022-06-16T11:17:07.647] sched: Allocate JobId=43891 NodeList=cpu15 #CPUs=64 Partition=cpu-epyc
[2022-06-16T11:29:59.069] sched: Allocate JobId=43892 NodeList=cpu13 #CPUs=32 Partition=cpu-epyc
[2022-06-16T11:43:17.703] sched: Allocate JobId=43894 NodeList=gpu02 #CPUs=16 Partition=gpu-titan
[2022-06-16T11:43:40.738] sched: Allocate JobId=43895 NodeList=cpu11 #CPUs=32 Partition=cpu-opteron
[2022-06-16T12:10:36.685] sched: Allocate JobId=43896 NodeList=cpu15 #CPUs=32 Partition=cpu-epyc
[2022-06-16T12:25:09.617] sched: Allocate JobId=43897 NodeList=cpu11 #CPUs=32 Partition=cpu-opteron
[2022-06-16T12:25:29.294] sched: Allocate JobId=43898 NodeList=cpu11 #CPUs=32 Partition=cpu-opteron
[2022-06-16T12:43:16.671] sched: Allocate JobId=43899 NodeList=cpu11 #CPUs=32 Partition=cpu-opteron
[2022-06-16T12:57:28.404] sched: Allocate JobId=43900 NodeList=cpu03 #CPUs=1 Partition=cpu-opteron
[2022-06-16T12:58:06.499] sched: Allocate JobId=43901 NodeList=cpu03 #CPUs=1 Partition=cpu-opteron
[2022-06-16T12:58:09.507] sched: Allocate JobId=43902 NodeList=cpu11 #CPUs=32 Partition=cpu-opteron
[2022-06-16T13:19:22.863] sched: Allocate JobId=43903 NodeList=cpu15 #CPUs=32 Partition=cpu-epyc
[2022-06-16T13:21:01.993] sched: Allocate JobId=43905 NodeList=cpu04 #CPUs=32 Partition=cpu-opteron
[2022-06-16T13:21:57.085] sched: Allocate JobId=43906 NodeList=cpu09 #CPUs=32 Partition=cpu-opteron
[2022-06-16T13:22:50.309] sched: Allocate JobId=43907 NodeList=cpu11 #CPUs=32 Partition=cpu-opteron
[2022-06-16T13:23:38.864] sched: _slurm_rpc_allocate_resources JobId=43908 NodeList=cpu03 usec=17201
[2022-06-16T14:22:06.750] sched: Allocate JobId=43910 NodeList=cpu11 #CPUs=32 Partition=cpu-opteron
[2022-06-16T14:31:32.117] sched: Allocate JobId=43912 NodeList=cpu12 #CPUs=1 Partition=cpu-epyc
[2022-06-16T14:36:58.701] sched: Allocate JobId=43913 NodeList=cpu12 #CPUs=8 Partition=cpu-epyc
[2022-06-16T14:41:14.181] sched: Allocate JobId=43914 NodeList=cpu12 #CPUs=8 Partition=cpu-epyc
[2022-06-16T14:49:25.128] sched: Allocate JobId=43915 NodeList=cpu12 #CPUs=8 Partition=cpu-epyc
[2022-06-16T14:54:39.710] sched: Allocate JobId=43916 NodeList=cpu03 #CPUs=1 Partition=cpu-opteron
[2022-06-16T14:55:33.774] sched: Allocate JobId=43917 NodeList=cpu03 #CPUs=1 Partition=cpu-opteron
[2022-06-16T14:56:13.831] sched: Allocate JobId=43918 NodeList=cpu12 #CPUs=8 Partition=cpu-epyc
[2022-06-16T14:57:55.090] sched: Allocate JobId=43919 NodeList=cpu03 #CPUs=1 Partition=cpu-opteron
[2022-06-16T14:58:46.162] sched: Allocate JobId=43920 NodeList=cpu03 #CPUs=2 Partition=cpu-opteron
[2022-06-16T15:00:17.285] sched: Allocate JobId=43921 NodeList=cpu12 #CPUs=8 Partition=cpu-epyc
[2022-06-16T15:00:44.574] sched: _slurm_rpc_allocate_resources JobId=43922 NodeList=cpu03 usec=1471
[2022-06-16T15:02:40.568] sched: Allocate JobId=43923 NodeList=cpu12 #CPUs=8 Partition=cpu-epyc
[2022-06-16T15:03:22.631] sched: Allocate JobId=43924 NodeList=cpu12 #CPUs=8 Partition=cpu-epyc
[2022-06-16T15:08:37.199] sched: Allocate JobId=43925 NodeList=cpu03 #CPUs=8 Partition=cpu-opteron
[2022-06-16T15:23:30.922] sched: Allocate JobId=43926 NodeList=cpu12 #CPUs=8 Partition=cpu-epyc
[2022-06-16T15:39:12.755] sched: Allocate JobId=43927 NodeList=cpu12 #CPUs=16 Partition=cpu-epyc
[2022-06-16T15:39:15.740] sched: Allocate JobId=43928 NodeList=gpu01 #CPUs=32 Partition=gpu-k10
[2022-06-16T15:43:28.303] sched: Allocate JobId=43929 NodeList=cpu12 #CPUs=16 Partition=cpu-epyc
[2022-06-16T15:43:31.307] sched: Allocate JobId=43930 NodeList=gpu01 #CPUs=32 Partition=gpu-k10
[2022-06-16T16:14:13.703] sched: Allocate JobId=43931 NodeList=gpu01 #CPUs=16 Partition=gpu-k10
[2022-06-16T16:44:37.055] sched: Allocate JobId=43934 NodeList=cpu03 #CPUs=1 Partition=cpu-opteron
[2022-06-16T16:47:15.274] sched: Allocate JobId=43935 NodeList=cpu03 #CPUs=1 Partition=cpu-opteron
[2022-06-16T16:48:55.592] sched: Allocate JobId=43936 NodeList=cpu11 #CPUs=32 Partition=cpu-opteron
[2022-06-16T16:55:21.250] sched: Allocate JobId=43937 NodeList=cpu03 #CPUs=1 Partition=cpu-opteron
[2022-06-16T16:55:30.259] sched: Allocate JobId=43938 NodeList=cpu11 #CPUs=32 Partition=cpu-opteron
[2022-06-16T17:15:17.467] sched: Allocate JobId=43939 NodeList=cpu10 #CPUs=32 Partition=cpu-opteron
[2022-06-16T17:31:20.242] sched: Allocate JobId=43940 NodeList=cpu10 #CPUs=32 Partition=cpu-opteron
[2022-06-16T18:06:20.335] sched: Allocate JobId=43941 NodeList=cpu03 #CPUs=32 Partition=cpu-opteron
[2022-06-16T18:06:37.711] sched: Allocate JobId=43947 NodeList=cpu03 #CPUs=32 Partition=cpu-opteron
[2022-06-16T18:07:50.542] sched: Allocate JobId=43942 NodeList=cpu03 #CPUs=32 Partition=cpu-opteron
[2022-06-16T18:07:53.515] sched: Allocate JobId=43943 NodeList=cpu03 #CPUs=32 Partition=cpu-opteron
[2022-06-16T18:07:56.123] sched: Allocate JobId=43944 NodeList=cpu03 #CPUs=32 Partition=cpu-opteron
[2022-06-16T18:07:58.761] sched: Allocate JobId=43945 NodeList=cpu03 #CPUs=32 Partition=cpu-opteron
[2022-06-16T18:08:01.375] sched: Allocate JobId=43946 NodeList=cpu03 #CPUs=32 Partition=cpu-opteron
[2022-06-16T18:18:53.599] sched: Allocate JobId=43948 NodeList=cpu03 #CPUs=32 Partition=cpu-opteron
[2022-06-16T18:19:08.618] sched: Allocate JobId=43949 NodeList=cpu03 #CPUs=32 Partition=cpu-opteron
[2022-06-16T18:20:05.706] sched: Allocate JobId=43950 NodeList=cpu03 #CPUs=31 Partition=cpu-opteron
[2022-06-16T18:20:46.767] sched: Allocate JobId=43951 NodeList=cpu03 #CPUs=32 Partition=cpu-opteron
[2022-06-16T18:21:40.847] sched: Allocate JobId=43952 NodeList=cpu03 #CPUs=32 Partition=cpu-opteron
[2022-06-16T18:23:20.080] sched: Allocate JobId=43953 NodeList=cpu03 #CPUs=32 Partition=cpu-opteron
[2022-06-16T18:33:10.173] sched: Allocate JobId=43954 NodeList=cpu03 #CPUs=32 Partition=cpu-opteron
[2022-06-16T18:34:22.279] sched: Allocate JobId=43955 NodeList=cpu03 #CPUs=32 Partition=cpu-opteron
[2022-06-16T18:34:55.326] sched: Allocate JobId=43956 NodeList=cpu03 #CPUs=32 Partition=cpu-opteron
[2022-06-16T18:35:51.414] sched: Allocate JobId=43957 NodeList=cpu03 #CPUs=32 Partition=cpu-opteron
[2022-06-16T18:47:55.872] sched: Allocate JobId=43958 NodeList=cpu12 #CPUs=16 Partition=cpu-epyc
[2022-06-16T18:58:20.024] sched: Allocate JobId=43959 NodeList=cpu03 #CPUs=32 Partition=cpu-opteron
[2022-06-16T20:00:30.945] sched: Allocate JobId=43960 NodeList=cpu11 #CPUs=32 Partition=cpu-opteron
[2022-06-16T20:30:07.273] sched: Allocate JobId=43961 NodeList=cpu11 #CPUs=32 Partition=cpu-opteron
[2022-06-16T20:53:20.048] sched: Allocate JobId=43962 NodeList=cpu03 #CPUs=32 Partition=cpu-opteron
[2022-06-16T21:09:47.898] sched: Allocate JobId=43963 NodeList=cpu05 #CPUs=32 Partition=cpu-opteron
[2022-06-16T21:15:30.499] sched: Allocate JobId=43964 NodeList=cpu05 #CPUs=32 Partition=cpu-opteron
[2022-06-16T21:25:32.668] sched: Allocate JobId=43965 NodeList=cpu05 #CPUs=32 Partition=cpu-opteron
[2022-06-16T21:29:24.164] sched: Allocate JobId=43966 NodeList=cpu05 #CPUs=1 Partition=cpu-opteron
[2022-06-16T21:31:24.330] sched: Allocate JobId=43967 NodeList=cpu05 #CPUs=64 Partition=cpu-opteron
[2022-06-16T21:33:58.678] sched: Allocate JobId=43968 NodeList=cpu08 #CPUs=32 Partition=cpu-opteron
[2022-06-16T21:59:53.738] sched: Allocate JobId=43969 NodeList=cpu11 #CPUs=32 Partition=cpu-opteron
[2022-06-16T22:00:37.800] sched: Allocate JobId=43970 NodeList=cpu11 #CPUs=32 Partition=cpu-opteron
[2022-06-16T22:01:33.888] sched: Allocate JobId=43971 NodeList=cpu11 #CPUs=32 Partition=cpu-opteron
[2022-06-16T22:02:23.041] sched: Allocate JobId=43972 NodeList=cpu11 #CPUs=32 Partition=cpu-opteron
[2022-06-16T22:18:28.948] sched: Allocate JobId=43974 NodeList=cpu11 #CPUs=32 Partition=cpu-opteron
[2022-06-16T22:19:14.002] sched: Allocate JobId=43975 NodeList=cpu08 #CPUs=64 Partition=cpu-opteron
[2022-06-16T22:20:48.138] sched: Allocate JobId=43976 NodeList=cpu13 #CPUs=32 Partition=cpu-epyc
[2022-06-16T22:22:06.253] sched: Allocate JobId=43977 NodeList=cpu14 #CPUs=32 Partition=cpu-epyc
[2022-06-16T22:32:25.518] sched: Allocate JobId=43978 NodeList=cpu11 #CPUs=32 Partition=cpu-opteron
[2022-06-17T07:39:30.561] sched: Allocate JobId=43979 NodeList=cpu09 #CPUs=32 Partition=cpu-opteron
[2022-06-17T07:40:20.619] sched: Allocate JobId=43980 NodeList=cpu03 #CPUs=32 Partition=cpu-opteron
[2022-06-17T07:41:30.724] sched: Allocate JobId=43981 NodeList=cpu09 #CPUs=32 Partition=cpu-opteron
[2022-06-17T07:42:25.899] sched: Allocate JobId=43982 NodeList=cpu03 #CPUs=32 Partition=cpu-opteron
[2022-06-17T09:16:57.662] sched: Allocate JobId=43983 NodeList=cpu13 #CPUs=8 Partition=cpu-epyc
[2022-06-17T09:34:06.761] sched: Allocate JobId=43984 NodeList=cpu09 #CPUs=1 Partition=cpu-opteron
[2022-06-17T09:34:12.743] sched: Allocate JobId=43985 NodeList=cpu09 #CPUs=1 Partition=cpu-opteron
[2022-06-17T10:02:33.733] sched: Allocate JobId=43986 NodeList=cpu09 #CPUs=32 Partition=cpu-opteron
[2022-06-17T10:03:34.810] sched: Allocate JobId=43987 NodeList=cpu03 #CPUs=32 Partition=cpu-opteron
[2022-06-17T10:04:41.907] sched: Allocate JobId=43988 NodeList=cpu13 #CPUs=32 Partition=cpu-epyc
[2022-06-17T10:39:55.261] sched: Allocate JobId=43990 NodeList=cpu13 #CPUs=32 Partition=cpu-epyc
[2022-06-17T11:56:20.303] sched: Allocate JobId=43989 NodeList=cpu09 #CPUs=32 Partition=cpu-opteron
[2022-06-17T14:22:10.691] sched: Allocate JobId=43992 NodeList=cpu05 #CPUs=64 Partition=cpu-opteron
[2022-06-17T14:23:46.971] sched: Allocate JobId=43993 NodeList=cpu15 #CPUs=32 Partition=cpu-epyc
[2022-06-17T14:25:16.100] sched: Allocate JobId=43994 NodeList=cpu09 #CPUs=16 Partition=cpu-opteron
[2022-06-17T14:26:30.206] sched: Allocate JobId=43995 NodeList=cpu15 #CPUs=32 Partition=cpu-epyc
[2022-06-17T14:28:55.547] sched: Allocate JobId=43996 NodeList=cpu09 #CPUs=16 Partition=cpu-opteron
[2022-06-17T14:29:12.585] sched: Allocate JobId=43997 NodeList=cpu01 #CPUs=32 Partition=cpu-opteron
[2022-06-17T14:29:35.607] sched: Allocate JobId=43998 NodeList=cpu09 #CPUs=16 Partition=cpu-opteron
[2022-06-17T15:53:33.527] sched: Allocate JobId=43999 NodeList=cpu04 #CPUs=32 Partition=cpu-opteron
[2022-06-17T15:58:42.059] sched: Allocate JobId=44000 NodeList=cpu09 #CPUs=8 Partition=cpu-opteron
[2022-06-17T15:59:02.074] sched: Allocate JobId=44001 NodeList=cpu04 #CPUs=32 Partition=cpu-opteron
[2022-06-17T16:00:22.191] sched: Allocate JobId=44002 NodeList=cpu04 #CPUs=32 Partition=cpu-opteron
[2022-06-17T16:01:07.255] sched: Allocate JobId=44003 NodeList=cpu09 #CPUs=8 Partition=cpu-opteron
[2022-06-17T16:01:13.120] sched: Allocate JobId=44004 NodeList=cpu04 #CPUs=32 Partition=cpu-opteron
[2022-06-17T16:04:13.636] sched: Allocate JobId=44005 NodeList=cpu09 #CPUs=8 Partition=cpu-opteron
[2022-06-17T16:05:09.717] sched: Allocate JobId=44006 NodeList=cpu09 #CPUs=8 Partition=cpu-opteron
[2022-06-17T16:07:20.905] sched: Allocate JobId=44007 NodeList=cpu09 #CPUs=8 Partition=cpu-opteron
[2022-06-17T16:08:46.106] sched: Allocate JobId=44008 NodeList=cpu09 #CPUs=8 Partition=cpu-opteron
[2022-06-17T16:11:41.349] sched: Allocate JobId=44009 NodeList=cpu09 #CPUs=8 Partition=cpu-opteron
[2022-06-17T16:13:08.592] sched: Allocate JobId=44010 NodeList=cpu09 #CPUs=8 Partition=cpu-opteron
[2022-06-17T16:14:25.704] sched: Allocate JobId=44011 NodeList=cpu09 #CPUs=8 Partition=cpu-opteron
[2022-06-17T16:16:34.888] sched: Allocate JobId=44012 NodeList=cpu09 #CPUs=8 Partition=cpu-opteron
[2022-06-17T16:18:02.118] sched: Allocate JobId=44013 NodeList=cpu09 #CPUs=8 Partition=cpu-opteron
[2022-06-17T16:30:07.416] sched: Allocate JobId=44014 NodeList=cpu09 #CPUs=8 Partition=cpu-opteron
[2022-06-17T16:31:04.497] sched: Allocate JobId=44015 NodeList=cpu09 #CPUs=8 Partition=cpu-opteron
[2022-06-17T16:31:57.571] sched: Allocate JobId=44016 NodeList=cpu09 #CPUs=8 Partition=cpu-opteron
[2022-06-17T16:33:16.816] sched: Allocate JobId=44017 NodeList=cpu09 #CPUs=8 Partition=cpu-opteron
[2022-06-17T16:34:10.982] sched: Allocate JobId=44018 NodeList=cpu09 #CPUs=1 Partition=cpu-opteron
[2022-06-17T16:40:27.529] sched: Allocate JobId=44019 NodeList=cpu09 #CPUs=8 Partition=cpu-opteron
[2022-06-17T16:42:00.612] sched: _slurm_rpc_allocate_resources JobId=44020 NodeList=cpu09 usec=1100
[2022-06-17T16:42:45.855] sched: Allocate JobId=44021 NodeList=cpu04 #CPUs=8 Partition=cpu-opteron
[2022-06-17T16:49:11.653] sched: _slurm_rpc_allocate_resources JobId=44022 NodeList=(null) usec=884
[2022-06-17T16:49:22.516] sched: Allocate JobId=44023 NodeList=cpu09 #CPUs=8 Partition=cpu-opteron
[2022-06-17T16:50:26.785] sched: _slurm_rpc_allocate_resources JobId=44024 NodeList=(null) usec=894
[2022-06-17T16:51:47.512] sched: _slurm_rpc_allocate_resources JobId=44025 NodeList=(null) usec=1209
[2022-06-17T16:52:46.079] sched: _slurm_rpc_allocate_resources JobId=44026 NodeList=(null) usec=866
[2022-06-17T16:53:22.945] sched: Allocate JobId=44027 NodeList=cpu09 #CPUs=8 Partition=cpu-opteron
[2022-06-17T16:56:45.299] sched: Allocate JobId=44028 NodeList=cpu09 #CPUs=1 Partition=cpu-opteron
[2022-06-17T16:59:02.303] sched: _slurm_rpc_allocate_resources JobId=44029 NodeList=cpu09 usec=3941
[2022-06-17T17:03:44.038] sched: Allocate JobId=44030 NodeList=cpu09 #CPUs=8 Partition=cpu-opteron
[2022-06-17T17:05:39.216] sched: Allocate JobId=44031 NodeList=cpu04 #CPUs=16 Partition=cpu-opteron
[2022-06-17T17:05:44.212] sched: Allocate JobId=44032 NodeList=cpu04 #CPUs=16 Partition=cpu-opteron
[2022-06-17T17:05:49.222] sched: Allocate JobId=44033 NodeList=cpu03 #CPUs=16 Partition=cpu-opteron
[2022-06-17T17:05:53.227] sched: Allocate JobId=44034 NodeList=cpu03 #CPUs=16 Partition=cpu-opteron
[2022-06-17T17:10:26.728] sched: Allocate JobId=44053 NodeList=cpu09 #CPUs=8 Partition=cpu-opteron
[2022-06-17T17:10:45.289] sched: Allocate JobId=44052 NodeList=cpu03 #CPUs=1 Partition=cpu-opteron
[2022-06-17T17:10:45.290] sched: Allocate JobId=44035 NodeList=cpu09 #CPUs=16 Partition=cpu-opteron
[2022-06-17T17:14:09.238] sched: Allocate JobId=44055 NodeList=gpu05 #CPUs=8 Partition=gpu-v100s
[2022-06-17T17:17:27.607] sched: Allocate JobId=44056 NodeList=gpu05 #CPUs=8 Partition=gpu-v100s
[2022-06-17T17:17:33.657] sched: Allocate JobId=44057 NodeList=cpu03 #CPUs=1 Partition=cpu-opteron
[2022-06-17T17:19:27.827] sched: Allocate JobId=44058 NodeList=cpu03 #CPUs=1 Partition=cpu-opteron
[2022-06-17T17:19:37.840] sched: Allocate JobId=44059 NodeList=gpu05 #CPUs=8 Partition=gpu-v100s
[2022-06-17T17:22:09.052] sched: Allocate JobId=44060 NodeList=gpu05 #CPUs=8 Partition=gpu-v100s
[2022-06-17T17:23:25.310] sched: Allocate JobId=44061 NodeList=gpu05 #CPUs=8 Partition=gpu-v100s
[2022-06-17T17:24:52.435] sched: Allocate JobId=44062 NodeList=gpu05 #CPUs=8 Partition=gpu-v100s
[2022-06-17T17:26:15.552] sched: Allocate JobId=44063 NodeList=gpu05 #CPUs=8 Partition=gpu-v100s
[2022-06-17T17:31:20.089] sched: Allocate JobId=44064 NodeList=gpu05 #CPUs=8 Partition=gpu-v100s
[2022-06-17T17:31:27.093] sched: Allocate JobId=44054 NodeList=cpu10 #CPUs=8 Partition=cpu-opteron
[2022-06-17T17:31:27.098] sched: Allocate JobId=44036 NodeList=cpu10 #CPUs=16 Partition=cpu-opteron
[2022-06-17T17:31:38.705] sched: Allocate JobId=44037 NodeList=cpu10 #CPUs=16 Partition=cpu-opteron
[2022-06-17T17:42:26.429] sched: Allocate JobId=44065 NodeList=gpu05 #CPUs=8 Partition=gpu-v100s
[2022-06-17T17:42:39.501] sched: _slurm_rpc_allocate_resources JobId=44066 NodeList=gpu01 usec=13760
[2022-06-17T17:43:46.585] sched: Allocate JobId=44067 NodeList=gpu05 #CPUs=8 Partition=gpu-v100s
[2022-06-17T17:45:00.691] sched: Allocate JobId=44068 NodeList=gpu05 #CPUs=8 Partition=gpu-v100s
[2022-06-17T17:45:44.752] sched: Allocate JobId=44069 NodeList=gpu05 #CPUs=8 Partition=gpu-v100s
[2022-06-17T17:46:51.849] sched: Allocate JobId=44070 NodeList=gpu05 #CPUs=8 Partition=gpu-v100s
[2022-06-17T18:20:26.918] sched: Allocate JobId=44071 NodeList=cpu03 #CPUs=32 Partition=cpu-opteron
[2022-06-17T18:20:59.229] sched: Allocate JobId=44038 NodeList=cpu03 #CPUs=16 Partition=cpu-opteron
[2022-06-17T18:20:59.229] sched: Allocate JobId=44039 NodeList=cpu03 #CPUs=16 Partition=cpu-opteron
[2022-06-17T18:31:12.878] sched: _slurm_rpc_allocate_resources JobId=44072 NodeList=gpu01 usec=4819
[2022-06-17T20:15:45.784] sched: Allocate JobId=44075 NodeList=gpu01 #CPUs=16 Partition=gpu-k10
[2022-06-17T20:17:01.852] sched: Allocate JobId=44076 NodeList=gpu01 #CPUs=16 Partition=gpu-k10
[2022-06-17T20:56:37.387] sched: _slurm_rpc_allocate_resources JobId=44078 NodeList=gpu01 usec=4681
[2022-06-17T20:58:34.946] sched: _slurm_rpc_allocate_resources JobId=44079 NodeList=gpu01 usec=1012
[2022-06-17T21:16:22.571] sched: Allocate JobId=44080 NodeList=gpu02 #CPUs=16 Partition=gpu-titan
[2022-06-17T21:18:07.851] sched: Allocate JobId=44081 NodeList=gpu02 #CPUs=16 Partition=gpu-titan
[2022-06-17T21:19:40.001] sched: Allocate JobId=44082 NodeList=gpu03 #CPUs=32 Partition=gpu-k10
[2022-06-17T21:24:48.583] sched: Allocate JobId=44084 NodeList=gpu02 #CPUs=16 Partition=gpu-titan
[2022-06-17T21:32:21.332] sched: Allocate JobId=44087 NodeList=cpu12 #CPUs=2 Partition=cpu-epyc
[2022-06-17T21:33:01.592] sched: _slurm_rpc_allocate_resources JobId=44088 NodeList=(null) usec=844
[2022-06-17T21:33:22.527] sched: Allocate JobId=44089 NodeList=cpu12 #CPUs=2 Partition=cpu-epyc
[2022-06-17T21:34:06.309] sched: _slurm_rpc_allocate_resources JobId=44090 NodeList=(null) usec=860
[2022-06-17T21:34:57.668] sched: Allocate JobId=44091 NodeList=gpu02 #CPUs=16 Partition=gpu-titan
[2022-06-17T21:36:54.833] sched: Allocate JobId=44092 NodeList=gpu02 #CPUs=16 Partition=gpu-titan
[2022-06-17T21:44:00.661] sched: Allocate JobId=44093 NodeList=gpu02 #CPUs=16 Partition=gpu-titan
[2022-06-17T21:44:38.719] sched: Allocate JobId=44094 NodeList=gpu02 #CPUs=16 Partition=gpu-titan
[2022-06-17T21:51:33.460] sched: Allocate JobId=44096 NodeList=gpu02 #CPUs=16 Partition=gpu-titan
[2022-06-17T21:57:45.226] sched: Allocate JobId=44097 NodeList=gpu02 #CPUs=16 Partition=gpu-titan
[2022-06-17T22:01:51.580] sched: Allocate JobId=44098 NodeList=gpu02 #CPUs=16 Partition=gpu-titan
[2022-06-17T22:03:37.853] sched: Allocate JobId=44099 NodeList=gpu02 #CPUs=16 Partition=gpu-titan
[2022-06-17T22:09:25.526] sched: Allocate JobId=44100 NodeList=gpu02 #CPUs=16 Partition=gpu-titan
[2022-06-17T22:13:22.996] sched: Allocate JobId=44101 NodeList=gpu02 #CPUs=16 Partition=gpu-titan
[2022-06-17T22:16:40.130] sched/backfill: _start_job: Started JobId=44102 in gpu-titan on gpu02
[2022-06-17T22:18:54.597] sched: Allocate JobId=44103 NodeList=gpu02 #CPUs=16 Partition=gpu-titan
[2022-06-17T22:18:58.150] sched: Allocate JobId=44083 NodeList=cpu11 #CPUs=1 Partition=cpu-opteron
[2022-06-17T22:18:58.152] sched: Allocate JobId=44095 NodeList=cpu11 #CPUs=1 Partition=cpu-opteron
[2022-06-17T22:18:58.164] sched: Allocate JobId=44040 NodeList=cpu11 #CPUs=16 Partition=cpu-opteron
[2022-06-17T22:19:29.695] sched: Allocate JobId=44073 NodeList=cpu08 #CPUs=32 Partition=cpu-opteron
[2022-06-17T22:19:29.696] sched: Allocate JobId=44074 NodeList=cpu08 #CPUs=32 Partition=cpu-opteron
[2022-06-17T22:19:50.679] sched: Allocate JobId=44104 NodeList=gpu02 #CPUs=16 Partition=gpu-titan
[2022-06-17T22:20:03.540] sched: Allocate JobId=44041 NodeList=cpu08 #CPUs=16 Partition=cpu-opteron
[2022-06-17T22:20:03.540] sched: Allocate JobId=44042 NodeList=cpu08 #CPUs=16 Partition=cpu-opteron
[2022-06-17T22:20:04.866] sched: Allocate JobId=44043 NodeList=cpu08 #CPUs=16 Partition=cpu-opteron
[2022-06-17T22:20:04.867] sched: Allocate JobId=44044 NodeList=cpu08 #CPUs=16 Partition=cpu-opteron
[2022-06-17T22:20:35.741] sched: Allocate JobId=44105 NodeList=gpu02 #CPUs=16 Partition=gpu-titan
[2022-06-17T22:21:20.808] sched: Allocate JobId=44106 NodeList=gpu02 #CPUs=16 Partition=gpu-titan
[2022-06-17T22:22:20.899] sched: Allocate JobId=44107 NodeList=gpu02 #CPUs=16 Partition=gpu-titan
[2022-06-17T22:22:46.035] sched: Allocate JobId=44108 NodeList=cpu14 #CPUs=2 Partition=cpu-epyc
[2022-06-17T22:26:00.322] sched: Allocate JobId=44109 NodeList=gpu02 #CPUs=16 Partition=gpu-titan
[2022-06-17T22:29:09.725] sched: Allocate JobId=44110 NodeList=gpu02 #CPUs=16 Partition=gpu-titan
[2022-06-17T22:43:15.557] sched: Allocate JobId=44045 NodeList=cpu11 #CPUs=16 Partition=cpu-opteron
[2022-06-17T22:50:52.199] sched: Allocate JobId=44114 NodeList=cpu14 #CPUs=2 Partition=cpu-epyc
[2022-06-17T23:16:48.874] sched: Allocate JobId=44077 NodeList=gpu02 #CPUs=16 Partition=gpu-titan
[2022-06-17T23:23:06.851] sched: Allocate JobId=44116 NodeList=cpu12 #CPUs=64 Partition=cpu-epyc
[2022-06-17T23:24:14.935] sched: Allocate JobId=44117 NodeList=cpu14 #CPUs=32 Partition=cpu-epyc
[2022-06-17T23:33:33.996] sched: Allocate JobId=44118 NodeList=cpu13 #CPUs=64 Partition=cpu-epyc
[2022-06-17T23:46:49.795] sched: Allocate JobId=44046 NodeList=cpu04 #CPUs=16 Partition=cpu-opteron
[2022-06-17T23:49:10.761] sched: Allocate JobId=44119 NodeList=cpu12 #CPUs=16 Partition=cpu-epyc
[2022-06-17T23:50:24.867] sched: Allocate JobId=44120 NodeList=cpu12 #CPUs=16 Partition=cpu-epyc
[2022-06-17T23:52:38.608] sched: Allocate JobId=44047 NodeList=cpu04 #CPUs=16 Partition=cpu-opteron
[2022-06-17T23:53:30.272] sched: Allocate JobId=44121 NodeList=cpu12 #CPUs=16 Partition=cpu-epyc
[2022-06-17T23:56:03.493] sched: Allocate JobId=44122 NodeList=cpu12 #CPUs=16 Partition=cpu-epyc
[2022-06-17T23:56:56.569] sched: Allocate JobId=44123 NodeList=cpu12 #CPUs=32 Partition=cpu-epyc
[2022-06-18T00:25:59.448] sched: Allocate JobId=44048 NodeList=cpu03 #CPUs=16 Partition=cpu-opteron
[2022-06-18T00:47:30.294] sched: Allocate JobId=44124 NodeList=gpu02 #CPUs=16 Partition=gpu-titan
[2022-06-18T00:48:19.388] sched: Allocate JobId=44125 NodeList=gpu01 #CPUs=16 Partition=gpu-k10
[2022-06-18T01:39:02.497] sched: Allocate JobId=44162 NodeList=cpu12 #CPUs=1 Partition=cpu-epyc
[2022-06-18T01:40:11.593] sched: Allocate JobId=44049 NodeList=cpu10 #CPUs=16 Partition=cpu-opteron
[2022-06-18T01:40:27.607] sched: Allocate JobId=44163 NodeList=cpu12 #CPUs=32 Partition=cpu-epyc
[2022-06-18T01:41:34.700] sched: Allocate JobId=44164 NodeList=cpu12 #CPUs=32 Partition=cpu-epyc
[2022-06-18T02:34:35.204] sched: Allocate JobId=44050 NodeList=cpu10 #CPUs=16 Partition=cpu-opteron
[2022-06-18T02:35:12.424] sched: Allocate JobId=44115 NodeList=cpu09 #CPUs=32 Partition=cpu-opteron
[2022-06-18T02:35:44.598] sched: Allocate JobId=44051 NodeList=cpu09 #CPUs=16 Partition=cpu-opteron
[2022-06-18T04:22:23.099] sched: Allocate JobId=44165 NodeList=cpu12 #CPUs=32 Partition=cpu-epyc
[2022-06-18T05:13:00.447] sched: Allocate JobId=44152 NodeList=cpu10 #CPUs=32 Partition=cpu-opteron
[2022-06-18T05:17:53.239] sched: Allocate JobId=44153 NodeList=cpu10 #CPUs=32 Partition=cpu-opteron
[2022-06-18T05:20:22.063] sched: Allocate JobId=44154 NodeList=cpu10 #CPUs=32 Partition=cpu-opteron
[2022-06-18T05:25:14.738] sched: Allocate JobId=44155 NodeList=cpu10 #CPUs=32 Partition=cpu-opteron
[2022-06-18T05:25:26.373] sched: Allocate JobId=44156 NodeList=cpu10 #CPUs=32 Partition=cpu-opteron
[2022-06-18T05:25:34.875] sched: Allocate JobId=44157 NodeList=cpu10 #CPUs=32 Partition=cpu-opteron
[2022-06-18T05:27:26.854] sched: Allocate JobId=44158 NodeList=cpu09 #CPUs=32 Partition=cpu-opteron
[2022-06-18T05:28:00.544] sched: Allocate JobId=44159 NodeList=cpu10 #CPUs=32 Partition=cpu-opteron
[2022-06-18T05:29:56.707] sched: Allocate JobId=44160 NodeList=cpu09 #CPUs=32 Partition=cpu-opteron
[2022-06-18T05:30:09.973] sched: Allocate JobId=44161 NodeList=cpu09 #CPUs=32 Partition=cpu-opteron
[2022-06-18T08:18:02.402] sched: Allocate JobId=44168 NodeList=cpu03 #CPUs=32 Partition=cpu-opteron
[2022-06-18T08:18:51.456] sched: Allocate JobId=44169 NodeList=cpu08 #CPUs=32 Partition=cpu-opteron
[2022-06-18T08:19:44.536] sched: Allocate JobId=44170 NodeList=cpu03 #CPUs=32 Partition=cpu-opteron
[2022-06-18T08:20:50.632] sched: Allocate JobId=44171 NodeList=cpu08 #CPUs=32 Partition=cpu-opteron
[2022-06-18T09:48:20.724] sched: Allocate JobId=44172 NodeList=cpu04 #CPUs=32 Partition=cpu-opteron
[2022-06-18T09:49:14.787] sched: Allocate JobId=44173 NodeList=cpu03 #CPUs=32 Partition=cpu-opteron
[2022-06-18T09:50:11.889] sched: Allocate JobId=44174 NodeList=cpu03 #CPUs=32 Partition=cpu-opteron
[2022-06-18T09:50:14.650] sched: Allocate JobId=44175 NodeList=cpu09 #CPUs=32 Partition=cpu-opteron
[2022-06-18T09:51:03.945] sched: Allocate JobId=44176 NodeList=cpu03 #CPUs=32 Partition=cpu-opteron
[2022-06-18T09:51:06.949] sched: Allocate JobId=44177 NodeList=cpu08 #CPUs=32 Partition=cpu-opteron
[2022-06-18T09:52:31.162] sched: Allocate JobId=44178 NodeList=cpu10 #CPUs=32 Partition=cpu-opteron
[2022-06-18T09:59:57.009] sched: Allocate JobId=44179 NodeList=cpu03 #CPUs=32 Partition=cpu-opteron
[2022-06-18T10:01:54.184] sched: Allocate JobId=44180 NodeList=cpu03 #CPUs=32 Partition=cpu-opteron
[2022-06-18T10:19:54.329] sched: Allocate JobId=44181 NodeList=cpu03 #CPUs=32 Partition=cpu-opteron
[2022-06-18T10:25:58.962] sched: Allocate JobId=44182 NodeList=cpu03 #CPUs=32 Partition=cpu-opteron
[2022-06-18T10:26:14.985] sched: Allocate JobId=44183 NodeList=cpu03 #CPUs=32 Partition=cpu-opteron
[2022-06-18T10:32:24.628] sched: Allocate JobId=44184 NodeList=cpu03 #CPUs=32 Partition=cpu-opteron
[2022-06-18T10:32:34.688] sched: Allocate JobId=44185 NodeList=cpu04 #CPUs=32 Partition=cpu-opteron
[2022-06-18T10:32:38.694] sched: Allocate JobId=44186 NodeList=cpu10 #CPUs=32 Partition=cpu-opteron
[2022-06-18T10:32:42.700] sched: Allocate JobId=44187 NodeList=cpu10 #CPUs=32 Partition=cpu-opteron
[2022-06-18T10:32:58.724] sched: Allocate JobId=44188 NodeList=cpu10 #CPUs=32 Partition=cpu-opteron
[2022-06-18T10:33:09.744] sched: Allocate JobId=44189 NodeList=cpu10 #CPUs=32 Partition=cpu-opteron
[2022-06-18T10:36:51.968] sched: Allocate JobId=44190 NodeList=cpu10 #CPUs=32 Partition=cpu-opteron
[2022-06-18T10:36:53.013] sched: Allocate JobId=44191 NodeList=cpu04 #CPUs=32 Partition=cpu-opteron
[2022-06-18T10:37:02.088] sched: Allocate JobId=44192 NodeList=cpu10 #CPUs=32 Partition=cpu-opteron
[2022-06-18T10:37:03.334] sched: Allocate JobId=44193 NodeList=cpu04 #CPUs=32 Partition=cpu-opteron
[2022-06-18T10:37:07.122] sched: Allocate JobId=44195 NodeList=cpu10 #CPUs=32 Partition=cpu-opteron
[2022-06-18T10:39:13.369] sched: Allocate JobId=44196 NodeList=gpu02 #CPUs=8 Partition=gpu-titan
[2022-06-18T10:39:33.119] sched: _slurm_rpc_allocate_resources JobId=44197 NodeList=cpu08 usec=15136
[2022-06-18T10:43:31.870] sched: Allocate JobId=44198 NodeList=cpu08 #CPUs=1 Partition=cpu-opteron
[2022-06-18T10:59:34.547] sched: Allocate JobId=44199 NodeList=cpu10 #CPUs=32 Partition=cpu-opteron
[2022-06-18T11:00:52.658] sched: Allocate JobId=44200 NodeList=cpu10 #CPUs=32 Partition=cpu-opteron
[2022-06-18T11:01:15.984] sched: _slurm_rpc_allocate_resources JobId=44201 NodeList=cpu08 usec=4086
[2022-06-18T11:01:38.729] sched: Allocate JobId=44202 NodeList=cpu10 #CPUs=32 Partition=cpu-opteron
[2022-06-18T11:03:09.001] sched: Allocate JobId=44203 NodeList=cpu10 #CPUs=32 Partition=cpu-opteron
[2022-06-18T11:19:43.842] sched: Allocate JobId=44204 NodeList=cpu01 #CPUs=32 Partition=cpu-opteron
[2022-06-18T11:24:18.366] sched: Allocate JobId=44205 NodeList=cpu03 #CPUs=32 Partition=cpu-opteron
[2022-06-18T11:31:36.034] sched: _slurm_rpc_allocate_resources JobId=44206 NodeList=cpu08 usec=4325
[2022-06-18T11:33:51.433] sched: Allocate JobId=44207 NodeList=cpu03 #CPUs=32 Partition=cpu-opteron
[2022-06-18T11:38:40.333] sched: _slurm_rpc_allocate_resources JobId=44208 NodeList=cpu08 usec=1303
[2022-06-18T11:45:51.680] sched: Allocate JobId=44209 NodeList=cpu10 #CPUs=32 Partition=cpu-opteron
[2022-06-18T11:56:22.834] sched: Allocate JobId=44210 NodeList=cpu03 #CPUs=32 Partition=cpu-opteron
[2022-06-18T12:31:05.694] sched: Allocate JobId=44211 NodeList=cpu03 #CPUs=32 Partition=cpu-opteron
[2022-06-18T12:31:52.756] sched: Allocate JobId=44212 NodeList=cpu04 #CPUs=32 Partition=cpu-opteron
[2022-06-18T12:38:47.545] sched: Allocate JobId=44213 NodeList=cpu03 #CPUs=32 Partition=cpu-opteron
[2022-06-18T12:48:44.670] sched: Allocate JobId=44215 NodeList=cpu03 #CPUs=32 Partition=cpu-opteron
[2022-06-18T14:52:56.091] sched: Allocate JobId=44216 NodeList=cpu12 #CPUs=16 Partition=cpu-epyc
[2022-06-18T15:00:08.809] sched: Allocate JobId=44217 NodeList=cpu13 #CPUs=16 Partition=cpu-epyc
[2022-06-18T15:16:20.515] sched: Allocate JobId=44218 NodeList=cpu13 #CPUs=16 Partition=cpu-epyc
[2022-06-18T15:46:04.830] sched: Allocate JobId=44219 NodeList=cpu14 #CPUs=16 Partition=cpu-epyc
[2022-06-18T15:47:15.932] sched: Allocate JobId=44220 NodeList=cpu15 #CPUs=16 Partition=cpu-epyc
[2022-06-18T15:49:54.442] sched: Allocate JobId=44221 NodeList=cpu03 #CPUs=64 Partition=cpu-opteron
[2022-06-18T15:51:26.577] sched: Allocate JobId=44222 NodeList=cpu04 #CPUs=64 Partition=cpu-opteron
[2022-06-18T16:04:30.296] sched: Allocate JobId=44223 NodeList=cpu01 #CPUs=32 Partition=cpu-opteron
[2022-06-18T16:04:34.283] sched: Allocate JobId=44224 NodeList=cpu05 #CPUs=32 Partition=cpu-opteron
[2022-06-18T16:49:30.298] sched: Allocate JobId=44228 NodeList=cpu01 #CPUs=2 Partition=cpu-opteron
[2022-06-18T16:52:01.500] sched: Allocate JobId=44229 NodeList=cpu01 #CPUs=2 Partition=cpu-opteron
[2022-06-18T16:53:14.742] sched: Allocate JobId=44230 NodeList=gpu05 #CPUs=8 Partition=gpu-v100s
[2022-06-18T16:53:35.759] sched: Allocate JobId=44231 NodeList=cpu01 #CPUs=2 Partition=cpu-opteron
[2022-06-18T17:05:43.054] sched: Allocate JobId=44232 NodeList=gpu05 #CPUs=8 Partition=gpu-v100s
[2022-06-18T17:08:02.391] sched: Allocate JobId=44233 NodeList=gpu05 #CPUs=8 Partition=gpu-v100s
[2022-06-18T17:08:26.428] sched: Allocate JobId=44234 NodeList=cpu01 #CPUs=2 Partition=cpu-opteron
[2022-06-18T17:08:58.472] sched: Allocate JobId=44235 NodeList=gpu05 #CPUs=8 Partition=gpu-v100s
[2022-06-18T17:20:56.760] sched: Allocate JobId=44236 NodeList=gpu05 #CPUs=8 Partition=gpu-v100s
[2022-06-18T17:24:41.197] sched: Allocate JobId=44237 NodeList=gpu05 #CPUs=8 Partition=gpu-v100s
[2022-06-18T17:33:15.188] sched: Allocate JobId=44238 NodeList=gpu05 #CPUs=8 Partition=gpu-v100s
[2022-06-18T17:33:57.248] sched: Allocate JobId=44239 NodeList=cpu01 #CPUs=4 Partition=cpu-opteron
[2022-06-18T17:36:00.420] sched: Allocate JobId=44240 NodeList=cpu01 #CPUs=4 Partition=cpu-opteron
[2022-06-18T17:40:59.996] sched: Allocate JobId=44241 NodeList=cpu01 #CPUs=4 Partition=cpu-opteron
[2022-06-18T17:43:39.366] sched: Allocate JobId=44242 NodeList=gpu05 #CPUs=8 Partition=gpu-v100s
[2022-06-18T17:48:38.880] sched: Allocate JobId=44243 NodeList=gpu05 #CPUs=8 Partition=gpu-v100s
[2022-06-18T17:53:02.388] sched: Allocate JobId=44244 NodeList=gpu05 #CPUs=8 Partition=gpu-v100s
[2022-06-18T17:53:50.460] sched: Allocate JobId=44245 NodeList=gpu05 #CPUs=8 Partition=gpu-v100s
[2022-06-18T17:54:27.509] sched: Allocate JobId=44246 NodeList=gpu05 #CPUs=8 Partition=gpu-v100s
[2022-06-18T18:02:03.287] sched: Allocate JobId=44247 NodeList=gpu05 #CPUs=8 Partition=gpu-v100s
[2022-06-18T18:11:14.426] sched: Allocate JobId=44248 NodeList=gpu05 #CPUs=8 Partition=gpu-v100s
[2022-06-18T18:12:11.504] sched: Allocate JobId=44249 NodeList=gpu05 #CPUs=8 Partition=gpu-v100s
[2022-06-18T18:20:53.471] sched: Allocate JobId=44250 NodeList=gpu05 #CPUs=8 Partition=gpu-v100s
[2022-06-18T18:27:45.339] sched: Allocate JobId=44251 NodeList=gpu05 #CPUs=8 Partition=gpu-v100s
[2022-06-18T18:30:17.552] sched: Allocate JobId=44252 NodeList=gpu05 #CPUs=8 Partition=gpu-v100s
[2022-06-18T18:31:43.089] sched/backfill: _start_job: Started JobId=44253 in gpu-v100s on gpu05
[2022-06-18T18:33:15.972] sched: Allocate JobId=44254 NodeList=gpu05 #CPUs=8 Partition=gpu-v100s
[2022-06-18T18:51:15.875] sched: Allocate JobId=44255 NodeList=gpu05 #CPUs=8 Partition=gpu-v100s
[2022-06-18T18:51:56.931] sched: Allocate JobId=44256 NodeList=gpu05 #CPUs=8 Partition=gpu-v100s
[2022-06-18T18:52:36.106] sched: Allocate JobId=44257 NodeList=gpu05 #CPUs=8 Partition=gpu-v100s
[2022-06-18T19:14:25.410] sched: Allocate JobId=44258 NodeList=gpu05 #CPUs=8 Partition=gpu-v100s
[2022-06-18T21:14:42.660] sched: Allocate JobId=44259 NodeList=gpu03 #CPUs=16 Partition=gpu-k10
[2022-06-18T21:21:21.328] sched: Allocate JobId=44260 NodeList=cpu05 #CPUs=32 Partition=cpu-opteron
[2022-06-18T21:22:12.384] sched: Allocate JobId=44261 NodeList=cpu11 #CPUs=32 Partition=cpu-opteron
[2022-06-18T21:23:14.557] sched: Allocate JobId=44262 NodeList=cpu08 #CPUs=32 Partition=cpu-opteron
[2022-06-18T21:24:02.626] sched: Allocate JobId=44263 NodeList=cpu09 #CPUs=32 Partition=cpu-opteron
[2022-06-18T21:57:13.254] sched: Allocate JobId=44264 NodeList=gpu02 #CPUs=4 Partition=gpu-titan
[2022-06-18T22:32:38.188] sched: _slurm_rpc_allocate_resources JobId=44265 NodeList=cpu01 usec=4360
[2022-06-18T22:42:30.332] sched: Allocate JobId=44266 NodeList=gpu02 #CPUs=8 Partition=gpu-titan
[2022-06-18T22:44:49.551] sched: Allocate JobId=44267 NodeList=gpu02 #CPUs=8 Partition=gpu-titan
[2022-06-18T22:46:10.674] sched: Allocate JobId=44268 NodeList=gpu02 #CPUs=8 Partition=gpu-titan
[2022-06-18T22:47:07.760] sched: Allocate JobId=44269 NodeList=gpu02 #CPUs=8 Partition=gpu-titan
[2022-06-18T22:48:46.020] sched: Allocate JobId=44270 NodeList=gpu02 #CPUs=8 Partition=gpu-titan
[2022-06-18T23:19:37.726] sched: Allocate JobId=44271 NodeList=cpu01 #CPUs=1 Partition=cpu-opteron
[2022-06-18T23:20:12.759] sched: Allocate JobId=44272 NodeList=cpu01 #CPUs=1 Partition=cpu-opteron
[2022-06-18T23:22:19.943] sched: Allocate JobId=44273 NodeList=cpu01 #CPUs=1 Partition=cpu-opteron
[2022-06-18T23:23:06.139] sched: Allocate JobId=44274 NodeList=cpu05 #CPUs=64 Partition=cpu-opteron
[2022-06-18T23:38:40.830] sched: Allocate JobId=44275 NodeList=gpu05 #CPUs=8 Partition=gpu-v100s
[2022-06-18T23:44:37.464] sched: Allocate JobId=44276 NodeList=gpu05 #CPUs=8 Partition=gpu-v100s
[2022-06-18T23:50:36.105] sched: Allocate JobId=44277 NodeList=gpu05 #CPUs=8 Partition=gpu-v100s
[2022-06-18T23:55:21.600] sched: Allocate JobId=44278 NodeList=gpu05 #CPUs=8 Partition=gpu-v100s
[2022-06-19T00:01:21.181] sched: Allocate JobId=44279 NodeList=gpu05 #CPUs=8 Partition=gpu-v100s
[2022-06-19T00:09:47.141] sched: Allocate JobId=44280 NodeList=gpu05 #CPUs=8 Partition=gpu-v100s
[2022-06-19T00:14:53.706] sched: Allocate JobId=44281 NodeList=gpu05 #CPUs=8 Partition=gpu-v100s
[2022-06-19T01:46:47.525] sched: Allocate JobId=44282 NodeList=gpu05 #CPUs=8 Partition=gpu-v100s
[2022-06-19T03:16:30.407] sched: _slurm_rpc_allocate_resources JobId=44283 NodeList=cpu12 usec=4865
[2022-06-19T07:35:21.791] sched: Allocate JobId=44284 NodeList=gpu02 #CPUs=16 Partition=gpu-titan
[2022-06-19T07:37:31.119] sched: Allocate JobId=44285 NodeList=gpu02 #CPUs=16 Partition=gpu-titan
[2022-06-19T07:39:35.338] sched: Allocate JobId=44286 NodeList=gpu02 #CPUs=16 Partition=gpu-titan
[2022-06-19T07:42:06.268] sched: Allocate JobId=44287 NodeList=gpu02 #CPUs=16 Partition=gpu-titan
[2022-06-19T08:13:43.402] sched/backfill: _start_job: Started JobId=44295 in gpu-titan on gpu02
[2022-06-19T10:27:16.251] sched: Allocate JobId=44296 NodeList=cpu12 #CPUs=32 Partition=cpu-epyc
[2022-06-19T10:37:06.239] sched: Allocate JobId=44297 NodeList=cpu01 #CPUs=32 Partition=cpu-opteron
[2022-06-19T10:40:57.668] sched: Allocate JobId=44298 NodeList=cpu11 #CPUs=32 Partition=cpu-opteron
[2022-06-19T11:25:54.146] sched: Allocate JobId=44299 NodeList=gpu02 #CPUs=4 Partition=gpu-titan
[2022-06-19T11:25:54.147] sched: Allocate JobId=44300 NodeList=gpu02 #CPUs=4 Partition=gpu-titan
[2022-06-19T11:34:42.843] sched: Allocate JobId=44301 NodeList=gpu02 #CPUs=4 Partition=gpu-titan
[2022-06-19T11:35:31.914] sched: Allocate JobId=44302 NodeList=gpu02 #CPUs=4 Partition=gpu-titan
[2022-06-19T14:37:01.263] sched: Allocate JobId=44303 NodeList=gpu02 #CPUs=4 Partition=gpu-titan
[2022-06-19T14:37:07.256] sched: Allocate JobId=44304 NodeList=gpu02 #CPUs=4 Partition=gpu-titan
[2022-06-19T14:42:18.878] sched: Allocate JobId=44307 NodeList=cpu15 #CPUs=16 Partition=cpu-epyc
[2022-06-19T15:09:17.269] sched: Allocate JobId=44305 NodeList=gpu02 #CPUs=4 Partition=gpu-titan
[2022-06-19T15:57:42.628] sched: Allocate JobId=43911 NodeList=gpu05 #CPUs=16 Partition=gpu-v100s
[2022-06-19T15:57:42.629] sched: Allocate JobId=43991 NodeList=gpu05 #CPUs=16 Partition=gpu-v100s
[2022-06-19T15:57:43.337] sched: Allocate JobId=44085 NodeList=gpu05 #CPUs=32 Partition=gpu-v100s
[2022-06-19T16:20:59.175] sched: Allocate JobId=43870 NodeList=gpu05 #CPUs=16 Partition=gpu-v100s
[2022-06-19T16:20:59.194] sched: Allocate JobId=43932 NodeList=gpu05 #CPUs=16 Partition=gpu-v100s
[2022-06-19T16:23:40.594] sched: Allocate JobId=44308 NodeList=gpu05 #CPUs=8 Partition=gpu-v100s
[2022-06-19T17:11:37.131] sched: Allocate JobId=44306 NodeList=gpu02 #CPUs=4 Partition=gpu-titan
[2022-06-19T17:29:42.108] sched: Allocate JobId=43933 NodeList=gpu05 #CPUs=16 Partition=gpu-v100s
[2022-06-19T18:07:41.549] sched: Allocate JobId=44225 NodeList=gpu05 #CPUs=16 Partition=gpu-v100s
[2022-06-19T18:19:44.704] sched: Allocate JobId=44310 NodeList=gpu02 #CPUs=4 Partition=gpu-titan
[2022-06-19T18:19:47.705] sched: Allocate JobId=44311 NodeList=gpu02 #CPUs=4 Partition=gpu-titan
[2022-06-19T18:19:50.710] sched: Allocate JobId=44312 NodeList=gpu02 #CPUs=4 Partition=gpu-titan
[2022-06-19T18:21:58.894] sched: Allocate JobId=44313 NodeList=gpu02 #CPUs=4 Partition=gpu-titan
[2022-06-19T18:23:50.165] sched: Allocate JobId=44314 NodeList=gpu02 #CPUs=4 Partition=gpu-titan
[2022-06-19T18:25:18.295] sched: Allocate JobId=44315 NodeList=gpu02 #CPUs=4 Partition=gpu-titan
[2022-06-19T18:25:21.299] sched: Allocate JobId=44316 NodeList=gpu02 #CPUs=4 Partition=gpu-titan
[2022-06-19T18:25:54.728] sched: Allocate JobId=44317 NodeList=gpu02 #CPUs=4 Partition=gpu-titan
[2022-06-19T18:25:57.095] sched: Allocate JobId=44318 NodeList=gpu02 #CPUs=4 Partition=gpu-titan
[2022-06-19T18:38:20.979] sched: Allocate JobId=44226 NodeList=gpu05 #CPUs=16 Partition=gpu-v100s
[2022-06-19T19:02:46.612] sched: Allocate JobId=44319 NodeList=gpu02 #CPUs=4 Partition=gpu-titan
[2022-06-19T19:03:41.677] sched: Allocate JobId=44320 NodeList=gpu02 #CPUs=4 Partition=gpu-titan
[2022-06-19T19:17:43.672] sched: Allocate JobId=44309 NodeList=gpu05 #CPUs=16 Partition=gpu-v100s
[2022-06-19T19:33:45.160] sched: Allocate JobId=44323 NodeList=cpu12 #CPUs=32 Partition=cpu-epyc
[2022-06-19T19:43:09.482] sched: Allocate JobId=44321 NodeList=gpu02 #CPUs=4 Partition=gpu-titan
[2022-06-19T19:47:38.393] sched: Allocate JobId=44322 NodeList=gpu05 #CPUs=16 Partition=gpu-v100s
[2022-06-19T20:22:44.782] sched: Allocate JobId=44324 NodeList=gpu05 #CPUs=8 Partition=gpu-v100s
[2022-06-19T20:25:37.020] sched: Allocate JobId=44325 NodeList=gpu05 #CPUs=8 Partition=gpu-v100s
[2022-06-19T21:37:57.149] sched: Allocate JobId=44326 NodeList=gpu05 #CPUs=16 Partition=gpu-v100s
[2022-06-19T22:38:59.377] sched: Allocate JobId=44327 NodeList=gpu05 #CPUs=16 Partition=gpu-v100s
[2022-06-19T23:41:43.742] sched/backfill: _start_job: Started JobId=44329 in cpu-opteron on cpu11
[2022-06-20T01:05:54.155] sched: Allocate JobId=44328 NodeList=gpu05 #CPUs=16 Partition=gpu-v100s
[2022-06-20T01:31:58.493] sched: Allocate JobId=44292 NodeList=gpu05 #CPUs=64 Partition=gpu-v100s
[2022-06-20T07:50:14.694] sched: Allocate JobId=44330 NodeList=gpu05 #CPUs=32 Partition=gpu-v100s
[2022-06-20T07:51:11.764] sched: Allocate JobId=44331 NodeList=gpu05 #CPUs=32 Partition=gpu-v100s
[2022-06-20T07:52:55.066] sched: Allocate JobId=44332 NodeList=gpu05 #CPUs=64 Partition=gpu-v100s
[2022-06-20T07:55:00.252] sched: Allocate JobId=44333 NodeList=gpu05 #CPUs=64 Partition=gpu-v100s
[2022-06-20T07:57:01.694] sched: Allocate JobId=44334 NodeList=gpu05 #CPUs=32 Partition=gpu-v100s
[2022-06-20T07:57:20.453] sched: Allocate JobId=44335 NodeList=gpu05 #CPUs=32 Partition=gpu-v100s
[2022-06-20T07:58:21.655] sched: Allocate JobId=44336 NodeList=gpu05 #CPUs=32 Partition=gpu-v100s
[2022-06-20T07:59:12.729] sched: Allocate JobId=44337 NodeList=gpu05 #CPUs=32 Partition=gpu-v100s
[2022-06-20T08:01:43.953] sched: Allocate JobId=44338 NodeList=gpu05 #CPUs=32 Partition=gpu-v100s
[2022-06-20T08:03:01.211] sched: Allocate JobId=44339 NodeList=gpu05 #CPUs=64 Partition=gpu-v100s
[2022-06-20T08:04:27.333] sched: Allocate JobId=44340 NodeList=gpu05 #CPUs=64 Partition=gpu-v100s
[2022-06-20T08:08:18.857] sched: Allocate JobId=44341 NodeList=gpu05 #CPUs=32 Partition=gpu-v100s
[2022-06-20T08:09:23.970] sched: Allocate JobId=44342 NodeList=gpu05 #CPUs=16 Partition=gpu-v100s
[2022-06-20T08:10:57.086] sched: Allocate JobId=44343 NodeList=gpu05 #CPUs=16 Partition=gpu-v100s
[2022-06-20T08:12:54.430] sched: Allocate JobId=44345 NodeList=gpu05 #CPUs=32 Partition=gpu-v100s
[2022-06-20T08:14:28.566] sched: Allocate JobId=44346 NodeList=gpu05 #CPUs=32 Partition=gpu-v100s
[2022-06-20T08:17:02.375] sched: Allocate JobId=44347 NodeList=gpu05 #CPUs=32 Partition=gpu-v100s
[2022-06-20T08:18:38.107] sched: Allocate JobId=44348 NodeList=gpu05 #CPUs=32 Partition=gpu-v100s
[2022-06-20T08:20:29.265] sched: Allocate JobId=44349 NodeList=gpu05 #CPUs=32 Partition=gpu-v100s
[2022-06-20T08:48:44.858] sched: Allocate JobId=44353 NodeList=cpu13 #CPUs=16 Partition=cpu-epyc
[2022-06-20T08:54:12.429] sched: Allocate JobId=44354 NodeList=cpu13 #CPUs=16 Partition=cpu-epyc
[2022-06-20T08:57:05.031] sched: _slurm_rpc_allocate_resources JobId=44355 NodeList=cpu03 usec=14711
[2022-06-20T09:18:28.796] sched: Allocate JobId=44357 NodeList=cpu03 #CPUs=48 Partition=cpu-opteron
[2022-06-20T10:17:23.064] sched: Allocate JobId=44359 NodeList=cpu13 #CPUs=16 Partition=cpu-epyc
[2022-06-20T10:17:53.200] sched: Allocate JobId=44360 NodeList=gpu02 #CPUs=8 Partition=gpu-titan
[2022-06-20T10:40:02.911] sched: Allocate JobId=44362 NodeList=gpu02 #CPUs=8 Partition=gpu-titan
[2022-06-20T11:49:54.984] sched: Allocate JobId=44363 NodeList=cpu03 #CPUs=16 Partition=cpu-opteron
[2022-06-20T12:13:28.590] sched: Allocate JobId=44364 NodeList=cpu15 #CPUs=32 Partition=cpu-epyc
[2022-06-20T12:16:36.865] sched: Allocate JobId=44365 NodeList=cpu13 #CPUs=16 Partition=cpu-epyc
[2022-06-20T12:24:52.810] sched: Allocate JobId=44366 NodeList=cpu03 #CPUs=4 Partition=cpu-opteron
[2022-06-20T12:25:27.856] sched: Allocate JobId=44367 NodeList=cpu03 #CPUs=4 Partition=cpu-opteron
[2022-06-20T12:28:49.242] sched: Allocate JobId=44368 NodeList=cpu03 #CPUs=4 Partition=cpu-opteron
[2022-06-20T12:29:19.285] sched: Allocate JobId=44369 NodeList=cpu03 #CPUs=4 Partition=cpu-opteron
[2022-06-20T12:29:50.328] sched: Allocate JobId=44370 NodeList=cpu03 #CPUs=4 Partition=cpu-opteron
[2022-06-20T12:32:20.545] sched: Allocate JobId=44371 NodeList=cpu03 #CPUs=4 Partition=cpu-opteron
[2022-06-20T12:33:04.704] sched: Allocate JobId=44372 NodeList=cpu03 #CPUs=4 Partition=cpu-opteron
[2022-06-20T12:33:32.740] sched: Allocate JobId=44373 NodeList=cpu03 #CPUs=4 Partition=cpu-opteron
[2022-06-20T12:36:58.039] sched: Allocate JobId=44374 NodeList=cpu03 #CPUs=4 Partition=cpu-opteron
[2022-06-20T12:39:15.318] sched: Allocate JobId=44375 NodeList=cpu03 #CPUs=4 Partition=cpu-opteron
[2022-06-20T12:43:29.367] sched: Allocate JobId=44361 NodeList=gpu05 #CPUs=16 Partition=gpu-v100s
[2022-06-20T12:45:18.984] sched: Allocate JobId=44376 NodeList=cpu03 #CPUs=4 Partition=cpu-opteron
[2022-06-20T12:45:52.030] sched: Allocate JobId=44377 NodeList=cpu03 #CPUs=4 Partition=cpu-opteron
[2022-06-20T12:48:32.426] sched: Allocate JobId=44378 NodeList=cpu03 #CPUs=4 Partition=cpu-opteron
[2022-06-20T14:45:36.377] sched: Allocate JobId=44379 NodeList=cpu01 #CPUs=16 Partition=cpu-opteron
[2022-06-20T14:46:22.446] sched: Allocate JobId=44380 NodeList=cpu01 #CPUs=1 Partition=cpu-opteron
[2022-06-20T14:48:59.783] sched: Allocate JobId=44381 NodeList=cpu01 #CPUs=16 Partition=cpu-opteron
[2022-06-20T14:49:07.159] sched: _slurm_rpc_allocate_resources JobId=44382 NodeList=cpu01 usec=13632
[2022-06-20T14:49:17.810] sched: Allocate JobId=44383 NodeList=cpu13 #CPUs=16 Partition=cpu-epyc
[2022-06-20T14:49:36.848] sched: Allocate JobId=44384 NodeList=gpu02 #CPUs=8 Partition=gpu-titan
[2022-06-20T14:49:49.855] sched: Allocate JobId=44385 NodeList=cpu13 #CPUs=16 Partition=cpu-epyc
[2022-06-20T14:50:37.925] sched: Allocate JobId=44386 NodeList=gpu02 #CPUs=8 Partition=gpu-titan
[2022-06-20T14:53:06.244] sched: Allocate JobId=44387 NodeList=cpu01 #CPUs=16 Partition=cpu-opteron
[2022-06-20T14:54:02.352] sched: Allocate JobId=44388 NodeList=cpu01 #CPUs=4 Partition=cpu-opteron
[2022-06-20T14:54:17.348] sched: Allocate JobId=44389 NodeList=cpu01 #CPUs=16 Partition=cpu-opteron
[2022-06-20T14:55:43.476] sched: Allocate JobId=44390 NodeList=cpu01 #CPUs=16 Partition=cpu-opteron
[2022-06-20T14:58:25.015] sched: Allocate JobId=44391 NodeList=cpu01 #CPUs=16 Partition=cpu-opteron
[2022-06-20T14:58:48.061] sched: Allocate JobId=44392 NodeList=cpu01 #CPUs=4 Partition=cpu-opteron
[2022-06-20T14:59:20.095] sched: Allocate JobId=44393 NodeList=cpu01 #CPUs=16 Partition=cpu-opteron
[2022-06-20T14:59:23.100] sched: Allocate JobId=44394 NodeList=cpu03 #CPUs=16 Partition=cpu-opteron
[2022-06-20T15:00:08.163] sched: Allocate JobId=44395 NodeList=gpu02 #CPUs=1 Partition=gpu-titan
[2022-06-20T15:01:33.287] sched: Allocate JobId=44396 NodeList=cpu01 #CPUs=4 Partition=cpu-opteron
[2022-06-20T15:01:43.302] sched: Allocate JobId=44397 NodeList=cpu01 #CPUs=16 Partition=cpu-opteron
[2022-06-20T15:02:20.354] sched: Allocate JobId=44398 NodeList=cpu01 #CPUs=4 Partition=cpu-opteron
[2022-06-20T15:02:33.428] sched: Allocate JobId=44399 NodeList=gpu02 #CPUs=1 Partition=gpu-titan
[2022-06-20T15:02:37.478] sched: Allocate JobId=44400 NodeList=cpu13 #CPUs=2 Partition=cpu-epyc
[2022-06-20T15:02:40.480] sched: Allocate JobId=44401 NodeList=gpu02 #CPUs=10 Partition=gpu-titan
[2022-06-20T15:03:12.528] sched: Allocate JobId=44402 NodeList=cpu03 #CPUs=16 Partition=cpu-opteron
[2022-06-20T15:03:56.593] sched: Allocate JobId=44403 NodeList=gpu02 #CPUs=1 Partition=gpu-titan
[2022-06-20T15:04:01.601] sched: Allocate JobId=44404 NodeList=gpu02 #CPUs=10 Partition=gpu-titan
[2022-06-20T15:04:04.606] sched: Allocate JobId=44405 NodeList=cpu03 #CPUs=16 Partition=cpu-opteron
[2022-06-20T15:05:33.732] sched: Allocate JobId=44406 NodeList=cpu03 #CPUs=16 Partition=cpu-opteron
[2022-06-20T15:07:18.885] sched: Allocate JobId=44407 NodeList=cpu03 #CPUs=16 Partition=cpu-opteron
[2022-06-20T15:14:07.713] sched: Allocate JobId=44408 NodeList=cpu01 #CPUs=4 Partition=cpu-opteron
[2022-06-20T15:15:20.823] sched: Allocate JobId=44409 NodeList=cpu13 #CPUs=2 Partition=cpu-epyc
[2022-06-20T15:15:29.832] sched: Allocate JobId=44410 NodeList=cpu01 #CPUs=4 Partition=cpu-opteron
[2022-06-20T15:17:32.076] sched: Allocate JobId=44411 NodeList=cpu01 #CPUs=4 Partition=cpu-opteron
[2022-06-20T15:19:06.256] sched: Allocate JobId=44412 NodeList=gpu02 #CPUs=8 Partition=gpu-titan
[2022-06-20T15:19:40.303] sched: Allocate JobId=44413 NodeList=gpu02 #CPUs=8 Partition=gpu-titan
[2022-06-20T15:21:08.430] sched: Allocate JobId=44414 NodeList=cpu01 #CPUs=4 Partition=cpu-opteron
[2022-06-20T15:21:47.490] sched: Allocate JobId=44415 NodeList=cpu03 #CPUs=16 Partition=cpu-opteron
[2022-06-20T15:25:08.944] sched: Allocate JobId=44416 NodeList=cpu03 #CPUs=16 Partition=cpu-opteron
[2022-06-20T15:30:05.495] sched: Allocate JobId=44417 NodeList=cpu01 #CPUs=1 Partition=cpu-opteron
[2022-06-20T15:31:22.605] sched: Allocate JobId=44418 NodeList=cpu01 #CPUs=1 Partition=cpu-opteron
[2022-06-20T15:31:42.634] sched: Allocate JobId=44419 NodeList=cpu01 #CPUs=1 Partition=cpu-opteron
[2022-06-20T15:32:56.856] sched: Allocate JobId=44420 NodeList=cpu03 #CPUs=16 Partition=cpu-opteron
[2022-06-20T15:33:29.900] sched: Allocate JobId=44421 NodeList=cpu01 #CPUs=1 Partition=cpu-opteron
[2022-06-20T15:34:32.993] sched: Allocate JobId=44422 NodeList=cpu01 #CPUs=1 Partition=cpu-opteron
[2022-06-20T15:35:25.070] sched: Allocate JobId=44423 NodeList=cpu11 #CPUs=16 Partition=cpu-opteron
[2022-06-20T15:39:48.581] sched: Allocate JobId=44424 NodeList=cpu[13-14] #CPUs=32 Partition=cpu-epyc
[2022-06-20T15:50:58.785] sched: Allocate JobId=44425 NodeList=cpu05 #CPUs=64 Partition=cpu-opteron
[2022-06-20T16:21:13.123] sched: Allocate JobId=44426 NodeList=gpu03 #CPUs=16 Partition=gpu-k10
[2022-06-20T16:26:05.656] sched: Allocate JobId=44427 NodeList=cpu07 #CPUs=64 Partition=cpu-opteron
[2022-06-20T16:34:19.620] sched: Allocate JobId=44428 NodeList=cpu07 #CPUs=64 Partition=cpu-opteron
[2022-06-20T16:41:14.358] sched: Allocate JobId=44429 NodeList=gpu01 #CPUs=20 Partition=gpu-k10
[2022-06-20T16:42:32.487] sched: Allocate JobId=44430 NodeList=gpu01 #CPUs=20 Partition=gpu-k10
[2022-06-20T16:42:55.561] sched: Allocate JobId=44431 NodeList=gpu01 #CPUs=20 Partition=gpu-k10
[2022-06-20T16:44:24.695] sched: Allocate JobId=44432 NodeList=gpu01 #CPUs=20 Partition=gpu-k10
[2022-06-20T16:56:40.995] sched: Allocate JobId=44433 NodeList=cpu07 #CPUs=64 Partition=cpu-opteron
[2022-06-20T17:16:05.576] sched: Allocate JobId=44350 NodeList=gpu05 #CPUs=32 Partition=gpu-v100s
[2022-06-20T17:16:10.554] sched: Allocate JobId=44351 NodeList=gpu05 #CPUs=32 Partition=gpu-v100s
[2022-06-20T17:25:23.077] sched: _slurm_rpc_allocate_resources JobId=44434 NodeList=cpu01 usec=11463
[2022-06-20T17:31:31.410] sched: _slurm_rpc_allocate_resources JobId=44435 NodeList=cpu01 usec=1454
[2022-06-20T17:39:53.817] sched: Allocate JobId=44436 NodeList=cpu01 #CPUs=4 Partition=cpu-opteron
[2022-06-20T17:41:48.979] sched: Allocate JobId=44437 NodeList=cpu01 #CPUs=4 Partition=cpu-opteron
[2022-06-20T17:42:55.219] sched: Allocate JobId=44438 NodeList=gpu05 #CPUs=16 Partition=gpu-v100s
[2022-06-20T17:43:38.251] sched: Allocate JobId=44439 NodeList=gpu05 #CPUs=16 Partition=gpu-v100s
[2022-06-20T17:50:00.963] sched: Allocate JobId=44440 NodeList=gpu05 #CPUs=16 Partition=gpu-v100s
[2022-06-20T17:52:38.319] sched: Allocate JobId=44441 NodeList=gpu05 #CPUs=16 Partition=gpu-v100s
[2022-06-20T17:54:04.445] sched: Allocate JobId=44442 NodeList=gpu05 #CPUs=16 Partition=gpu-v100s
[2022-06-20T17:54:49.512] sched: Allocate JobId=44443 NodeList=gpu05 #CPUs=16 Partition=gpu-v100s
[2022-06-20T18:00:19.074] sched: Allocate JobId=44444 NodeList=gpu05 #CPUs=16 Partition=gpu-v100s
[2022-06-20T18:16:59.872] sched: Allocate JobId=44445 NodeList=gpu05 #CPUs=16 Partition=gpu-v100s
[2022-06-20T18:22:41.610] sched: Allocate JobId=44446 NodeList=gpu05 #CPUs=16 Partition=gpu-v100s
[2022-06-20T18:28:56.250] sched: Allocate JobId=44447 NodeList=gpu05 #CPUs=16 Partition=gpu-v100s
[2022-06-20T18:46:12.024] sched: Allocate JobId=44448 NodeList=gpu05 #CPUs=32 Partition=gpu-v100s
[2022-06-20T20:22:21.218] sched: _slurm_rpc_allocate_resources JobId=44449 NodeList=cpu01 usec=13709
[2022-06-20T21:58:32.836] sched: Allocate JobId=44452 NodeList=cpu12 #CPUs=2 Partition=cpu-epyc
[2022-06-20T22:03:13.383] sched: Allocate JobId=44453 NodeList=gpu04 #CPUs=16 Partition=gpu-k40c
[2022-06-20T22:30:51.393] sched: Allocate JobId=44454 NodeList=cpu01 #CPUs=1 Partition=cpu-opteron
[2022-06-20T22:31:32.448] sched: Allocate JobId=44455 NodeList=cpu[13-14] #CPUs=32 Partition=cpu-epyc
[2022-06-20T22:44:08.885] sched: Allocate JobId=44457 NodeList=gpu02 #CPUs=10 Partition=gpu-titan
[2022-06-20T22:51:00.644] sched: Allocate JobId=44458 NodeList=gpu02 #CPUs=10 Partition=gpu-titan
[2022-06-20T23:40:51.274] sched: Allocate JobId=44459 NodeList=gpu02 #CPUs=10 Partition=gpu-titan
[2022-06-21T00:56:32.559] sched: Allocate JobId=44460 NodeList=cpu13 #CPUs=2 Partition=cpu-epyc
[2022-06-21T01:16:22.230] sched: Allocate JobId=44461 NodeList=cpu01 #CPUs=1 Partition=cpu-opteron
[2022-06-21T01:16:37.249] sched: Allocate JobId=44462 NodeList=cpu[12-13] #CPUs=32 Partition=cpu-epyc
[2022-06-21T08:29:16.055] sched: Allocate JobId=44463 NodeList=cpu14 #CPUs=1 Partition=cpu-epyc
[2022-06-21T08:30:22.132] sched: Allocate JobId=44464 NodeList=cpu14 #CPUs=1 Partition=cpu-epyc
[2022-06-21T08:31:42.246] sched: Allocate JobId=44465 NodeList=cpu15 #CPUs=48 Partition=cpu-epyc
[2022-06-21T08:35:45.762] sched: Allocate JobId=44466 NodeList=cpu01 #CPUs=1 Partition=cpu-opteron
[2022-06-21T08:37:17.894] sched: Allocate JobId=44467 NodeList=cpu15 #CPUs=48 Partition=cpu-epyc
[2022-06-21T08:38:50.167] sched: Allocate JobId=44468 NodeList=cpu12 #CPUs=96 Partition=cpu-epyc
[2022-06-21T08:38:58.176] sched: Allocate JobId=44469 NodeList=cpu01 #CPUs=32 Partition=cpu-opteron
[2022-06-21T08:39:39.218] sched: Allocate JobId=44470 NodeList=cpu01 #CPUs=32 Partition=cpu-opteron
[2022-06-21T08:40:34.298] sched: Allocate JobId=44471 NodeList=cpu13 #CPUs=64 Partition=cpu-epyc
[2022-06-21T08:42:51.587] sched: Allocate JobId=44472 NodeList=cpu01 #CPUs=32 Partition=cpu-opteron
[2022-06-21T08:44:00.698] sched: Allocate JobId=44473 NodeList=cpu01 #CPUs=1 Partition=cpu-opteron
[2022-06-21T08:50:09.388] sched: Allocate JobId=44474 NodeList=cpu13 #CPUs=16 Partition=cpu-epyc
[2022-06-21T08:50:23.380] sched: Allocate JobId=44475 NodeList=cpu13 #CPUs=16 Partition=cpu-epyc
[2022-06-21T08:50:51.435] sched: Allocate JobId=44476 NodeList=gpu04 #CPUs=16 Partition=gpu-k40c
[2022-06-21T08:51:36.485] sched: Allocate JobId=44477 NodeList=cpu13 #CPUs=16 Partition=cpu-epyc
[2022-06-21T08:51:55.514] sched: Allocate JobId=44478 NodeList=cpu14 #CPUs=16 Partition=cpu-epyc
[2022-06-21T08:52:52.743] sched: Allocate JobId=44479 NodeList=cpu13 #CPUs=16 Partition=cpu-epyc
[2022-06-21T08:56:02.020] sched: Allocate JobId=44480 NodeList=cpu13 #CPUs=16 Partition=cpu-epyc
[2022-06-21T09:00:41.529] sched: Allocate JobId=44481 NodeList=cpu13 #CPUs=16 Partition=cpu-epyc
[2022-06-21T09:01:17.624] sched: Allocate JobId=44482 NodeList=cpu01 #CPUs=32 Partition=cpu-opteron
[2022-06-21T09:05:55.161] sched: Allocate JobId=44483 NodeList=cpu[13-14] #CPUs=32 Partition=cpu-epyc
[2022-06-21T09:07:34.413] sched: Allocate JobId=44484 NodeList=cpu[13-14] #CPUs=16 Partition=cpu-epyc
[2022-06-21T09:13:30.341] sched: _slurm_rpc_allocate_resources JobId=44485 NodeList=cpu01 usec=4533
[2022-06-21T09:18:02.109] sched: Allocate JobId=44486 NodeList=cpu03 #CPUs=32 Partition=cpu-opteron
[2022-06-21T09:22:39.963] sched: Allocate JobId=44488 NodeList=cpu03 #CPUs=64 Partition=cpu-opteron
[2022-06-21T09:22:52.980] sched: Allocate JobId=44489 NodeList=cpu11 #CPUs=32 Partition=cpu-opteron
[2022-06-21T09:35:01.624] sched: Allocate JobId=44490 NodeList=cpu11 #CPUs=32 Partition=cpu-opteron
[2022-06-21T09:46:10.116] sched: Allocate JobId=44491 NodeList=cpu12 #CPUs=96 Partition=cpu-epyc
[2022-06-21T09:46:13.119] sched: Allocate JobId=44492 NodeList=cpu11 #CPUs=32 Partition=cpu-opteron
[2022-06-21T09:47:01.186] sched: Allocate JobId=44493 NodeList=cpu12 #CPUs=64 Partition=cpu-epyc
[2022-06-21T10:01:01.839] sched: Allocate JobId=44494 NodeList=cpu12 #CPUs=2 Partition=cpu-epyc
[2022-06-21T10:03:14.099] sched: Allocate JobId=44495 NodeList=cpu08 #CPUs=32 Partition=cpu-opteron
[2022-06-21T10:12:47.438] sched: Allocate JobId=44496 NodeList=cpu09 #CPUs=32 Partition=cpu-opteron
[2022-06-21T10:21:40.500] sched: Allocate JobId=44497 NodeList=cpu10 #CPUs=32 Partition=cpu-opteron
[2022-06-21T10:21:43.505] sched: Allocate JobId=44498 NodeList=cpu01 #CPUs=1 Partition=cpu-opteron
[2022-06-21T10:22:16.552] sched: Allocate JobId=44499 NodeList=cpu01 #CPUs=1 Partition=cpu-opteron
[2022-06-21T10:22:45.676] sched: Allocate JobId=44500 NodeList=cpu15 #CPUs=48 Partition=cpu-epyc
[2022-06-21T10:44:10.597] sched: _slurm_rpc_allocate_resources JobId=44505 NodeList=cpu01 usec=17733
[2022-06-21T10:44:31.072] sched: Allocate JobId=44506 NodeList=cpu01 #CPUs=8 Partition=cpu-opteron
[2022-06-21T11:07:07.587] sched: Allocate JobId=44507 NodeList=cpu01 #CPUs=8 Partition=cpu-opteron
[2022-06-21T11:11:47.133] sched: Allocate JobId=44508 NodeList=cpu12 #CPUs=16 Partition=cpu-epyc
[2022-06-21T11:13:38.378] sched: Allocate JobId=44509 NodeList=cpu01 #CPUs=8 Partition=cpu-opteron
[2022-06-21T11:18:29.468] sched: _slurm_rpc_allocate_resources JobId=44510 NodeList=cpu12 usec=30831
[2022-06-21T11:19:13.056] sched: _slurm_rpc_allocate_resources JobId=44511 NodeList=cpu12 usec=1562
[2022-06-21T11:20:37.798] sched: _slurm_rpc_allocate_resources JobId=44512 NodeList=cpu12 usec=1079
[2022-06-21T11:25:35.727] sched: Allocate JobId=44513 NodeList=cpu12 #CPUs=16 Partition=cpu-epyc
[2022-06-21T11:28:49.082] sched: Allocate JobId=44514 NodeList=cpu01 #CPUs=8 Partition=cpu-opteron
[2022-06-21T11:30:29.248] sched: _slurm_rpc_allocate_resources JobId=44515 NodeList=cpu01 usec=4601
[2022-06-21T11:31:33.636] sched: _slurm_rpc_allocate_resources JobId=44516 NodeList=cpu12 usec=1281
[2022-06-21T11:38:51.265] sched: _slurm_rpc_allocate_resources JobId=44517 NodeList=cpu12 usec=4465
[2022-06-21T11:40:03.836] sched: _slurm_rpc_allocate_resources JobId=44518 NodeList=cpu13 usec=15067
[2022-06-21T11:41:45.231] sched: _slurm_rpc_allocate_resources JobId=44519 NodeList=cpu12 usec=1519
[2022-06-21T11:42:43.895] sched: _slurm_rpc_allocate_resources JobId=44520 NodeList=cpu12 usec=1389
[2022-06-21T11:44:51.918] sched: Allocate JobId=44521 NodeList=cpu01 #CPUs=8 Partition=cpu-opteron
[2022-06-21T11:47:14.141] sched: Allocate JobId=44522 NodeList=cpu12 #CPUs=2 Partition=cpu-epyc
[2022-06-21T11:54:30.972] sched: Allocate JobId=44524 NodeList=cpu01 #CPUs=8 Partition=cpu-opteron
[2022-06-21T12:01:16.748] sched: Allocate JobId=44523 NodeList=cpu08 #CPUs=32 Partition=cpu-opteron
[2022-06-21T12:06:12.243] sched: Allocate JobId=44525 NodeList=cpu12 #CPUs=16 Partition=cpu-epyc
[2022-06-21T12:06:25.245] sched: Allocate JobId=44526 NodeList=cpu13 #CPUs=16 Partition=cpu-epyc
[2022-06-21T12:06:28.250] sched: Allocate JobId=44527 NodeList=cpu14 #CPUs=16 Partition=cpu-epyc
[2022-06-21T12:06:31.254] sched: Allocate JobId=44528 NodeList=cpu15 #CPUs=16 Partition=cpu-epyc
[2022-06-21T12:06:31.255] sched: Allocate JobId=44529 NodeList=cpu15 #CPUs=16 Partition=cpu-epyc
[2022-06-21T12:06:35.260] sched: Allocate JobId=44530 NodeList=cpu15 #CPUs=16 Partition=cpu-epyc
[2022-06-21T12:10:10.718] sched: Allocate JobId=44535 NodeList=cpu01 #CPUs=16 Partition=cpu-opteron
[2022-06-21T12:12:02.857] sched: Allocate JobId=44536 NodeList=cpu08 #CPUs=16 Partition=cpu-opteron
[2022-06-21T12:13:01.069] sched: Allocate JobId=44537 NodeList=cpu01 #CPUs=16 Partition=cpu-opteron
[2022-06-21T12:13:21.100] sched: Allocate JobId=44538 NodeList=cpu08 #CPUs=16 Partition=cpu-opteron
[2022-06-21T12:14:34.212] sched: Allocate JobId=44539 NodeList=cpu01 #CPUs=1 Partition=cpu-opteron
[2022-06-21T12:16:13.351] sched: Allocate JobId=44540 NodeList=cpu01 #CPUs=16 Partition=cpu-opteron
[2022-06-21T12:17:49.595] sched: Allocate JobId=44541 NodeList=cpu01 #CPUs=16 Partition=cpu-opteron
[2022-06-21T12:18:49.680] sched: Allocate JobId=44542 NodeList=cpu01 #CPUs=16 Partition=cpu-opteron
[2022-06-21T12:19:45.759] sched: Allocate JobId=44543 NodeList=cpu08 #CPUs=16 Partition=cpu-opteron
[2022-06-21T12:19:51.767] sched: Allocate JobId=44544 NodeList=cpu01 #CPUs=1 Partition=cpu-opteron
[2022-06-21T12:20:22.817] sched: Allocate JobId=44545 NodeList=cpu08 #CPUs=16 Partition=cpu-opteron
[2022-06-21T12:20:27.821] sched: Allocate JobId=44546 NodeList=cpu01 #CPUs=1 Partition=cpu-opteron
[2022-06-21T12:21:54.950] sched: Allocate JobId=44547 NodeList=cpu09 #CPUs=64 Partition=cpu-opteron
[2022-06-21T12:29:58.948] sched: Allocate JobId=44570 NodeList=cpu01 #CPUs=16 Partition=cpu-opteron
[2022-06-21T12:34:49.464] sched: Allocate JobId=44572 NodeList=gpu02 #CPUs=22 Partition=gpu-titan
[2022-06-21T12:36:41.620] sched: Allocate JobId=44573 NodeList=gpu02 #CPUs=22 Partition=gpu-titan
[2022-06-21T12:37:16.672] sched: Allocate JobId=44574 NodeList=gpu02 #CPUs=22 Partition=gpu-titan
[2022-06-21T13:03:41.813] sched: Allocate JobId=44599 NodeList=cpu01 #CPUs=1 Partition=cpu-opteron
[2022-06-21T13:04:06.829] sched: Allocate JobId=44600 NodeList=cpu01 #CPUs=16 Partition=cpu-opteron
[2022-06-21T13:05:00.506] sched: Allocate JobId=44531 NodeList=cpu15 #CPUs=16 Partition=cpu-epyc
[2022-06-21T13:13:40.979] sched: Allocate JobId=44532 NodeList=cpu15 #CPUs=16 Partition=cpu-epyc
[2022-06-21T13:17:36.363] sched: Allocate JobId=44601 NodeList=cpu[10-11] #CPUs=32 Partition=cpu-opteron
[2022-06-21T13:25:10.480] sched: Allocate JobId=44533 NodeList=cpu14 #CPUs=16 Partition=cpu-epyc
[2022-06-21T13:28:53.675] sched: Allocate JobId=44602 NodeList=cpu[10-11] #CPUs=32 Partition=cpu-opteron
[2022-06-21T13:29:44.503] sched/backfill: _start_job: Started JobId=44603 in gpu-titan on gpu02
[2022-06-21T13:34:27.263] sched: Allocate JobId=44604 NodeList=cpu[10-11] #CPUs=32 Partition=cpu-opteron
[2022-06-21T13:37:52.643] sched: Allocate JobId=44605 NodeList=cpu[10-11] #CPUs=32 Partition=cpu-opteron
[2022-06-21T13:41:10.936] sched: Allocate JobId=44607 NodeList=cpu01 #CPUs=32 Partition=cpu-opteron
[2022-06-21T13:48:28.377] sched: Allocate JobId=44534 NodeList=cpu13 #CPUs=16 Partition=cpu-epyc
[2022-06-21T13:51:06.476] sched: Allocate JobId=44548 NodeList=cpu15 #CPUs=16 Partition=cpu-epyc
[2022-06-21T14:08:03.954] sched: Allocate JobId=44612 NodeList=cpu01 #CPUs=32 Partition=cpu-opteron
[2022-06-21T14:11:39.434] sched: Allocate JobId=44549 NodeList=cpu15 #CPUs=16 Partition=cpu-epyc
[2022-06-21T14:14:27.642] sched: Allocate JobId=44613 NodeList=cpu01 #CPUs=16 Partition=cpu-opteron
[2022-06-21T14:17:03.899] sched: Allocate JobId=44609 NodeList=gpu02 #CPUs=22 Partition=gpu-titan
[2022-06-21T14:19:36.710] sched: Allocate JobId=44550 NodeList=cpu15 #CPUs=16 Partition=cpu-epyc
[2022-06-21T14:28:43.407] sched: Allocate JobId=44610 NodeList=gpu02 #CPUs=22 Partition=gpu-titan
[2022-06-21T14:33:38.116] sched: Allocate JobId=44614 NodeList=cpu01 #CPUs=32 Partition=cpu-opteron
[2022-06-21T14:38:17.612] sched: Allocate JobId=44615 NodeList=cpu08 #CPUs=32 Partition=cpu-opteron
[2022-06-21T14:38:20.373] sched: Allocate JobId=44551 NodeList=cpu14 #CPUs=16 Partition=cpu-epyc
[2022-06-21T14:41:34.900] sched: Allocate JobId=44616 NodeList=cpu01 #CPUs=32 Partition=cpu-opteron
[2022-06-21T14:45:01.338] sched: Allocate JobId=44617 NodeList=gpu01 #CPUs=16 Partition=gpu-k10
[2022-06-21T14:46:34.471] sched: Allocate JobId=44618 NodeList=gpu03 #CPUs=16 Partition=gpu-k10
[2022-06-21T14:48:16.725] sched: Allocate JobId=44619 NodeList=gpu03 #CPUs=16 Partition=gpu-k10
[2022-06-21T14:48:57.784] sched: Allocate JobId=44620 NodeList=gpu01 #CPUs=16 Partition=gpu-k10
[2022-06-21T14:52:13.071] sched: Allocate JobId=44621 NodeList=cpu01 #CPUs=1 Partition=cpu-opteron
[2022-06-21T14:54:21.046] sched: Allocate JobId=44611 NodeList=gpu02 #CPUs=22 Partition=gpu-titan
[2022-06-21T14:59:19.981] sched: Allocate JobId=44626 NodeList=cpu01 #CPUs=16 Partition=cpu-opteron
[2022-06-21T15:03:34.455] sched: Allocate JobId=44627 NodeList=gpu02 #CPUs=10 Partition=gpu-titan
[2022-06-21T15:10:10.165] sched: Allocate JobId=44628 NodeList=cpu01 #CPUs=4 Partition=cpu-opteron
[2022-06-21T15:19:48.838] sched: Allocate JobId=44552 NodeList=cpu15 #CPUs=16 Partition=cpu-epyc
[2022-06-21T15:26:10.888] sched: Allocate JobId=44629 NodeList=gpu02 #CPUs=10 Partition=gpu-titan
[2022-06-21T15:26:13.619] sched: Allocate JobId=44553 NodeList=cpu15 #CPUs=16 Partition=cpu-epyc
[2022-06-21T15:29:09.654] sched: Allocate JobId=44554 NodeList=cpu15 #CPUs=16 Partition=cpu-epyc
[2022-06-21T15:29:16.302] sched: Allocate JobId=44630 NodeList=gpu02 #CPUs=10 Partition=gpu-titan
[2022-06-21T15:33:40.231] sched: Allocate JobId=44555 NodeList=cpu13 #CPUs=16 Partition=cpu-epyc
[2022-06-21T15:33:56.218] sched: _slurm_rpc_allocate_resources JobId=44631 NodeList=cpu01 usec=4096
[2022-06-21T15:52:30.082] sched: Allocate JobId=44556 NodeList=cpu14 #CPUs=16 Partition=cpu-epyc
[2022-06-21T16:46:29.375] sched: Allocate JobId=44557 NodeList=cpu15 #CPUs=16 Partition=cpu-epyc
[2022-06-21T16:55:45.912] sched: Allocate JobId=44640 NodeList=cpu04 #CPUs=64 Partition=cpu-opteron
[2022-06-21T16:57:51.068] sched: Allocate JobId=44558 NodeList=cpu13 #CPUs=16 Partition=cpu-epyc
[2022-06-21T16:58:18.144] sched: Allocate JobId=44559 NodeList=cpu15 #CPUs=16 Partition=cpu-epyc
[2022-06-21T17:02:10.454] sched: Allocate JobId=44560 NodeList=cpu14 #CPUs=16 Partition=cpu-epyc
[2022-06-21T17:13:03.860] sched: Allocate JobId=44641 NodeList=gpu02 #CPUs=8 Partition=gpu-titan
[2022-06-21T17:45:24.863] sched: Allocate JobId=44561 NodeList=cpu15 #CPUs=16 Partition=cpu-epyc
[2022-06-21T18:07:19.654] sched: Allocate JobId=44562 NodeList=cpu15 #CPUs=16 Partition=cpu-epyc
[2022-06-21T18:20:45.163] sched/backfill: _start_job: Started JobId=44642 in gpu-titan on gpu02
[2022-06-21T18:33:11.530] sched: Allocate JobId=44563 NodeList=cpu13 #CPUs=16 Partition=cpu-epyc
[2022-06-21T18:36:39.065] sched: Allocate JobId=44644 NodeList=gpu02 #CPUs=3 Partition=gpu-titan
[2022-06-21T18:50:24.289] sched: Allocate JobId=44564 NodeList=cpu15 #CPUs=16 Partition=cpu-epyc
[2022-06-21T18:59:47.697] sched: Allocate JobId=44565 NodeList=cpu15 #CPUs=16 Partition=cpu-epyc
[2022-06-21T19:04:02.043] sched: Allocate JobId=44645 NodeList=gpu02 #CPUs=3 Partition=gpu-titan
[2022-06-21T19:08:10.520] sched: Allocate JobId=44646 NodeList=gpu02 #CPUs=10 Partition=gpu-titan
[2022-06-21T19:10:14.692] sched: Allocate JobId=44647 NodeList=cpu04 #CPUs=64 Partition=cpu-opteron
[2022-06-21T19:11:48.812] sched: Allocate JobId=44648 NodeList=gpu02 #CPUs=11 Partition=gpu-titan
[2022-06-21T19:12:36.974] sched: Allocate JobId=44649 NodeList=cpu04 #CPUs=64 Partition=cpu-opteron
[2022-06-21T19:13:41.077] sched: Allocate JobId=44650 NodeList=cpu04 #CPUs=64 Partition=cpu-opteron
[2022-06-21T19:22:02.234] sched: Allocate JobId=44566 NodeList=cpu15 #CPUs=16 Partition=cpu-epyc
[2022-06-21T19:22:30.114] sched: Allocate JobId=44651 NodeList=gpu02 #CPUs=11 Partition=gpu-titan
[2022-06-21T19:47:03.671] sched: Allocate JobId=44656 NodeList=cpu04 #CPUs=64 Partition=cpu-opteron
[2022-06-21T19:48:34.892] sched: Allocate JobId=44657 NodeList=cpu04 #CPUs=64 Partition=cpu-opteron
[2022-06-21T19:51:03.354] sched: Allocate JobId=44567 NodeList=cpu13 #CPUs=16 Partition=cpu-epyc
[2022-06-21T19:54:14.060] sched: Allocate JobId=44568 NodeList=cpu12 #CPUs=16 Partition=cpu-epyc
[2022-06-21T20:02:06.002] sched: Allocate JobId=44569 NodeList=cpu15 #CPUs=16 Partition=cpu-epyc
[2022-06-21T20:38:55.197] sched: Allocate JobId=44575 NodeList=cpu15 #CPUs=16 Partition=cpu-epyc
[2022-06-21T20:39:14.561] sched: _slurm_rpc_allocate_resources JobId=44659 NodeList=cpu01 usec=4051
[2022-06-21T20:57:42.733] sched: Allocate JobId=44576 NodeList=cpu15 #CPUs=16 Partition=cpu-epyc
[2022-06-21T21:04:10.376] sched: Allocate JobId=44661 NodeList=cpu01 #CPUs=2 Partition=cpu-opteron
[2022-06-21T21:04:30.088] sched: Allocate JobId=44577 NodeList=cpu13 #CPUs=16 Partition=cpu-epyc
[2022-06-21T21:05:18.368] sched: Allocate JobId=44578 NodeList=cpu12 #CPUs=16 Partition=cpu-epyc
[2022-06-21T21:09:14.422] sched: Allocate JobId=44579 NodeList=cpu15 #CPUs=16 Partition=cpu-epyc
[2022-06-21T21:21:24.935] sched: _slurm_rpc_allocate_resources JobId=44662 NodeList=cpu01 usec=18554
[2022-06-21T21:35:07.329] sched: _slurm_rpc_allocate_resources JobId=44663 NodeList=cpu01 usec=4217
[2022-06-21T21:51:55.557] sched: Allocate JobId=44664 NodeList=cpu01 #CPUs=2 Partition=cpu-opteron
[2022-06-21T21:57:23.194] sched: Allocate JobId=44665 NodeList=cpu01 #CPUs=1 Partition=cpu-opteron
[2022-06-21T21:59:45.483] sched: Allocate JobId=44666 NodeList=cpu08 #CPUs=64 Partition=cpu-opteron
[2022-06-21T22:08:02.930] sched: Allocate JobId=44580 NodeList=cpu13 #CPUs=16 Partition=cpu-epyc
[2022-06-21T22:11:34.232] sched: Allocate JobId=44581 NodeList=cpu15 #CPUs=16 Partition=cpu-epyc
[2022-06-21T22:15:23.752] sched: Allocate JobId=44582 NodeList=cpu15 #CPUs=16 Partition=cpu-epyc
[2022-06-21T22:16:46.176] sched: Allocate JobId=44583 NodeList=cpu15 #CPUs=16 Partition=cpu-epyc
[2022-06-21T22:25:34.033] sched: Allocate JobId=44584 NodeList=cpu12 #CPUs=16 Partition=cpu-epyc
[2022-06-21T22:37:45.619] sched: _slurm_rpc_allocate_resources JobId=44669 NodeList=cpu01 usec=19311
[2022-06-21T22:43:48.762] sched: Allocate JobId=44670 NodeList=cpu01 #CPUs=16 Partition=cpu-opteron
[2022-06-21T22:45:25.901] sched: Allocate JobId=44671 NodeList=cpu01 #CPUs=16 Partition=cpu-opteron
[2022-06-21T22:45:53.943] sched: Allocate JobId=44672 NodeList=cpu01 #CPUs=16 Partition=cpu-opteron
[2022-06-21T22:46:25.990] sched: Allocate JobId=44673 NodeList=cpu09 #CPUs=64 Partition=cpu-opteron
[2022-06-21T22:47:23.425] sched: Allocate JobId=44653 NodeList=gpu02 #CPUs=10 Partition=gpu-titan
[2022-06-21T22:47:58.940] sched: Allocate JobId=44655 NodeList=gpu02 #CPUs=11 Partition=gpu-titan
[2022-06-21T22:59:26.089] sched: Allocate JobId=44667 NodeList=gpu02 #CPUs=11 Partition=gpu-titan
[2022-06-21T23:10:27.324] sched: Allocate JobId=44585 NodeList=cpu15 #CPUs=16 Partition=cpu-epyc
[2022-06-21T23:17:09.440] sched: Allocate JobId=44675 NodeList=cpu09 #CPUs=64 Partition=cpu-opteron
[2022-06-21T23:18:08.243] sched: Allocate JobId=44586 NodeList=cpu15 #CPUs=16 Partition=cpu-epyc
[2022-06-21T23:19:41.755] sched: Allocate JobId=44676 NodeList=cpu01 #CPUs=1 Partition=cpu-opteron
[2022-06-21T23:20:49.852] sched: Allocate JobId=44677 NodeList=cpu01 #CPUs=1 Partition=cpu-opteron
[2022-06-21T23:21:31.915] sched: Allocate JobId=44678 NodeList=cpu09 #CPUs=64 Partition=cpu-opteron
[2022-06-21T23:21:32.917] sched: Allocate JobId=44679 NodeList=cpu10 #CPUs=64 Partition=cpu-opteron
[2022-06-21T23:26:03.115] sched: Allocate JobId=44587 NodeList=cpu13 #CPUs=16 Partition=cpu-epyc
[2022-06-21T23:33:54.588] sched: Allocate JobId=44588 NodeList=cpu15 #CPUs=16 Partition=cpu-epyc
[2022-06-21T23:35:56.908] sched: Allocate JobId=44589 NodeList=cpu12 #CPUs=16 Partition=cpu-epyc
[2022-06-22T00:22:56.219] sched: Allocate JobId=44590 NodeList=cpu15 #CPUs=16 Partition=cpu-epyc
[2022-06-22T00:25:22.108] sched: Allocate JobId=44591 NodeList=cpu15 #CPUs=16 Partition=cpu-epyc
[2022-06-22T00:51:29.610] sched: Allocate JobId=44592 NodeList=cpu12 #CPUs=16 Partition=cpu-epyc
[2022-06-22T00:57:44.924] sched: Allocate JobId=44593 NodeList=cpu15 #CPUs=16 Partition=cpu-epyc
[2022-06-22T01:20:03.452] sched: Allocate JobId=44594 NodeList=cpu13 #CPUs=16 Partition=cpu-epyc
[2022-06-22T01:22:40.671] sched: Allocate JobId=44595 NodeList=cpu15 #CPUs=16 Partition=cpu-epyc
[2022-06-22T01:31:52.286] sched: Allocate JobId=44596 NodeList=cpu15 #CPUs=16 Partition=cpu-epyc
[2022-06-22T02:19:31.949] sched: _slurm_rpc_allocate_resources JobId=44680 NodeList=cpu01 usec=18282
[2022-06-22T02:25:30.084] sched: Allocate JobId=44597 NodeList=cpu15 #CPUs=16 Partition=cpu-epyc
[2022-06-22T02:28:41.970] sched: Allocate JobId=44598 NodeList=cpu13 #CPUs=16 Partition=cpu-epyc
[2022-06-22T02:40:40.959] sched: Allocate JobId=44681 NodeList=cpu01 #CPUs=8 Partition=cpu-opteron
[2022-06-22T02:47:22.666] sched: Allocate JobId=44682 NodeList=cpu01 #CPUs=8 Partition=cpu-opteron
[2022-06-22T04:36:32.021] sched: Allocate JobId=44683 NodeList=cpu15 #CPUs=48 Partition=cpu-epyc
[2022-06-22T06:39:41.309] sched: _slurm_rpc_allocate_resources JobId=44685 NodeList=cpu01 usec=16997
[2022-06-22T07:12:47.467] sched: Allocate JobId=44686 NodeList=gpu02 #CPUs=10 Partition=gpu-titan
[2022-06-22T07:17:55.095] sched: Allocate JobId=44687 NodeList=gpu02 #CPUs=10 Partition=gpu-titan
[2022-06-22T07:23:17.662] sched: Allocate JobId=44688 NodeList=gpu02 #CPUs=10 Partition=gpu-titan
[2022-06-22T07:30:40.433] sched: Allocate JobId=44689 NodeList=gpu02 #CPUs=10 Partition=gpu-titan
[2022-06-22T07:35:36.993] sched: Allocate JobId=44690 NodeList=gpu02 #CPUs=10 Partition=gpu-titan
[2022-06-22T08:32:29.664] sched: _slurm_rpc_allocate_resources JobId=44691 NodeList=cpu01 usec=18829
[2022-06-22T10:11:23.714] sched: Allocate JobId=44684 NodeList=cpu14 #CPUs=48 Partition=cpu-epyc
[2022-06-22T10:25:47.825] sched: _slurm_rpc_allocate_resources JobId=44693 NodeList=cpu08 usec=17268
[2022-06-22T10:26:48.591] sched: Allocate JobId=44694 NodeList=cpu08 #CPUs=32 Partition=cpu-opteron
[2022-06-22T10:34:23.531] sched: Allocate JobId=44695 NodeList=cpu10 #CPUs=64 Partition=cpu-opteron
[2022-06-22T10:36:37.738] sched: Allocate JobId=44696 NodeList=gpu02 #CPUs=4 Partition=gpu-titan
[2022-06-22T10:39:51.084] sched: Allocate JobId=44697 NodeList=gpu02 #CPUs=4 Partition=gpu-titan
[2022-06-22T10:41:27.223] sched: Allocate JobId=44698 NodeList=gpu02 #CPUs=4 Partition=gpu-titan
[2022-06-22T11:26:43.434] sched: Allocate JobId=44456 NodeList=gpu05 #CPUs=16 Partition=gpu-v100s
[2022-06-22T11:27:18.750] sched: Allocate JobId=44450 NodeList=gpu05 #CPUs=32 Partition=gpu-v100s
[2022-06-22T11:27:24.584] sched: Allocate JobId=44451 NodeList=gpu05 #CPUs=32 Partition=gpu-v100s
[2022-06-22T11:33:02.915] sched: Allocate JobId=44700 NodeList=gpu05 #CPUs=16 Partition=gpu-v100s
[2022-06-22T11:34:46.070] sched: _slurm_rpc_allocate_resources JobId=44701 NodeList=cpu11 usec=4320
[2022-06-22T11:36:05.177] sched: Allocate JobId=44702 NodeList=gpu05 #CPUs=16 Partition=gpu-v100s
[2022-06-22T11:38:32.654] sched: Allocate JobId=44703 NodeList=gpu05 #CPUs=16 Partition=gpu-v100s
[2022-06-22T11:41:22.900] sched: Allocate JobId=44704 NodeList=gpu05 #CPUs=16 Partition=gpu-v100s
[2022-06-22T11:42:39.168] sched: Allocate JobId=44705 NodeList=gpu05 #CPUs=16 Partition=gpu-v100s
[2022-06-22T11:43:59.298] sched: Allocate JobId=44706 NodeList=cpu08 #CPUs=48 Partition=cpu-opteron
[2022-06-22T11:48:00.160] sched: Allocate JobId=44692 NodeList=cpu15 #CPUs=32 Partition=cpu-epyc
[2022-06-22T11:48:16.793] sched: Allocate JobId=44707 NodeList=gpu05 #CPUs=16 Partition=gpu-v100s
[2022-06-22T11:53:50.434] sched: Allocate JobId=44710 NodeList=cpu11 #CPUs=32 Partition=cpu-opteron
[2022-06-22T11:54:45.498] sched: Allocate JobId=44711 NodeList=cpu08 #CPUs=16 Partition=cpu-opteron
[2022-06-22T11:56:17.628] sched: Allocate JobId=44712 NodeList=cpu08 #CPUs=16 Partition=cpu-opteron
[2022-06-22T11:57:30.775] sched: Allocate JobId=44713 NodeList=cpu08 #CPUs=32 Partition=cpu-opteron
[2022-06-22T12:00:02.037] sched: Allocate JobId=44714 NodeList=cpu15 #CPUs=16 Partition=cpu-epyc
[2022-06-22T12:01:10.136] sched: Allocate JobId=44716 NodeList=cpu12 #CPUs=16 Partition=cpu-epyc
[2022-06-22T12:02:15.129] sched: _slurm_rpc_allocate_resources JobId=44717 NodeList=(null) usec=790
[2022-06-22T12:02:38.398] sched: Allocate JobId=44718 NodeList=cpu13 #CPUs=16 Partition=cpu-epyc
[2022-06-22T12:11:21.895] sched: _slurm_rpc_allocate_resources JobId=44720 NodeList=cpu01 usec=18555
[2022-06-22T12:18:46.013] sched/backfill: _start_job: Started JobId=44725 in gpu-k40c on gpu04
[2022-06-22T12:47:13.113] sched: Allocate JobId=44726 NodeList=cpu01 #CPUs=32 Partition=cpu-opteron
[2022-06-22T12:51:44.924] sched: Allocate JobId=44727 NodeList=cpu01 #CPUs=8 Partition=cpu-opteron
[2022-06-22T12:52:21.979] sched: Allocate JobId=44728 NodeList=cpu01 #CPUs=32 Partition=cpu-opteron
[2022-06-22T12:53:46.032] sched/backfill: _start_job: Started JobId=44730 in gpu-k40c on gpu04
[2022-06-22T12:57:46.037] sched/backfill: _start_job: Started JobId=44731 in gpu-k40c on gpu04
[2022-06-22T13:00:04.370] sched: Allocate JobId=44699 NodeList=gpu02 #CPUs=10 Partition=gpu-titan
[2022-06-22T13:00:27.290] sched: Allocate JobId=44732 NodeList=gpu02 #CPUs=8 Partition=gpu-titan
[2022-06-22T13:00:46.040] sched/backfill: _start_job: Started JobId=44733 in gpu-k40c on gpu04
[2022-06-22T13:40:17.014] sched: Allocate JobId=44734 NodeList=cpu01 #CPUs=32 Partition=cpu-opteron
[2022-06-22T13:56:46.087] sched/backfill: _start_job: Started JobId=44736 in gpu-titan on gpu02
[2022-06-22T14:24:04.534] sched: _slurm_rpc_allocate_resources JobId=44738 NodeList=(null) usec=1221
[2022-06-22T14:31:09.927] sched: Allocate JobId=44739 NodeList=gpu05 #CPUs=10 Partition=gpu-v100s
[2022-06-22T14:34:33.301] sched: Allocate JobId=44742 NodeList=gpu05 #CPUs=12 Partition=gpu-v100s
[2022-06-22T14:35:29.764] sched: Allocate JobId=44738 NodeList=cpu01 #CPUs=1 Partition=cpu-opteron
[2022-06-22T14:35:29.765] sched: Allocate JobId=44737 NodeList=cpu01 #CPUs=2 Partition=cpu-opteron
[2022-06-22T14:36:03.430] sched: Allocate JobId=44743 NodeList=cpu01 #CPUs=16 Partition=cpu-opteron
[2022-06-22T14:37:21.542] sched: Allocate JobId=44745 NodeList=cpu01 #CPUs=8 Partition=cpu-opteron
[2022-06-22T14:40:47.938] sched: Allocate JobId=44746 NodeList=cpu01 #CPUs=8 Partition=cpu-opteron
[2022-06-22T14:45:35.203] sched: _slurm_rpc_allocate_resources JobId=44747 NodeList=cpu01 usec=16978
[2022-06-22T14:51:07.196] sched: Allocate JobId=44749 NodeList=gpu02 #CPUs=5 Partition=gpu-titan
[2022-06-22T14:52:00.131] sched: Allocate JobId=44750 NodeList=gpu02 #CPUs=5 Partition=gpu-titan
[2022-06-22T14:54:06.396] sched: Allocate JobId=44751 NodeList=gpu02 #CPUs=5 Partition=gpu-titan
[2022-06-22T14:59:02.951] sched: Allocate JobId=44752 NodeList=gpu02 #CPUs=5 Partition=gpu-titan
[2022-06-22T15:02:32.211] sched: Allocate JobId=44658 NodeList=gpu04 #CPUs=16 Partition=gpu-k40c
[2022-06-22T15:23:06.690] sched: Allocate JobId=44755 NodeList=cpu01 #CPUs=8 Partition=cpu-opteron
[2022-06-22T15:23:25.700] sched: Allocate JobId=44756 NodeList=cpu01 #CPUs=8 Partition=cpu-opteron
[2022-06-22T15:27:17.045] sched: Allocate JobId=44758 NodeList=gpu04 #CPUs=16 Partition=gpu-k40c
[2022-06-22T15:37:42.302] sched: Allocate JobId=44759 NodeList=cpu01 #CPUs=22 Partition=cpu-opteron
[2022-06-22T16:18:58.325] sched: Allocate JobId=44729 NodeList=cpu14 #CPUs=48 Partition=cpu-epyc
[2022-06-22T18:06:15.985] sched: Allocate JobId=44753 NodeList=cpu01 #CPUs=32 Partition=cpu-opteron
[2022-06-22T18:38:47.826] sched: Allocate JobId=44761 NodeList=cpu01 #CPUs=32 Partition=cpu-opteron
[2022-06-22T18:43:34.326] sched: Allocate JobId=44762 NodeList=gpu02 #CPUs=1 Partition=gpu-titan
[2022-06-22T18:43:46.242] sched/backfill: _start_job: Started JobId=44763 in gpu-titan on gpu02
[2022-06-22T20:35:18.714] sched: _slurm_rpc_allocate_resources JobId=44764 NodeList=(null) usec=765
[2022-06-22T20:39:59.332] sched: Allocate JobId=44765 NodeList=gpu02 #CPUs=1 Partition=gpu-titan
[2022-06-22T20:54:03.803] sched: Allocate JobId=44766 NodeList=gpu05 #CPUs=2 Partition=gpu-v100s
[2022-06-22T20:55:57.968] sched: Allocate JobId=44767 NodeList=gpu05 #CPUs=2 Partition=gpu-v100s
[2022-06-22T21:06:14.095] sched: Allocate JobId=44771 NodeList=gpu02 #CPUs=1 Partition=gpu-titan
[2022-06-22T21:08:22.410] sched: Allocate JobId=44772 NodeList=gpu02 #CPUs=1 Partition=gpu-titan
[2022-06-22T21:17:06.256] sched: Allocate JobId=44774 NodeList=gpu02 #CPUs=1 Partition=gpu-titan
[2022-06-22T21:36:50.616] sched: _slurm_rpc_allocate_resources JobId=44775 NodeList=(null) usec=870
[2022-06-22T21:37:30.890] sched: _slurm_rpc_allocate_resources JobId=44776 NodeList=(null) usec=1149
[2022-06-22T23:25:53.057] sched: Allocate JobId=44777 NodeList=cpu01 #CPUs=32 Partition=cpu-opteron
[2022-06-22T23:26:29.112] sched: Allocate JobId=44778 NodeList=cpu01 #CPUs=32 Partition=cpu-opteron
[2022-06-22T23:27:00.555] sched: Allocate JobId=44779 NodeList=cpu01 #CPUs=32 Partition=cpu-opteron
[2022-06-22T23:27:33.109] sched: Allocate JobId=44780 NodeList=cpu01 #CPUs=32 Partition=cpu-opteron
[2022-06-22T23:28:03.584] sched: Allocate JobId=44773 NodeList=cpu01 #CPUs=32 Partition=cpu-opteron
[2022-06-23T00:06:44.901] sched: Allocate JobId=44719 NodeList=cpu14 #CPUs=16 Partition=cpu-epyc
[2022-06-23T01:52:47.503] sched: Allocate JobId=44760 NodeList=gpu04 #CPUs=16 Partition=gpu-k40c
[2022-06-23T02:03:06.638] sched: Allocate JobId=44785 NodeList=cpu14 #CPUs=32 Partition=cpu-epyc
[2022-06-23T02:05:20.803] sched: Allocate JobId=44787 NodeList=cpu01 #CPUs=32 Partition=cpu-opteron
[2022-06-23T02:06:14.876] sched: Allocate JobId=44788 NodeList=cpu08 #CPUs=32 Partition=cpu-opteron
[2022-06-23T07:13:58.141] sched: Allocate JobId=44789 NodeList=cpu11 #CPUs=32 Partition=cpu-opteron
[2022-06-23T07:23:57.387] sched: Allocate JobId=44790 NodeList=cpu11 #CPUs=32 Partition=cpu-opteron
[2022-06-23T07:28:53.979] sched: Allocate JobId=44791 NodeList=gpu04 #CPUs=16 Partition=gpu-k40c
[2022-06-23T07:38:23.082] sched: Allocate JobId=44623 NodeList=gpu03 #CPUs=16 Partition=gpu-k10
[2022-06-23T07:38:34.102] sched: Allocate JobId=44792 NodeList=cpu01 #CPUs=32 Partition=cpu-opteron
[2022-06-23T07:47:14.038] sched: Allocate JobId=44793 NodeList=cpu01 #CPUs=32 Partition=cpu-opteron
[2022-06-23T08:03:54.931] sched: Allocate JobId=44794 NodeList=cpu01 #CPUs=32 Partition=cpu-opteron
[2022-06-23T08:39:48.006] sched: Allocate JobId=44795 NodeList=cpu11 #CPUs=32 Partition=cpu-opteron
[2022-06-23T09:13:37.077] sched: Allocate JobId=44797 NodeList=cpu08 #CPUs=32 Partition=cpu-opteron
[2022-06-23T09:29:39.907] sched: Allocate JobId=44798 NodeList=cpu13 #CPUs=16 Partition=cpu-epyc
[2022-06-23T09:32:18.118] sched: Allocate JobId=44799 NodeList=gpu01 #CPUs=16 Partition=gpu-k10
[2022-06-23T09:35:42.860] sched: _slurm_rpc_allocate_resources JobId=44800 NodeList=(null) usec=887
[2022-06-23T09:37:15.632] sched: Allocate JobId=44801 NodeList=cpu13 #CPUs=1 Partition=cpu-epyc
[2022-06-23T09:38:09.844] sched: Allocate JobId=44802 NodeList=cpu13 #CPUs=16 Partition=cpu-epyc
[2022-06-23T09:39:21.730] sched: _slurm_rpc_allocate_resources JobId=44803 NodeList=(null) usec=970
[2022-06-23T09:51:48.133] sched: _slurm_rpc_allocate_resources JobId=44804 NodeList=(null) usec=1170
[2022-06-23T09:52:22.055] sched: _slurm_rpc_allocate_resources JobId=44805 NodeList=cpu13 usec=16395
[2022-06-23T09:52:45.654] sched: _slurm_rpc_allocate_resources JobId=44806 NodeList=cpu13 usec=1285
[2022-06-23T09:53:15.969] sched: _slurm_rpc_allocate_resources JobId=44807 NodeList=cpu13 usec=1297
[2022-06-23T09:53:23.340] sched: _slurm_rpc_allocate_resources JobId=44808 NodeList=(null) usec=677
[2022-06-23T09:55:18.926] sched: Allocate JobId=44808 NodeList=cpu13 #CPUs=1 Partition=cpu-epyc
[2022-06-23T09:58:18.447] sched: _slurm_rpc_allocate_resources JobId=44809 NodeList=(null) usec=1030
[2022-06-23T10:33:52.222] sched: Allocate JobId=44814 NodeList=cpu01 #CPUs=1 Partition=cpu-opteron
[2022-06-23T10:34:08.421] sched: _slurm_rpc_allocate_resources JobId=44815 NodeList=cpu01 usec=18932
[2022-06-23T11:43:54.974] sched: Allocate JobId=44820 NodeList=cpu01 #CPUs=1 Partition=cpu-opteron
[2022-06-23T11:45:34.101] sched: Allocate JobId=44821 NodeList=cpu13 #CPUs=16 Partition=cpu-epyc
[2022-06-23T11:57:49.056] sched: Allocate JobId=44722 NodeList=cpu08 #CPUs=48 Partition=cpu-opteron
[2022-06-23T12:20:30.712] sched: Allocate JobId=44822 NodeList=gpu01 #CPUs=16 Partition=gpu-k10
[2022-06-23T12:38:31.806] sched: Allocate JobId=44823 NodeList=cpu01 #CPUs=16 Partition=cpu-opteron
[2022-06-23T12:41:17.039] sched: Allocate JobId=44826 NodeList=cpu12 #CPUs=16 Partition=cpu-epyc
[2022-06-23T12:42:22.120] sched: Allocate JobId=44827 NodeList=cpu15 #CPUs=16 Partition=cpu-epyc
[2022-06-23T12:50:01.219] sched: Allocate JobId=44754 NodeList=gpu05 #CPUs=16 Partition=gpu-v100s
[2022-06-23T12:50:08.720] sched: Allocate JobId=44748 NodeList=gpu05 #CPUs=16 Partition=gpu-v100s
[2022-06-23T13:09:34.565] sched: Allocate JobId=44828 NodeList=cpu08 #CPUs=32 Partition=cpu-opteron
[2022-06-23T13:10:53.680] sched: Allocate JobId=44829 NodeList=gpu04 #CPUs=16 Partition=gpu-k40c
[2022-06-23T13:43:44.470] sched: _slurm_rpc_allocate_resources JobId=44830 NodeList=cpu01 usec=16002
[2022-06-23T14:00:29.229] sched: Allocate JobId=44831 NodeList=cpu15 #CPUs=16 Partition=cpu-epyc
[2022-06-23T14:01:32.314] sched: Allocate JobId=44832 NodeList=cpu15 #CPUs=16 Partition=cpu-epyc
[2022-06-23T14:02:08.365] sched: Allocate JobId=44833 NodeList=cpu15 #CPUs=16 Partition=cpu-epyc
[2022-06-23T14:02:37.547] sched: Allocate JobId=44834 NodeList=cpu15 #CPUs=16 Partition=cpu-epyc
[2022-06-23T14:03:07.592] sched: Allocate JobId=44835 NodeList=cpu15 #CPUs=16 Partition=cpu-epyc
[2022-06-23T14:03:54.659] sched: Allocate JobId=44836 NodeList=cpu15 #CPUs=16 Partition=cpu-epyc
[2022-06-23T14:04:52.744] sched: Allocate JobId=44837 NodeList=cpu15 #CPUs=16 Partition=cpu-epyc
[2022-06-23T14:05:28.798] sched: Allocate JobId=44838 NodeList=cpu15 #CPUs=16 Partition=cpu-epyc
[2022-06-23T14:06:01.846] sched: Allocate JobId=44839 NodeList=cpu15 #CPUs=16 Partition=cpu-epyc
[2022-06-23T14:07:45.119] sched: Allocate JobId=44840 NodeList=cpu15 #CPUs=16 Partition=cpu-epyc
[2022-06-23T14:08:13.156] sched: Allocate JobId=44841 NodeList=cpu15 #CPUs=32 Partition=cpu-epyc
[2022-06-23T14:11:34.455] sched: Allocate JobId=44842 NodeList=gpu05 #CPUs=16 Partition=gpu-v100s
[2022-06-23T14:20:44.480] sched: Allocate JobId=44843 NodeList=cpu08 #CPUs=32 Partition=cpu-opteron
[2022-06-23T14:36:32.229] sched: Allocate JobId=44845 NodeList=cpu10 #CPUs=64 Partition=cpu-opteron
[2022-06-23T14:47:05.379] sched: Allocate JobId=44846 NodeList=cpu01 #CPUs=1 Partition=cpu-opteron
[2022-06-23T14:48:20.673] sched: Allocate JobId=44847 NodeList=cpu15 #CPUs=32 Partition=cpu-epyc
[2022-06-23T16:03:55.921] sched: Allocate JobId=44849 NodeList=cpu01 #CPUs=16 Partition=cpu-opteron
[2022-06-23T16:15:56.730] sched: Allocate JobId=44723 NodeList=cpu13 #CPUs=48 Partition=cpu-epyc
[2022-06-23T16:16:06.364] sched: Allocate JobId=44848 NodeList=cpu13 #CPUs=32 Partition=cpu-epyc
[2022-06-23T16:19:38.651] sched: Allocate JobId=44851 NodeList=cpu08 #CPUs=64 Partition=cpu-opteron
[2022-06-23T16:44:48.499] sched: Allocate JobId=44852 NodeList=gpu01 #CPUs=16 Partition=gpu-k10
[2022-06-23T17:20:02.434] sched: Allocate JobId=44857 NodeList=cpu10 #CPUs=64 Partition=cpu-opteron
[2022-06-23T19:21:56.795] sched: Allocate JobId=44859 NodeList=cpu15 #CPUs=32 Partition=cpu-epyc
[2022-06-23T19:56:02.551] sched: Allocate JobId=44861 NodeList=cpu12 #CPUs=32 Partition=cpu-epyc
[2022-06-23T20:00:22.061] sched: Allocate JobId=44862 NodeList=cpu13 #CPUs=48 Partition=cpu-epyc
[2022-06-23T20:16:14.785] sched: Allocate JobId=44865 NodeList=cpu05 #CPUs=16 Partition=cpu-opteron
[2022-06-23T20:34:16.826] sched: Allocate JobId=44866 NodeList=cpu12 #CPUs=32 Partition=cpu-epyc
[2022-06-23T20:36:59.066] sched: Allocate JobId=44867 NodeList=cpu05 #CPUs=64 Partition=cpu-opteron
[2022-06-23T20:50:08.574] sched: Allocate JobId=44868 NodeList=cpu11 #CPUs=16 Partition=cpu-opteron
[2022-06-23T20:55:54.253] sched: Allocate JobId=44869 NodeList=cpu11 #CPUs=16 Partition=cpu-opteron
[2022-06-23T20:56:43.324] sched: Allocate JobId=44870 NodeList=cpu11 #CPUs=16 Partition=cpu-opteron
[2022-06-23T20:58:46.619] sched: Allocate JobId=44871 NodeList=cpu11 #CPUs=16 Partition=cpu-opteron
[2022-06-23T21:03:00.128] sched: Allocate JobId=44872 NodeList=cpu11 #CPUs=16 Partition=cpu-opteron
[2022-06-23T21:21:00.030] sched: Allocate JobId=44874 NodeList=cpu11 #CPUs=32 Partition=cpu-opteron
[2022-06-23T21:21:17.053] sched: Allocate JobId=44875 NodeList=cpu10 #CPUs=32 Partition=cpu-opteron
[2022-06-23T21:21:32.076] sched: Allocate JobId=44876 NodeList=cpu10 #CPUs=32 Partition=cpu-opteron
[2022-06-23T21:22:48.328] sched: Allocate JobId=44877 NodeList=gpu05 #CPUs=16 Partition=gpu-v100s
[2022-06-23T21:23:01.334] sched: Allocate JobId=44878 NodeList=cpu01 #CPUs=1 Partition=cpu-opteron
[2022-06-23T21:25:20.533] sched: Allocate JobId=44879 NodeList=gpu05 #CPUs=16 Partition=gpu-v100s
[2022-06-23T21:27:31.882] sched: _slurm_rpc_allocate_resources JobId=44880 NodeList=cpu01 usec=19023
[2022-06-23T21:28:28.934] sched: Allocate JobId=44881 NodeList=cpu01 #CPUs=32 Partition=cpu-opteron
[2022-06-23T22:05:27.461] sched: _slurm_rpc_allocate_resources JobId=44882 NodeList=cpu01 usec=4388
[2022-06-23T22:14:40.081] sched: Allocate JobId=44883 NodeList=cpu01 #CPUs=1 Partition=cpu-opteron
[2022-06-23T22:16:08.213] sched: Allocate JobId=44884 NodeList=cpu01 #CPUs=1 Partition=cpu-opteron
[2022-06-23T22:19:10.596] sched: Allocate JobId=44885 NodeList=cpu01 #CPUs=1 Partition=cpu-opteron
[2022-06-23T22:22:15.869] sched: Allocate JobId=44886 NodeList=cpu01 #CPUs=1 Partition=cpu-opteron
[2022-06-23T22:26:48.425] sched: Allocate JobId=44887 NodeList=gpu05 #CPUs=4 Partition=gpu-v100s
[2022-06-23T22:33:45.207] sched: Allocate JobId=44888 NodeList=cpu14 #CPUs=16 Partition=cpu-epyc
[2022-06-23T22:35:24.351] sched: Allocate JobId=44889 NodeList=gpu05 #CPUs=4 Partition=gpu-v100s
[2022-06-23T22:35:41.376] sched: Allocate JobId=44890 NodeList=cpu14 #CPUs=16 Partition=cpu-epyc
[2022-06-23T22:38:03.722] sched: Allocate JobId=44891 NodeList=cpu14 #CPUs=16 Partition=cpu-epyc
[2022-06-23T22:44:09.405] sched: Allocate JobId=44892 NodeList=cpu14 #CPUs=16 Partition=cpu-epyc
[2022-06-23T22:55:06.608] sched: Allocate JobId=44893 NodeList=cpu14 #CPUs=16 Partition=cpu-epyc
[2022-06-23T22:57:02.770] sched: Allocate JobId=44894 NodeList=cpu14 #CPUs=16 Partition=cpu-epyc
[2022-06-23T23:50:06.679] sched: Allocate JobId=44827 NodeList=cpu15 #CPUs=16 Partition=cpu-epyc
[2022-06-23T23:50:06.693] sched: Allocate JobId=44859 NodeList=cpu15 #CPUs=32 Partition=cpu-epyc
[2022-06-23T23:51:15.767] sched: Allocate JobId=44895 NodeList=cpu01 #CPUs=1 Partition=cpu-opteron
[2022-06-23T23:52:07.840] sched: Allocate JobId=44896 NodeList=cpu01 #CPUs=1 Partition=cpu-opteron
[2022-06-23T23:53:12.049] sched: Allocate JobId=44897 NodeList=cpu01 #CPUs=1 Partition=cpu-opteron
[2022-06-23T23:55:59.290] sched: Allocate JobId=44898 NodeList=cpu03 #CPUs=64 Partition=cpu-opteron
[2022-06-23T23:59:54.718] sched: Allocate JobId=44899 NodeList=cpu01 #CPUs=2 Partition=cpu-opteron
[2022-06-24T00:11:27.272] sched: Allocate JobId=44850 NodeList=gpu04 #CPUs=16 Partition=gpu-k40c
[2022-06-24T00:19:52.015] sched: Allocate JobId=44900 NodeList=gpu04 #CPUs=16 Partition=gpu-k40c
[2022-06-24T01:00:31.623] sched: Allocate JobId=44901 NodeList=cpu13 #CPUs=48 Partition=cpu-epyc
[2022-06-24T01:01:45.427] sched: Allocate JobId=44902 NodeList=cpu13 #CPUs=48 Partition=cpu-epyc
[2022-06-24T01:12:32.937] sched: Allocate JobId=44903 NodeList=cpu13 #CPUs=48 Partition=cpu-epyc
[2022-06-24T02:40:45.593] sched: Allocate JobId=44853 NodeList=gpu01 #CPUs=16 Partition=gpu-k10
[2022-06-24T05:37:22.550] sched: Allocate JobId=44854 NodeList=gpu03 #CPUs=16 Partition=gpu-k10
[2022-06-24T05:42:35.242] sched: Allocate JobId=44827 NodeList=cpu12 #CPUs=16 Partition=cpu-epyc
[2022-06-24T05:42:35.257] sched: Allocate JobId=44859 NodeList=cpu13 #CPUs=32 Partition=cpu-epyc
[2022-06-24T08:28:16.191] sched: _slurm_rpc_allocate_resources JobId=44905 NodeList=cpu01 usec=15997
[2022-06-24T08:28:29.428] sched: Allocate JobId=44906 NodeList=cpu14 #CPUs=48 Partition=cpu-epyc
[2022-06-24T08:31:55.705] sched: Allocate JobId=44907 NodeList=cpu15 #CPUs=48 Partition=cpu-epyc
[2022-06-24T09:07:18.814] sched: Allocate JobId=44908 NodeList=gpu02 #CPUs=10 Partition=gpu-titan
[2022-06-24T09:08:36.000] sched: Allocate JobId=44910 NodeList=gpu02 #CPUs=1 Partition=gpu-titan
[2022-06-24T09:08:42.009] sched: Allocate JobId=44911 NodeList=gpu02 #CPUs=10 Partition=gpu-titan
[2022-06-24T09:10:23.153] sched: Allocate JobId=44913 NodeList=gpu02 #CPUs=1 Partition=gpu-titan
[2022-06-24T09:11:00.211] sched: Allocate JobId=44915 NodeList=cpu01 #CPUs=31 Partition=cpu-opteron
[2022-06-24T09:15:20.510] sched: _slurm_rpc_allocate_resources JobId=44916 NodeList=(null) usec=851
[2022-06-24T09:15:23.748] sched: Allocate JobId=44917 NodeList=gpu02 #CPUs=4 Partition=gpu-titan
[2022-06-24T09:17:08.903] sched: Allocate JobId=44918 NodeList=gpu02 #CPUs=1 Partition=gpu-titan
[2022-06-24T09:17:20.924] sched: Allocate JobId=44919 NodeList=gpu02 #CPUs=4 Partition=gpu-titan
[2022-06-24T09:26:21.927] sched: _slurm_rpc_allocate_resources JobId=44922 NodeList=(null) usec=1011
[2022-06-24T09:32:47.182] sched: _slurm_rpc_allocate_resources JobId=44923 NodeList=cpu01 usec=4550
[2022-06-24T09:33:10.782] sched: Allocate JobId=44924 NodeList=cpu12 #CPUs=16 Partition=cpu-epyc
[2022-06-24T09:38:45.397] sched: Allocate JobId=44927 NodeList=cpu12 #CPUs=16 Partition=cpu-epyc
[2022-06-24T09:39:35.468] sched: Allocate JobId=44928 NodeList=cpu12 #CPUs=16 Partition=cpu-epyc
[2022-06-24T09:41:34.098] sched: _slurm_rpc_allocate_resources JobId=44929 NodeList=cpu01 usec=944
[2022-06-24T09:42:42.938] sched: Allocate JobId=44931 NodeList=cpu01 #CPUs=30 Partition=cpu-opteron
[2022-06-24T09:48:19.519] sched: Allocate JobId=44932 NodeList=cpu01 #CPUs=30 Partition=cpu-opteron
[2022-06-24T09:49:32.645] sched: Allocate JobId=44933 NodeList=gpu02 #CPUs=2 Partition=gpu-titan
[2022-06-24T10:06:26.643] sched: Allocate JobId=44934 NodeList=gpu02 #CPUs=1 Partition=gpu-titan
[2022-06-24T10:06:36.653] sched: Allocate JobId=44935 NodeList=gpu02 #CPUs=5 Partition=gpu-titan
[2022-06-24T10:11:41.327] sched: _slurm_rpc_allocate_resources JobId=44936 NodeList=cpu01 usec=15714
[2022-06-24T10:12:37.429] sched: Allocate JobId=44938 NodeList=cpu12 #CPUs=16 Partition=cpu-epyc
[2022-06-24T10:21:29.326] sched: Allocate JobId=44939 NodeList=cpu13 #CPUs=48 Partition=cpu-epyc
[2022-06-24T10:25:27.768] sched: Allocate JobId=44940 NodeList=cpu01 #CPUs=30 Partition=cpu-opteron
[2022-06-24T10:36:50.024] sched: Allocate JobId=44941 NodeList=cpu01 #CPUs=30 Partition=cpu-opteron
[2022-06-24T10:38:26.920] sched: _slurm_rpc_allocate_resources JobId=44942 NodeList=cpu01 usec=14860
[2022-06-24T10:41:52.291] sched: _slurm_rpc_allocate_resources JobId=44943 NodeList=cpu01 usec=977
[2022-06-24T10:41:57.444] sched: _slurm_rpc_allocate_resources JobId=44944 NodeList=(null) usec=1199
[2022-06-24T10:44:33.689] sched: _slurm_rpc_allocate_resources JobId=44945 NodeList=cpu01 usec=1113
[2022-06-24T10:45:52.042] sched: Allocate JobId=44946 NodeList=cpu01 #CPUs=30 Partition=cpu-opteron
[2022-06-24T10:51:48.796] sched: _slurm_rpc_allocate_resources JobId=44947 NodeList=cpu01 usec=4724
[2022-06-24T10:52:22.563] sched: _slurm_rpc_allocate_resources JobId=44948 NodeList=cpu01 usec=1295
[2022-06-24T11:33:25.255] sched: _slurm_rpc_allocate_resources JobId=44949 NodeList=cpu01 usec=4347
[2022-06-24T11:42:18.778] sched: _slurm_rpc_allocate_resources JobId=44950 NodeList=cpu01 usec=16720
[2022-06-24T11:43:42.826] sched: Allocate JobId=44953 NodeList=cpu13 #CPUs=1 Partition=cpu-epyc
[2022-06-24T11:43:45.840] sched: Allocate JobId=44954 NodeList=cpu13 #CPUs=32 Partition=cpu-epyc
[2022-06-24T11:44:37.904] sched: Allocate JobId=44956 NodeList=cpu13 #CPUs=1 Partition=cpu-epyc
[2022-06-24T11:46:43.083] sched: Allocate JobId=44958 NodeList=cpu13 #CPUs=16 Partition=cpu-epyc
[2022-06-24T11:51:03.559] sched: Allocate JobId=44960 NodeList=cpu01 #CPUs=1 Partition=cpu-opteron
[2022-06-24T11:58:06.179] sched: Allocate JobId=44920 NodeList=gpu05 #CPUs=10 Partition=gpu-v100s
[2022-06-24T12:10:12.360] sched: _slurm_rpc_allocate_resources JobId=44977 NodeList=(null) usec=868
[2022-06-24T12:10:35.674] sched: _slurm_rpc_allocate_resources JobId=44978 NodeList=cpu01 usec=16340
[2022-06-24T12:11:36.390] sched: _slurm_rpc_allocate_resources JobId=44979 NodeList=cpu01 usec=15227
[2022-06-24T12:14:25.096] sched: Allocate JobId=44961 NodeList=cpu15 #CPUs=16 Partition=cpu-epyc
[2022-06-24T12:14:25.096] sched: Allocate JobId=44962 NodeList=cpu15 #CPUs=16 Partition=cpu-epyc
[2022-06-24T12:14:25.097] sched: Allocate JobId=44963 NodeList=cpu15 #CPUs=16 Partition=cpu-epyc
[2022-06-24T12:14:27.234] sched: Allocate JobId=44964 NodeList=cpu14 #CPUs=16 Partition=cpu-epyc
[2022-06-24T12:14:27.235] sched: Allocate JobId=44965 NodeList=cpu14 #CPUs=16 Partition=cpu-epyc
[2022-06-24T12:14:27.235] sched: Allocate JobId=44966 NodeList=cpu14 #CPUs=16 Partition=cpu-epyc
[2022-06-24T12:16:34.291] sched: Allocate JobId=44980 NodeList=cpu01 #CPUs=32 Partition=cpu-opteron
[2022-06-24T12:16:43.291] sched: Allocate JobId=44981 NodeList=cpu05 #CPUs=32 Partition=cpu-opteron
[2022-06-24T12:16:50.302] sched: Allocate JobId=44982 NodeList=cpu05 #CPUs=32 Partition=cpu-opteron
[2022-06-24T12:17:08.328] sched: Allocate JobId=44983 NodeList=cpu11 #CPUs=32 Partition=cpu-opteron
[2022-06-24T12:17:16.339] sched: Allocate JobId=44984 NodeList=cpu10 #CPUs=32 Partition=cpu-opteron
[2022-06-24T12:21:59.832] sched: Allocate JobId=44967 NodeList=cpu12 #CPUs=16 Partition=cpu-epyc
[2022-06-24T12:25:07.222] sched: Allocate JobId=44985 NodeList=cpu01 #CPUs=16 Partition=cpu-opteron
[2022-06-24T12:27:03.389] sched: Allocate JobId=44986 NodeList=cpu01 #CPUs=16 Partition=cpu-opteron
[2022-06-24T12:41:24.795] sched: Allocate JobId=44968 NodeList=cpu12 #CPUs=16 Partition=cpu-epyc
[2022-06-24T12:51:52.048] sched: Allocate JobId=44987 NodeList=cpu10 #CPUs=32 Partition=cpu-opteron
[2022-06-24T12:51:58.053] sched: Allocate JobId=44988 NodeList=cpu11 #CPUs=32 Partition=cpu-opteron
[2022-06-24T13:52:06.168] sched: Allocate JobId=44969 NodeList=cpu14 #CPUs=16 Partition=cpu-epyc
[2022-06-24T13:54:14.424] sched: Allocate JobId=44970 NodeList=cpu15 #CPUs=16 Partition=cpu-epyc
[2022-06-24T14:00:34.192] sched: Allocate JobId=44971 NodeList=cpu15 #CPUs=16 Partition=cpu-epyc
[2022-06-24T14:30:34.697] sched: Allocate JobId=44972 NodeList=cpu15 #CPUs=16 Partition=cpu-epyc
[2022-06-24T14:52:43.760] sched: Allocate JobId=44973 NodeList=cpu12 #CPUs=16 Partition=cpu-epyc
[2022-06-24T15:19:41.791] sched: Allocate JobId=44974 NodeList=cpu14 #CPUs=16 Partition=cpu-epyc
[2022-06-24T15:26:36.582] sched: Allocate JobId=44975 NodeList=cpu14 #CPUs=16 Partition=cpu-epyc
[2022-06-24T15:28:15.682] sched: Allocate JobId=44976 NodeList=cpu12 #CPUs=16 Partition=cpu-epyc
[2022-06-24T16:10:11.079] sched: Allocate JobId=44990 NodeList=cpu14 #CPUs=16 Partition=cpu-epyc
[2022-06-24T16:10:16.083] sched: Allocate JobId=44991 NodeList=cpu15 #CPUs=16 Partition=cpu-epyc
[2022-06-24T16:22:59.116] sched: Allocate JobId=44992 NodeList=cpu15 #CPUs=16 Partition=cpu-epyc
[2022-06-24T16:23:02.785] sched: Allocate JobId=44993 NodeList=cpu14 #CPUs=16 Partition=cpu-epyc
[2022-06-24T16:30:35.645] sched: Allocate JobId=44994 NodeList=cpu15 #CPUs=16 Partition=cpu-epyc
[2022-06-24T16:35:42.516] sched: Allocate JobId=44995 NodeList=cpu15 #CPUs=16 Partition=cpu-epyc
[2022-06-24T16:36:27.992] sched: Allocate JobId=44996 NodeList=cpu14 #CPUs=16 Partition=cpu-epyc
[2022-06-24T16:48:52.693] sched: Allocate JobId=44997 NodeList=cpu15 #CPUs=16 Partition=cpu-epyc
[2022-06-24T16:49:30.158] sched: Allocate JobId=44998 NodeList=cpu14 #CPUs=16 Partition=cpu-epyc
[2022-06-24T16:49:34.207] sched: Allocate JobId=45006 NodeList=cpu01 #CPUs=16 Partition=cpu-opteron
[2022-06-24T16:50:07.237] sched: Allocate JobId=45007 NodeList=cpu01 #CPUs=16 Partition=cpu-opteron
[2022-06-24T16:57:39.774] sched: Allocate JobId=44999 NodeList=cpu15 #CPUs=16 Partition=cpu-epyc
[2022-06-24T17:00:20.610] sched: Allocate JobId=45000 NodeList=cpu15 #CPUs=16 Partition=cpu-epyc
[2022-06-24T17:02:32.384] sched: Allocate JobId=45001 NodeList=cpu12 #CPUs=16 Partition=cpu-epyc
[2022-06-24T17:03:16.194] sched: Allocate JobId=45002 NodeList=cpu14 #CPUs=16 Partition=cpu-epyc
[2022-06-24T17:04:10.426] sched: Allocate JobId=45003 NodeList=cpu15 #CPUs=16 Partition=cpu-epyc
[2022-06-24T17:12:45.541] sched: Allocate JobId=45004 NodeList=cpu15 #CPUs=16 Partition=cpu-epyc
[2022-06-24T17:16:03.604] sched: Allocate JobId=45005 NodeList=cpu15 #CPUs=16 Partition=cpu-epyc
[2022-06-24T17:17:16.226] sched: Allocate JobId=44989 NodeList=cpu14 #CPUs=24 Partition=cpu-epyc
[2022-06-24T20:56:29.111] sched: Allocate JobId=45008 NodeList=cpu15 #CPUs=32 Partition=cpu-epyc
[2022-06-24T20:58:46.910] sched: Allocate JobId=45009 NodeList=cpu15 #CPUs=32 Partition=cpu-epyc
[2022-06-24T21:01:50.167] sched: Allocate JobId=45010 NodeList=cpu12 #CPUs=32 Partition=cpu-epyc
[2022-06-24T21:03:45.823] sched: Allocate JobId=45011 NodeList=cpu13 #CPUs=32 Partition=cpu-epyc
[2022-06-24T21:06:12.712] sched: Allocate JobId=45012 NodeList=cpu15 #CPUs=32 Partition=cpu-epyc
[2022-06-24T21:06:50.086] sched: Allocate JobId=45014 NodeList=cpu03 #CPUs=32 Partition=cpu-opteron
[2022-06-24T21:14:59.122] sched: Allocate JobId=45013 NodeList=cpu12 #CPUs=32 Partition=cpu-epyc
[2022-06-24T21:17:38.595] sched: Allocate JobId=45015 NodeList=cpu03 #CPUs=64 Partition=cpu-opteron
[2022-06-24T21:54:09.587] sched: Allocate JobId=45017 NodeList=cpu01 #CPUs=1 Partition=cpu-opteron
[2022-06-24T21:58:56.083] sched: Allocate JobId=45021 NodeList=cpu03 #CPUs=64 Partition=cpu-opteron
[2022-06-24T23:11:43.878] sched: Allocate JobId=45018 NodeList=cpu14 #CPUs=32 Partition=cpu-epyc
[2022-06-25T00:06:07.760] sched: Allocate JobId=45023 NodeList=gpu02 #CPUs=7 Partition=gpu-titan
[2022-06-25T00:08:47.857] sched: _slurm_rpc_allocate_resources JobId=45024 NodeList=cpu01 usec=1428
[2022-06-25T00:38:49.212] sched: Allocate JobId=45025 NodeList=cpu01 #CPUs=1 Partition=cpu-opteron
[2022-06-25T00:40:39.358] sched: Allocate JobId=45026 NodeList=cpu01 #CPUs=1 Partition=cpu-opteron
[2022-06-25T00:41:00.385] sched: Allocate JobId=45027 NodeList=cpu14 #CPUs=48 Partition=cpu-epyc
[2022-06-25T01:05:45.739] sched: Allocate JobId=45028 NodeList=cpu01 #CPUs=1 Partition=cpu-opteron
[2022-06-25T01:13:17.728] sched: Allocate JobId=45029 NodeList=cpu15 #CPUs=16 Partition=cpu-epyc
[2022-06-25T01:14:55.861] sched: Allocate JobId=45030 NodeList=cpu15 #CPUs=16 Partition=cpu-epyc
[2022-06-25T01:16:02.020] sched: Allocate JobId=45031 NodeList=cpu15 #CPUs=16 Partition=cpu-epyc
[2022-06-25T01:17:54.202] sched: Allocate JobId=45032 NodeList=cpu15 #CPUs=16 Partition=cpu-epyc
[2022-06-25T01:53:13.836] sched: Allocate JobId=45033 NodeList=cpu15 #CPUs=16 Partition=cpu-epyc
[2022-06-25T02:32:01.074] sched: Allocate JobId=45034 NodeList=cpu15 #CPUs=16 Partition=cpu-epyc
[2022-06-25T02:35:32.666] sched: Allocate JobId=45035 NodeList=cpu15 #CPUs=16 Partition=cpu-epyc
[2022-06-25T08:02:46.928] sched: Allocate JobId=45036 NodeList=gpu02 #CPUs=4 Partition=gpu-titan
[2022-06-25T08:08:23.535] sched: Allocate JobId=45037 NodeList=gpu02 #CPUs=4 Partition=gpu-titan
[2022-06-25T08:13:03.069] sched: Allocate JobId=45038 NodeList=gpu02 #CPUs=4 Partition=gpu-titan
[2022-06-25T08:17:23.422] sched: Allocate JobId=45039 NodeList=gpu02 #CPUs=4 Partition=gpu-titan
[2022-06-25T08:29:21.867] sched: Allocate JobId=45040 NodeList=gpu02 #CPUs=4 Partition=gpu-titan
[2022-06-25T08:31:51.074] sched: Allocate JobId=45041 NodeList=gpu02 #CPUs=4 Partition=gpu-titan
[2022-06-25T08:44:59.695] sched: Allocate JobId=45042 NodeList=gpu02 #CPUs=4 Partition=gpu-titan
[2022-06-25T09:27:38.893] sched: Allocate JobId=45043 NodeList=cpu12 #CPUs=48 Partition=cpu-epyc
[2022-06-25T09:40:21.939] sched: Allocate JobId=45044 NodeList=cpu12 #CPUs=32 Partition=cpu-epyc
[2022-06-25T09:40:59.974] sched: Allocate JobId=45045 NodeList=cpu15 #CPUs=32 Partition=cpu-epyc
[2022-06-25T09:50:07.956] sched: Allocate JobId=45046 NodeList=gpu02 #CPUs=4 Partition=gpu-titan
[2022-06-25T11:05:29.065] sched: Allocate JobId=45048 NodeList=gpu02 #CPUs=4 Partition=gpu-titan
[2022-06-25T11:37:11.495] sched: Allocate JobId=44921 NodeList=gpu05 #CPUs=10 Partition=gpu-v100s
[2022-06-25T13:42:04.009] sched: Allocate JobId=45049 NodeList=gpu02 #CPUs=4 Partition=gpu-titan
[2022-06-25T15:38:34.658] sched: Allocate JobId=45050 NodeList=cpu15 #CPUs=16 Partition=cpu-epyc
[2022-06-25T15:40:18.792] sched: Allocate JobId=45051 NodeList=cpu12 #CPUs=16 Partition=cpu-epyc
[2022-06-25T15:40:52.843] sched: Allocate JobId=45052 NodeList=cpu13 #CPUs=16 Partition=cpu-epyc
[2022-06-25T15:44:32.230] sched: Allocate JobId=45053 NodeList=cpu13 #CPUs=16 Partition=cpu-epyc
[2022-06-25T15:47:23.469] sched: Allocate JobId=45054 NodeList=cpu13 #CPUs=16 Partition=cpu-epyc
[2022-06-25T16:47:10.192] sched: Allocate JobId=45055 NodeList=cpu01 #CPUs=16 Partition=cpu-opteron
[2022-06-25T16:48:14.431] sched: Allocate JobId=45056 NodeList=cpu14 #CPUs=16 Partition=cpu-epyc
[2022-06-25T16:49:05.506] sched: Allocate JobId=45057 NodeList=cpu14 #CPUs=16 Partition=cpu-epyc
[2022-06-25T16:57:49.458] sched: Allocate JobId=45058 NodeList=cpu14 #CPUs=16 Partition=cpu-epyc
[2022-06-25T16:59:47.629] sched: Allocate JobId=45060 NodeList=cpu01 #CPUs=2 Partition=cpu-opteron
[2022-06-25T17:09:11.712] sched: Allocate JobId=45061 NodeList=cpu03 #CPUs=32 Partition=cpu-opteron
[2022-06-25T17:11:15.882] sched: Allocate JobId=45062 NodeList=cpu03 #CPUs=32 Partition=cpu-opteron
[2022-06-25T17:12:20.969] sched: Allocate JobId=45063 NodeList=cpu03 #CPUs=32 Partition=cpu-opteron
[2022-06-25T17:13:34.155] sched: Allocate JobId=45064 NodeList=cpu03 #CPUs=32 Partition=cpu-opteron
[2022-06-25T17:14:10.204] sched: Allocate JobId=45065 NodeList=cpu03 #CPUs=32 Partition=cpu-opteron
[2022-06-25T17:20:23.860] sched: Allocate JobId=45066 NodeList=cpu03 #CPUs=32 Partition=cpu-opteron
[2022-06-25T17:21:37.961] sched: Allocate JobId=45067 NodeList=cpu03 #CPUs=32 Partition=cpu-opteron
[2022-06-25T17:36:33.518] sched: Allocate JobId=45068 NodeList=cpu03 #CPUs=32 Partition=cpu-opteron
[2022-06-25T18:24:20.823] sched: Allocate JobId=45069 NodeList=gpu02 #CPUs=5 Partition=gpu-titan
[2022-06-25T18:24:51.870] sched: Allocate JobId=45070 NodeList=cpu03 #CPUs=32 Partition=cpu-opteron
[2022-06-25T18:25:53.937] sched: Allocate JobId=45071 NodeList=cpu01 #CPUs=16 Partition=cpu-opteron
[2022-06-25T18:27:18.056] sched: Allocate JobId=45072 NodeList=cpu03 #CPUs=32 Partition=cpu-opteron
[2022-06-25T18:29:16.318] sched: Allocate JobId=45073 NodeList=cpu01 #CPUs=16 Partition=cpu-opteron
[2022-06-25T18:30:14.398] sched: Allocate JobId=45074 NodeList=cpu01 #CPUs=16 Partition=cpu-opteron
[2022-06-25T18:32:14.566] sched: Allocate JobId=45075 NodeList=cpu03 #CPUs=16 Partition=cpu-opteron
[2022-06-25T18:46:47.953] sched/backfill: _start_job: Started JobId=45076 in cpu-opteron on cpu03
[2022-06-25T18:49:53.616] sched: Allocate JobId=45077 NodeList=cpu03 #CPUs=32 Partition=cpu-opteron
[2022-06-25T18:53:03.537] sched: Allocate JobId=45078 NodeList=cpu03 #CPUs=32 Partition=cpu-opteron
[2022-06-25T18:56:09.979] sched: Allocate JobId=45079 NodeList=cpu03 #CPUs=32 Partition=cpu-opteron
[2022-06-25T20:32:44.485] sched: Allocate JobId=45047 NodeList=gpu01 #CPUs=16 Partition=gpu-k10
[2022-06-25T20:39:37.996] sched: Allocate JobId=45080 NodeList=cpu12 #CPUs=32 Partition=cpu-epyc
[2022-06-25T20:46:17.681] sched: Allocate JobId=45081 NodeList=cpu15 #CPUs=32 Partition=cpu-epyc
[2022-06-25T21:11:14.337] sched: Allocate JobId=45086 NodeList=cpu03 #CPUs=32 Partition=cpu-opteron
[2022-06-25T21:12:31.538] sched: Allocate JobId=45087 NodeList=cpu03 #CPUs=32 Partition=cpu-opteron
[2022-06-25T21:14:38.764] sched: Allocate JobId=45088 NodeList=cpu03 #CPUs=32 Partition=cpu-opteron
[2022-06-25T21:20:13.376] sched: Allocate JobId=45089 NodeList=cpu03 #CPUs=2 Partition=cpu-opteron
[2022-06-25T21:20:15.964] sched: Allocate JobId=45090 NodeList=cpu03 #CPUs=32 Partition=cpu-opteron
[2022-06-25T21:31:43.538] sched: Allocate JobId=45091 NodeList=cpu01 #CPUs=2 Partition=cpu-opteron
[2022-06-25T21:34:39.930] sched: Allocate JobId=45092 NodeList=cpu01 #CPUs=2 Partition=cpu-opteron
[2022-06-25T21:35:47.027] sched: Allocate JobId=45093 NodeList=cpu01 #CPUs=2 Partition=cpu-opteron
[2022-06-25T21:37:21.159] sched: Allocate JobId=45094 NodeList=cpu01 #CPUs=2 Partition=cpu-opteron
[2022-06-25T21:46:35.097] sched: Allocate JobId=45095 NodeList=cpu13 #CPUs=16 Partition=cpu-epyc
[2022-06-25T21:53:21.829] sched: Allocate JobId=45096 NodeList=cpu13 #CPUs=16 Partition=cpu-epyc
[2022-06-25T21:58:26.368] sched: _slurm_rpc_allocate_resources JobId=45097 NodeList=cpu01 usec=4416
[2022-06-25T22:09:08.461] sched: Allocate JobId=45098 NodeList=cpu01 #CPUs=2 Partition=cpu-opteron
[2022-06-25T22:10:34.576] sched: Allocate JobId=45099 NodeList=cpu03 #CPUs=32 Partition=cpu-opteron
[2022-06-25T22:12:12.718] sched: Allocate JobId=45100 NodeList=cpu03 #CPUs=64 Partition=cpu-opteron
[2022-06-25T23:00:31.894] sched: Allocate JobId=45101 NodeList=cpu13 #CPUs=16 Partition=cpu-epyc
[2022-06-25T23:19:32.664] sched: _slurm_rpc_allocate_resources JobId=45102 NodeList=cpu01 usec=16448
[2022-06-26T05:20:29.855] sched: Allocate JobId=45104 NodeList=gpu03 #CPUs=16 Partition=gpu-k10
[2022-06-26T09:22:08.875] sched: Allocate JobId=45105 NodeList=cpu07 #CPUs=64 Partition=cpu-opteron
[2022-06-26T11:02:36.572] sched: Allocate JobId=45106 NodeList=cpu01 #CPUs=16 Partition=cpu-opteron
[2022-06-26T11:06:34.933] sched: Allocate JobId=45107 NodeList=cpu01 #CPUs=16 Partition=cpu-opteron
[2022-06-26T11:10:02.700] sched: Allocate JobId=45108 NodeList=cpu01 #CPUs=16 Partition=cpu-opteron
[2022-06-26T12:41:05.321] sched: Allocate JobId=45109 NodeList=cpu01 #CPUs=16 Partition=cpu-opteron
[2022-06-26T13:12:06.006] sched: Allocate JobId=45110 NodeList=gpu02 #CPUs=4 Partition=gpu-titan
[2022-06-26T14:14:35.707] sched: Allocate JobId=45111 NodeList=cpu01 #CPUs=16 Partition=cpu-opteron
[2022-06-26T14:15:31.270] sched: Allocate JobId=45103 NodeList=cpu15 #CPUs=16 Partition=cpu-epyc
[2022-06-26T14:16:31.852] sched: Allocate JobId=45112 NodeList=cpu01 #CPUs=4 Partition=cpu-opteron
[2022-06-26T14:19:10.156] sched: Allocate JobId=45113 NodeList=cpu01 #CPUs=16 Partition=cpu-opteron
[2022-06-26T14:23:47.664] sched: Allocate JobId=45114 NodeList=gpu05 #CPUs=8 Partition=gpu-v100s
[2022-06-26T14:24:58.766] sched: Allocate JobId=45115 NodeList=gpu05 #CPUs=8 Partition=gpu-v100s
[2022-06-26T14:27:35.027] sched: Allocate JobId=45116 NodeList=gpu05 #CPUs=8 Partition=gpu-v100s
[2022-06-26T14:32:18.463] sched: Allocate JobId=45118 NodeList=gpu05 #CPUs=8 Partition=gpu-v100s
[2022-06-26T14:33:58.708] sched: Allocate JobId=45119 NodeList=gpu05 #CPUs=8 Partition=gpu-v100s
[2022-06-26T14:36:15.902] sched: Allocate JobId=45120 NodeList=cpu15 #CPUs=16 Partition=cpu-epyc
[2022-06-26T14:38:09.169] sched: Allocate JobId=45121 NodeList=gpu05 #CPUs=8 Partition=gpu-v100s
[2022-06-26T14:40:29.363] sched: Allocate JobId=45122 NodeList=gpu05 #CPUs=8 Partition=gpu-v100s
[2022-06-26T14:56:18.564] sched: _slurm_rpc_allocate_resources JobId=45124 NodeList=(null) usec=1005
[2022-06-26T14:57:39.833] sched: _slurm_rpc_allocate_resources JobId=45125 NodeList=(null) usec=938
[2022-06-26T14:58:26.936] sched: _slurm_rpc_allocate_resources JobId=45127 NodeList=gpu05 usec=19219
[2022-06-26T15:02:30.927] sched: Allocate JobId=45123 NodeList=cpu15 #CPUs=16 Partition=cpu-epyc
[2022-06-26T16:03:25.712] sched: Allocate JobId=45117 NodeList=cpu01 #CPUs=16 Partition=cpu-opteron
[2022-06-26T17:46:22.578] sched: Allocate JobId=45129 NodeList=cpu12 #CPUs=16 Partition=cpu-epyc
[2022-06-26T17:47:05.625] sched: Allocate JobId=45130 NodeList=cpu13 #CPUs=16 Partition=cpu-epyc
[2022-06-26T17:48:36.823] sched: Allocate JobId=45131 NodeList=cpu01 #CPUs=16 Partition=cpu-opteron
[2022-06-26T17:49:32.903] sched: Allocate JobId=45132 NodeList=cpu13 #CPUs=16 Partition=cpu-epyc
[2022-06-26T17:50:31.978] sched: Allocate JobId=45133 NodeList=cpu15 #CPUs=16 Partition=cpu-epyc
[2022-06-26T17:51:22.048] sched: Allocate JobId=45134 NodeList=cpu15 #CPUs=16 Partition=cpu-epyc
[2022-06-26T17:52:12.117] sched: Allocate JobId=45135 NodeList=cpu14 #CPUs=16 Partition=cpu-epyc
[2022-06-26T17:54:11.409] sched: Allocate JobId=45136 NodeList=cpu14 #CPUs=16 Partition=cpu-epyc
[2022-06-26T17:55:01.480] sched: Allocate JobId=45137 NodeList=cpu14 #CPUs=16 Partition=cpu-epyc
[2022-06-26T19:28:39.530] sched: Allocate JobId=45138 NodeList=cpu12 #CPUs=32 Partition=cpu-epyc
[2022-06-26T21:21:19.998] sched: Allocate JobId=45128 NodeList=gpu05 #CPUs=12 Partition=gpu-v100s
[2022-06-26T22:57:17.792] sched: Allocate JobId=45140 NodeList=cpu01 #CPUs=16 Partition=cpu-opteron
[2022-06-26T22:59:00.025] sched: Allocate JobId=45141 NodeList=gpu05 #CPUs=8 Partition=gpu-v100s
[2022-06-26T23:04:08.550] sched: Allocate JobId=45142 NodeList=gpu05 #CPUs=8 Partition=gpu-v100s
[2022-06-26T23:07:01.789] sched: Allocate JobId=45143 NodeList=gpu05 #CPUs=8 Partition=gpu-v100s
[2022-06-26T23:09:52.105] sched: Allocate JobId=45144 NodeList=cpu01 #CPUs=16 Partition=cpu-opteron
[2022-06-26T23:28:20.251] sched: _slurm_rpc_allocate_resources JobId=45148 NodeList=gpu05 usec=17778
[2022-06-26T23:35:22.729] sched: _slurm_rpc_allocate_resources JobId=45149 NodeList=(null) usec=765
[2022-06-26T23:35:59.921] sched: _slurm_rpc_allocate_resources JobId=45150 NodeList=(null) usec=741
[2022-06-26T23:37:01.008] sched: _slurm_rpc_allocate_resources JobId=45151 NodeList=gpu02 usec=1010
[2022-06-27T00:02:45.821] sched: _slurm_rpc_allocate_resources JobId=45152 NodeList=gpu05 usec=4372
[2022-06-27T00:35:03.873] sched: Allocate JobId=45145 NodeList=cpu11 #CPUs=16 Partition=cpu-opteron
[2022-06-27T00:50:31.404] sched: Allocate JobId=45146 NodeList=cpu01 #CPUs=16 Partition=cpu-opteron
[2022-06-27T01:39:11.357] sched: Allocate JobId=45147 NodeList=cpu11 #CPUs=16 Partition=cpu-opteron
[2022-06-27T06:10:39.726] sched: Allocate JobId=45139 NodeList=cpu12 #CPUs=32 Partition=cpu-epyc
[2022-06-27T07:57:28.156] sched: _slurm_rpc_allocate_resources JobId=45153 NodeList=cpu01 usec=17007
[2022-06-27T10:16:58.432] sched: Allocate JobId=45154 NodeList=cpu01 #CPUs=16 Partition=cpu-opteron
[2022-06-27T10:18:19.631] sched: Allocate JobId=45155 NodeList=cpu13 #CPUs=16 Partition=cpu-epyc
[2022-06-27T10:23:36.144] sched: Allocate JobId=45156 NodeList=cpu13 #CPUs=16 Partition=cpu-epyc
[2022-06-27T11:20:34.498] sched: Allocate JobId=45158 NodeList=cpu01 #CPUs=1 Partition=cpu-opteron
[2022-06-27T11:30:15.521] sched: Allocate JobId=45159 NodeList=cpu13 #CPUs=16 Partition=cpu-epyc
[2022-06-27T11:38:14.177] sched: Allocate JobId=45160 NodeList=cpu13 #CPUs=16 Partition=cpu-epyc
[2022-06-27T11:42:54.272] sched: Allocate JobId=45161 NodeList=cpu13 #CPUs=16 Partition=cpu-epyc
[2022-06-27T11:46:10.536] sched: Allocate JobId=45162 NodeList=cpu01 #CPUs=1 Partition=cpu-opteron
[2022-06-27T11:54:28.556] sched: Allocate JobId=45163 NodeList=cpu01 #CPUs=1 Partition=cpu-opteron
[2022-06-27T12:01:47.365] sched: Allocate JobId=45164 NodeList=cpu01 #CPUs=1 Partition=cpu-opteron
[2022-06-27T13:22:27.843] sched: Allocate JobId=45165 NodeList=cpu13 #CPUs=2 Partition=cpu-epyc
[2022-06-27T13:28:05.451] sched: Allocate JobId=45166 NodeList=cpu13 #CPUs=2 Partition=cpu-epyc
[2022-06-27T13:30:31.653] sched: Allocate JobId=45167 NodeList=cpu13 #CPUs=2 Partition=cpu-epyc
[2022-06-27T13:36:23.287] sched: Allocate JobId=45168 NodeList=cpu13 #CPUs=2 Partition=cpu-epyc
[2022-06-27T13:42:52.033] sched: Allocate JobId=45169 NodeList=cpu01 #CPUs=16 Partition=cpu-opteron
[2022-06-27T13:45:33.253] sched: Allocate JobId=45171 NodeList=cpu14 #CPUs=16 Partition=cpu-epyc
[2022-06-27T14:05:17.420] sched: Allocate JobId=45172 NodeList=cpu13 #CPUs=16 Partition=cpu-epyc
[2022-06-27T14:06:32.500] sched: Allocate JobId=45173 NodeList=cpu13 #CPUs=16 Partition=cpu-epyc
[2022-06-27T14:09:43.900] sched: Allocate JobId=45174 NodeList=cpu13 #CPUs=16 Partition=cpu-epyc
[2022-06-27T14:10:41.978] sched: Allocate JobId=45175 NodeList=cpu13 #CPUs=16 Partition=cpu-epyc
[2022-06-27T14:11:37.056] sched: Allocate JobId=45176 NodeList=cpu13 #CPUs=16 Partition=cpu-epyc
[2022-06-27T14:12:32.190] sched: Allocate JobId=45177 NodeList=cpu13 #CPUs=16 Partition=cpu-epyc
[2022-06-27T14:12:35.198] sched: Allocate JobId=45178 NodeList=cpu14 #CPUs=16 Partition=cpu-epyc
[2022-06-27T14:28:21.718] sched: _slurm_rpc_allocate_resources JobId=45179 NodeList=(null) usec=1165
[2022-06-27T14:28:21.866] sched: Allocate JobId=45179 NodeList=gpu02 #CPUs=8 Partition=gpu-titan
[2022-06-27T15:50:42.945] sched: Allocate JobId=45180 NodeList=cpu13 #CPUs=16 Partition=cpu-epyc
[2022-06-27T15:51:21.997] sched: Allocate JobId=45181 NodeList=cpu01 #CPUs=16 Partition=cpu-opteron
[2022-06-27T15:52:14.055] sched: Allocate JobId=45182 NodeList=cpu13 #CPUs=16 Partition=cpu-epyc
[2022-06-27T16:19:37.112] sched: Allocate JobId=45184 NodeList=cpu07 #CPUs=64 Partition=cpu-opteron
[2022-06-27T16:23:52.552] sched: Allocate JobId=45185 NodeList=cpu01 #CPUs=16 Partition=cpu-opteron
[2022-06-27T16:24:32.587] sched: Allocate JobId=45186 NodeList=cpu01 #CPUs=16 Partition=cpu-opteron
[2022-06-27T16:27:19.833] sched: Allocate JobId=45187 NodeList=cpu01 #CPUs=1 Partition=cpu-opteron
[2022-06-27T16:30:34.180] sched: Allocate JobId=45188 NodeList=cpu01 #CPUs=1 Partition=cpu-opteron
[2022-06-27T16:33:10.505] sched: Allocate JobId=45189 NodeList=cpu01 #CPUs=16 Partition=cpu-opteron
[2022-06-27T16:42:46.556] sched: Allocate JobId=45190 NodeList=cpu13 #CPUs=16 Partition=cpu-epyc
[2022-06-27T16:48:56.184] sched: Allocate JobId=45209 NodeList=cpu01 #CPUs=16 Partition=cpu-opteron
[2022-06-27T16:59:31.298] sched: Allocate JobId=45210 NodeList=cpu01 #CPUs=16 Partition=cpu-opteron
[2022-06-27T17:03:13.395] sched: Allocate JobId=45191 NodeList=cpu13 #CPUs=16 Partition=cpu-epyc
[2022-06-27T17:24:35.715] sched: Allocate JobId=45192 NodeList=cpu13 #CPUs=16 Partition=cpu-epyc
[2022-06-27T17:32:11.768] sched: Allocate JobId=45211 NodeList=cpu01 #CPUs=16 Partition=cpu-opteron
[2022-06-27T17:46:41.266] sched: Allocate JobId=45193 NodeList=cpu12 #CPUs=16 Partition=cpu-epyc
[2022-06-27T17:47:11.322] sched: Allocate JobId=45194 NodeList=cpu13 #CPUs=16 Partition=cpu-epyc
[2022-06-27T17:48:15.269] sched: Allocate JobId=45195 NodeList=cpu13 #CPUs=16 Partition=cpu-epyc
[2022-06-27T17:49:41.706] sched: Allocate JobId=45196 NodeList=cpu13 #CPUs=16 Partition=cpu-epyc
[2022-06-27T17:50:41.739] sched: Allocate JobId=45197 NodeList=cpu15 #CPUs=16 Partition=cpu-epyc
[2022-06-27T17:51:41.805] sched: Allocate JobId=45198 NodeList=cpu15 #CPUs=16 Partition=cpu-epyc
[2022-06-27T17:52:41.022] sched: Allocate JobId=45199 NodeList=cpu14 #CPUs=16 Partition=cpu-epyc
[2022-06-27T17:55:11.231] sched: Allocate JobId=45200 NodeList=cpu14 #CPUs=16 Partition=cpu-epyc
[2022-06-27T17:55:24.715] sched: Allocate JobId=45201 NodeList=cpu13 #CPUs=16 Partition=cpu-epyc
[2022-06-27T17:56:04.966] sched: Allocate JobId=45202 NodeList=cpu15 #CPUs=16 Partition=cpu-epyc
[2022-06-27T17:57:47.995] sched: Allocate JobId=45203 NodeList=cpu15 #CPUs=16 Partition=cpu-epyc
[2022-06-27T17:58:07.658] sched: Allocate JobId=45204 NodeList=cpu14 #CPUs=16 Partition=cpu-epyc
[2022-06-27T18:00:56.588] sched: Allocate JobId=45205 NodeList=cpu14 #CPUs=16 Partition=cpu-epyc
[2022-06-27T18:01:22.111] sched: Allocate JobId=45206 NodeList=cpu13 #CPUs=16 Partition=cpu-epyc
[2022-06-27T18:03:45.223] sched: Allocate JobId=45207 NodeList=cpu12 #CPUs=16 Partition=cpu-epyc
[2022-06-27T18:04:19.779] sched: Allocate JobId=45208 NodeList=cpu13 #CPUs=16 Partition=cpu-epyc
[2022-06-27T18:09:38.069] sched: Allocate JobId=45183 NodeList=cpu13 #CPUs=48 Partition=cpu-epyc
[2022-06-27T18:10:27.997] sched: Allocate JobId=45212 NodeList=cpu12 #CPUs=16 Partition=cpu-epyc
[2022-06-27T18:11:47.089] sched: Allocate JobId=45213 NodeList=cpu14 #CPUs=16 Partition=cpu-epyc
[2022-06-27T18:13:44.386] sched: Allocate JobId=45216 NodeList=cpu01 #CPUs=16 Partition=cpu-opteron
[2022-06-27T18:14:08.152] sched: Allocate JobId=45214 NodeList=cpu15 #CPUs=16 Partition=cpu-epyc
[2022-06-27T18:15:05.500] sched: Allocate JobId=45217 NodeList=cpu01 #CPUs=16 Partition=cpu-opteron
[2022-06-27T18:15:53.163] sched: Allocate JobId=45215 NodeList=cpu14 #CPUs=16 Partition=cpu-epyc
[2022-06-27T18:18:38.883] sched: Allocate JobId=45218 NodeList=cpu11 #CPUs=16 Partition=cpu-opteron
[2022-06-27T18:21:57.158] sched: Allocate JobId=45219 NodeList=cpu11 #CPUs=16 Partition=cpu-opteron
[2022-06-27T19:02:32.625] sched: Allocate JobId=45220 NodeList=cpu12 #CPUs=32 Partition=cpu-epyc
[2022-06-27T21:13:01.534] sched: Allocate JobId=45221 NodeList=cpu15 #CPUs=16 Partition=cpu-epyc
[2022-06-27T21:14:51.675] sched: Allocate JobId=45222 NodeList=cpu11 #CPUs=32 Partition=cpu-opteron
[2022-06-27T21:19:00.124] sched: Allocate JobId=45223 NodeList=cpu11 #CPUs=32 Partition=cpu-opteron
[2022-06-27T21:37:26.102] sched: Allocate JobId=45224 NodeList=cpu15 #CPUs=16 Partition=cpu-epyc
[2022-06-27T22:02:24.622] sched: Allocate JobId=45227 NodeList=cpu15 #CPUs=16 Partition=cpu-epyc
[2022-06-27T22:09:33.788] sched: Allocate JobId=45225 NodeList=cpu11 #CPUs=32 Partition=cpu-opteron
[2022-06-27T22:59:58.319] sched: Allocate JobId=45226 NodeList=cpu11 #CPUs=32 Partition=cpu-opteron
[2022-06-27T23:17:06.965] sched: _slurm_rpc_allocate_resources JobId=45228 NodeList=(null) usec=1025
[2022-06-27T23:18:06.638] sched: _slurm_rpc_allocate_resources JobId=45229 NodeList=(null) usec=799
[2022-06-27T23:18:06.825] sched: Allocate JobId=45229 NodeList=cpu15 #CPUs=4 Partition=cpu-epyc
[2022-06-27T23:29:34.033] sched: Allocate JobId=45231 NodeList=gpu02 #CPUs=12 Partition=gpu-titan
[2022-06-27T23:32:16.247] sched: Allocate JobId=45232 NodeList=gpu02 #CPUs=12 Partition=gpu-titan
[2022-06-28T01:37:20.576] sched: Allocate JobId=44358 NodeList=gpu05 #CPUs=64 Partition=gpu-v100s
[2022-06-28T01:37:43.686] sched: Allocate JobId=44781 NodeList=gpu05 #CPUs=32 Partition=gpu-v100s
[2022-06-28T09:49:51.743] sched: Allocate JobId=45233 NodeList=cpu11 #CPUs=1 Partition=cpu-opteron
[2022-06-28T09:50:28.783] sched: Allocate JobId=45234 NodeList=cpu13 #CPUs=48 Partition=cpu-epyc
[2022-06-28T11:14:25.278] sched: Allocate JobId=45235 NodeList=cpu11 #CPUs=1 Partition=cpu-opteron
[2022-06-28T11:14:31.281] sched: Allocate JobId=45236 NodeList=cpu13 #CPUs=48 Partition=cpu-epyc
[2022-06-28T11:54:06.421] sched: _slurm_rpc_allocate_resources JobId=45237 NodeList=cpu11 usec=4213
[2022-06-28T12:08:21.039] sched: Allocate JobId=45238 NodeList=cpu11 #CPUs=2 Partition=cpu-opteron
[2022-06-28T12:09:49.518] sched/backfill: _start_job: Started JobId=45239 in cpu-opteron on cpu11
[2022-06-28T12:10:10.192] sched: Allocate JobId=45240 NodeList=cpu11 #CPUs=2 Partition=cpu-opteron
[2022-06-28T12:10:38.230] sched: Allocate JobId=45241 NodeList=cpu11 #CPUs=2 Partition=cpu-opteron
[2022-06-28T12:11:11.275] sched: Allocate JobId=45242 NodeList=cpu11 #CPUs=2 Partition=cpu-opteron
[2022-06-28T13:18:55.057] sched: Allocate JobId=44782 NodeList=gpu05 #CPUs=32 Partition=gpu-v100s
[2022-06-28T13:19:15.309] sched: Allocate JobId=45230 NodeList=gpu05 #CPUs=12 Partition=gpu-v100s
[2022-06-28T13:30:53.907] sched: Allocate JobId=45244 NodeList=cpu12 #CPUs=32 Partition=cpu-epyc
[2022-06-28T13:32:01.989] sched: Allocate JobId=45245 NodeList=cpu12 #CPUs=32 Partition=cpu-epyc
[2022-06-28T14:09:21.110] sched: Allocate JobId=45246 NodeList=cpu12 #CPUs=32 Partition=cpu-epyc
[2022-06-28T14:24:31.631] sched: Allocate JobId=45247 NodeList=cpu12 #CPUs=32 Partition=cpu-epyc
[2022-06-28T14:34:08.608] sched: Allocate JobId=45248 NodeList=cpu12 #CPUs=32 Partition=cpu-epyc
[2022-06-28T14:35:51.757] sched: Allocate JobId=45249 NodeList=cpu15 #CPUs=32 Partition=cpu-epyc
[2022-06-28T14:38:41.119] sched: Allocate JobId=45250 NodeList=cpu15 #CPUs=32 Partition=cpu-epyc
[2022-06-28T14:42:05.401] sched: Allocate JobId=45252 NodeList=cpu03 #CPUs=64 Partition=cpu-opteron
[2022-06-28T14:44:12.417] sched: Allocate JobId=45251 NodeList=cpu13 #CPUs=32 Partition=cpu-epyc
[2022-06-28T15:03:49.574] sched/backfill: _start_job: Started JobId=45253 in cpu-opteron on cpu07
[2022-06-28T15:04:56.869] sched: Allocate JobId=45255 NodeList=cpu11 #CPUs=48 Partition=cpu-opteron
[2022-06-28T16:30:05.364] sched: Allocate JobId=45256 NodeList=cpu12 #CPUs=32 Partition=cpu-epyc
[2022-06-28T16:59:40.644] sched: _slurm_rpc_allocate_resources JobId=45257 NodeList=cpu01 usec=13580
[2022-06-28T17:01:19.230] sched: Allocate JobId=45258 NodeList=cpu13 #CPUs=16 Partition=cpu-epyc
[2022-06-28T17:03:51.576] sched: Allocate JobId=45259 NodeList=cpu13 #CPUs=16 Partition=cpu-epyc
[2022-06-28T17:04:19.614] sched: Allocate JobId=45260 NodeList=cpu13 #CPUs=16 Partition=cpu-epyc
[2022-06-28T17:05:05.680] sched: Allocate JobId=45261 NodeList=cpu13 #CPUs=16 Partition=cpu-epyc
[2022-06-28T17:06:09.770] sched: Allocate JobId=45262 NodeList=cpu13 #CPUs=16 Partition=cpu-epyc
[2022-06-28T17:06:48.823] sched: Allocate JobId=45263 NodeList=cpu13 #CPUs=16 Partition=cpu-epyc
[2022-06-28T17:08:53.167] sched: Allocate JobId=45264 NodeList=cpu13 #CPUs=16 Partition=cpu-epyc
[2022-06-28T17:09:22.208] sched: Allocate JobId=45265 NodeList=cpu13 #CPUs=16 Partition=cpu-epyc
[2022-06-28T17:11:43.405] sched: Allocate JobId=45266 NodeList=cpu13 #CPUs=16 Partition=cpu-epyc
[2022-06-28T17:14:11.753] sched: Allocate JobId=45267 NodeList=cpu13 #CPUs=16 Partition=cpu-epyc
[2022-06-28T17:15:11.840] sched: Allocate JobId=45268 NodeList=cpu15 #CPUs=16 Partition=cpu-epyc
[2022-06-28T17:24:16.487] sched: Allocate JobId=45273 NodeList=cpu14 #CPUs=16 Partition=cpu-epyc
[2022-06-28T17:25:25.582] sched: Allocate JobId=45274 NodeList=cpu10 #CPUs=32 Partition=cpu-opteron
[2022-06-28T17:27:52.085] sched: Allocate JobId=45275 NodeList=cpu14 #CPUs=16 Partition=cpu-epyc
[2022-06-28T17:30:51.340] sched: Allocate JobId=45276 NodeList=cpu14 #CPUs=16 Partition=cpu-epyc
[2022-06-28T17:31:55.428] sched: Allocate JobId=45277 NodeList=cpu10 #CPUs=32 Partition=cpu-opteron
[2022-06-28T18:06:51.113] sched: Allocate JobId=45278 NodeList=cpu11 #CPUs=2 Partition=cpu-opteron
[2022-06-28T18:08:51.404] sched: Allocate JobId=45279 NodeList=gpu02 #CPUs=4 Partition=gpu-titan
[2022-06-28T18:34:48.187] sched: Allocate JobId=45280 NodeList=cpu14 #CPUs=48 Partition=cpu-epyc
[2022-06-28T18:40:15.779] sched: Allocate JobId=45281 NodeList=cpu14 #CPUs=48 Partition=cpu-epyc
[2022-06-28T18:59:59.882] sched: Allocate JobId=45282 NodeList=cpu01 #CPUs=48 Partition=cpu-opteron
[2022-06-28T20:30:21.905] sched: Allocate JobId=45283 NodeList=gpu05 #CPUs=32 Partition=gpu-v100s
[2022-06-28T20:32:31.134] sched: Allocate JobId=45285 NodeList=gpu05 #CPUs=16 Partition=gpu-v100s
[2022-06-28T20:33:34.266] sched: Allocate JobId=45286 NodeList=gpu05 #CPUs=16 Partition=gpu-v100s
[2022-06-28T20:33:48.285] sched: Allocate JobId=45287 NodeList=gpu05 #CPUs=16 Partition=gpu-v100s
[2022-06-28T21:08:13.931] sched: Allocate JobId=45288 NodeList=cpu07 #CPUs=64 Partition=cpu-opteron
[2022-06-28T21:14:38.551] sched: Allocate JobId=45289 NodeList=cpu07 #CPUs=64 Partition=cpu-opteron
[2022-06-28T22:41:33.813] sched: Allocate JobId=45290 NodeList=cpu14 #CPUs=48 Partition=cpu-epyc
[2022-06-28T22:50:05.764] sched: Allocate JobId=45291 NodeList=cpu14 #CPUs=48 Partition=cpu-epyc
[2022-06-28T23:01:27.949] sched: Allocate JobId=45292 NodeList=cpu14 #CPUs=48 Partition=cpu-epyc
[2022-06-28T23:19:04.786] sched: Allocate JobId=45293 NodeList=cpu14 #CPUs=48 Partition=cpu-epyc
[2022-06-28T23:20:38.909] sched: Allocate JobId=45294 NodeList=cpu14 #CPUs=48 Partition=cpu-epyc
[2022-06-28T23:32:42.194] sched: Allocate JobId=45295 NodeList=cpu01 #CPUs=2 Partition=cpu-opteron
[2022-06-28T23:33:17.241] sched: Allocate JobId=45296 NodeList=cpu01 #CPUs=2 Partition=cpu-opteron
[2022-06-29T00:25:46.875] sched: Allocate JobId=45297 NodeList=cpu15 #CPUs=48 Partition=cpu-epyc
[2022-06-29T00:26:55.959] sched: Allocate JobId=45298 NodeList=cpu15 #CPUs=48 Partition=cpu-epyc
[2022-06-29T00:28:42.188] sched: Allocate JobId=45299 NodeList=cpu01 #CPUs=2 Partition=cpu-opteron
[2022-06-29T00:36:37.951] sched: Allocate JobId=45300 NodeList=cpu14 #CPUs=48 Partition=cpu-epyc
[2022-06-29T00:56:03.992] sched: Allocate JobId=45301 NodeList=cpu15 #CPUs=48 Partition=cpu-epyc
[2022-06-29T00:58:33.285] sched: Allocate JobId=45302 NodeList=cpu15 #CPUs=48 Partition=cpu-epyc
[2022-06-29T01:05:36.354] sched: Allocate JobId=45304 NodeList=gpu01 #CPUs=16 Partition=gpu-k10
[2022-06-29T04:00:25.465] sched: Allocate JobId=45305 NodeList=cpu12 #CPUs=48 Partition=cpu-epyc
[2022-06-29T07:02:13.437] sched: Allocate JobId=45306 NodeList=cpu12 #CPUs=32 Partition=cpu-epyc
[2022-06-29T07:10:01.301] sched: Allocate JobId=45307 NodeList=cpu14 #CPUs=48 Partition=cpu-epyc
[2022-06-29T07:10:49.819] sched/backfill: _start_job: Started JobId=45308 in cpu-epyc on cpu14
[2022-06-29T07:15:46.948] sched: Allocate JobId=45311 NodeList=cpu05 #CPUs=64 Partition=cpu-opteron
[2022-06-29T07:16:15.985] sched: Allocate JobId=45312 NodeList=cpu10 #CPUs=64 Partition=cpu-opteron
[2022-06-29T07:49:48.376] sched: _slurm_rpc_allocate_resources JobId=45313 NodeList=cpu01 usec=15960
[2022-06-29T08:24:18.647] sched: Allocate JobId=45310 NodeList=cpu14 #CPUs=32 Partition=cpu-epyc
[2022-06-29T08:50:21.033] sched: Allocate JobId=45315 NodeList=cpu12 #CPUs=16 Partition=cpu-epyc
[2022-06-29T08:56:30.801] sched: Allocate JobId=45319 NodeList=gpu02 #CPUs=4 Partition=gpu-titan
[2022-06-29T08:56:56.824] sched: Allocate JobId=45320 NodeList=cpu12 #CPUs=16 Partition=cpu-epyc
[2022-06-29T10:13:15.535] sched: Allocate JobId=45321 NodeList=cpu11 #CPUs=16 Partition=cpu-opteron
[2022-06-29T10:18:02.993] sched: Allocate JobId=45323 NodeList=cpu13 #CPUs=16 Partition=cpu-epyc
[2022-06-29T10:28:42.592] sched: _slurm_rpc_allocate_resources JobId=45324 NodeList=cpu01 usec=18333
[2022-06-29T10:42:31.480] sched: Allocate JobId=45325 NodeList=cpu01 #CPUs=2 Partition=cpu-opteron
[2022-06-29T10:53:07.625] sched: Allocate JobId=45326 NodeList=cpu01 #CPUs=2 Partition=cpu-opteron
[2022-06-29T10:57:52.116] sched: Allocate JobId=45327 NodeList=cpu01 #CPUs=2 Partition=cpu-opteron
[2022-06-29T11:08:24.228] sched: Allocate JobId=45328 NodeList=cpu13 #CPUs=16 Partition=cpu-epyc
[2022-06-29T11:09:26.314] sched: Allocate JobId=45329 NodeList=cpu13 #CPUs=16 Partition=cpu-epyc
[2022-06-29T11:20:38.507] sched: Allocate JobId=45330 NodeList=cpu13 #CPUs=16 Partition=cpu-epyc
[2022-06-29T11:21:40.593] sched: Allocate JobId=45331 NodeList=cpu13 #CPUs=16 Partition=cpu-epyc
[2022-06-29T11:22:36.786] sched: Allocate JobId=45332 NodeList=cpu13 #CPUs=16 Partition=cpu-epyc
[2022-06-29T11:27:54.385] sched: Allocate JobId=45333 NodeList=cpu14 #CPUs=16 Partition=cpu-epyc
[2022-06-29T11:28:48.463] sched: Allocate JobId=45334 NodeList=cpu14 #CPUs=16 Partition=cpu-epyc
[2022-06-29T11:33:51.968] sched: Allocate JobId=45335 NodeList=cpu13 #CPUs=16 Partition=cpu-epyc
[2022-06-29T11:43:59.088] sched: Allocate JobId=45337 NodeList=gpu03 #CPUs=16 Partition=gpu-k10
[2022-06-29T11:47:19.358] sched: Allocate JobId=45338 NodeList=gpu01 #CPUs=16 Partition=gpu-k10
[2022-06-29T12:56:23.035] sched: Allocate JobId=45339 NodeList=cpu01 #CPUs=4 Partition=cpu-opteron
[2022-06-29T12:58:55.327] sched: Allocate JobId=45340 NodeList=cpu01 #CPUs=4 Partition=cpu-opteron
[2022-06-29T13:01:13.520] sched: Allocate JobId=45341 NodeList=cpu11 #CPUs=16 Partition=cpu-opteron
[2022-06-29T13:07:41.245] sched: Allocate JobId=45342 NodeList=cpu01 #CPUs=2 Partition=cpu-opteron
[2022-06-29T13:18:14.328] sched: Allocate JobId=45343 NodeList=cpu01 #CPUs=2 Partition=cpu-opteron
[2022-06-29T13:20:49.904] sched/backfill: _start_job: Started JobId=45344 in cpu-opteron on cpu01
[2022-06-29T13:26:27.414] sched: Allocate JobId=45345 NodeList=cpu01 #CPUs=16 Partition=cpu-opteron
[2022-06-29T13:27:07.469] sched: Allocate JobId=45346 NodeList=cpu01 #CPUs=16 Partition=cpu-opteron
[2022-06-29T13:28:36.029] sched: Allocate JobId=45347 NodeList=cpu01 #CPUs=16 Partition=cpu-opteron
[2022-06-29T13:49:57.309] sched: Allocate JobId=45350 NodeList=gpu02 #CPUs=4 Partition=gpu-titan
[2022-06-29T14:12:26.743] sched: Allocate JobId=45356 NodeList=gpu03 #CPUs=16 Partition=gpu-k10
[2022-06-29T14:26:00.106] sched: Allocate JobId=45360 NodeList=gpu01 #CPUs=16 Partition=gpu-k10
[2022-06-29T14:51:10.920] sched: Allocate JobId=45352 NodeList=cpu01 #CPUs=16 Partition=cpu-opteron
[2022-06-29T14:51:10.921] sched: Allocate JobId=45353 NodeList=cpu01 #CPUs=16 Partition=cpu-opteron
[2022-06-29T14:51:10.922] sched: Allocate JobId=45354 NodeList=cpu01 #CPUs=16 Partition=cpu-opteron
[2022-06-29T14:57:12.705] sched: Allocate JobId=45355 NodeList=cpu11 #CPUs=16 Partition=cpu-opteron
[2022-06-29T14:59:42.520] sched: Allocate JobId=45357 NodeList=cpu01 #CPUs=16 Partition=cpu-opteron
[2022-06-29T15:02:03.150] sched: Allocate JobId=45358 NodeList=cpu01 #CPUs=16 Partition=cpu-opteron
[2022-06-29T15:06:25.624] sched: Allocate JobId=45359 NodeList=cpu01 #CPUs=16 Partition=cpu-opteron
[2022-06-29T15:08:04.547] sched: Allocate JobId=45361 NodeList=cpu13 #CPUs=16 Partition=cpu-epyc
[2022-06-29T15:09:20.636] sched: Allocate JobId=45362 NodeList=cpu14 #CPUs=16 Partition=cpu-epyc
[2022-06-29T15:12:40.211] sched: Allocate JobId=45363 NodeList=gpu04 #CPUs=16 Partition=gpu-k40c
[2022-06-29T15:14:56.382] sched: Allocate JobId=45364 NodeList=gpu04 #CPUs=16 Partition=gpu-k40c
[2022-06-29T16:13:20.655] sched: Allocate JobId=45366 NodeList=cpu01 #CPUs=48 Partition=cpu-opteron
[2022-06-29T17:09:32.653] sched: Allocate JobId=45368 NodeList=cpu11 #CPUs=16 Partition=cpu-opteron
[2022-06-29T18:49:43.628] sched: Allocate JobId=45376 NodeList=cpu12 #CPUs=32 Partition=cpu-epyc
[2022-06-29T18:51:33.763] sched: Allocate JobId=45377 NodeList=cpu12 #CPUs=32 Partition=cpu-epyc
[2022-06-29T20:06:08.654] sched: Allocate JobId=45378 NodeList=cpu13 #CPUs=16 Partition=cpu-epyc
[2022-06-29T20:16:36.795] sched: Allocate JobId=45379 NodeList=cpu14 #CPUs=16 Partition=cpu-epyc
[2022-06-29T20:40:48.635] sched: Allocate JobId=45380 NodeList=gpu05 #CPUs=16 Partition=gpu-v100s
[2022-06-29T20:41:16.675] sched: Allocate JobId=45381 NodeList=gpu05 #CPUs=16 Partition=gpu-v100s
[2022-06-29T21:30:27.713] sched: Allocate JobId=45369 NodeList=cpu05 #CPUs=16 Partition=cpu-opteron
[2022-06-29T21:30:27.714] sched: Allocate JobId=45370 NodeList=cpu05 #CPUs=16 Partition=cpu-opteron
[2022-06-29T21:30:27.714] sched: Allocate JobId=45371 NodeList=cpu05 #CPUs=16 Partition=cpu-opteron
[2022-06-29T21:30:27.715] sched: Allocate JobId=45372 NodeList=cpu05 #CPUs=16 Partition=cpu-opteron
[2022-06-29T21:30:31.300] sched: Allocate JobId=45373 NodeList=cpu05 #CPUs=16 Partition=cpu-opteron
[2022-06-29T21:30:49.283] sched: Allocate JobId=45374 NodeList=cpu05 #CPUs=16 Partition=cpu-opteron
[2022-06-29T23:17:53.213] sched: Allocate JobId=45383 NodeList=gpu01 #CPUs=4 Partition=gpu-k10
[2022-06-29T23:20:46.439] sched: Allocate JobId=45385 NodeList=gpu05 #CPUs=2 Partition=gpu-v100s
[2022-06-30T00:14:11.310] sched: Allocate JobId=45387 NodeList=gpu01 #CPUs=16 Partition=gpu-k10
[2022-06-30T00:16:07.471] sched: Allocate JobId=45388 NodeList=gpu05 #CPUs=16 Partition=gpu-v100s
[2022-06-30T00:22:13.109] sched: Allocate JobId=45390 NodeList=gpu05 #CPUs=16 Partition=gpu-v100s
[2022-06-30T00:55:34.010] sched: Allocate JobId=45391 NodeList=gpu05 #CPUs=16 Partition=gpu-v100s
[2022-06-30T00:56:58.115] sched: Allocate JobId=45392 NodeList=gpu05 #CPUs=16 Partition=gpu-v100s
[2022-06-30T01:21:47.681] sched: Allocate JobId=45393 NodeList=gpu05 #CPUs=16 Partition=gpu-v100s
[2022-06-30T01:22:58.862] sched: Allocate JobId=45394 NodeList=gpu05 #CPUs=16 Partition=gpu-v100s
[2022-06-30T01:24:24.984] sched: Allocate JobId=45395 NodeList=gpu05 #CPUs=16 Partition=gpu-v100s
[2022-06-30T01:30:21.621] sched: Allocate JobId=45396 NodeList=gpu05 #CPUs=16 Partition=gpu-v100s
[2022-06-30T01:32:02.767] sched: Allocate JobId=45397 NodeList=gpu05 #CPUs=16 Partition=gpu-v100s
[2022-06-30T01:45:57.417] sched: Allocate JobId=45398 NodeList=cpu12 #CPUs=24 Partition=cpu-epyc
[2022-06-30T06:37:43.477] sched: Allocate JobId=45375 NodeList=cpu05 #CPUs=16 Partition=cpu-opteron
[2022-06-30T07:57:21.093] sched: Allocate JobId=45384 NodeList=cpu11 #CPUs=2 Partition=cpu-opteron
[2022-06-30T07:57:24.567] sched: Allocate JobId=45386 NodeList=cpu11 #CPUs=16 Partition=cpu-opteron
[2022-06-30T09:33:19.336] sched: Allocate JobId=45399 NodeList=cpu04 #CPUs=64 Partition=cpu-opteron
[2022-06-30T10:10:12.721] sched: Allocate JobId=45400 NodeList=cpu01 #CPUs=8 Partition=cpu-opteron
[2022-06-30T10:12:44.057] sched: Allocate JobId=45401 NodeList=cpu01 #CPUs=16 Partition=cpu-opteron
[2022-06-30T10:20:09.754] sched: Allocate JobId=45402 NodeList=cpu12 #CPUs=8 Partition=cpu-epyc
[2022-06-30T10:25:13.290] sched: Allocate JobId=45403 NodeList=cpu12 #CPUs=8 Partition=cpu-epyc
[2022-06-30T11:01:37.233] sched: Allocate JobId=45404 NodeList=cpu12 #CPUs=8 Partition=cpu-epyc
[2022-06-30T11:06:08.111] sched: Allocate JobId=45405 NodeList=cpu12 #CPUs=8 Partition=cpu-epyc
[2022-06-30T13:44:58.153] sched: Allocate JobId=45410 NodeList=cpu05 #CPUs=64 Partition=cpu-opteron
[2022-06-30T13:47:03.309] sched: Allocate JobId=45411 NodeList=cpu13 #CPUs=32 Partition=cpu-epyc
[2022-06-30T13:48:08.519] sched: Allocate JobId=45412 NodeList=cpu13 #CPUs=32 Partition=cpu-epyc
[2022-06-30T13:56:44.118] sched: _slurm_rpc_allocate_resources JobId=45413 NodeList=cpu01 usec=18192
[2022-06-30T14:43:49.035] sched: Allocate JobId=45365 NodeList=gpu04 #CPUs=16 Partition=gpu-k40c
[2022-06-30T16:31:09.889] sched: Allocate JobId=45414 NodeList=cpu10 #CPUs=32 Partition=cpu-opteron
[2022-06-30T16:32:53.146] sched: Allocate JobId=45415 NodeList=cpu10 #CPUs=32 Partition=cpu-opteron
[2022-06-30T16:36:31.448] sched: Allocate JobId=45416 NodeList=cpu10 #CPUs=32 Partition=cpu-opteron
[2022-06-30T18:49:08.396] sched: Allocate JobId=45417 NodeList=cpu13 #CPUs=32 Partition=cpu-epyc
[2022-06-30T19:05:41.299] sched: Allocate JobId=45418 NodeList=cpu01 #CPUs=48 Partition=cpu-opteron
[2022-06-30T21:48:12.232] sched: Allocate JobId=45419 NodeList=gpu02 #CPUs=8 Partition=gpu-titan
[2022-06-30T21:58:38.570] sched: _slurm_rpc_allocate_resources JobId=45420 NodeList=cpu11 usec=15429
[2022-06-30T22:11:07.504] sched: Allocate JobId=45422 NodeList=cpu12 #CPUs=32 Partition=cpu-epyc
[2022-06-30T22:19:10.431] sched: Allocate JobId=45423 NodeList=cpu12 #CPUs=32 Partition=cpu-epyc
[2022-06-30T22:20:35.544] sched: Allocate JobId=45424 NodeList=cpu12 #CPUs=32 Partition=cpu-epyc
[2022-06-30T22:29:03.527] sched: Allocate JobId=45425 NodeList=cpu11 #CPUs=48 Partition=cpu-opteron
[2022-06-30T22:53:01.184] sched: Allocate JobId=45426 NodeList=cpu11 #CPUs=48 Partition=cpu-opteron
[2022-06-30T23:18:50.883] sched: Allocate JobId=45427 NodeList=cpu11 #CPUs=48 Partition=cpu-opteron
[2022-06-30T23:19:55.980] sched: Allocate JobId=45428 NodeList=cpu13 #CPUs=16 Partition=cpu-epyc
[2022-06-30T23:52:03.410] sched: Allocate JobId=45429 NodeList=cpu13 #CPUs=16 Partition=cpu-epyc
[2022-06-30T23:52:56.652] sched: Allocate JobId=45430 NodeList=cpu13 #CPUs=16 Partition=cpu-epyc
[2022-06-30T23:53:58.736] sched: Allocate JobId=45431 NodeList=cpu13 #CPUs=16 Partition=cpu-epyc
[2022-07-01T00:29:27.416] sched: Allocate JobId=45432 NodeList=cpu12 #CPUs=32 Partition=cpu-epyc
[2022-07-01T00:47:09.263] sched: Allocate JobId=45434 NodeList=cpu11 #CPUs=16 Partition=cpu-opteron
[2022-07-01T05:11:29.507] sched: Allocate JobId=45433 NodeList=cpu01 #CPUs=16 Partition=cpu-opteron
[2022-07-01T08:17:06.111] sched: Allocate JobId=45435 NodeList=cpu12 #CPUs=32 Partition=cpu-epyc
[2022-07-01T08:18:47.351] sched: Allocate JobId=45436 NodeList=cpu11 #CPUs=48 Partition=cpu-opteron
[2022-07-01T08:21:29.572] sched: Allocate JobId=45437 NodeList=cpu11 #CPUs=48 Partition=cpu-opteron
[2022-07-01T08:25:14.106] sched: Allocate JobId=45438 NodeList=cpu11 #CPUs=48 Partition=cpu-opteron
[2022-07-01T08:30:54.900] sched: Allocate JobId=45439 NodeList=cpu13 #CPUs=32 Partition=cpu-epyc
[2022-07-01T09:12:55.918] sched: _slurm_rpc_allocate_resources JobId=45440 NodeList=cpu11 usec=15448
[2022-07-01T09:42:35.101] sched: Allocate JobId=45441 NodeList=cpu11 #CPUs=36 Partition=cpu-opteron
[2022-07-01T10:14:54.938] sched: Allocate JobId=45442 NodeList=cpu03 #CPUs=64 Partition=cpu-opteron
[2022-07-01T11:48:15.701] sched: Allocate JobId=45443 NodeList=cpu07 #CPUs=32 Partition=cpu-opteron
[2022-07-01T11:53:33.290] sched: Allocate JobId=45444 NodeList=cpu07 #CPUs=32 Partition=cpu-opteron
[2022-07-01T11:54:39.369] sched: Allocate JobId=45445 NodeList=cpu11 #CPUs=11 Partition=cpu-opteron
[2022-07-01T13:14:07.785] sched: Allocate JobId=45446 NodeList=cpu04 #CPUs=32 Partition=cpu-opteron
[2022-07-01T13:38:46.798] sched: Allocate JobId=45447 NodeList=cpu04 #CPUs=64 Partition=cpu-opteron
[2022-07-01T14:21:08.072] sched: Allocate JobId=45448 NodeList=cpu04 #CPUs=64 Partition=cpu-opteron
[2022-07-01T14:31:56.265] sched: Allocate JobId=45449 NodeList=cpu05 #CPUs=64 Partition=cpu-opteron
[2022-07-01T14:47:51.105] sched: Allocate JobId=45452 NodeList=gpu05 #CPUs=16 Partition=gpu-v100s
[2022-07-01T14:54:03.716] sched: Allocate JobId=45454 NodeList=gpu05 #CPUs=16 Partition=gpu-v100s
[2022-07-01T15:04:42.838] sched: Allocate JobId=45457 NodeList=gpu05 #CPUs=16 Partition=gpu-v100s
[2022-07-01T15:05:51.930] sched: Allocate JobId=45458 NodeList=gpu05 #CPUs=16 Partition=gpu-v100s
[2022-07-01T18:32:35.038] sched: Allocate JobId=45450 NodeList=cpu11 #CPUs=16 Partition=cpu-opteron
[2022-07-01T18:32:35.039] sched: Allocate JobId=45451 NodeList=cpu11 #CPUs=16 Partition=cpu-opteron
[2022-07-01T19:51:37.073] sched: Allocate JobId=45459 NodeList=gpu05 #CPUs=16 Partition=gpu-v100s
[2022-07-01T21:30:40.752] sched: Allocate JobId=45453 NodeList=cpu04 #CPUs=16 Partition=cpu-opteron
[2022-07-01T21:30:40.753] sched: Allocate JobId=45455 NodeList=cpu04 #CPUs=16 Partition=cpu-opteron
[2022-07-01T21:30:40.754] sched: Allocate JobId=45456 NodeList=cpu04 #CPUs=16 Partition=cpu-opteron
[2022-07-01T21:30:40.754] sched: Allocate JobId=45460 NodeList=cpu04 #CPUs=16 Partition=cpu-opteron
[2022-07-01T23:05:27.733] sched: Allocate JobId=45473 NodeList=cpu14 #CPUs=32 Partition=cpu-epyc
[2022-07-01T23:34:27.811] sched: Allocate JobId=45461 NodeList=cpu07 #CPUs=16 Partition=cpu-opteron
[2022-07-01T23:34:27.811] sched: Allocate JobId=45462 NodeList=cpu07 #CPUs=16 Partition=cpu-opteron
[2022-07-02T00:31:44.129] sched: Allocate JobId=45476 NodeList=cpu11 #CPUs=5 Partition=cpu-opteron
[2022-07-02T00:47:25.667] sched: Allocate JobId=45463 NodeList=cpu11 #CPUs=16 Partition=cpu-opteron
[2022-07-02T03:58:26.835] sched: Allocate JobId=45474 NodeList=cpu14 #CPUs=32 Partition=cpu-epyc
[2022-07-02T04:46:23.174] sched: Allocate JobId=45472 NodeList=cpu15 #CPUs=48 Partition=cpu-epyc
[2022-07-02T04:52:52.219] sched: Allocate JobId=45475 NodeList=cpu15 #CPUs=32 Partition=cpu-epyc
[2022-07-02T05:11:54.773] sched: Allocate JobId=45464 NodeList=cpu01 #CPUs=16 Partition=cpu-opteron
[2022-07-02T05:39:58.926] sched: Allocate JobId=45465 NodeList=cpu04 #CPUs=16 Partition=cpu-opteron
[2022-07-02T06:37:13.716] sched: Allocate JobId=45466 NodeList=cpu04 #CPUs=16 Partition=cpu-opteron
[2022-07-02T08:18:25.823] sched: Allocate JobId=45477 NodeList=cpu14 #CPUs=32 Partition=cpu-epyc
[2022-07-02T08:20:20.525] sched: Allocate JobId=45478 NodeList=cpu15 #CPUs=32 Partition=cpu-epyc
[2022-07-02T08:55:58.516] sched: Allocate JobId=45467 NodeList=cpu11 #CPUs=16 Partition=cpu-opteron
[2022-07-02T09:25:42.178] sched: Allocate JobId=45480 NodeList=cpu15 #CPUs=16 Partition=cpu-epyc
[2022-07-02T11:40:58.088] sched: Allocate JobId=45468 NodeList=cpu04 #CPUs=16 Partition=cpu-opteron
[2022-07-02T11:53:55.955] sched: Allocate JobId=45469 NodeList=cpu07 #CPUs=16 Partition=cpu-opteron
[2022-07-02T11:53:55.955] sched: Allocate JobId=45470 NodeList=cpu07 #CPUs=16 Partition=cpu-opteron
[2022-07-02T14:39:46.530] sched: Allocate JobId=45471 NodeList=cpu04 #CPUs=16 Partition=cpu-opteron
[2022-07-02T15:15:22.499] sched: Allocate JobId=45484 NodeList=gpu02 #CPUs=8 Partition=gpu-titan
[2022-07-02T15:29:12.251] sched: Allocate JobId=45483 NodeList=cpu11 #CPUs=16 Partition=cpu-opteron
[2022-07-02T16:00:47.631] sched: _slurm_rpc_allocate_resources JobId=45485 NodeList=(null) usec=852
[2022-07-02T16:00:47.651] sched: Allocate JobId=45485 NodeList=cpu11 #CPUs=1 Partition=cpu-opteron
[2022-07-02T16:19:14.728] sched: Allocate JobId=45488 NodeList=cpu11 #CPUs=2 Partition=cpu-opteron
[2022-07-02T16:30:01.899] sched: Allocate JobId=45489 NodeList=cpu11 #CPUs=2 Partition=cpu-opteron
[2022-07-02T16:35:14.458] sched: Allocate JobId=45490 NodeList=gpu05 #CPUs=16 Partition=gpu-v100s
[2022-07-02T16:36:03.529] sched: Allocate JobId=45491 NodeList=gpu05 #CPUs=16 Partition=gpu-v100s
[2022-07-02T16:37:21.640] sched: Allocate JobId=45492 NodeList=gpu05 #CPUs=16 Partition=gpu-v100s
[2022-07-02T17:28:44.847] sched: Allocate JobId=45487 NodeList=cpu07 #CPUs=16 Partition=cpu-opteron
[2022-07-02T17:59:05.787] sched: Allocate JobId=45481 NodeList=cpu11 #CPUs=16 Partition=cpu-opteron
[2022-07-02T18:06:36.602] sched: Allocate JobId=45482 NodeList=cpu07 #CPUs=16 Partition=cpu-opteron
[2022-07-02T19:17:54.943] sched: Allocate JobId=45493 NodeList=cpu05 #CPUs=64 Partition=cpu-opteron
[2022-07-02T19:25:30.456] sched: Allocate JobId=45494 NodeList=cpu03 #CPUs=64 Partition=cpu-opteron
[2022-07-02T20:16:40.245] sched: Allocate JobId=45495 NodeList=cpu07 #CPUs=16 Partition=cpu-opteron
[2022-07-02T20:43:02.531] sched: Allocate JobId=45496 NodeList=cpu15 #CPUs=32 Partition=cpu-epyc
[2022-07-02T20:56:48.220] sched: Allocate JobId=45498 NodeList=cpu04 #CPUs=32 Partition=cpu-opteron
[2022-07-02T22:20:46.421] sched: Allocate JobId=45499 NodeList=cpu04 #CPUs=32 Partition=cpu-opteron
[2022-07-02T22:39:29.586] sched: Allocate JobId=45500 NodeList=cpu05 #CPUs=64 Partition=cpu-opteron
[2022-07-02T22:41:51.767] sched: Allocate JobId=45501 NodeList=cpu03 #CPUs=64 Partition=cpu-opteron
[2022-07-03T07:36:27.143] sched: Allocate JobId=45502 NodeList=cpu14 #CPUs=32 Partition=cpu-epyc
[2022-07-03T07:38:21.084] sched: Allocate JobId=45503 NodeList=cpu15 #CPUs=32 Partition=cpu-epyc
[2022-07-03T07:40:21.252] sched: Allocate JobId=45504 NodeList=cpu05 #CPUs=64 Partition=cpu-opteron
[2022-07-03T07:41:43.365] sched: Allocate JobId=45505 NodeList=cpu03 #CPUs=64 Partition=cpu-opteron
[2022-07-03T07:49:52.334] sched: Allocate JobId=45506 NodeList=cpu11 #CPUs=48 Partition=cpu-opteron
[2022-07-03T08:59:59.576] sched: Allocate JobId=45508 NodeList=cpu01 #CPUs=64 Partition=cpu-opteron
[2022-07-03T09:07:28.496] sched: Allocate JobId=45509 NodeList=cpu01 #CPUs=64 Partition=cpu-opteron
[2022-07-03T09:10:59.837] sched: Allocate JobId=45510 NodeList=cpu01 #CPUs=64 Partition=cpu-opteron
[2022-07-03T09:17:00.499] sched: Allocate JobId=45511 NodeList=cpu01 #CPUs=64 Partition=cpu-opteron
[2022-07-03T10:27:46.894] sched: Allocate JobId=45512 NodeList=cpu14 #CPUs=32 Partition=cpu-epyc
[2022-07-03T10:29:24.542] sched: Allocate JobId=45513 NodeList=cpu15 #CPUs=32 Partition=cpu-epyc
[2022-07-03T10:31:36.732] sched: Allocate JobId=45514 NodeList=cpu03 #CPUs=64 Partition=cpu-opteron
[2022-07-03T10:33:15.992] sched: Allocate JobId=45515 NodeList=cpu05 #CPUs=64 Partition=cpu-opteron
[2022-07-03T10:41:16.334] sched: _slurm_rpc_allocate_resources JobId=45517 NodeList=(null) usec=939
[2022-07-03T10:41:16.780] sched: Allocate JobId=45517 NodeList=gpu02 #CPUs=8 Partition=gpu-titan
[2022-07-03T12:17:05.450] sched: Allocate JobId=45516 NodeList=cpu13 #CPUs=32 Partition=cpu-epyc
[2022-07-03T12:51:00.517] sched: Allocate JobId=45518 NodeList=cpu13 #CPUs=16 Partition=cpu-epyc
[2022-07-03T17:18:03.819] sched: Allocate JobId=45519 NodeList=cpu13 #CPUs=32 Partition=cpu-epyc
[2022-07-03T17:20:17.991] sched: Allocate JobId=45520 NodeList=cpu14 #CPUs=32 Partition=cpu-epyc
[2022-07-03T17:22:39.468] sched: Allocate JobId=45521 NodeList=cpu15 #CPUs=48 Partition=cpu-epyc
[2022-07-03T17:25:34.757] sched: Allocate JobId=45522 NodeList=cpu03 #CPUs=64 Partition=cpu-opteron
[2022-07-03T17:27:27.957] sched: Allocate JobId=45523 NodeList=cpu05 #CPUs=64 Partition=cpu-opteron
[2022-07-03T18:39:02.942] sched: Allocate JobId=45421 NodeList=gpu04 #CPUs=16 Partition=gpu-k40c
[2022-07-03T18:39:07.128] sched: Allocate JobId=45524 NodeList=cpu04 #CPUs=32 Partition=cpu-opteron
[2022-07-03T18:58:53.332] sched: Allocate JobId=45525 NodeList=cpu04 #CPUs=32 Partition=cpu-opteron
[2022-07-03T19:00:55.514] sched: Allocate JobId=45526 NodeList=cpu13 #CPUs=32 Partition=cpu-epyc
[2022-07-03T19:02:48.227] sched: Allocate JobId=45527 NodeList=cpu14 #CPUs=32 Partition=cpu-epyc
[2022-07-03T19:04:19.910] sched: Allocate JobId=45528 NodeList=gpu01 #CPUs=16 Partition=gpu-k10
[2022-07-03T19:04:44.929] sched: Allocate JobId=45529 NodeList=cpu15 #CPUs=48 Partition=cpu-epyc
[2022-07-03T19:06:26.071] sched: Allocate JobId=45530 NodeList=cpu03 #CPUs=64 Partition=cpu-opteron
[2022-07-03T19:08:32.353] sched: Allocate JobId=45531 NodeList=cpu05 #CPUs=64 Partition=cpu-opteron
[2022-07-03T20:43:00.542] sched: Allocate JobId=45532 NodeList=cpu04 #CPUs=32 Partition=cpu-opteron
[2022-07-03T20:45:00.693] sched: Allocate JobId=45533 NodeList=cpu04 #CPUs=32 Partition=cpu-opteron
[2022-07-03T21:23:26.095] sched: Allocate JobId=45534 NodeList=cpu04 #CPUs=32 Partition=cpu-opteron
[2022-07-03T22:11:54.196] sched: Allocate JobId=45535 NodeList=cpu07 #CPUs=32 Partition=cpu-opteron
[2022-07-03T22:13:13.475] sched: Allocate JobId=45536 NodeList=cpu13 #CPUs=32 Partition=cpu-epyc
[2022-07-03T22:16:53.130] sched: Allocate JobId=45539 NodeList=cpu15 #CPUs=48 Partition=cpu-epyc
[2022-07-03T22:20:31.254] sched: Allocate JobId=45542 NodeList=cpu13 #CPUs=32 Partition=cpu-epyc
[2022-07-03T22:26:04.852] sched: Allocate JobId=45545 NodeList=cpu03 #CPUs=64 Partition=cpu-opteron
[2022-07-03T22:27:27.003] sched: Allocate JobId=45546 NodeList=cpu05 #CPUs=64 Partition=cpu-opteron
[2022-07-03T22:30:24.104] sched: Allocate JobId=45543 NodeList=cpu15 #CPUs=48 Partition=cpu-epyc
[2022-07-03T22:31:59.778] sched: Allocate JobId=45544 NodeList=cpu15 #CPUs=48 Partition=cpu-epyc
[2022-07-03T22:32:47.610] sched: Allocate JobId=45549 NodeList=cpu03 #CPUs=64 Partition=cpu-opteron
[2022-07-03T22:33:31.671] sched: Allocate JobId=45550 NodeList=cpu05 #CPUs=64 Partition=cpu-opteron
[2022-07-03T22:36:06.892] sched: Allocate JobId=45551 NodeList=cpu15 #CPUs=48 Partition=cpu-epyc
[2022-07-03T22:37:27.023] sched: Allocate JobId=45552 NodeList=cpu13 #CPUs=32 Partition=cpu-epyc
[2022-07-03T22:50:05.368] sched: Allocate JobId=45555 NodeList=cpu14 #CPUs=32 Partition=cpu-epyc
[2022-07-04T00:22:32.500] sched: Allocate JobId=45556 NodeList=cpu04 #CPUs=32 Partition=cpu-opteron
[2022-07-04T09:11:49.430] sched: Allocate JobId=45557 NodeList=cpu13 #CPUs=32 Partition=cpu-epyc
[2022-07-04T09:14:58.834] sched: Allocate JobId=45559 NodeList=cpu03 #CPUs=64 Partition=cpu-opteron
[2022-07-04T10:11:23.455] sched: Allocate JobId=45560 NodeList=cpu07 #CPUs=64 Partition=cpu-opteron
[2022-07-04T11:03:08.132] sched: Allocate JobId=45561 NodeList=cpu04 #CPUs=32 Partition=cpu-opteron
[2022-07-04T11:08:58.914] sched: _slurm_rpc_allocate_resources JobId=45562 NodeList=(null) usec=768
[2022-07-04T11:09:01.741] sched: Allocate JobId=45562 NodeList=cpu11 #CPUs=1 Partition=cpu-opteron
[2022-07-04T11:12:15.010] sched: Allocate JobId=45563 NodeList=cpu04 #CPUs=32 Partition=cpu-opteron
[2022-07-04T11:18:03.736] sched: Allocate JobId=45564 NodeList=cpu04 #CPUs=16 Partition=cpu-opteron
[2022-07-04T11:32:30.206] sched: Allocate JobId=45566 NodeList=cpu04 #CPUs=32 Partition=cpu-opteron
[2022-07-04T14:15:36.608] sched: Allocate JobId=45576 NodeList=cpu11 #CPUs=16 Partition=cpu-opteron
[2022-07-04T14:16:19.654] sched: Allocate JobId=45577 NodeList=cpu11 #CPUs=16 Partition=cpu-opteron
[2022-07-04T16:07:01.589] sched: Allocate JobId=45575 NodeList=cpu04 #CPUs=32 Partition=cpu-opteron
[2022-07-04T16:09:25.084] sched: Allocate JobId=45569 NodeList=cpu04 #CPUs=32 Partition=cpu-opteron
[2022-07-04T16:09:32.539] sched: Allocate JobId=45570 NodeList=cpu04 #CPUs=32 Partition=cpu-opteron
[2022-07-04T16:09:34.681] sched: Allocate JobId=45571 NodeList=cpu04 #CPUs=32 Partition=cpu-opteron
[2022-07-04T16:09:37.237] sched: Allocate JobId=45572 NodeList=cpu04 #CPUs=32 Partition=cpu-opteron
[2022-07-04T16:09:40.065] sched: Allocate JobId=45573 NodeList=cpu04 #CPUs=32 Partition=cpu-opteron
[2022-07-04T16:09:42.673] sched: Allocate JobId=45574 NodeList=cpu04 #CPUs=32 Partition=cpu-opteron
[2022-07-04T16:23:39.840] sched: Allocate JobId=45554 NodeList=cpu15 #CPUs=36 Partition=cpu-epyc
[2022-07-04T18:36:57.771] sched: Allocate JobId=45578 NodeList=cpu04 #CPUs=32 Partition=cpu-opteron
[2022-07-04T18:51:12.352] sched: Allocate JobId=45579 NodeList=cpu04 #CPUs=32 Partition=cpu-opteron
[2022-07-04T20:19:25.811] sched: Allocate JobId=45602 NodeList=cpu15 #CPUs=12 Partition=cpu-epyc
[2022-07-04T20:21:48.997] sched: Allocate JobId=45603 NodeList=cpu15 #CPUs=12 Partition=cpu-epyc
[2022-07-04T20:49:22.986] sched: Allocate JobId=45604 NodeList=cpu15 #CPUs=12 Partition=cpu-epyc
[2022-07-04T21:11:36.607] sched: Allocate JobId=45580 NodeList=cpu10 #CPUs=8 Partition=cpu-opteron
[2022-07-04T21:11:36.608] sched: Allocate JobId=45581 NodeList=cpu10 #CPUs=8 Partition=cpu-opteron
[2022-07-04T21:24:14.155] sched: Allocate JobId=45605 NodeList=cpu15 #CPUs=12 Partition=cpu-epyc
[2022-07-04T21:28:19.620] sched: Allocate JobId=45606 NodeList=cpu15 #CPUs=12 Partition=cpu-epyc
[2022-07-04T21:33:09.101] sched: Allocate JobId=45607 NodeList=cpu10 #CPUs=4 Partition=cpu-opteron
[2022-07-04T21:36:12.346] sched: Allocate JobId=45608 NodeList=cpu10 #CPUs=16 Partition=cpu-opteron
[2022-07-04T21:36:15.351] sched: Allocate JobId=45609 NodeList=cpu15 #CPUs=12 Partition=cpu-epyc
[2022-07-04T21:37:07.424] sched: Allocate JobId=45610 NodeList=gpu05 #CPUs=1 Partition=gpu-v100s
[2022-07-04T21:37:41.584] sched: Allocate JobId=45611 NodeList=cpu10 #CPUs=4 Partition=cpu-opteron
[2022-07-04T21:40:41.843] sched: Allocate JobId=45612 NodeList=cpu10 #CPUs=16 Partition=cpu-opteron
[2022-07-04T21:48:11.726] sched: Allocate JobId=45616 NodeList=gpu05 #CPUs=16 Partition=gpu-v100s
[2022-07-04T21:48:52.781] sched: Allocate JobId=45617 NodeList=cpu10 #CPUs=8 Partition=cpu-opteron
[2022-07-04T21:50:45.937] sched: Allocate JobId=45618 NodeList=gpu05 #CPUs=1 Partition=gpu-v100s
[2022-07-04T21:51:12.977] sched: Allocate JobId=45619 NodeList=cpu10 #CPUs=4 Partition=cpu-opteron
[2022-07-04T21:52:13.061] sched: Allocate JobId=45620 NodeList=cpu10 #CPUs=16 Partition=cpu-opteron
[2022-07-04T21:53:26.240] sched: Allocate JobId=45621 NodeList=gpu05 #CPUs=16 Partition=gpu-v100s
[2022-07-04T21:55:13.392] sched: Allocate JobId=45622 NodeList=gpu02 #CPUs=1 Partition=gpu-titan
[2022-07-04T21:55:58.455] sched: Allocate JobId=45623 NodeList=cpu10 #CPUs=4 Partition=cpu-opteron
[2022-07-04T21:56:46.522] sched: Allocate JobId=45624 NodeList=cpu10 #CPUs=16 Partition=cpu-opteron
[2022-07-04T21:57:18.567] sched: Allocate JobId=45625 NodeList=gpu05 #CPUs=16 Partition=gpu-v100s
[2022-07-04T22:13:29.507] sched: Allocate JobId=45582 NodeList=cpu10 #CPUs=8 Partition=cpu-opteron
[2022-07-04T22:13:29.507] sched: Allocate JobId=45583 NodeList=cpu10 #CPUs=8 Partition=cpu-opteron
[2022-07-04T22:23:53.453] sched: Allocate JobId=45626 NodeList=cpu10 #CPUs=16 Partition=cpu-opteron
[2022-07-04T22:26:01.621] sched: Allocate JobId=45627 NodeList=cpu10 #CPUs=16 Partition=cpu-opteron
[2022-07-05T00:44:33.958] sched: _slurm_rpc_allocate_resources JobId=45630 NodeList=(null) usec=1150
[2022-07-05T00:45:31.586] sched: _slurm_rpc_allocate_resources JobId=45631 NodeList=(null) usec=1140
[2022-07-05T00:45:32.197] sched: Allocate JobId=45631 NodeList=cpu15 #CPUs=12 Partition=cpu-epyc
[2022-07-05T01:29:44.991] sched: Allocate JobId=45584 NodeList=cpu04 #CPUs=8 Partition=cpu-opteron
[2022-07-05T01:29:44.991] sched: Allocate JobId=45585 NodeList=cpu04 #CPUs=8 Partition=cpu-opteron
[2022-07-05T01:29:44.992] sched: Allocate JobId=45586 NodeList=cpu04 #CPUs=8 Partition=cpu-opteron
[2022-07-05T01:40:45.690] sched: Allocate JobId=45632 NodeList=cpu15 #CPUs=12 Partition=cpu-epyc
[2022-07-05T02:14:52.516] sched: Allocate JobId=45587 NodeList=cpu10 #CPUs=8 Partition=cpu-opteron
[2022-07-05T02:30:52.192] sched: Allocate JobId=45588 NodeList=cpu10 #CPUs=8 Partition=cpu-opteron
[2022-07-05T02:50:08.269] sched: Allocate JobId=45589 NodeList=cpu10 #CPUs=8 Partition=cpu-opteron
[2022-07-05T03:17:41.922] sched: Allocate JobId=45633 NodeList=cpu15 #CPUs=12 Partition=cpu-epyc
[2022-07-05T03:19:33.656] sched: Allocate JobId=45590 NodeList=cpu10 #CPUs=8 Partition=cpu-opteron
[2022-07-05T03:27:38.931] sched: Allocate JobId=45634 NodeList=cpu15 #CPUs=12 Partition=cpu-epyc
[2022-07-05T03:32:53.539] sched: Allocate JobId=45635 NodeList=cpu10 #CPUs=32 Partition=cpu-opteron
[2022-07-05T03:34:55.711] sched: Allocate JobId=45636 NodeList=cpu10 #CPUs=32 Partition=cpu-opteron
[2022-07-05T05:32:44.885] sched: Allocate JobId=45591 NodeList=cpu04 #CPUs=8 Partition=cpu-opteron
[2022-07-05T05:37:23.081] sched: Allocate JobId=45592 NodeList=cpu04 #CPUs=8 Partition=cpu-opteron
[2022-07-05T05:38:52.207] sched: Allocate JobId=45593 NodeList=cpu04 #CPUs=8 Partition=cpu-opteron
[2022-07-05T06:19:04.104] sched: Allocate JobId=45594 NodeList=cpu10 #CPUs=8 Partition=cpu-opteron
[2022-07-05T06:21:57.047] sched: Allocate JobId=45595 NodeList=cpu10 #CPUs=8 Partition=cpu-opteron
[2022-07-05T06:24:11.952] sched: Allocate JobId=45596 NodeList=cpu10 #CPUs=8 Partition=cpu-opteron
[2022-07-05T07:44:48.739] sched: Allocate JobId=45640 NodeList=cpu10 #CPUs=16 Partition=cpu-opteron
[2022-07-05T07:59:31.409] sched: Allocate JobId=45641 NodeList=cpu15 #CPUs=12 Partition=cpu-epyc
[2022-07-05T08:11:36.708] sched: Allocate JobId=45642 NodeList=cpu10 #CPUs=12 Partition=cpu-opteron
[2022-07-05T08:34:19.369] sched: Allocate JobId=45643 NodeList=cpu15 #CPUs=12 Partition=cpu-epyc
[2022-07-05T08:42:16.108] sched: Allocate JobId=45597 NodeList=cpu10 #CPUs=8 Partition=cpu-opteron
[2022-07-05T08:53:10.646] sched: Allocate JobId=45645 NodeList=cpu15 #CPUs=12 Partition=cpu-epyc
[2022-07-05T09:06:30.141] sched: Allocate JobId=45646 NodeList=cpu15 #CPUs=12 Partition=cpu-epyc
[2022-07-05T09:14:34.230] sched: Allocate JobId=45647 NodeList=cpu10 #CPUs=16 Partition=cpu-opteron
[2022-07-05T10:12:33.446] sched: Allocate JobId=45598 NodeList=cpu04 #CPUs=8 Partition=cpu-opteron
[2022-07-05T10:13:57.301] sched: Allocate JobId=45599 NodeList=cpu10 #CPUs=8 Partition=cpu-opteron
[2022-07-05T10:25:34.613] sched: Allocate JobId=45600 NodeList=cpu10 #CPUs=8 Partition=cpu-opteron
[2022-07-05T11:29:50.367] sched: Allocate JobId=45648 NodeList=cpu15 #CPUs=12 Partition=cpu-epyc
[2022-07-05T12:21:05.761] sched: Allocate JobId=45649 NodeList=cpu04 #CPUs=20 Partition=cpu-opteron
[2022-07-05T12:39:17.750] sched: Allocate JobId=45650 NodeList=cpu03 #CPUs=64 Partition=cpu-opteron
[2022-07-05T12:40:53.867] sched: Allocate JobId=45651 NodeList=cpu03 #CPUs=64 Partition=cpu-opteron
[2022-07-05T12:42:25.992] sched: Allocate JobId=45652 NodeList=cpu03 #CPUs=64 Partition=cpu-opteron
[2022-07-05T13:16:53.740] sched: Allocate JobId=45653 NodeList=cpu04 #CPUs=24 Partition=cpu-opteron
[2022-07-05T13:31:37.328] sched: Allocate JobId=45654 NodeList=cpu04 #CPUs=24 Partition=cpu-opteron
[2022-07-05T13:43:22.679] sched: Allocate JobId=45655 NodeList=cpu04 #CPUs=24 Partition=cpu-opteron
[2022-07-05T13:56:33.195] sched: Allocate JobId=45656 NodeList=cpu04 #CPUs=24 Partition=cpu-opteron
[2022-07-05T14:24:15.374] sched: Allocate JobId=45657 NodeList=cpu04 #CPUs=24 Partition=cpu-opteron
[2022-07-05T15:20:13.195] sched: Allocate JobId=45658 NodeList=cpu04 #CPUs=32 Partition=cpu-opteron
[2022-07-05T15:25:09.943] sched: Allocate JobId=45659 NodeList=cpu04 #CPUs=32 Partition=cpu-opteron
[2022-07-05T15:26:58.093] sched: Allocate JobId=45660 NodeList=cpu01 #CPUs=64 Partition=cpu-opteron
[2022-07-05T15:32:10.686] sched: Allocate JobId=45661 NodeList=gpu02 #CPUs=16 Partition=gpu-titan
[2022-07-05T15:32:26.710] sched: Allocate JobId=45662 NodeList=cpu11 #CPUs=1 Partition=cpu-opteron
[2022-07-05T15:34:51.969] sched: Allocate JobId=45663 NodeList=cpu11 #CPUs=1 Partition=cpu-opteron
[2022-07-05T15:36:50.977] sched: _slurm_rpc_allocate_resources JobId=45664 NodeList=(null) usec=840
[2022-07-05T15:36:51.126] sched: Allocate JobId=45664 NodeList=cpu04 #CPUs=1 Partition=cpu-opteron
[2022-07-05T15:42:10.655] sched: Allocate JobId=45665 NodeList=cpu04 #CPUs=1 Partition=cpu-opteron
[2022-07-05T16:06:36.545] sched: Allocate JobId=45666 NodeList=cpu04 #CPUs=32 Partition=cpu-opteron
[2022-07-05T16:06:48.558] sched: Allocate JobId=45667 NodeList=cpu04 #CPUs=32 Partition=cpu-opteron
[2022-07-05T16:07:39.763] sched: Allocate JobId=45668 NodeList=cpu04 #CPUs=32 Partition=cpu-opteron
[2022-07-05T16:09:49.988] sched: Allocate JobId=45669 NodeList=cpu10 #CPUs=32 Partition=cpu-opteron
[2022-07-05T16:25:10.607] sched: Allocate JobId=45670 NodeList=cpu04 #CPUs=32 Partition=cpu-opteron
[2022-07-05T16:25:20.619] sched: Allocate JobId=45671 NodeList=cpu10 #CPUs=32 Partition=cpu-opteron
[2022-07-05T16:33:28.595] sched: Allocate JobId=45672 NodeList=cpu04 #CPUs=32 Partition=cpu-opteron
[2022-07-05T16:36:07.824] sched: Allocate JobId=45673 NodeList=cpu04 #CPUs=32 Partition=cpu-opteron
[2022-07-05T16:44:29.708] sched: Allocate JobId=45674 NodeList=cpu04 #CPUs=32 Partition=cpu-opteron
[2022-07-05T16:49:57.275] sched: Allocate JobId=45675 NodeList=cpu10 #CPUs=32 Partition=cpu-opteron
[2022-07-05T16:53:53.733] sched: Allocate JobId=45676 NodeList=cpu10 #CPUs=32 Partition=cpu-opteron
[2022-07-05T16:57:37.142] sched: Allocate JobId=45677 NodeList=cpu11 #CPUs=16 Partition=cpu-opteron
[2022-07-05T17:00:58.457] sched: Allocate JobId=45678 NodeList=cpu11 #CPUs=8 Partition=cpu-opteron
[2022-07-05T17:01:52.534] sched: Allocate JobId=45679 NodeList=cpu11 #CPUs=8 Partition=cpu-opteron
[2022-07-05T17:15:23.034] sched: Allocate JobId=45680 NodeList=cpu11 #CPUs=8 Partition=cpu-opteron
[2022-07-05T17:16:50.150] sched: Allocate JobId=45681 NodeList=cpu11 #CPUs=8 Partition=cpu-opteron
[2022-07-05T17:18:25.398] sched: Allocate JobId=45682 NodeList=cpu10 #CPUs=32 Partition=cpu-opteron
[2022-07-05T21:04:44.364] sched: Allocate JobId=45683 NodeList=cpu04 #CPUs=32 Partition=cpu-opteron
[2022-07-05T21:09:38.871] sched: Allocate JobId=45684 NodeList=cpu10 #CPUs=32 Partition=cpu-opteron
[2022-07-05T21:10:44.945] sched: Allocate JobId=45685 NodeList=cpu10 #CPUs=32 Partition=cpu-opteron
[2022-07-05T21:12:37.160] sched: Allocate JobId=45687 NodeList=cpu11 #CPUs=16 Partition=cpu-opteron
[2022-07-05T21:12:57.065] sched: Allocate JobId=45686 NodeList=cpu10 #CPUs=64 Partition=cpu-opteron
[2022-07-05T22:29:34.409] sched: Allocate JobId=45691 NodeList=gpu02 #CPUs=16 Partition=gpu-titan
[2022-07-05T22:31:11.530] sched: Allocate JobId=45692 NodeList=gpu01 #CPUs=12 Partition=gpu-k10
[2022-07-05T22:32:11.154] sched: Allocate JobId=45693 NodeList=gpu01 #CPUs=12 Partition=gpu-k10
[2022-07-05T22:45:12.320] sched: Allocate JobId=45694 NodeList=gpu02 #CPUs=16 Partition=gpu-titan
[2022-07-05T22:54:04.991] sched: Allocate JobId=45695 NodeList=gpu02 #CPUs=16 Partition=gpu-titan
[2022-07-05T23:21:40.042] sched: Allocate JobId=45690 NodeList=cpu09 #CPUs=16 Partition=cpu-opteron
[2022-07-05T23:21:40.042] sched: Allocate JobId=45689 NodeList=cpu09 #CPUs=32 Partition=cpu-opteron
[2022-07-05T23:28:14.872] sched: Allocate JobId=45696 NodeList=cpu09 #CPUs=16 Partition=cpu-opteron
[2022-07-05T23:35:39.588] sched: Allocate JobId=45698 NodeList=cpu09 #CPUs=16 Partition=cpu-opteron
[2022-07-05T23:43:12.437] sched: Allocate JobId=45699 NodeList=cpu09 #CPUs=16 Partition=cpu-opteron
[2022-07-05T23:45:34.634] sched: Allocate JobId=45700 NodeList=cpu09 #CPUs=16 Partition=cpu-opteron
[2022-07-05T23:54:30.636] sched: Allocate JobId=45701 NodeList=gpu02 #CPUs=16 Partition=gpu-titan
[2022-07-06T00:05:18.746] sched: Allocate JobId=45702 NodeList=gpu02 #CPUs=16 Partition=gpu-titan
[2022-07-06T00:12:30.182] sched: Allocate JobId=45697 NodeList=cpu10 #CPUs=32 Partition=cpu-opteron
[2022-07-06T00:12:48.551] sched: Allocate JobId=45688 NodeList=cpu10 #CPUs=64 Partition=cpu-opteron
[2022-07-06T00:33:23.695] sched: Allocate JobId=45703 NodeList=cpu10 #CPUs=64 Partition=cpu-opteron
[2022-07-06T02:57:33.969] sched: Allocate JobId=45706 NodeList=gpu01 #CPUs=16 Partition=gpu-k10
[2022-07-06T03:00:04.202] sched: Allocate JobId=45707 NodeList=cpu04 #CPUs=32 Partition=cpu-opteron
[2022-07-06T03:00:24.474] sched: Allocate JobId=45708 NodeList=cpu04 #CPUs=32 Partition=cpu-opteron
[2022-07-06T03:00:45.794] sched: Allocate JobId=45709 NodeList=cpu04 #CPUs=32 Partition=cpu-opteron
[2022-07-06T03:00:51.268] sched: Allocate JobId=45710 NodeList=cpu04 #CPUs=32 Partition=cpu-opteron
[2022-07-06T03:01:18.307] sched: Allocate JobId=45711 NodeList=cpu04 #CPUs=32 Partition=cpu-opteron
[2022-07-06T03:01:23.314] sched: Allocate JobId=45712 NodeList=cpu04 #CPUs=32 Partition=cpu-opteron
[2022-07-06T03:01:33.328] sched: Allocate JobId=45713 NodeList=cpu04 #CPUs=32 Partition=cpu-opteron
[2022-07-06T03:02:36.462] sched: Allocate JobId=45714 NodeList=cpu04 #CPUs=32 Partition=cpu-opteron
[2022-07-06T03:02:55.952] sched: Allocate JobId=45715 NodeList=cpu04 #CPUs=32 Partition=cpu-opteron
[2022-07-06T03:03:15.714] sched: Allocate JobId=45716 NodeList=cpu04 #CPUs=32 Partition=cpu-opteron
[2022-07-06T03:03:20.227] sched: Allocate JobId=45717 NodeList=cpu04 #CPUs=32 Partition=cpu-opteron
[2022-07-06T03:03:33.141] sched: Allocate JobId=45718 NodeList=cpu04 #CPUs=32 Partition=cpu-opteron
[2022-07-06T03:04:49.018] sched: Allocate JobId=45719 NodeList=cpu04 #CPUs=32 Partition=cpu-opteron
[2022-07-06T03:06:07.839] sched: Allocate JobId=45720 NodeList=cpu04 #CPUs=32 Partition=cpu-opteron
[2022-07-06T03:06:22.007] sched: Allocate JobId=45722 NodeList=cpu04 #CPUs=32 Partition=cpu-opteron
[2022-07-06T03:08:42.168] sched: Allocate JobId=45723 NodeList=cpu04 #CPUs=32 Partition=cpu-opteron
[2022-07-06T03:09:24.226] sched: Allocate JobId=45724 NodeList=cpu04 #CPUs=32 Partition=cpu-opteron
[2022-07-06T03:09:46.256] sched: Allocate JobId=45725 NodeList=cpu04 #CPUs=32 Partition=cpu-opteron
[2022-07-06T03:10:04.281] sched: Allocate JobId=45726 NodeList=cpu04 #CPUs=32 Partition=cpu-opteron
[2022-07-06T03:12:29.529] sched: Allocate JobId=45727 NodeList=cpu04 #CPUs=32 Partition=cpu-opteron
[2022-07-06T03:12:49.320] sched: Allocate JobId=45728 NodeList=cpu04 #CPUs=32 Partition=cpu-opteron
[2022-07-06T03:13:14.106] sched: Allocate JobId=45729 NodeList=cpu04 #CPUs=32 Partition=cpu-opteron
[2022-07-06T03:13:18.823] sched: Allocate JobId=45730 NodeList=cpu04 #CPUs=32 Partition=cpu-opteron
[2022-07-06T03:13:33.125] sched: Allocate JobId=45731 NodeList=cpu04 #CPUs=32 Partition=cpu-opteron
[2022-07-06T03:14:47.764] sched: Allocate JobId=45732 NodeList=cpu04 #CPUs=32 Partition=cpu-opteron
[2022-07-06T03:14:50.392] sched: Allocate JobId=45733 NodeList=cpu04 #CPUs=32 Partition=cpu-opteron
[2022-07-06T03:15:11.801] sched: Allocate JobId=45734 NodeList=cpu04 #CPUs=32 Partition=cpu-opteron
[2022-07-06T03:15:31.444] sched: Allocate JobId=45735 NodeList=cpu04 #CPUs=32 Partition=cpu-opteron
[2022-07-06T03:15:56.570] sched: Allocate JobId=45736 NodeList=cpu04 #CPUs=32 Partition=cpu-opteron
[2022-07-06T03:16:01.336] sched: Allocate JobId=45737 NodeList=cpu04 #CPUs=32 Partition=cpu-opteron
[2022-07-06T03:16:15.750] sched: Allocate JobId=45738 NodeList=cpu04 #CPUs=32 Partition=cpu-opteron
[2022-07-06T03:17:25.365] sched: Allocate JobId=45739 NodeList=cpu04 #CPUs=32 Partition=cpu-opteron
[2022-07-06T03:17:27.982] sched: Allocate JobId=45740 NodeList=cpu04 #CPUs=32 Partition=cpu-opteron
[2022-07-06T03:18:09.129] sched: Allocate JobId=45741 NodeList=cpu04 #CPUs=32 Partition=cpu-opteron
[2022-07-06T03:18:28.054] sched: Allocate JobId=45742 NodeList=cpu04 #CPUs=32 Partition=cpu-opteron
[2022-07-06T03:18:47.429] sched: Allocate JobId=45743 NodeList=cpu04 #CPUs=32 Partition=cpu-opteron
[2022-07-06T03:18:51.903] sched: Allocate JobId=45744 NodeList=cpu04 #CPUs=32 Partition=cpu-opteron
[2022-07-06T03:19:05.098] sched: Allocate JobId=45745 NodeList=cpu04 #CPUs=32 Partition=cpu-opteron
[2022-07-06T03:20:22.425] sched: Allocate JobId=45746 NodeList=cpu04 #CPUs=32 Partition=cpu-opteron
[2022-07-06T03:21:42.061] sched: Allocate JobId=45747 NodeList=cpu04 #CPUs=32 Partition=cpu-opteron
[2022-07-06T03:24:06.737] sched: Allocate JobId=45748 NodeList=cpu14 #CPUs=32 Partition=cpu-epyc
[2022-07-06T03:34:47.875] sched: Allocate JobId=45750 NodeList=cpu04 #CPUs=32 Partition=cpu-opteron
[2022-07-06T03:39:20.333] sched: Allocate JobId=45751 NodeList=cpu04 #CPUs=32 Partition=cpu-opteron
[2022-07-06T03:39:40.746] sched: Allocate JobId=45752 NodeList=cpu04 #CPUs=32 Partition=cpu-opteron
[2022-07-06T03:40:50.461] sched: Allocate JobId=45753 NodeList=cpu04 #CPUs=32 Partition=cpu-opteron
[2022-07-06T03:41:21.505] sched: Allocate JobId=45754 NodeList=cpu04 #CPUs=32 Partition=cpu-opteron
[2022-07-06T03:42:34.273] sched: Allocate JobId=45755 NodeList=cpu04 #CPUs=32 Partition=cpu-opteron
[2022-07-06T03:43:51.008] sched: Allocate JobId=45756 NodeList=cpu04 #CPUs=32 Partition=cpu-opteron
[2022-07-06T03:46:43.118] sched: Allocate JobId=45757 NodeList=cpu04 #CPUs=32 Partition=cpu-opteron
[2022-07-06T05:24:59.553] sched: Allocate JobId=45758 NodeList=cpu04 #CPUs=32 Partition=cpu-opteron
[2022-07-06T05:25:05.959] sched: Allocate JobId=45759 NodeList=cpu04 #CPUs=32 Partition=cpu-opteron
[2022-07-06T05:25:09.698] sched: Allocate JobId=45760 NodeList=cpu04 #CPUs=32 Partition=cpu-opteron
[2022-07-06T05:25:12.170] sched: Allocate JobId=45761 NodeList=cpu04 #CPUs=32 Partition=cpu-opteron
[2022-07-06T05:25:14.177] sched: Allocate JobId=45762 NodeList=cpu04 #CPUs=32 Partition=cpu-opteron
[2022-07-06T05:25:16.587] sched: Allocate JobId=45763 NodeList=cpu04 #CPUs=32 Partition=cpu-opteron
[2022-07-06T05:25:19.036] sched: Allocate JobId=45764 NodeList=cpu04 #CPUs=32 Partition=cpu-opteron
[2022-07-06T05:25:23.363] sched: Allocate JobId=45765 NodeList=cpu04 #CPUs=32 Partition=cpu-opteron
[2022-07-06T05:25:47.493] sched: Allocate JobId=45766 NodeList=cpu04 #CPUs=32 Partition=cpu-opteron
[2022-07-06T05:26:16.080] sched: Allocate JobId=45767 NodeList=cpu04 #CPUs=32 Partition=cpu-opteron
[2022-07-06T05:26:45.290] sched: Allocate JobId=45768 NodeList=cpu04 #CPUs=32 Partition=cpu-opteron
[2022-07-06T06:16:31.338] sched: Allocate JobId=45749 NodeList=cpu14 #CPUs=32 Partition=cpu-epyc
[2022-07-06T09:33:46.320] sched: Allocate JobId=45769 NodeList=gpu05 #CPUs=16 Partition=gpu-v100s
[2022-07-06T09:34:27.361] sched: Allocate JobId=45770 NodeList=gpu05 #CPUs=16 Partition=gpu-v100s
[2022-07-06T09:35:51.481] sched: Allocate JobId=45771 NodeList=gpu05 #CPUs=16 Partition=gpu-v100s
[2022-07-06T09:37:15.602] sched: Allocate JobId=45772 NodeList=gpu05 #CPUs=16 Partition=gpu-v100s
[2022-07-06T09:40:30.092] sched: Allocate JobId=45773 NodeList=gpu05 #CPUs=16 Partition=gpu-v100s
[2022-07-06T09:44:06.484] sched: Allocate JobId=45774 NodeList=gpu05 #CPUs=16 Partition=gpu-v100s
[2022-07-06T09:45:51.628] sched: Allocate JobId=45775 NodeList=gpu05 #CPUs=16 Partition=gpu-v100s
[2022-07-06T09:49:03.009] sched: Allocate JobId=45776 NodeList=gpu05 #CPUs=16 Partition=gpu-v100s
[2022-07-06T09:51:45.240] sched: Allocate JobId=45777 NodeList=gpu05 #CPUs=16 Partition=gpu-v100s
[2022-07-06T09:53:49.567] sched: Allocate JobId=45778 NodeList=gpu05 #CPUs=16 Partition=gpu-v100s
[2022-07-06T09:58:11.045] sched: Allocate JobId=45779 NodeList=gpu05 #CPUs=16 Partition=gpu-v100s
[2022-07-06T10:05:56.890] sched: Allocate JobId=45780 NodeList=gpu05 #CPUs=16 Partition=gpu-v100s
[2022-07-06T10:10:50.558] sched: Allocate JobId=45781 NodeList=gpu02 #CPUs=10 Partition=gpu-titan
[2022-07-06T10:31:46.968] sched: Allocate JobId=45704 NodeList=cpu10 #CPUs=64 Partition=cpu-opteron
[2022-07-06T10:34:06.121] sched: Allocate JobId=45782 NodeList=gpu02 #CPUs=6 Partition=gpu-titan
[2022-07-06T10:34:49.948] sched: Allocate JobId=45783 NodeList=gpu02 #CPUs=6 Partition=gpu-titan
[2022-07-06T10:45:17.248] sched: Allocate JobId=45784 NodeList=cpu04 #CPUs=4 Partition=cpu-opteron
[2022-07-06T10:47:14.398] sched: Allocate JobId=45785 NodeList=gpu02 #CPUs=6 Partition=gpu-titan
[2022-07-06T10:48:34.425] sched: _slurm_rpc_allocate_resources JobId=45786 NodeList=(null) usec=1234
[2022-07-06T10:48:34.580] sched: Allocate JobId=45786 NodeList=cpu04 #CPUs=4 Partition=cpu-opteron
[2022-07-06T10:57:26.428] sched: Allocate JobId=45787 NodeList=cpu12 #CPUs=16 Partition=cpu-epyc
[2022-07-06T10:59:31.680] sched: Allocate JobId=45797 NodeList=cpu04 #CPUs=32 Partition=cpu-opteron
[2022-07-06T11:00:10.731] sched: Allocate JobId=45798 NodeList=cpu04 #CPUs=32 Partition=cpu-opteron
[2022-07-06T11:00:32.762] sched: Allocate JobId=45799 NodeList=cpu04 #CPUs=32 Partition=cpu-opteron
[2022-07-06T11:01:29.840] sched: Allocate JobId=45800 NodeList=cpu04 #CPUs=32 Partition=cpu-opteron
[2022-07-06T11:08:42.646] sched: Allocate JobId=45801 NodeList=cpu09 #CPUs=1 Partition=cpu-opteron
[2022-07-06T11:11:06.825] sched: Allocate JobId=45802 NodeList=cpu09 #CPUs=1 Partition=cpu-opteron
[2022-07-06T11:13:09.100] sched: Allocate JobId=45803 NodeList=cpu09 #CPUs=1 Partition=cpu-opteron
[2022-07-06T11:14:00.177] sched: Allocate JobId=45804 NodeList=gpu02 #CPUs=6 Partition=gpu-titan
[2022-07-06T11:14:54.249] sched: Allocate JobId=45805 NodeList=gpu02 #CPUs=6 Partition=gpu-titan
[2022-07-06T11:21:37.920] sched: Allocate JobId=45806 NodeList=cpu14 #CPUs=32 Partition=cpu-epyc
[2022-07-06T11:23:17.441] sched: _slurm_rpc_allocate_resources JobId=45807 NodeList=(null) usec=829
[2022-07-06T11:23:18.257] sched: Allocate JobId=45807 NodeList=cpu09 #CPUs=1 Partition=cpu-opteron
[2022-07-06T11:24:36.369] sched: Allocate JobId=45808 NodeList=cpu14 #CPUs=32 Partition=cpu-epyc
[2022-07-06T11:25:13.421] sched: Allocate JobId=45809 NodeList=cpu14 #CPUs=32 Partition=cpu-epyc
[2022-07-06T11:29:57.914] sched: Allocate JobId=45810 NodeList=cpu09 #CPUs=4 Partition=cpu-opteron
[2022-07-06T11:31:09.009] sched: Allocate JobId=45811 NodeList=cpu09 #CPUs=4 Partition=cpu-opteron
[2022-07-06T11:31:21.038] sched: Allocate JobId=45812 NodeList=gpu05 #CPUs=16 Partition=gpu-v100s
[2022-07-06T11:31:32.040] sched: Allocate JobId=45813 NodeList=cpu09 #CPUs=4 Partition=cpu-opteron
[2022-07-06T11:32:11.119] sched: _slurm_rpc_allocate_resources JobId=45814 NodeList=(null) usec=717
[2022-07-06T11:32:12.094] sched: Allocate JobId=45814 NodeList=cpu09 #CPUs=8 Partition=cpu-opteron
[2022-07-06T11:33:30.331] sched: Allocate JobId=45815 NodeList=gpu05 #CPUs=16 Partition=gpu-v100s
[2022-07-06T11:34:38.427] sched: Allocate JobId=45816 NodeList=gpu05 #CPUs=16 Partition=gpu-v100s
[2022-07-06T11:36:18.567] sched: Allocate JobId=45817 NodeList=gpu05 #CPUs=16 Partition=gpu-v100s
[2022-07-06T11:41:15.103] sched: Allocate JobId=45818 NodeList=cpu14 #CPUs=32 Partition=cpu-epyc
[2022-07-06T11:42:02.168] sched: Allocate JobId=45819 NodeList=cpu14 #CPUs=32 Partition=cpu-epyc
[2022-07-06T11:43:51.467] sched: Allocate JobId=45820 NodeList=cpu14 #CPUs=32 Partition=cpu-epyc
[2022-07-06T11:44:41.536] sched: Allocate JobId=45821 NodeList=cpu14 #CPUs=32 Partition=cpu-epyc
[2022-07-06T11:48:49.985] sched: Allocate JobId=45822 NodeList=cpu09 #CPUs=32 Partition=cpu-opteron
[2022-07-06T12:23:45.833] sched: Allocate JobId=45828 NodeList=gpu01 #CPUs=1 Partition=gpu-k10
[2022-07-06T12:40:09.538] sched: Allocate JobId=45823 NodeList=cpu10 #CPUs=1 Partition=cpu-opteron
[2022-07-06T12:41:07.618] sched: Allocate JobId=45830 NodeList=cpu10 #CPUs=32 Partition=cpu-opteron
[2022-07-06T12:41:41.654] sched: Allocate JobId=45831 NodeList=cpu10 #CPUs=15 Partition=cpu-opteron
[2022-07-06T12:41:45.660] sched: Allocate JobId=45832 NodeList=cpu10 #CPUs=1 Partition=cpu-opteron
[2022-07-06T12:43:18.896] sched: Allocate JobId=45834 NodeList=cpu10 #CPUs=15 Partition=cpu-opteron
[2022-07-06T13:22:50.518] sched: Allocate JobId=45705 NodeList=cpu03 #CPUs=64 Partition=cpu-opteron
[2022-07-06T13:24:32.289] sched: Allocate JobId=45835 NodeList=cpu01 #CPUs=64 Partition=cpu-opteron
[2022-07-06T13:26:21.430] sched: Allocate JobId=45836 NodeList=cpu01 #CPUs=64 Partition=cpu-opteron
[2022-07-06T13:27:58.678] sched: Allocate JobId=45837 NodeList=cpu01 #CPUs=64 Partition=cpu-opteron
[2022-07-06T13:30:15.867] sched: Allocate JobId=45838 NodeList=cpu05 #CPUs=64 Partition=cpu-opteron
[2022-07-06T13:31:38.981] sched: Allocate JobId=45839 NodeList=cpu11 #CPUs=48 Partition=cpu-opteron
[2022-07-06T13:50:12.010] sched: Allocate JobId=45841 NodeList=gpu01 #CPUs=10 Partition=gpu-k10
[2022-07-06T13:54:26.431] sched: Allocate JobId=45842 NodeList=cpu10 #CPUs=2 Partition=cpu-opteron
[2022-07-06T13:55:58.558] sched: Allocate JobId=45843 NodeList=gpu01 #CPUs=10 Partition=gpu-k10
[2022-07-06T13:57:56.836] sched: Allocate JobId=45844 NodeList=gpu01 #CPUs=10 Partition=gpu-k10
[2022-07-06T13:58:31.887] sched: Allocate JobId=45845 NodeList=cpu10 #CPUs=2 Partition=cpu-opteron
[2022-07-06T14:00:33.058] sched: Allocate JobId=45846 NodeList=gpu01 #CPUs=10 Partition=gpu-k10
[2022-07-06T14:00:54.083] sched: Allocate JobId=45847 NodeList=cpu10 #CPUs=2 Partition=cpu-opteron
[2022-07-06T14:01:59.171] sched: Allocate JobId=45848 NodeList=gpu03 #CPUs=10 Partition=gpu-k10
[2022-07-06T14:03:32.395] sched: Allocate JobId=45849 NodeList=cpu10 #CPUs=2 Partition=cpu-opteron
[2022-07-06T14:04:21.463] sched: Allocate JobId=45850 NodeList=cpu10 #CPUs=2 Partition=cpu-opteron
[2022-07-06T14:06:02.602] sched: Allocate JobId=45851 NodeList=cpu10 #CPUs=2 Partition=cpu-opteron
[2022-07-06T14:07:08.694] sched: Allocate JobId=45852 NodeList=gpu01 #CPUs=10 Partition=gpu-k10
[2022-07-06T14:11:09.167] sched: Allocate JobId=45853 NodeList=cpu10 #CPUs=2 Partition=cpu-opteron
[2022-07-06T14:49:49.307] sched: Allocate JobId=45854 NodeList=cpu09 #CPUs=16 Partition=cpu-opteron
[2022-07-06T14:50:46.382] sched: Allocate JobId=45855 NodeList=cpu09 #CPUs=16 Partition=cpu-opteron
[2022-07-06T14:51:48.340] sched: Allocate JobId=45788 NodeList=cpu15 #CPUs=16 Partition=cpu-epyc
[2022-07-06T14:51:56.480] sched: Allocate JobId=45856 NodeList=cpu09 #CPUs=16 Partition=cpu-opteron
[2022-07-06T14:55:19.905] sched: Allocate JobId=45857 NodeList=cpu09 #CPUs=16 Partition=cpu-opteron
[2022-07-06T14:56:44.024] sched: Allocate JobId=45858 NodeList=cpu09 #CPUs=16 Partition=cpu-opteron
[2022-07-06T15:06:09.035] sched: Allocate JobId=45859 NodeList=cpu09 #CPUs=16 Partition=cpu-opteron
[2022-07-06T15:43:58.778] sched: Allocate JobId=45860 NodeList=cpu15 #CPUs=20 Partition=cpu-epyc
[2022-07-06T15:44:24.801] sched: Allocate JobId=45861 NodeList=cpu15 #CPUs=20 Partition=cpu-epyc
[2022-07-06T16:10:34.636] sched: Allocate JobId=45862 NodeList=cpu15 #CPUs=20 Partition=cpu-epyc
[2022-07-06T16:22:21.896] sched: Allocate JobId=45789 NodeList=cpu12 #CPUs=16 Partition=cpu-epyc
[2022-07-06T16:51:27.059] sched: Allocate JobId=45863 NodeList=cpu09 #CPUs=8 Partition=cpu-opteron
[2022-07-06T17:03:39.398] sched: Allocate JobId=45864 NodeList=cpu15 #CPUs=20 Partition=cpu-epyc
[2022-07-06T17:24:31.701] sched: Allocate JobId=45865 NodeList=cpu03 #CPUs=64 Partition=cpu-opteron
[2022-07-06T18:52:12.871] sched: Allocate JobId=45868 NodeList=cpu13 #CPUs=32 Partition=cpu-epyc
[2022-07-06T18:55:40.558] sched: Allocate JobId=45869 NodeList=cpu08 #CPUs=64 Partition=cpu-opteron
[2022-07-06T19:10:52.084] sched: Allocate JobId=45870 NodeList=cpu13 #CPUs=32 Partition=cpu-epyc
[2022-07-06T19:25:30.909] sched: Allocate JobId=45871 NodeList=cpu13 #CPUs=32 Partition=cpu-epyc
[2022-07-06T20:01:34.566] sched: Allocate JobId=45790 NodeList=cpu15 #CPUs=16 Partition=cpu-epyc
[2022-07-06T20:36:01.261] sched/backfill: _start_job: Started JobId=45872 in cpu-epyc on cpu13
[2022-07-06T20:47:27.796] sched: Allocate JobId=45873 NodeList=cpu13 #CPUs=32 Partition=cpu-epyc
[2022-07-06T21:16:45.862] sched: Allocate JobId=45791 NodeList=cpu14 #CPUs=16 Partition=cpu-epyc
[2022-07-06T21:42:16.052] sched: Allocate JobId=45792 NodeList=cpu12 #CPUs=16 Partition=cpu-epyc
[2022-07-06T21:52:40.823] sched: Allocate JobId=45875 NodeList=cpu13 #CPUs=32 Partition=cpu-epyc
[2022-07-06T21:53:43.927] sched: Allocate JobId=45876 NodeList=cpu15 #CPUs=16 Partition=cpu-epyc
[2022-07-06T21:56:42.165] sched: Allocate JobId=45877 NodeList=cpu15 #CPUs=20 Partition=cpu-epyc
[2022-07-06T21:56:49.175] sched: Allocate JobId=45878 NodeList=cpu13 #CPUs=16 Partition=cpu-epyc
[2022-07-06T21:57:22.221] sched: Allocate JobId=45879 NodeList=cpu13 #CPUs=16 Partition=cpu-epyc
[2022-07-06T21:58:11.460] sched: Allocate JobId=45880 NodeList=cpu13 #CPUs=16 Partition=cpu-epyc
[2022-07-06T21:59:10.544] sched: Allocate JobId=45881 NodeList=cpu13 #CPUs=20 Partition=cpu-epyc
[2022-07-06T21:59:40.585] sched: Allocate JobId=45882 NodeList=cpu13 #CPUs=20 Partition=cpu-epyc
[2022-07-06T22:04:32.078] sched: Allocate JobId=45887 NodeList=cpu13 #CPUs=12 Partition=cpu-epyc
[2022-07-06T22:05:30.158] sched: Allocate JobId=45888 NodeList=cpu13 #CPUs=12 Partition=cpu-epyc
[2022-07-06T22:05:54.190] sched: Allocate JobId=45889 NodeList=cpu13 #CPUs=12 Partition=cpu-epyc
[2022-07-06T22:06:21.227] sched: Allocate JobId=45890 NodeList=cpu13 #CPUs=12 Partition=cpu-epyc
[2022-07-06T22:08:23.570] sched: Allocate JobId=45891 NodeList=cpu13 #CPUs=12 Partition=cpu-epyc
[2022-07-06T22:09:51.902] sched: Allocate JobId=45892 NodeList=cpu13 #CPUs=12 Partition=cpu-epyc
[2022-07-06T22:11:27.015] sched: Allocate JobId=45893 NodeList=cpu13 #CPUs=12 Partition=cpu-epyc
[2022-07-06T22:13:05.683] sched: Allocate JobId=45894 NodeList=cpu13 #CPUs=12 Partition=cpu-epyc
[2022-07-06T22:14:43.226] sched: Allocate JobId=45895 NodeList=cpu13 #CPUs=12 Partition=cpu-epyc
[2022-07-06T22:16:17.832] sched: Allocate JobId=45896 NodeList=cpu13 #CPUs=12 Partition=cpu-epyc
[2022-07-06T23:20:56.407] sched: Allocate JobId=45899 NodeList=cpu13 #CPUs=8 Partition=cpu-epyc
[2022-07-06T23:23:26.702] sched: Allocate JobId=45900 NodeList=cpu09 #CPUs=8 Partition=cpu-opteron
[2022-07-06T23:42:26.133] sched: Allocate JobId=45898 NodeList=cpu13 #CPUs=24 Partition=cpu-epyc
[2022-07-06T23:46:28.096] sched: Allocate JobId=45901 NodeList=cpu13 #CPUs=8 Partition=cpu-epyc
[2022-07-07T00:14:06.616] sched: _slurm_rpc_allocate_resources JobId=45902 NodeList=(null) usec=1163
[2022-07-07T00:14:08.395] sched: Allocate JobId=45902 NodeList=cpu09 #CPUs=8 Partition=cpu-opteron
[2022-07-07T00:18:52.928] sched: Allocate JobId=45903 NodeList=cpu15 #CPUs=20 Partition=cpu-epyc
[2022-07-07T00:25:56.676] sched: Allocate JobId=45904 NodeList=cpu13 #CPUs=8 Partition=cpu-epyc
[2022-07-07T01:12:06.574] sched: Allocate JobId=45793 NodeList=cpu15 #CPUs=16 Partition=cpu-epyc
[2022-07-07T02:59:06.585] sched: Allocate JobId=45794 NodeList=cpu14 #CPUs=16 Partition=cpu-epyc
[2022-07-07T03:18:04.913] sched: Allocate JobId=45795 NodeList=cpu12 #CPUs=16 Partition=cpu-epyc
[2022-07-07T04:30:43.977] sched: Allocate JobId=45905 NodeList=cpu13 #CPUs=24 Partition=cpu-epyc
[2022-07-07T04:33:19.284] sched: Allocate JobId=45906 NodeList=cpu09 #CPUs=32 Partition=cpu-opteron
[2022-07-07T04:34:36.393] sched: Allocate JobId=45907 NodeList=cpu09 #CPUs=32 Partition=cpu-opteron
[2022-07-07T06:17:02.634] sched: Allocate JobId=45796 NodeList=cpu14 #CPUs=16 Partition=cpu-epyc
[2022-07-07T07:02:33.677] sched: Allocate JobId=45908 NodeList=cpu13 #CPUs=24 Partition=cpu-epyc
[2022-07-07T07:04:08.843] sched: Allocate JobId=45909 NodeList=cpu14 #CPUs=8 Partition=cpu-epyc
[2022-07-07T07:20:29.676] sched: Allocate JobId=45910 NodeList=cpu14 #CPUs=8 Partition=cpu-epyc
[2022-07-07T07:27:39.570] sched: Allocate JobId=45911 NodeList=cpu13 #CPUs=24 Partition=cpu-epyc
[2022-07-07T07:42:30.270] sched: Allocate JobId=45912 NodeList=cpu11 #CPUs=8 Partition=cpu-opteron
[2022-07-07T07:46:57.683] sched: Allocate JobId=45913 NodeList=cpu14 #CPUs=16 Partition=cpu-epyc
[2022-07-07T08:36:01.453] sched: Allocate JobId=45914 NodeList=cpu13 #CPUs=24 Partition=cpu-epyc
[2022-07-07T08:42:42.268] sched: Allocate JobId=45915 NodeList=cpu13 #CPUs=24 Partition=cpu-epyc
[2022-07-07T09:16:11.926] sched: Allocate JobId=45917 NodeList=cpu11 #CPUs=16 Partition=cpu-opteron
[2022-07-07T09:17:54.170] sched: Allocate JobId=45919 NodeList=cpu12 #CPUs=16 Partition=cpu-epyc
[2022-07-07T09:20:16.364] sched: Allocate JobId=45920 NodeList=cpu12 #CPUs=16 Partition=cpu-epyc
[2022-07-07T09:23:27.782] sched: Allocate JobId=45921 NodeList=cpu12 #CPUs=16 Partition=cpu-epyc
[2022-07-07T09:24:44.886] sched: Allocate JobId=45922 NodeList=cpu14 #CPUs=16 Partition=cpu-epyc
[2022-07-07T09:26:22.020] sched: Allocate JobId=45923 NodeList=cpu15 #CPUs=16 Partition=cpu-epyc
[2022-07-07T09:27:26.105] sched: Allocate JobId=45924 NodeList=cpu11 #CPUs=16 Partition=cpu-opteron
[2022-07-07T09:49:38.636] sched: Allocate JobId=45916 NodeList=cpu14 #CPUs=32 Partition=cpu-epyc
[2022-07-07T10:02:19.106] sched: Allocate JobId=45925 NodeList=cpu11 #CPUs=4 Partition=cpu-opteron
[2022-07-07T10:07:29.623] sched: Allocate JobId=45926 NodeList=cpu12 #CPUs=16 Partition=cpu-epyc
[2022-07-07T10:26:55.770] sched: Allocate JobId=45927 NodeList=gpu02 #CPUs=10 Partition=gpu-titan
[2022-07-07T10:34:32.884] sched: _slurm_rpc_allocate_resources JobId=45928 NodeList=(null) usec=762
[2022-07-07T10:34:33.644] sched: Allocate JobId=45928 NodeList=cpu10 #CPUs=1 Partition=cpu-opteron
[2022-07-07T11:12:12.454] sched: Allocate JobId=45929 NodeList=gpu02 #CPUs=6 Partition=gpu-titan
[2022-07-07T11:28:08.221] sched: Allocate JobId=45930 NodeList=gpu05 #CPUs=16 Partition=gpu-v100s
[2022-07-07T11:36:56.106] sched: Allocate JobId=45931 NodeList=cpu12 #CPUs=16 Partition=cpu-epyc
[2022-07-07T11:38:32.323] sched: Allocate JobId=45932 NodeList=cpu15 #CPUs=16 Partition=cpu-epyc
[2022-07-07T11:51:48.907] sched: Allocate JobId=45933 NodeList=cpu14 #CPUs=16 Partition=cpu-epyc
[2022-07-07T11:54:28.928] sched: Allocate JobId=45936 NodeList=gpu05 #CPUs=16 Partition=gpu-v100s
[2022-07-07T12:40:49.847] sched: Allocate JobId=45984 NodeList=cpu13 #CPUs=16 Partition=cpu-epyc
[2022-07-07T12:42:20.942] sched: Allocate JobId=45985 NodeList=cpu13 #CPUs=16 Partition=cpu-epyc
[2022-07-07T12:42:55.069] sched: Allocate JobId=45986 NodeList=cpu13 #CPUs=16 Partition=cpu-epyc
[2022-07-07T12:43:45.138] sched: Allocate JobId=45987 NodeList=cpu13 #CPUs=16 Partition=cpu-epyc
[2022-07-07T12:44:12.173] sched: Allocate JobId=45988 NodeList=cpu13 #CPUs=16 Partition=cpu-epyc
[2022-07-07T12:44:51.198] sched: Allocate JobId=45934 NodeList=cpu12 #CPUs=16 Partition=cpu-epyc
[2022-07-07T12:46:42.381] sched: Allocate JobId=45989 NodeList=cpu13 #CPUs=16 Partition=cpu-epyc
[2022-07-07T12:51:08.885] sched: Allocate JobId=45991 NodeList=cpu13 #CPUs=24 Partition=cpu-epyc
[2022-07-07T12:52:20.843] sched: Allocate JobId=45937 NodeList=cpu14 #CPUs=16 Partition=cpu-epyc
[2022-07-07T12:52:37.029] sched: Allocate JobId=45992 NodeList=cpu13 #CPUs=16 Partition=cpu-epyc
[2022-07-07T12:53:49.161] sched: Allocate JobId=45993 NodeList=cpu13 #CPUs=16 Partition=cpu-epyc
[2022-07-07T12:56:01.793] sched/backfill: _start_job: Started JobId=45994 in gpu-titan on gpu02
[2022-07-07T12:56:39.394] sched: Allocate JobId=45995 NodeList=cpu13 #CPUs=16 Partition=cpu-epyc
[2022-07-07T12:57:44.652] sched: Allocate JobId=45996 NodeList=gpu01 #CPUs=16 Partition=gpu-k10
[2022-07-07T12:57:50.659] sched: Allocate JobId=45997 NodeList=cpu13 #CPUs=16 Partition=cpu-epyc
[2022-07-07T12:58:51.117] sched: Allocate JobId=45938 NodeList=cpu15 #CPUs=16 Partition=cpu-epyc
[2022-07-07T13:00:16.861] sched: Allocate JobId=45998 NodeList=cpu13 #CPUs=16 Partition=cpu-epyc
[2022-07-07T13:02:54.434] sched: Allocate JobId=46001 NodeList=gpu03 #CPUs=16 Partition=gpu-k10
[2022-07-07T13:08:52.218] sched: Allocate JobId=46002 NodeList=cpu13 #CPUs=16 Partition=cpu-epyc
[2022-07-07T13:17:27.179] sched: Allocate JobId=46003 NodeList=cpu13 #CPUs=16 Partition=cpu-epyc
[2022-07-07T13:18:47.345] sched: Allocate JobId=46004 NodeList=cpu11 #CPUs=2 Partition=cpu-opteron
[2022-07-07T13:24:45.955] sched: Allocate JobId=46005 NodeList=cpu11 #CPUs=2 Partition=cpu-opteron
[2022-07-07T13:26:32.105] sched: Allocate JobId=46006 NodeList=gpu03 #CPUs=16 Partition=gpu-k10
[2022-07-07T13:29:37.486] sched: Allocate JobId=46007 NodeList=gpu01 #CPUs=16 Partition=gpu-k10
[2022-07-07T13:38:43.485] sched: Allocate JobId=46008 NodeList=cpu13 #CPUs=24 Partition=cpu-epyc
[2022-07-07T13:39:19.531] sched: Allocate JobId=46009 NodeList=cpu13 #CPUs=24 Partition=cpu-epyc
[2022-07-07T13:39:59.591] sched: Allocate JobId=46010 NodeList=gpu05 #CPUs=16 Partition=gpu-v100s
[2022-07-07T13:44:39.066] sched: Allocate JobId=46011 NodeList=gpu03 #CPUs=16 Partition=gpu-k10
[2022-07-07T13:45:04.100] sched: Allocate JobId=46012 NodeList=cpu13 #CPUs=16 Partition=cpu-epyc
[2022-07-07T13:47:08.262] sched: Allocate JobId=46013 NodeList=gpu01 #CPUs=16 Partition=gpu-k10
[2022-07-07T13:49:27.556] sched: Allocate JobId=46014 NodeList=cpu13 #CPUs=16 Partition=cpu-epyc
[2022-07-07T13:49:30.562] sched: Allocate JobId=46015 NodeList=gpu03 #CPUs=16 Partition=gpu-k10
[2022-07-07T13:53:18.977] sched: Allocate JobId=46016 NodeList=cpu13 #CPUs=16 Partition=cpu-epyc
[2022-07-07T13:55:21.411] sched: Allocate JobId=45939 NodeList=cpu14 #CPUs=16 Partition=cpu-epyc
[2022-07-07T14:02:09.813] sched: Allocate JobId=46017 NodeList=cpu13 #CPUs=16 Partition=cpu-epyc
[2022-07-07T14:06:36.084] sched: Allocate JobId=45940 NodeList=cpu12 #CPUs=16 Partition=cpu-epyc
[2022-07-07T14:09:52.731] sched: Allocate JobId=46018 NodeList=cpu13 #CPUs=24 Partition=cpu-epyc
[2022-07-07T14:33:41.313] sched: Allocate JobId=45941 NodeList=cpu15 #CPUs=16 Partition=cpu-epyc
[2022-07-07T14:38:11.001] sched: Allocate JobId=46019 NodeList=gpu01 #CPUs=16 Partition=gpu-k10
[2022-07-07T14:45:13.641] sched: Allocate JobId=46020 NodeList=cpu13 #CPUs=24 Partition=cpu-epyc
[2022-07-07T14:46:25.741] sched: Allocate JobId=46021 NodeList=cpu10 #CPUs=64 Partition=cpu-opteron
[2022-07-07T14:57:31.499] sched: Allocate JobId=46022 NodeList=cpu11 #CPUs=16 Partition=cpu-opteron
[2022-07-07T14:58:51.938] sched: Allocate JobId=45942 NodeList=cpu14 #CPUs=16 Partition=cpu-epyc
[2022-07-07T15:16:27.835] sched: Allocate JobId=45943 NodeList=cpu12 #CPUs=16 Partition=cpu-epyc
[2022-07-07T15:17:11.653] sched: Allocate JobId=46024 NodeList=cpu13 #CPUs=24 Partition=cpu-epyc
[2022-07-07T15:36:59.916] sched: Allocate JobId=45944 NodeList=cpu15 #CPUs=16 Partition=cpu-epyc
[2022-07-07T16:12:32.787] sched: Allocate JobId=46025 NodeList=cpu13 #CPUs=24 Partition=cpu-epyc
[2022-07-07T16:25:07.585] sched: Allocate JobId=45945 NodeList=cpu12 #CPUs=16 Partition=cpu-epyc
[2022-07-07T16:34:41.372] sched: Allocate JobId=45946 NodeList=cpu15 #CPUs=16 Partition=cpu-epyc
[2022-07-07T16:37:10.533] sched: Allocate JobId=46041 NodeList=cpu11 #CPUs=16 Partition=cpu-opteron
[2022-07-07T16:40:06.907] sched: Allocate JobId=46042 NodeList=cpu11 #CPUs=16 Partition=cpu-opteron
[2022-07-07T16:41:21.012] sched: Allocate JobId=46043 NodeList=cpu11 #CPUs=16 Partition=cpu-opteron
[2022-07-07T16:44:43.421] sched: Allocate JobId=46044 NodeList=cpu11 #CPUs=16 Partition=cpu-opteron
[2022-07-07T16:45:25.477] sched: Allocate JobId=46045 NodeList=cpu11 #CPUs=16 Partition=cpu-opteron
[2022-07-07T16:49:27.569] sched: Allocate JobId=45947 NodeList=cpu14 #CPUs=16 Partition=cpu-epyc
[2022-07-07T17:14:34.828] sched: Allocate JobId=46046 NodeList=cpu13 #CPUs=24 Partition=cpu-epyc
[2022-07-07T17:35:09.313] sched: Allocate JobId=45948 NodeList=cpu15 #CPUs=16 Partition=cpu-epyc
[2022-07-07T17:42:45.323] sched: Allocate JobId=45949 NodeList=cpu12 #CPUs=16 Partition=cpu-epyc
[2022-07-07T17:50:34.139] sched: Allocate JobId=45950 NodeList=cpu14 #CPUs=16 Partition=cpu-epyc
[2022-07-07T17:50:44.746] sched: Allocate JobId=46048 NodeList=cpu11 #CPUs=16 Partition=cpu-opteron
[2022-07-07T17:52:12.854] sched: Allocate JobId=46049 NodeList=cpu11 #CPUs=16 Partition=cpu-opteron
[2022-07-07T18:06:15.345] sched: Allocate JobId=46050 NodeList=cpu11 #CPUs=16 Partition=cpu-opteron
[2022-07-07T18:40:51.481] sched: Allocate JobId=45951 NodeList=cpu15 #CPUs=16 Partition=cpu-epyc
[2022-07-07T18:53:43.377] sched: Allocate JobId=45952 NodeList=cpu14 #CPUs=16 Partition=cpu-epyc
[2022-07-07T19:22:51.034] sched: Allocate JobId=45953 NodeList=cpu12 #CPUs=16 Partition=cpu-epyc
[2022-07-07T20:06:58.100] sched: Allocate JobId=45954 NodeList=cpu14 #CPUs=16 Partition=cpu-epyc
[2022-07-07T20:13:53.004] sched: Allocate JobId=45955 NodeList=cpu15 #CPUs=16 Partition=cpu-epyc
[2022-07-07T20:45:06.309] sched: Allocate JobId=45956 NodeList=cpu12 #CPUs=16 Partition=cpu-epyc
[2022-07-07T21:17:06.974] sched: Allocate JobId=45957 NodeList=cpu14 #CPUs=16 Partition=cpu-epyc
[2022-07-07T21:24:29.343] sched: Allocate JobId=45958 NodeList=cpu15 #CPUs=16 Partition=cpu-epyc
[2022-07-07T21:46:59.297] sched: Allocate JobId=46052 NodeList=gpu03 #CPUs=16 Partition=gpu-k10
[2022-07-07T21:48:34.562] sched: Allocate JobId=46053 NodeList=gpu03 #CPUs=16 Partition=gpu-k10
[2022-07-07T21:52:11.001] sched: Allocate JobId=45959 NodeList=cpu12 #CPUs=16 Partition=cpu-epyc
[2022-07-07T22:00:09.022] sched: Allocate JobId=45960 NodeList=cpu13 #CPUs=16 Partition=cpu-epyc
[2022-07-07T22:00:09.023] sched: Allocate JobId=45961 NodeList=cpu13 #CPUs=16 Partition=cpu-epyc
[2022-07-07T22:01:04.852] sched: Allocate JobId=46054 NodeList=cpu10 #CPUs=64 Partition=cpu-opteron
[2022-07-07T22:50:04.696] sched: Allocate JobId=45962 NodeList=cpu15 #CPUs=16 Partition=cpu-epyc
[2022-07-07T23:02:24.440] sched: Allocate JobId=45963 NodeList=cpu12 #CPUs=16 Partition=cpu-epyc
[2022-07-07T23:11:53.580] sched: Allocate JobId=45964 NodeList=cpu14 #CPUs=16 Partition=cpu-epyc
[2022-07-07T23:12:32.221] sched: Allocate JobId=45965 NodeList=cpu13 #CPUs=16 Partition=cpu-epyc
[2022-07-07T23:20:02.935] sched: Allocate JobId=45966 NodeList=cpu13 #CPUs=16 Partition=cpu-epyc
[2022-07-07T23:49:52.407] sched: Allocate JobId=45967 NodeList=cpu15 #CPUs=16 Partition=cpu-epyc
[2022-07-08T00:16:54.767] sched: Allocate JobId=45968 NodeList=cpu14 #CPUs=16 Partition=cpu-epyc
[2022-07-08T00:20:41.205] sched: Allocate JobId=45969 NodeList=cpu12 #CPUs=16 Partition=cpu-epyc
[2022-07-08T00:21:09.463] sched: Allocate JobId=45970 NodeList=cpu13 #CPUs=16 Partition=cpu-epyc
[2022-07-08T00:56:05.383] sched: Allocate JobId=45971 NodeList=cpu15 #CPUs=16 Partition=cpu-epyc
[2022-07-08T01:28:17.059] sched: Allocate JobId=45972 NodeList=cpu14 #CPUs=16 Partition=cpu-epyc
[2022-07-08T01:33:42.579] sched: Allocate JobId=45973 NodeList=cpu13 #CPUs=16 Partition=cpu-epyc
[2022-07-08T01:49:18.702] sched: Allocate JobId=45974 NodeList=cpu12 #CPUs=16 Partition=cpu-epyc
[2022-07-08T01:55:29.042] sched: Allocate JobId=45975 NodeList=cpu15 #CPUs=16 Partition=cpu-epyc
[2022-07-08T03:00:06.415] sched: Allocate JobId=45976 NodeList=cpu12 #CPUs=16 Partition=cpu-epyc
[2022-07-08T03:05:31.512] sched: Allocate JobId=45977 NodeList=cpu15 #CPUs=16 Partition=cpu-epyc
[2022-07-08T03:13:33.282] sched: Allocate JobId=45978 NodeList=cpu14 #CPUs=16 Partition=cpu-epyc
[2022-07-08T03:23:03.561] sched/backfill: _start_job: Started JobId=46055 in gpu-titan on gpu02
[2022-07-08T03:28:07.724] sched: Allocate JobId=45979 NodeList=cpu13 #CPUs=16 Partition=cpu-epyc
[2022-07-08T03:46:08.394] sched: Allocate JobId=45935 NodeList=gpu02 #CPUs=10 Partition=gpu-titan
[2022-07-08T04:12:17.820] sched: Allocate JobId=45980 NodeList=cpu12 #CPUs=16 Partition=cpu-epyc
[2022-07-08T04:17:26.573] sched: Allocate JobId=45981 NodeList=cpu15 #CPUs=16 Partition=cpu-epyc
[2022-07-08T04:23:30.419] sched: Allocate JobId=45982 NodeList=cpu14 #CPUs=16 Partition=cpu-epyc
[2022-07-08T05:17:31.680] sched: Allocate JobId=45983 NodeList=cpu12 #CPUs=16 Partition=cpu-epyc
[2022-07-08T05:28:11.672] sched: Allocate JobId=46023 NodeList=cpu13 #CPUs=16 Partition=cpu-epyc
[2022-07-08T05:32:17.300] sched: Allocate JobId=46026 NodeList=cpu14 #CPUs=16 Partition=cpu-epyc
[2022-07-08T06:13:49.018] sched: Allocate JobId=46027 NodeList=cpu12 #CPUs=16 Partition=cpu-epyc
[2022-07-08T06:13:49.018] sched: Allocate JobId=46028 NodeList=cpu12 #CPUs=16 Partition=cpu-epyc
[2022-07-08T08:26:46.529] sched: Allocate JobId=46056 NodeList=cpu13 #CPUs=32 Partition=cpu-epyc
[2022-07-08T08:44:24.912] sched: Allocate JobId=46057 NodeList=cpu13 #CPUs=32 Partition=cpu-epyc
[2022-07-08T08:49:23.491] sched: Allocate JobId=46058 NodeList=gpu04 #CPUs=16 Partition=gpu-k40c
[2022-07-08T09:05:51.369] sched: Allocate JobId=46059 NodeList=cpu12 #CPUs=16 Partition=cpu-epyc
[2022-07-08T09:31:37.233] sched: Allocate JobId=46060 NodeList=gpu02 #CPUs=1 Partition=gpu-titan
[2022-07-08T09:51:34.428] sched: Allocate JobId=46062 NodeList=cpu12 #CPUs=16 Partition=cpu-epyc
[2022-07-08T10:02:16.684] sched: _slurm_rpc_allocate_resources JobId=46063 NodeList=cpu11 usec=17703
[2022-07-08T10:06:55.081] sched: Allocate JobId=46064 NodeList=cpu12 #CPUs=16 Partition=cpu-epyc
[2022-07-08T10:34:15.084] sched: Allocate JobId=46066 NodeList=gpu03 #CPUs=2 Partition=gpu-k10
[2022-07-08T10:56:14.359] sched: Allocate JobId=46067 NodeList=cpu12 #CPUs=16 Partition=cpu-epyc
[2022-07-08T12:12:04.664] sched: Allocate JobId=46068 NodeList=cpu12 #CPUs=16 Partition=cpu-epyc
[2022-07-08T12:13:34.900] sched: Allocate JobId=46069 NodeList=cpu12 #CPUs=16 Partition=cpu-epyc
[2022-07-08T12:16:15.128] sched: Allocate JobId=46071 NodeList=cpu15 #CPUs=16 Partition=cpu-epyc
[2022-07-08T14:34:15.553] sched: _slurm_rpc_allocate_resources JobId=46072 NodeList=cpu11 usec=14292
[2022-07-08T14:53:57.158] sched: Allocate JobId=46061 NodeList=gpu02 #CPUs=8 Partition=gpu-titan
[2022-07-08T15:17:49.741] sched: Allocate JobId=46073 NodeList=cpu12 #CPUs=16 Partition=cpu-epyc
[2022-07-08T15:19:29.867] sched: Allocate JobId=46074 NodeList=cpu12 #CPUs=16 Partition=cpu-epyc
[2022-07-08T15:21:28.032] sched: Allocate JobId=46075 NodeList=cpu12 #CPUs=16 Partition=cpu-epyc
[2022-07-08T15:25:59.613] sched: Allocate JobId=46076 NodeList=cpu12 #CPUs=16 Partition=cpu-epyc
[2022-07-08T15:35:22.189] sched: Allocate JobId=46065 NodeList=gpu02 #CPUs=8 Partition=gpu-titan
[2022-07-08T16:03:45.803] sched: Allocate JobId=46077 NodeList=cpu15 #CPUs=2 Partition=cpu-epyc
[2022-07-08T16:08:59.359] sched: Allocate JobId=46078 NodeList=gpu05 #CPUs=16 Partition=gpu-v100s
[2022-07-08T16:11:54.594] sched: Allocate JobId=46079 NodeList=gpu05 #CPUs=16 Partition=gpu-v100s
[2022-07-08T16:13:17.829] sched: Allocate JobId=46080 NodeList=gpu05 #CPUs=16 Partition=gpu-v100s
[2022-07-08T16:14:25.926] sched: Allocate JobId=46081 NodeList=gpu05 #CPUs=16 Partition=gpu-v100s
[2022-07-08T16:20:03.540] sched: Allocate JobId=46082 NodeList=cpu11 #CPUs=2 Partition=cpu-opteron
[2022-07-08T16:28:01.719] sched: Allocate JobId=46083 NodeList=cpu11 #CPUs=4 Partition=cpu-opteron
[2022-07-08T16:28:48.771] sched: Allocate JobId=46084 NodeList=cpu15 #CPUs=16 Partition=cpu-epyc
[2022-07-08T17:19:12.106] sched: Allocate JobId=46086 NodeList=cpu12 #CPUs=2 Partition=cpu-epyc
[2022-07-08T20:06:28.460] sched: Allocate JobId=46089 NodeList=cpu12 #CPUs=16 Partition=cpu-epyc
[2022-07-08T23:07:19.696] sched: Allocate JobId=46087 NodeList=gpu05 #CPUs=16 Partition=gpu-v100s
[2022-07-08T23:17:31.303] sched: Allocate JobId=46029 NodeList=cpu13 #CPUs=16 Partition=cpu-epyc
[2022-07-08T23:43:39.227] sched: Allocate JobId=46090 NodeList=gpu03 #CPUs=16 Partition=gpu-k10
[2022-07-08T23:45:58.419] sched: Allocate JobId=46091 NodeList=gpu03 #CPUs=16 Partition=gpu-k10
[2022-07-08T23:47:58.695] sched: Allocate JobId=46092 NodeList=gpu01 #CPUs=16 Partition=gpu-k10
[2022-07-09T00:02:27.517] sched: Allocate JobId=46093 NodeList=gpu04 #CPUs=16 Partition=gpu-k40c
[2022-07-09T02:27:23.611] sched: Allocate JobId=46030 NodeList=cpu12 #CPUs=16 Partition=cpu-epyc
[2022-07-09T03:19:43.355] sched: Allocate JobId=46031 NodeList=cpu14 #CPUs=16 Partition=cpu-epyc
[2022-07-09T04:11:09.304] sched: Allocate JobId=46096 NodeList=gpu02 #CPUs=10 Partition=gpu-titan
[2022-07-09T04:21:52.412] sched: Allocate JobId=46097 NodeList=gpu02 #CPUs=10 Partition=gpu-titan
[2022-07-09T07:33:40.841] sched: Allocate JobId=46098 NodeList=gpu05 #CPUs=16 Partition=gpu-v100s
[2022-07-09T07:34:35.651] sched: Allocate JobId=46094 NodeList=gpu05 #CPUs=16 Partition=gpu-v100s
[2022-07-09T07:39:27.038] sched: Allocate JobId=46032 NodeList=cpu12 #CPUs=16 Partition=cpu-epyc
[2022-07-09T10:39:27.403] sched: Allocate JobId=46099 NodeList=cpu07 #CPUs=64 Partition=cpu-opteron
[2022-07-09T13:15:15.170] sched: Allocate JobId=46101 NodeList=cpu15 #CPUs=16 Partition=cpu-epyc
[2022-07-09T13:16:50.283] sched: Allocate JobId=46103 NodeList=cpu09 #CPUs=32 Partition=cpu-opteron
[2022-07-09T16:07:29.773] sched: Allocate JobId=46033 NodeList=cpu13 #CPUs=16 Partition=cpu-epyc
[2022-07-09T18:22:31.530] sched: Allocate JobId=46034 NodeList=cpu12 #CPUs=16 Partition=cpu-epyc
[2022-07-09T21:34:04.967] sched: Allocate JobId=46035 NodeList=cpu14 #CPUs=16 Partition=cpu-epyc
[2022-07-09T21:35:32.420] sched: Allocate JobId=46104 NodeList=gpu05 #CPUs=16 Partition=gpu-v100s
[2022-07-10T00:04:45.409] sched: Allocate JobId=46105 NodeList=gpu02 #CPUs=16 Partition=gpu-titan
[2022-07-10T00:11:17.979] sched: Allocate JobId=46106 NodeList=gpu02 #CPUs=16 Partition=gpu-titan
[2022-07-10T00:42:22.237] sched: Allocate JobId=46107 NodeList=cpu04 #CPUs=32 Partition=cpu-opteron
[2022-07-10T00:52:05.184] sched: Allocate JobId=46108 NodeList=cpu04 #CPUs=32 Partition=cpu-opteron
[2022-07-10T00:59:42.103] sched: Allocate JobId=46109 NodeList=gpu02 #CPUs=6 Partition=gpu-titan
[2022-07-10T01:01:15.223] sched: Allocate JobId=46110 NodeList=cpu04 #CPUs=32 Partition=cpu-opteron
[2022-07-10T01:02:59.875] sched: Allocate JobId=46111 NodeList=gpu05 #CPUs=6 Partition=gpu-v100s
[2022-07-10T01:09:02.555] sched: Allocate JobId=46112 NodeList=cpu04 #CPUs=32 Partition=cpu-opteron
[2022-07-10T01:09:59.629] sched: Allocate JobId=46113 NodeList=cpu04 #CPUs=32 Partition=cpu-opteron
[2022-07-10T01:11:40.772] sched: Allocate JobId=46114 NodeList=cpu04 #CPUs=32 Partition=cpu-opteron
[2022-07-10T01:16:21.279] sched: Allocate JobId=46115 NodeList=cpu04 #CPUs=32 Partition=cpu-opteron
[2022-07-10T01:18:40.616] sched: Allocate JobId=46116 NodeList=cpu04 #CPUs=32 Partition=cpu-opteron
[2022-07-10T01:28:00.663] sched: Allocate JobId=46117 NodeList=cpu04 #CPUs=32 Partition=cpu-opteron
[2022-07-10T01:34:17.289] sched: Allocate JobId=46118 NodeList=cpu04 #CPUs=32 Partition=cpu-opteron
[2022-07-10T01:42:33.151] sched: Allocate JobId=46119 NodeList=cpu04 #CPUs=32 Partition=cpu-opteron
[2022-07-10T01:43:56.309] sched: Allocate JobId=46120 NodeList=cpu04 #CPUs=32 Partition=cpu-opteron
[2022-07-10T01:48:04.757] sched: Allocate JobId=46121 NodeList=cpu04 #CPUs=32 Partition=cpu-opteron
[2022-07-10T01:53:39.329] sched: Allocate JobId=46122 NodeList=cpu04 #CPUs=32 Partition=cpu-opteron
[2022-07-10T01:54:01.355] sched: Allocate JobId=46123 NodeList=cpu04 #CPUs=32 Partition=cpu-opteron
[2022-07-10T01:54:15.375] sched: Allocate JobId=46124 NodeList=cpu04 #CPUs=32 Partition=cpu-opteron
[2022-07-10T01:54:26.389] sched: Allocate JobId=46125 NodeList=cpu04 #CPUs=32 Partition=cpu-opteron
[2022-07-10T01:54:50.425] sched: Allocate JobId=46126 NodeList=cpu04 #CPUs=32 Partition=cpu-opteron
[2022-07-10T01:56:06.667] sched: Allocate JobId=46127 NodeList=cpu04 #CPUs=32 Partition=cpu-opteron
[2022-07-10T01:57:23.699] sched: Allocate JobId=46128 NodeList=cpu04 #CPUs=32 Partition=cpu-opteron
[2022-07-10T02:08:54.259] sched: Allocate JobId=46129 NodeList=cpu04 #CPUs=32 Partition=cpu-opteron
[2022-07-10T02:47:15.717] sched: Allocate JobId=46130 NodeList=gpu04 #CPUs=16 Partition=gpu-k40c
[2022-07-10T07:33:19.803] sched: Allocate JobId=46102 NodeList=cpu15 #CPUs=16 Partition=cpu-epyc
[2022-07-10T09:00:15.645] sched: Allocate JobId=46036 NodeList=cpu12 #CPUs=16 Partition=cpu-epyc
[2022-07-10T14:08:43.103] sched: Allocate JobId=46037 NodeList=cpu13 #CPUs=16 Partition=cpu-epyc
[2022-07-10T14:39:04.735] sched: Allocate JobId=46038 NodeList=cpu14 #CPUs=16 Partition=cpu-epyc
[2022-07-10T15:15:53.465] sched: Allocate JobId=46039 NodeList=cpu12 #CPUs=16 Partition=cpu-epyc
[2022-07-11T04:05:45.305] sched: Allocate JobId=46131 NodeList=gpu02 #CPUs=1 Partition=gpu-titan
[2022-07-11T07:39:02.117] sched: Allocate JobId=46040 NodeList=cpu13 #CPUs=16 Partition=cpu-epyc
[2022-07-11T07:58:36.375] sched: Allocate JobId=46132 NodeList=gpu04 #CPUs=16 Partition=gpu-k40c
[2022-07-11T10:01:53.097] sched: Allocate JobId=46133 NodeList=gpu02 #CPUs=1 Partition=gpu-titan
[2022-07-11T11:26:51.668] sched: Allocate JobId=46100 NodeList=cpu12 #CPUs=32 Partition=cpu-epyc
[2022-07-11T12:50:07.033] sched: Allocate JobId=46141 NodeList=cpu14 #CPUs=16 Partition=cpu-epyc
[2022-07-11T12:51:05.103] sched: Allocate JobId=46142 NodeList=cpu15 #CPUs=16 Partition=cpu-epyc
[2022-07-11T14:47:35.709] sched: Allocate JobId=46144 NodeList=cpu09 #CPUs=64 Partition=cpu-opteron
[2022-07-11T14:48:18.790] sched: Allocate JobId=46145 NodeList=cpu09 #CPUs=64 Partition=cpu-opteron
[2022-07-11T14:51:54.086] sched: Allocate JobId=46146 NodeList=cpu09 #CPUs=64 Partition=cpu-opteron
[2022-07-11T14:53:45.323] sched: Allocate JobId=46147 NodeList=cpu09 #CPUs=64 Partition=cpu-opteron
[2022-07-11T14:54:23.374] sched: Allocate JobId=46148 NodeList=cpu09 #CPUs=64 Partition=cpu-opteron
[2022-07-11T22:27:13.200] sched: _slurm_rpc_allocate_resources JobId=46149 NodeList=cpu11 usec=17468
[2022-07-11T22:46:34.053] sched: Allocate JobId=46150 NodeList=cpu15 #CPUs=16 Partition=cpu-epyc
[2022-07-11T22:47:57.280] sched: Allocate JobId=46151 NodeList=cpu15 #CPUs=16 Partition=cpu-epyc
[2022-07-11T23:10:30.601] sched: Allocate JobId=46152 NodeList=gpu05 #CPUs=16 Partition=gpu-v100s
[2022-07-11T23:12:22.754] sched: Allocate JobId=46153 NodeList=gpu05 #CPUs=16 Partition=gpu-v100s
[2022-07-11T23:20:28.590] sched: Allocate JobId=46154 NodeList=cpu04 #CPUs=32 Partition=cpu-opteron
[2022-07-12T00:38:15.681] sched: Allocate JobId=46167 NodeList=gpu02 #CPUs=16 Partition=gpu-titan
[2022-07-12T00:51:58.094] sched: Allocate JobId=46169 NodeList=gpu02 #CPUs=16 Partition=gpu-titan
[2022-07-12T00:53:57.363] sched: Allocate JobId=46170 NodeList=gpu02 #CPUs=16 Partition=gpu-titan
[2022-07-12T00:54:23.398] sched: Allocate JobId=46171 NodeList=gpu02 #CPUs=16 Partition=gpu-titan
[2022-07-12T00:56:35.586] sched: Allocate JobId=46172 NodeList=cpu04 #CPUs=16 Partition=cpu-opteron
[2022-07-12T01:08:30.595] sched: _slurm_rpc_allocate_resources JobId=46175 NodeList=gpu02 usec=4645
[2022-07-12T01:10:23.500] sched: Allocate JobId=46176 NodeList=gpu02 #CPUs=16 Partition=gpu-titan
[2022-07-12T01:25:04.067] sched: _slurm_rpc_allocate_resources JobId=46177 NodeList=(null) usec=902
[2022-07-12T01:25:05.038] sched: Allocate JobId=46177 NodeList=cpu11 #CPUs=16 Partition=cpu-opteron
[2022-07-12T01:39:38.363] sched: _slurm_rpc_allocate_resources JobId=46178 NodeList=(null) usec=838
[2022-07-12T01:39:38.594] sched: Allocate JobId=46178 NodeList=cpu11 #CPUs=16 Partition=cpu-opteron
[2022-07-12T02:39:01.605] sched: _slurm_rpc_allocate_resources JobId=46179 NodeList=(null) usec=943
[2022-07-12T02:39:01.858] sched: Allocate JobId=46179 NodeList=cpu11 #CPUs=16 Partition=cpu-opteron
[2022-07-12T09:15:47.384] sched: Allocate JobId=46182 NodeList=gpu02 #CPUs=10 Partition=gpu-titan
[2022-07-12T09:28:35.850] sched: Allocate JobId=46183 NodeList=gpu02 #CPUs=10 Partition=gpu-titan
[2022-07-12T09:34:14.546] sched: Allocate JobId=46184 NodeList=gpu02 #CPUs=1 Partition=gpu-titan
[2022-07-12T10:21:04.145] sched: Allocate JobId=46188 NodeList=cpu13 #CPUs=8 Partition=cpu-epyc
[2022-07-12T10:22:32.248] sched: Allocate JobId=46189 NodeList=cpu11 #CPUs=16 Partition=cpu-opteron
[2022-07-12T10:25:24.523] sched: Allocate JobId=46190 NodeList=cpu13 #CPUs=8 Partition=cpu-epyc
[2022-07-12T10:29:39.135] sched: Allocate JobId=46192 NodeList=cpu11 #CPUs=1 Partition=cpu-opteron
[2022-07-12T10:32:27.322] sched: Allocate JobId=46193 NodeList=cpu13 #CPUs=8 Partition=cpu-epyc
[2022-07-12T10:34:23.521] sched: Allocate JobId=46185 NodeList=gpu02 #CPUs=1 Partition=gpu-titan
[2022-07-12T10:35:06.463] sched/backfill: _start_job: Started JobId=46194 in cpu-epyc on cpu13
[2022-07-12T10:38:52.031] sched: Allocate JobId=46198 NodeList=cpu11 #CPUs=8 Partition=cpu-opteron
[2022-07-12T10:39:56.123] sched: Allocate JobId=46199 NodeList=cpu04 #CPUs=8 Partition=cpu-opteron
[2022-07-12T10:45:05.682] sched: Allocate JobId=46203 NodeList=cpu11 #CPUs=7 Partition=cpu-opteron
[2022-07-12T10:46:32.079] sched: Allocate JobId=46201 NodeList=cpu13 #CPUs=8 Partition=cpu-epyc
[2022-07-12T10:48:15.000] sched: Allocate JobId=46204 NodeList=cpu13 #CPUs=8 Partition=cpu-epyc
[2022-07-12T10:49:51.133] sched: Allocate JobId=46205 NodeList=cpu13 #CPUs=8 Partition=cpu-epyc
[2022-07-12T15:08:57.123] sched: Allocate JobId=46207 NodeList=gpu02 #CPUs=10 Partition=gpu-titan
[2022-07-12T15:48:23.084] sched: Allocate JobId=46209 NodeList=cpu11 #CPUs=16 Partition=cpu-opteron
[2022-07-12T15:51:30.326] sched: Allocate JobId=46211 NodeList=cpu04 #CPUs=16 Partition=cpu-opteron
[2022-07-12T16:28:06.833] sched/backfill: _start_job: Started JobId=46218 in cpu-epyc on cpu13
[2022-07-12T16:34:39.366] sched: Allocate JobId=46219 NodeList=cpu04 #CPUs=8 Partition=cpu-opteron
[2022-07-12T16:39:51.298] sched: Allocate JobId=46220 NodeList=cpu04 #CPUs=8 Partition=cpu-opteron
[2022-07-12T16:40:05.424] sched: Allocate JobId=46221 NodeList=cpu04 #CPUs=8 Partition=cpu-opteron
[2022-07-12T16:41:11.406] sched: Allocate JobId=46222 NodeList=cpu04 #CPUs=8 Partition=cpu-opteron
[2022-07-12T20:42:20.770] sched: Allocate JobId=46223 NodeList=gpu04 #CPUs=16 Partition=gpu-k40c
[2022-07-12T21:27:45.546] sched: Allocate JobId=46224 NodeList=gpu02 #CPUs=10 Partition=gpu-titan
[2022-07-12T23:55:58.326] sched: Allocate JobId=45637 NodeList=cpu13 #CPUs=48 Partition=cpu-epyc
[2022-07-13T00:09:35.307] sched: Allocate JobId=45638 NodeList=cpu13 #CPUs=48 Partition=cpu-epyc
[2022-07-13T00:19:34.250] sched: Allocate JobId=45639 NodeList=cpu13 #CPUs=48 Partition=cpu-epyc
[2022-07-13T01:08:06.017] sched: Allocate JobId=45628 NodeList=cpu13 #CPUs=48 Partition=cpu-epyc
[2022-07-13T01:08:07.384] sched/backfill: _start_job: Started JobId=46208 in cpu-epyc on cpu14
[2022-07-13T01:08:14.190] sched: Allocate JobId=45629 NodeList=cpu13 #CPUs=48 Partition=cpu-epyc
[2022-07-13T01:08:15.186] sched: Allocate JobId=46210 NodeList=cpu13 #CPUs=16 Partition=cpu-epyc
[2022-07-13T01:08:15.187] sched: Allocate JobId=46214 NodeList=cpu13 #CPUs=16 Partition=cpu-epyc
[2022-07-13T01:08:15.204] sched: Allocate JobId=46217 NodeList=cpu13 #CPUs=16 Partition=cpu-epyc
[2022-07-13T01:11:32.518] sched: Allocate JobId=46225 NodeList=cpu13 #CPUs=16 Partition=cpu-epyc
[2022-07-13T01:13:10.734] sched: Allocate JobId=46227 NodeList=cpu13 #CPUs=16 Partition=cpu-epyc
[2022-07-13T01:21:02.583] sched: Allocate JobId=46228 NodeList=cpu14 #CPUs=8 Partition=cpu-epyc
[2022-07-13T03:46:37.758] sched: Allocate JobId=46229 NodeList=cpu13 #CPUs=16 Partition=cpu-epyc
[2022-07-13T04:10:52.725] sched: Allocate JobId=46230 NodeList=cpu13 #CPUs=16 Partition=cpu-epyc
[2022-07-13T04:14:50.281] sched: Allocate JobId=46232 NodeList=gpu02 #CPUs=1 Partition=gpu-titan
[2022-07-13T04:20:53.021] sched: Allocate JobId=46231 NodeList=cpu13 #CPUs=16 Partition=cpu-epyc
[2022-07-13T04:47:06.830] sched: Allocate JobId=46234 NodeList=gpu03 #CPUs=1 Partition=gpu-k10
[2022-07-13T05:58:10.277] sched: Allocate JobId=46233 NodeList=gpu02 #CPUs=1 Partition=gpu-titan
[2022-07-13T09:24:33.529] sched: _slurm_rpc_allocate_resources JobId=46238 NodeList=(null) usec=845
[2022-07-13T09:27:50.848] sched: Allocate JobId=46238 NodeList=cpu04 #CPUs=1 Partition=cpu-opteron
[2022-07-13T09:45:15.297] sched: Allocate JobId=46236 NodeList=gpu02 #CPUs=1 Partition=gpu-titan
[2022-07-13T09:50:05.422] sched: Allocate JobId=46239 NodeList=gpu05 #CPUs=16 Partition=gpu-v100s
[2022-07-13T09:50:36.455] sched: Allocate JobId=46240 NodeList=gpu05 #CPUs=16 Partition=gpu-v100s
[2022-07-13T09:52:48.709] sched: Allocate JobId=46241 NodeList=gpu05 #CPUs=16 Partition=gpu-v100s
[2022-07-13T09:54:49.881] sched: Allocate JobId=46242 NodeList=gpu05 #CPUs=16 Partition=gpu-v100s
[2022-07-13T09:56:48.050] sched: Allocate JobId=46243 NodeList=gpu05 #CPUs=16 Partition=gpu-v100s
[2022-07-13T11:09:22.660] sched: Allocate JobId=46237 NodeList=gpu02 #CPUs=1 Partition=gpu-titan
[2022-07-13T11:55:49.150] sched: _slurm_rpc_allocate_resources JobId=46246 NodeList=cpu04 usec=15961
[2022-07-13T14:55:43.235] sched: Allocate JobId=46248 NodeList=cpu12 #CPUs=16 Partition=cpu-epyc
[2022-07-13T16:49:33.696] sched: Allocate JobId=46249 NodeList=cpu13 #CPUs=32 Partition=cpu-epyc
[2022-07-13T18:39:06.350] sched: Allocate JobId=46213 NodeList=cpu03 #CPUs=16 Partition=cpu-opteron
[2022-07-13T18:39:06.365] sched: Allocate JobId=46244 NodeList=cpu03 #CPUs=16 Partition=cpu-opteron
[2022-07-13T18:39:06.366] sched: Allocate JobId=46245 NodeList=cpu03 #CPUs=16 Partition=cpu-opteron
[2022-07-13T21:37:59.963] sched: Allocate JobId=46250 NodeList=gpu02 #CPUs=4 Partition=gpu-titan
[2022-07-13T21:42:00.298] sched: Allocate JobId=46252 NodeList=cpu03 #CPUs=64 Partition=cpu-opteron
[2022-07-13T21:56:40.414] sched: Allocate JobId=46253 NodeList=cpu12 #CPUs=32 Partition=cpu-epyc
[2022-07-13T23:34:04.626] sched: _slurm_rpc_allocate_resources JobId=46254 NodeList=cpu04 usec=14622
[2022-07-13T23:49:34.216] sched: Allocate JobId=46255 NodeList=cpu13 #CPUs=2 Partition=cpu-epyc
[2022-07-13T23:52:59.591] sched: Allocate JobId=46256 NodeList=cpu13 #CPUs=2 Partition=cpu-epyc
[2022-07-13T23:56:17.868] sched: Allocate JobId=46257 NodeList=cpu13 #CPUs=2 Partition=cpu-epyc
[2022-07-13T23:56:57.928] sched: Allocate JobId=46258 NodeList=cpu13 #CPUs=2 Partition=cpu-epyc
[2022-07-14T00:05:12.974] sched: Allocate JobId=46259 NodeList=cpu12 #CPUs=24 Partition=cpu-epyc
[2022-07-14T00:05:19.970] sched: Allocate JobId=46260 NodeList=cpu12 #CPUs=24 Partition=cpu-epyc
[2022-07-14T00:16:33.173] sched: Allocate JobId=46261 NodeList=cpu13 #CPUs=2 Partition=cpu-epyc
[2022-07-14T00:21:27.684] sched: Allocate JobId=46262 NodeList=gpu05 #CPUs=16 Partition=gpu-v100s
[2022-07-14T00:23:03.910] sched: Allocate JobId=46263 NodeList=gpu05 #CPUs=16 Partition=gpu-v100s
[2022-07-14T00:31:47.701] sched: Allocate JobId=46264 NodeList=cpu13 #CPUs=2 Partition=cpu-epyc
[2022-07-14T00:40:03.542] sched: Allocate JobId=46266 NodeList=cpu13 #CPUs=2 Partition=cpu-epyc
[2022-07-14T01:42:01.472] sched: Allocate JobId=46268 NodeList=cpu13 #CPUs=12 Partition=cpu-epyc
[2022-07-14T01:42:25.491] sched: Allocate JobId=46269 NodeList=cpu13 #CPUs=12 Partition=cpu-epyc
[2022-07-14T01:43:18.735] sched: Allocate JobId=46270 NodeList=cpu13 #CPUs=12 Partition=cpu-epyc
[2022-07-14T01:51:28.494] sched: Allocate JobId=46271 NodeList=cpu12 #CPUs=24 Partition=cpu-epyc
[2022-07-14T01:54:31.870] sched: Allocate JobId=46272 NodeList=cpu12 #CPUs=24 Partition=cpu-epyc
[2022-07-14T01:55:58.985] sched: Allocate JobId=46273 NodeList=cpu14 #CPUs=16 Partition=cpu-epyc
[2022-07-14T01:57:11.087] sched: Allocate JobId=46274 NodeList=cpu15 #CPUs=16 Partition=cpu-epyc
[2022-07-14T02:17:35.618] sched: Allocate JobId=46275 NodeList=cpu12 #CPUs=24 Partition=cpu-epyc
[2022-07-14T02:19:15.786] sched: Allocate JobId=46276 NodeList=cpu13 #CPUs=16 Partition=cpu-epyc
[2022-07-14T02:22:47.175] sched: Allocate JobId=46278 NodeList=cpu15 #CPUs=16 Partition=cpu-epyc
[2022-07-14T03:18:37.534] sched: Allocate JobId=46279 NodeList=gpu02 #CPUs=8 Partition=gpu-titan
[2022-07-14T08:09:32.010] sched: Allocate JobId=46280 NodeList=cpu03 #CPUs=64 Partition=cpu-opteron
[2022-07-14T08:12:38.393] sched: Allocate JobId=46281 NodeList=cpu15 #CPUs=32 Partition=cpu-epyc
[2022-07-14T08:30:01.318] sched: Allocate JobId=46282 NodeList=cpu15 #CPUs=32 Partition=cpu-epyc
[2022-07-14T08:30:54.388] sched: Allocate JobId=46283 NodeList=cpu03 #CPUs=64 Partition=cpu-opteron
[2022-07-14T10:17:22.679] sched: Allocate JobId=46284 NodeList=cpu13 #CPUs=16 Partition=cpu-epyc
[2022-07-14T10:20:10.081] sched: Allocate JobId=46285 NodeList=cpu13 #CPUs=16 Partition=cpu-epyc
[2022-07-14T10:22:37.323] sched: Allocate JobId=46286 NodeList=cpu13 #CPUs=16 Partition=cpu-epyc
[2022-07-14T10:28:44.989] sched: Allocate JobId=46287 NodeList=cpu13 #CPUs=16 Partition=cpu-epyc
[2022-07-14T10:29:49.073] sched: Allocate JobId=46288 NodeList=cpu14 #CPUs=16 Partition=cpu-epyc
[2022-07-14T10:31:14.194] sched: Allocate JobId=46289 NodeList=cpu12 #CPUs=16 Partition=cpu-epyc
[2022-07-14T10:33:36.491] sched: Allocate JobId=46290 NodeList=cpu12 #CPUs=16 Partition=cpu-epyc
[2022-07-14T10:39:57.180] sched: Allocate JobId=46291 NodeList=cpu12 #CPUs=16 Partition=cpu-epyc
[2022-07-14T10:42:53.523] sched: Allocate JobId=46292 NodeList=cpu12 #CPUs=16 Partition=cpu-epyc
[2022-07-14T10:46:03.789] sched: Allocate JobId=46293 NodeList=cpu12 #CPUs=16 Partition=cpu-epyc
[2022-07-14T10:49:02.214] sched: Allocate JobId=46294 NodeList=cpu13 #CPUs=16 Partition=cpu-epyc
[2022-07-14T10:53:06.685] sched: Allocate JobId=46295 NodeList=cpu13 #CPUs=16 Partition=cpu-epyc
[2022-07-14T10:57:51.168] sched: Allocate JobId=46296 NodeList=cpu14 #CPUs=16 Partition=cpu-epyc
[2022-07-14T10:59:10.276] sched: Allocate JobId=46297 NodeList=cpu14 #CPUs=16 Partition=cpu-epyc
[2022-07-14T11:15:06.996] sched: Allocate JobId=46298 NodeList=cpu15 #CPUs=16 Partition=cpu-epyc
[2022-07-14T11:16:40.121] sched: Allocate JobId=46299 NodeList=cpu15 #CPUs=16 Partition=cpu-epyc
[2022-07-14T11:17:03.152] sched: Allocate JobId=46300 NodeList=cpu15 #CPUs=16 Partition=cpu-epyc
[2022-07-14T11:21:27.612] sched: Allocate JobId=46301 NodeList=cpu15 #CPUs=16 Partition=cpu-epyc
[2022-07-14T11:22:20.027] sched: Allocate JobId=46265 NodeList=gpu05 #CPUs=16 Partition=gpu-v100s
[2022-07-14T11:22:29.350] sched: Allocate JobId=46267 NodeList=gpu05 #CPUs=16 Partition=gpu-v100s
[2022-07-14T11:23:30.898] sched: Allocate JobId=46302 NodeList=cpu11 #CPUs=16 Partition=cpu-opteron
[2022-07-14T11:35:27.058] sched: Allocate JobId=46303 NodeList=gpu01 #CPUs=16 Partition=gpu-k10
[2022-07-14T11:37:00.186] sched: Allocate JobId=46304 NodeList=cpu11 #CPUs=16 Partition=cpu-opteron
[2022-07-14T12:08:42.768] sched: Allocate JobId=46305 NodeList=cpu13 #CPUs=16 Partition=cpu-epyc
[2022-07-14T12:08:52.769] sched: Allocate JobId=46306 NodeList=cpu12 #CPUs=16 Partition=cpu-epyc
[2022-07-14T12:09:05.787] sched: Allocate JobId=46307 NodeList=cpu12 #CPUs=16 Partition=cpu-epyc
[2022-07-14T12:09:12.796] sched: Allocate JobId=46308 NodeList=cpu14 #CPUs=16 Partition=cpu-epyc
[2022-07-14T12:16:57.752] sched: Allocate JobId=46309 NodeList=cpu15 #CPUs=16 Partition=cpu-epyc
[2022-07-14T12:57:45.322] sched: Allocate JobId=46313 NodeList=cpu07 #CPUs=64 Partition=cpu-opteron
[2022-07-14T13:03:45.924] sched: Allocate JobId=46314 NodeList=cpu12 #CPUs=16 Partition=cpu-epyc
[2022-07-14T13:08:32.407] sched: Allocate JobId=46315 NodeList=cpu04 #CPUs=16 Partition=cpu-opteron
[2022-07-14T13:38:51.551] sched: Allocate JobId=46317 NodeList=gpu05 #CPUs=16 Partition=gpu-v100s
[2022-07-14T13:50:41.866] sched: Allocate JobId=46318 NodeList=gpu05 #CPUs=16 Partition=gpu-v100s
[2022-07-14T13:51:19.929] sched: Allocate JobId=46319 NodeList=cpu15 #CPUs=20 Partition=cpu-epyc
[2022-07-14T13:54:28.263] sched: Allocate JobId=46320 NodeList=cpu11 #CPUs=16 Partition=cpu-opteron
[2022-07-14T14:13:22.998] sched: Allocate JobId=46310 NodeList=cpu12 #CPUs=16 Partition=cpu-epyc
[2022-07-14T14:16:37.509] sched: Allocate JobId=46322 NodeList=cpu11 #CPUs=8 Partition=cpu-opteron
[2022-07-14T14:17:05.533] sched: Allocate JobId=46323 NodeList=cpu11 #CPUs=8 Partition=cpu-opteron
[2022-07-14T14:18:22.737] sched: Allocate JobId=46324 NodeList=cpu11 #CPUs=8 Partition=cpu-opteron
[2022-07-14T14:24:47.367] sched: Allocate JobId=46326 NodeList=cpu11 #CPUs=8 Partition=cpu-opteron
[2022-07-14T14:25:37.441] sched: Allocate JobId=46327 NodeList=cpu11 #CPUs=8 Partition=cpu-opteron
[2022-07-14T14:26:22.506] sched: Allocate JobId=46328 NodeList=cpu11 #CPUs=8 Partition=cpu-opteron
[2022-07-14T14:27:43.720] sched: Allocate JobId=46329 NodeList=cpu11 #CPUs=8 Partition=cpu-opteron
[2022-07-14T14:33:06.339] sched: Allocate JobId=46330 NodeList=cpu11 #CPUs=8 Partition=cpu-opteron
[2022-07-14T15:14:14.637] sched: Allocate JobId=46331 NodeList=cpu03 #CPUs=8 Partition=cpu-opteron
[2022-07-14T15:14:28.834] sched: Allocate JobId=46316 NodeList=cpu03 #CPUs=64 Partition=cpu-opteron
[2022-07-14T16:01:51.529] sched: Allocate JobId=46247 NodeList=gpu04 #CPUs=16 Partition=gpu-k40c
[2022-07-14T16:10:45.133] sched: Allocate JobId=46336 NodeList=gpu04 #CPUs=16 Partition=gpu-k40c
[2022-07-14T16:49:49.250] sched: Allocate JobId=46325 NodeList=cpu13 #CPUs=8 Partition=cpu-epyc
[2022-07-14T16:49:49.250] sched: Allocate JobId=46333 NodeList=cpu13 #CPUs=16 Partition=cpu-epyc
[2022-07-14T16:49:55.202] sched: Allocate JobId=46334 NodeList=cpu13 #CPUs=16 Partition=cpu-epyc
[2022-07-14T17:04:03.279] sched: Allocate JobId=46335 NodeList=cpu11 #CPUs=8 Partition=cpu-opteron
[2022-07-14T17:04:26.933] sched: Allocate JobId=46337 NodeList=cpu13 #CPUs=24 Partition=cpu-epyc
[2022-07-14T17:31:02.226] sched: Allocate JobId=46339 NodeList=cpu11 #CPUs=16 Partition=cpu-opteron
[2022-07-14T17:38:54.116] sched: Allocate JobId=46340 NodeList=cpu11 #CPUs=16 Partition=cpu-opteron
[2022-07-14T17:40:50.279] sched: Allocate JobId=46341 NodeList=cpu11 #CPUs=16 Partition=cpu-opteron
[2022-07-14T17:41:59.378] sched: Allocate JobId=46342 NodeList=cpu11 #CPUs=16 Partition=cpu-opteron
[2022-07-14T17:45:27.783] sched: Allocate JobId=46343 NodeList=cpu11 #CPUs=16 Partition=cpu-opteron
[2022-07-14T18:05:08.335] sched/backfill: _start_job: Started JobId=46344 in cpu-opteron on cpu11
[2022-07-14T18:05:43.882] sched: Allocate JobId=46345 NodeList=cpu11 #CPUs=16 Partition=cpu-opteron
[2022-07-14T18:17:03.039] sched: Allocate JobId=46346 NodeList=cpu11 #CPUs=16 Partition=cpu-opteron
[2022-07-14T19:49:35.103] sched: Allocate JobId=46311 NodeList=cpu12 #CPUs=16 Partition=cpu-epyc
[2022-07-14T21:55:28.814] sched: Allocate JobId=46347 NodeList=gpu04 #CPUs=16 Partition=gpu-k40c
[2022-07-14T22:00:50.664] sched: Allocate JobId=46338 NodeList=cpu09 #CPUs=64 Partition=cpu-opteron
[2022-07-14T23:09:17.099] sched: _slurm_rpc_allocate_resources JobId=46348 NodeList=cpu11 usec=15483
[2022-07-14T23:20:11.770] sched: Allocate JobId=46349 NodeList=cpu13 #CPUs=2 Partition=cpu-epyc
[2022-07-14T23:25:38.343] sched: Allocate JobId=46350 NodeList=cpu13 #CPUs=2 Partition=cpu-epyc
[2022-07-14T23:29:19.747] sched: Allocate JobId=46351 NodeList=gpu05 #CPUs=16 Partition=gpu-v100s
[2022-07-14T23:30:27.846] sched: Allocate JobId=46352 NodeList=gpu05 #CPUs=16 Partition=gpu-v100s
[2022-07-14T23:35:27.357] sched: Allocate JobId=46353 NodeList=gpu03 #CPUs=16 Partition=gpu-k10
[2022-07-14T23:41:41.002] sched: Allocate JobId=46354 NodeList=gpu03 #CPUs=16 Partition=gpu-k10
[2022-07-14T23:43:57.235] sched: Allocate JobId=46355 NodeList=gpu01 #CPUs=16 Partition=gpu-k10
[2022-07-14T23:46:08.413] sched: Allocate JobId=46356 NodeList=gpu02 #CPUs=8 Partition=gpu-titan
[2022-07-15T00:10:19.409] sched: Allocate JobId=46312 NodeList=cpu14 #CPUs=16 Partition=cpu-epyc
[2022-07-15T00:15:30.712] sched: Allocate JobId=46332 NodeList=cpu13 #CPUs=16 Partition=cpu-epyc
[2022-07-15T00:21:48.587] sched: Allocate JobId=46359 NodeList=cpu11 #CPUs=4 Partition=cpu-opteron
[2022-07-15T02:11:11.393] sched: Allocate JobId=46360 NodeList=cpu13 #CPUs=16 Partition=cpu-epyc
[2022-07-15T02:15:41.893] sched: Allocate JobId=46361 NodeList=cpu13 #CPUs=16 Partition=cpu-epyc
[2022-07-15T02:20:06.433] sched: Allocate JobId=46362 NodeList=cpu15 #CPUs=32 Partition=cpu-epyc
[2022-07-15T04:46:53.057] sched: Allocate JobId=46363 NodeList=cpu11 #CPUs=8 Partition=cpu-opteron
[2022-07-15T05:04:09.987] sched: Allocate JobId=46364 NodeList=cpu11 #CPUs=8 Partition=cpu-opteron
[2022-07-15T05:28:51.445] sched: Allocate JobId=46365 NodeList=cpu07 #CPUs=16 Partition=cpu-opteron
[2022-07-15T05:30:32.582] sched: Allocate JobId=46366 NodeList=cpu07 #CPUs=16 Partition=cpu-opteron
[2022-07-15T05:34:10.740] sched: Allocate JobId=46367 NodeList=cpu07 #CPUs=16 Partition=cpu-opteron
[2022-07-15T05:38:44.650] sched: Allocate JobId=46368 NodeList=cpu07 #CPUs=16 Partition=cpu-opteron
[2022-07-15T06:29:38.676] sched: Allocate JobId=46369 NodeList=gpu04 #CPUs=16 Partition=gpu-k40c
[2022-07-15T07:05:17.001] sched: Allocate JobId=46357 NodeList=gpu05 #CPUs=16 Partition=gpu-v100s
[2022-07-15T07:57:29.856] sched: Allocate JobId=46370 NodeList=cpu03 #CPUs=64 Partition=cpu-opteron
[2022-07-15T08:43:03.909] sched: Allocate JobId=46371 NodeList=cpu15 #CPUs=36 Partition=cpu-epyc
[2022-07-15T09:03:13.069] sched: Allocate JobId=46372 NodeList=cpu12 #CPUs=32 Partition=cpu-epyc
[2022-07-15T13:15:55.420] sched: Allocate JobId=46375 NodeList=cpu12 #CPUs=16 Partition=cpu-epyc
[2022-07-15T13:16:24.444] sched: Allocate JobId=46376 NodeList=cpu13 #CPUs=16 Partition=cpu-epyc
[2022-07-15T13:58:23.914] sched: Allocate JobId=46377 NodeList=cpu07 #CPUs=64 Partition=cpu-opteron
[2022-07-15T15:14:59.699] sched: Allocate JobId=46358 NodeList=gpu05 #CPUs=16 Partition=gpu-v100s
[2022-07-15T16:56:51.280] sched: Allocate JobId=46378 NodeList=cpu12 #CPUs=16 Partition=cpu-epyc
[2022-07-15T16:56:56.272] sched: Allocate JobId=46379 NodeList=cpu14 #CPUs=16 Partition=cpu-epyc
[2022-07-15T17:21:13.790] sched: Allocate JobId=46380 NodeList=cpu14 #CPUs=16 Partition=cpu-epyc
[2022-07-15T17:24:32.003] sched: Allocate JobId=46381 NodeList=cpu12 #CPUs=16 Partition=cpu-epyc
[2022-07-15T17:45:49.155] sched: Allocate JobId=46382 NodeList=cpu14 #CPUs=16 Partition=cpu-epyc
[2022-07-15T17:54:08.427] sched: Allocate JobId=46383 NodeList=cpu12 #CPUs=16 Partition=cpu-epyc
[2022-07-15T18:10:25.491] sched: Allocate JobId=46384 NodeList=cpu14 #CPUs=16 Partition=cpu-epyc
[2022-07-15T18:26:33.367] sched: Allocate JobId=46385 NodeList=cpu12 #CPUs=16 Partition=cpu-epyc
[2022-07-15T18:34:08.288] sched: Allocate JobId=46386 NodeList=cpu14 #CPUs=16 Partition=cpu-epyc
[2022-07-15T18:55:22.828] sched: Allocate JobId=46387 NodeList=cpu12 #CPUs=16 Partition=cpu-epyc
[2022-07-15T20:25:49.466] sched: Allocate JobId=46388 NodeList=cpu05 #CPUs=64 Partition=cpu-opteron
[2022-07-15T20:25:49.500] sched: Allocate JobId=46389 NodeList=cpu01 #CPUs=64 Partition=cpu-opteron
[2022-07-15T20:28:14.836] sched: Allocate JobId=46390 NodeList=cpu11 #CPUs=64 Partition=cpu-opteron
[2022-07-15T20:28:14.889] sched: Allocate JobId=46391 NodeList=cpu08 #CPUs=64 Partition=cpu-opteron
[2022-07-15T20:45:37.817] sched: Allocate JobId=46396 NodeList=cpu12 #CPUs=16 Partition=cpu-epyc
[2022-07-15T20:52:23.493] sched: Allocate JobId=46397 NodeList=cpu12 #CPUs=16 Partition=cpu-epyc
[2022-07-15T20:53:29.859] sched: Allocate JobId=46398 NodeList=cpu14 #CPUs=16 Partition=cpu-epyc
[2022-07-15T21:50:08.903] sched: Allocate JobId=46373 NodeList=cpu13 #CPUs=32 Partition=cpu-epyc
[2022-07-15T22:59:50.505] sched: Allocate JobId=46374 NodeList=gpu04 #CPUs=16 Partition=gpu-k40c
[2022-07-16T03:03:15.718] sched: Allocate JobId=46392 NodeList=cpu10 #CPUs=8 Partition=cpu-opteron
[2022-07-16T03:03:15.719] sched: Allocate JobId=46393 NodeList=cpu10 #CPUs=16 Partition=cpu-opteron
[2022-07-16T03:03:15.720] sched: Allocate JobId=46394 NodeList=cpu10 #CPUs=16 Partition=cpu-opteron
[2022-07-16T03:03:15.721] sched: Allocate JobId=46395 NodeList=cpu10 #CPUs=16 Partition=cpu-opteron
[2022-07-16T03:25:05.029] sched: Allocate JobId=46399 NodeList=cpu13 #CPUs=32 Partition=cpu-epyc
[2022-07-16T03:32:13.698] sched: Allocate JobId=46400 NodeList=cpu13 #CPUs=32 Partition=cpu-epyc
[2022-07-16T05:15:07.334] sched: Allocate JobId=46401 NodeList=cpu13 #CPUs=32 Partition=cpu-epyc
[2022-07-16T08:54:04.889] sched: Allocate JobId=46402 NodeList=cpu14 #CPUs=48 Partition=cpu-epyc
[2022-07-16T09:18:55.777] sched: Allocate JobId=46403 NodeList=cpu12 #CPUs=16 Partition=cpu-epyc
[2022-07-16T16:48:26.498] sched: Allocate JobId=46404 NodeList=cpu07 #CPUs=64 Partition=cpu-opteron
[2022-07-16T16:49:00.545] sched: Allocate JobId=46405 NodeList=cpu15 #CPUs=8 Partition=cpu-epyc
[2022-07-16T16:53:00.993] sched: Allocate JobId=46406 NodeList=cpu07 #CPUs=32 Partition=cpu-opteron
[2022-07-16T16:55:30.198] sched: Allocate JobId=46407 NodeList=cpu07 #CPUs=32 Partition=cpu-opteron
[2022-07-16T16:56:58.322] sched: Allocate JobId=46408 NodeList=cpu07 #CPUs=32 Partition=cpu-opteron
[2022-07-16T16:58:39.583] sched: Allocate JobId=46409 NodeList=cpu07 #CPUs=32 Partition=cpu-opteron
[2022-07-16T16:59:10.632] sched: Allocate JobId=46410 NodeList=cpu07 #CPUs=32 Partition=cpu-opteron
[2022-07-16T16:59:40.670] sched: Allocate JobId=46411 NodeList=cpu07 #CPUs=32 Partition=cpu-opteron
[2022-07-16T17:01:21.810] sched: Allocate JobId=46412 NodeList=cpu07 #CPUs=32 Partition=cpu-opteron
[2022-07-16T17:03:35.087] sched: Allocate JobId=46413 NodeList=cpu07 #CPUs=32 Partition=cpu-opteron
[2022-07-16T17:06:40.339] sched: Allocate JobId=46414 NodeList=cpu07 #CPUs=64 Partition=cpu-opteron
[2022-07-16T18:03:57.326] sched: Allocate JobId=46415 NodeList=cpu09 #CPUs=32 Partition=cpu-opteron
[2022-07-16T18:07:28.648] sched: Allocate JobId=46416 NodeList=cpu09 #CPUs=32 Partition=cpu-opteron
[2022-07-16T18:10:06.900] sched: Allocate JobId=46417 NodeList=cpu09 #CPUs=32 Partition=cpu-opteron
[2022-07-16T18:12:58.223] sched: Allocate JobId=46418 NodeList=cpu09 #CPUs=32 Partition=cpu-opteron
[2022-07-16T18:25:54.648] sched: Allocate JobId=46419 NodeList=cpu09 #CPUs=32 Partition=cpu-opteron
[2022-07-16T18:28:12.976] sched: Allocate JobId=46420 NodeList=cpu09 #CPUs=32 Partition=cpu-opteron
[2022-07-16T18:30:25.166] sched: Allocate JobId=46421 NodeList=cpu09 #CPUs=32 Partition=cpu-opteron
[2022-07-16T18:33:23.499] sched: Allocate JobId=46422 NodeList=cpu09 #CPUs=32 Partition=cpu-opteron
[2022-07-16T18:36:14.742] sched: Allocate JobId=46423 NodeList=cpu09 #CPUs=32 Partition=cpu-opteron
[2022-07-16T18:39:52.184] sched: Allocate JobId=46424 NodeList=cpu09 #CPUs=32 Partition=cpu-opteron
[2022-07-16T18:57:41.130] sched: Allocate JobId=46425 NodeList=cpu09 #CPUs=32 Partition=cpu-opteron
[2022-07-17T03:51:53.675] sched: Allocate JobId=46426 NodeList=gpu01 #CPUs=16 Partition=gpu-k10
[2022-07-17T03:57:58.360] sched: Allocate JobId=46427 NodeList=cpu09 #CPUs=32 Partition=cpu-opteron
[2022-07-17T04:02:04.697] sched: Allocate JobId=46428 NodeList=cpu09 #CPUs=32 Partition=cpu-opteron
[2022-07-17T04:05:35.070] sched: Allocate JobId=46429 NodeList=cpu09 #CPUs=32 Partition=cpu-opteron
[2022-07-17T04:10:22.522] sched: Allocate JobId=46430 NodeList=cpu09 #CPUs=32 Partition=cpu-opteron
[2022-07-17T04:13:34.905] sched: Allocate JobId=46431 NodeList=cpu09 #CPUs=32 Partition=cpu-opteron
[2022-07-17T10:39:52.531] sched: Allocate JobId=46432 NodeList=cpu09 #CPUs=32 Partition=cpu-opteron
[2022-07-17T11:00:05.538] sched: Allocate JobId=46433 NodeList=cpu09 #CPUs=32 Partition=cpu-opteron
[2022-07-17T11:14:28.116] sched: Allocate JobId=46434 NodeList=cpu09 #CPUs=32 Partition=cpu-opteron
[2022-07-17T11:32:56.114] sched: Allocate JobId=46435 NodeList=cpu09 #CPUs=32 Partition=cpu-opteron
[2022-07-17T11:46:11.435] sched: Allocate JobId=46436 NodeList=cpu09 #CPUs=32 Partition=cpu-opteron
[2022-07-17T12:02:09.177] sched: Allocate JobId=46437 NodeList=cpu10 #CPUs=32 Partition=cpu-opteron
[2022-07-17T12:19:59.201] sched: Allocate JobId=46438 NodeList=cpu10 #CPUs=32 Partition=cpu-opteron
[2022-07-17T12:37:20.069] sched: Allocate JobId=46439 NodeList=cpu10 #CPUs=32 Partition=cpu-opteron
[2022-07-17T12:53:00.864] sched: Allocate JobId=46440 NodeList=cpu10 #CPUs=32 Partition=cpu-opteron
[2022-07-17T14:41:46.376] sched: Allocate JobId=46441 NodeList=cpu09 #CPUs=32 Partition=cpu-opteron
[2022-07-17T15:07:54.146] sched: Allocate JobId=46442 NodeList=cpu09 #CPUs=32 Partition=cpu-opteron
[2022-07-17T15:41:35.745] sched: Allocate JobId=46443 NodeList=cpu09 #CPUs=32 Partition=cpu-opteron
[2022-07-17T15:46:04.230] sched: Allocate JobId=46444 NodeList=cpu09 #CPUs=32 Partition=cpu-opteron
[2022-07-17T16:04:35.318] sched: Allocate JobId=46445 NodeList=cpu09 #CPUs=32 Partition=cpu-opteron
[2022-07-17T16:17:40.663] sched: Allocate JobId=46446 NodeList=cpu09 #CPUs=32 Partition=cpu-opteron
[2022-07-17T16:58:23.910] sched: Allocate JobId=46447 NodeList=cpu09 #CPUs=32 Partition=cpu-opteron
[2022-07-17T18:34:01.978] sched: Allocate JobId=46448 NodeList=cpu09 #CPUs=32 Partition=cpu-opteron
[2022-07-17T18:51:33.761] sched: Allocate JobId=46449 NodeList=cpu09 #CPUs=32 Partition=cpu-opteron
[2022-07-17T22:44:46.121] sched: Allocate JobId=46450 NodeList=cpu09 #CPUs=64 Partition=cpu-opteron
[2022-07-17T23:27:59.788] sched: Allocate JobId=46451 NodeList=cpu10 #CPUs=32 Partition=cpu-opteron
[2022-07-17T23:46:55.703] sched: Allocate JobId=46452 NodeList=cpu10 #CPUs=32 Partition=cpu-opteron
[2022-07-18T00:12:05.505] sched: Allocate JobId=46453 NodeList=cpu10 #CPUs=32 Partition=cpu-opteron
[2022-07-18T00:32:24.746] sched: Allocate JobId=46454 NodeList=cpu10 #CPUs=32 Partition=cpu-opteron
[2022-07-18T00:51:08.789] sched: Allocate JobId=46455 NodeList=cpu10 #CPUs=32 Partition=cpu-opteron
[2022-07-18T01:40:02.590] sched: Allocate JobId=46456 NodeList=cpu10 #CPUs=32 Partition=cpu-opteron
[2022-07-18T03:55:58.250] sched: Allocate JobId=46457 NodeList=gpu05 #CPUs=32 Partition=gpu-v100s
[2022-07-18T03:57:19.345] sched: Allocate JobId=46458 NodeList=gpu05 #CPUs=32 Partition=gpu-v100s
[2022-07-18T08:06:46.013] sched: Allocate JobId=46459 NodeList=cpu03 #CPUs=32 Partition=cpu-opteron
[2022-07-18T08:15:46.930] sched: Allocate JobId=46460 NodeList=cpu13 #CPUs=48 Partition=cpu-epyc
[2022-07-18T08:18:55.367] sched: Allocate JobId=46461 NodeList=cpu03 #CPUs=32 Partition=cpu-opteron
[2022-07-18T08:30:20.556] sched: Allocate JobId=46462 NodeList=cpu03 #CPUs=32 Partition=cpu-opteron
[2022-07-18T08:39:25.528] sched: Allocate JobId=46463 NodeList=cpu03 #CPUs=32 Partition=cpu-opteron
[2022-07-18T08:39:59.576] sched: Allocate JobId=46464 NodeList=cpu03 #CPUs=32 Partition=cpu-opteron
[2022-07-18T08:46:59.391] sched: Allocate JobId=46465 NodeList=cpu03 #CPUs=32 Partition=cpu-opteron
[2022-07-18T08:55:52.323] sched: Allocate JobId=46466 NodeList=cpu03 #CPUs=32 Partition=cpu-opteron
[2022-07-18T09:16:31.744] sched: Allocate JobId=46467 NodeList=cpu10 #CPUs=32 Partition=cpu-opteron
[2022-07-18T09:30:26.328] sched: Allocate JobId=46468 NodeList=cpu10 #CPUs=32 Partition=cpu-opteron
[2022-07-18T09:39:56.518] sched: Allocate JobId=46469 NodeList=cpu03 #CPUs=32 Partition=cpu-opteron
[2022-07-18T09:50:21.679] sched: Allocate JobId=46470 NodeList=cpu03 #CPUs=32 Partition=cpu-opteron
[2022-07-18T09:54:03.265] sched: Allocate JobId=46471 NodeList=cpu15 #CPUs=8 Partition=cpu-epyc
[2022-07-18T09:55:58.408] sched: Allocate JobId=46472 NodeList=cpu15 #CPUs=8 Partition=cpu-epyc
[2022-07-18T09:56:22.443] sched: Allocate JobId=46473 NodeList=cpu12 #CPUs=8 Partition=cpu-epyc
[2022-07-18T09:57:06.505] sched: Allocate JobId=46474 NodeList=cpu12 #CPUs=8 Partition=cpu-epyc
[2022-07-18T09:58:09.623] sched/backfill: _start_job: Started JobId=46475 in cpu-epyc on cpu12
[2022-07-18T09:58:35.865] sched: Allocate JobId=46476 NodeList=cpu03 #CPUs=32 Partition=cpu-opteron
[2022-07-18T10:00:01.986] sched: Allocate JobId=46477 NodeList=cpu10 #CPUs=12 Partition=cpu-opteron
[2022-07-18T10:01:30.108] sched: Allocate JobId=46478 NodeList=cpu10 #CPUs=12 Partition=cpu-opteron
[2022-07-18T10:07:50.908] sched: Allocate JobId=46479 NodeList=cpu12 #CPUs=8 Partition=cpu-epyc
[2022-07-18T10:09:04.008] sched: Allocate JobId=46480 NodeList=cpu12 #CPUs=8 Partition=cpu-epyc
[2022-07-18T10:17:30.968] sched: Allocate JobId=46481 NodeList=cpu12 #CPUs=8 Partition=cpu-epyc
[2022-07-18T10:23:35.615] sched: Allocate JobId=46482 NodeList=cpu12 #CPUs=8 Partition=cpu-epyc
[2022-07-18T10:25:31.778] sched: Allocate JobId=46483 NodeList=cpu12 #CPUs=8 Partition=cpu-epyc
[2022-07-18T10:26:26.853] sched: Allocate JobId=46484 NodeList=cpu12 #CPUs=8 Partition=cpu-epyc
[2022-07-18T10:26:53.890] sched: Allocate JobId=46485 NodeList=cpu12 #CPUs=8 Partition=cpu-epyc
[2022-07-18T10:35:49.827] sched: Allocate JobId=46487 NodeList=cpu15 #CPUs=4 Partition=cpu-epyc
[2022-07-18T11:07:24.286] sched: Allocate JobId=46490 NodeList=cpu03 #CPUs=32 Partition=cpu-opteron
[2022-07-18T11:08:29.473] sched: Allocate JobId=46491 NodeList=cpu03 #CPUs=16 Partition=cpu-opteron
[2022-07-18T11:11:54.758] sched: Allocate JobId=46492 NodeList=cpu03 #CPUs=16 Partition=cpu-opteron
[2022-07-18T11:41:09.720] sched: Allocate JobId=46493 NodeList=gpu01 #CPUs=16 Partition=gpu-k10
[2022-07-18T13:54:55.116] sched: Allocate JobId=46494 NodeList=cpu12 #CPUs=16 Partition=cpu-epyc
[2022-07-18T14:21:08.816] sched: Allocate JobId=46495 NodeList=cpu15 #CPUs=12 Partition=cpu-epyc
[2022-07-18T14:38:31.953] sched: Allocate JobId=46496 NodeList=cpu10 #CPUs=32 Partition=cpu-opteron
[2022-07-18T15:30:39.421] sched: Allocate JobId=46497 NodeList=cpu03 #CPUs=16 Partition=cpu-opteron
[2022-07-18T15:50:14.511] sched: Allocate JobId=46498 NodeList=cpu10 #CPUs=32 Partition=cpu-opteron
[2022-07-18T15:52:35.791] sched: Allocate JobId=46499 NodeList=cpu04 #CPUs=16 Partition=cpu-opteron
[2022-07-18T17:46:59.828] sched: Allocate JobId=46506 NodeList=cpu04 #CPUs=16 Partition=cpu-opteron
[2022-07-18T20:09:54.557] sched: Allocate JobId=46512 NodeList=cpu04 #CPUs=16 Partition=cpu-opteron
[2022-07-18T20:10:25.586] sched: Allocate JobId=46513 NodeList=cpu04 #CPUs=16 Partition=cpu-opteron
[2022-07-18T20:12:04.724] sched: Allocate JobId=46514 NodeList=cpu04 #CPUs=16 Partition=cpu-opteron
[2022-07-18T20:36:48.453] sched: Allocate JobId=46515 NodeList=cpu04 #CPUs=16 Partition=cpu-opteron
[2022-07-18T21:22:45.236] sched: Allocate JobId=46516 NodeList=cpu04 #CPUs=16 Partition=cpu-opteron
[2022-07-18T21:28:14.811] sched: Allocate JobId=46517 NodeList=cpu04 #CPUs=16 Partition=cpu-opteron
[2022-07-18T21:33:41.385] sched: Allocate JobId=46518 NodeList=cpu04 #CPUs=16 Partition=cpu-opteron
[2022-07-18T21:58:53.539] sched: Allocate JobId=46519 NodeList=cpu04 #CPUs=16 Partition=cpu-opteron
[2022-07-18T22:04:06.576] sched: Allocate JobId=46520 NodeList=cpu04 #CPUs=16 Partition=cpu-opteron
[2022-07-18T22:05:26.686] sched: Allocate JobId=46521 NodeList=cpu04 #CPUs=16 Partition=cpu-opteron
[2022-07-19T01:05:00.941] sched: Allocate JobId=46522 NodeList=cpu04 #CPUs=16 Partition=cpu-opteron
[2022-07-19T01:29:45.239] sched: Allocate JobId=46523 NodeList=cpu04 #CPUs=16 Partition=cpu-opteron
[2022-07-19T08:34:45.297] sched: Allocate JobId=46524 NodeList=cpu04 #CPUs=16 Partition=cpu-opteron
[2022-07-19T08:43:06.259] sched: Allocate JobId=46525 NodeList=cpu04 #CPUs=16 Partition=cpu-opteron
[2022-07-19T09:24:37.576] sched: Allocate JobId=46526 NodeList=cpu04 #CPUs=8 Partition=cpu-opteron
[2022-07-19T09:51:27.546] sched: Allocate JobId=46527 NodeList=cpu04 #CPUs=8 Partition=cpu-opteron
[2022-07-19T10:06:55.358] sched: Allocate JobId=46528 NodeList=cpu04 #CPUs=8 Partition=cpu-opteron
[2022-07-19T10:27:09.241] sched: Allocate JobId=46501 NodeList=cpu04 #CPUs=32 Partition=cpu-opteron
[2022-07-19T10:50:28.006] sched: _slurm_rpc_allocate_resources JobId=46530 NodeList=cpu04 usec=14922
[2022-07-19T12:48:07.898] sched: Allocate JobId=46531 NodeList=gpu01 #CPUs=16 Partition=gpu-k10
[2022-07-19T12:50:05.067] sched: Allocate JobId=46532 NodeList=cpu04 #CPUs=8 Partition=cpu-opteron
[2022-07-19T13:12:39.067] sched: _slurm_rpc_allocate_resources JobId=46533 NodeList=cpu04 usec=15050
[2022-07-19T13:17:36.246] sched: Allocate JobId=46534 NodeList=cpu04 #CPUs=32 Partition=cpu-opteron
[2022-07-19T13:19:58.486] sched: Allocate JobId=46535 NodeList=cpu04 #CPUs=16 Partition=cpu-opteron
[2022-07-19T13:26:02.633] sched: Allocate JobId=46536 NodeList=cpu04 #CPUs=32 Partition=cpu-opteron
[2022-07-19T13:26:30.672] sched: _slurm_rpc_allocate_resources JobId=46537 NodeList=cpu04 usec=4417
[2022-07-19T13:46:19.307] sched: Allocate JobId=46538 NodeList=cpu04 #CPUs=8 Partition=cpu-opteron
[2022-07-19T15:24:18.516] sched: Allocate JobId=46539 NodeList=cpu10 #CPUs=32 Partition=cpu-opteron
[2022-07-19T15:26:59.722] sched: Allocate JobId=46540 NodeList=cpu10 #CPUs=16 Partition=cpu-opteron
[2022-07-19T15:28:12.968] sched: Allocate JobId=46541 NodeList=cpu04 #CPUs=32 Partition=cpu-opteron
[2022-07-19T15:42:33.401] sched: Allocate JobId=46542 NodeList=cpu10 #CPUs=32 Partition=cpu-opteron
[2022-07-19T16:46:44.128] sched: Allocate JobId=46543 NodeList=cpu12 #CPUs=16 Partition=cpu-epyc
[2022-07-19T16:51:09.631] sched: Allocate JobId=46544 NodeList=cpu14 #CPUs=16 Partition=cpu-epyc
[2022-07-19T17:19:48.782] sched: Allocate JobId=46545 NodeList=cpu04 #CPUs=24 Partition=cpu-opteron
[2022-07-19T17:21:11.885] sched: Allocate JobId=46546 NodeList=cpu04 #CPUs=24 Partition=cpu-opteron
[2022-07-19T17:25:10.311] sched: Allocate JobId=46547 NodeList=cpu04 #CPUs=24 Partition=cpu-opteron
[2022-07-19T17:27:38.580] sched: Allocate JobId=46548 NodeList=cpu04 #CPUs=24 Partition=cpu-opteron
[2022-07-19T17:28:26.687] sched: Allocate JobId=46549 NodeList=cpu04 #CPUs=24 Partition=cpu-opteron
[2022-07-19T17:32:02.991] sched: Allocate JobId=46550 NodeList=cpu04 #CPUs=24 Partition=cpu-opteron
[2022-07-19T17:33:03.190] sched: Allocate JobId=46551 NodeList=cpu04 #CPUs=24 Partition=cpu-opteron
[2022-07-19T17:33:54.260] sched: Allocate JobId=46552 NodeList=cpu04 #CPUs=24 Partition=cpu-opteron
[2022-07-19T17:34:24.303] sched: Allocate JobId=46553 NodeList=cpu04 #CPUs=24 Partition=cpu-opteron
[2022-07-19T17:35:50.426] sched: Allocate JobId=46554 NodeList=cpu04 #CPUs=24 Partition=cpu-opteron
[2022-07-19T17:36:16.463] sched: Allocate JobId=46555 NodeList=cpu04 #CPUs=24 Partition=cpu-opteron
[2022-07-19T17:41:05.852] sched: Allocate JobId=46500 NodeList=gpu05 #CPUs=16 Partition=gpu-v100s
[2022-07-19T17:43:12.363] sched: Allocate JobId=46556 NodeList=cpu15 #CPUs=24 Partition=cpu-epyc
[2022-07-19T17:47:46.837] sched: Allocate JobId=46558 NodeList=cpu15 #CPUs=24 Partition=cpu-epyc
[2022-07-19T17:49:47.004] sched: Allocate JobId=46559 NodeList=cpu14 #CPUs=32 Partition=cpu-epyc
[2022-07-19T20:21:02.514] sched: Allocate JobId=46560 NodeList=gpu05 #CPUs=16 Partition=gpu-v100s
[2022-07-19T20:23:33.736] sched: Allocate JobId=46561 NodeList=gpu05 #CPUs=16 Partition=gpu-v100s
[2022-07-19T21:22:43.265] sched: Allocate JobId=46529 NodeList=gpu04 #CPUs=16 Partition=gpu-k40c
[2022-07-19T21:28:48.682] sched: Allocate JobId=46562 NodeList=gpu04 #CPUs=16 Partition=gpu-k40c
[2022-07-19T21:33:54.181] sched: Allocate JobId=46563 NodeList=gpu04 #CPUs=16 Partition=gpu-k40c
[2022-07-19T23:12:16.892] sched: Allocate JobId=46564 NodeList=cpu12 #CPUs=16 Partition=cpu-epyc
[2022-07-19T23:16:52.423] sched: Allocate JobId=46565 NodeList=cpu04 #CPUs=64 Partition=cpu-opteron
[2022-07-19T23:20:19.809] sched: Allocate JobId=46566 NodeList=cpu04 #CPUs=64 Partition=cpu-opteron
[2022-07-19T23:20:44.844] sched: Allocate JobId=46567 NodeList=cpu10 #CPUs=64 Partition=cpu-opteron
[2022-07-19T23:43:41.928] sched: Allocate JobId=46568 NodeList=gpu04 #CPUs=16 Partition=gpu-k40c
[2022-07-20T00:46:50.750] sched: Allocate JobId=46569 NodeList=cpu03 #CPUs=16 Partition=cpu-opteron
[2022-07-20T02:07:53.412] sched: Allocate JobId=46572 NodeList=gpu04 #CPUs=16 Partition=gpu-k40c
[2022-07-20T11:08:21.251] sched: Allocate JobId=46573 NodeList=cpu12 #CPUs=16 Partition=cpu-epyc
[2022-07-20T11:08:45.285] sched: Allocate JobId=46574 NodeList=gpu04 #CPUs=16 Partition=gpu-k40c
[2022-07-20T13:47:20.985] sched: Allocate JobId=46575 NodeList=cpu12 #CPUs=16 Partition=cpu-epyc
[2022-07-20T13:50:20.357] sched: Allocate JobId=46576 NodeList=cpu14 #CPUs=16 Partition=cpu-epyc
[2022-07-20T13:59:35.712] sched: Allocate JobId=46577 NodeList=cpu14 #CPUs=16 Partition=cpu-epyc
[2022-07-20T13:59:36.671] sched: Allocate JobId=46578 NodeList=cpu14 #CPUs=16 Partition=cpu-epyc
[2022-07-20T14:35:08.055] sched: Allocate JobId=46579 NodeList=cpu14 #CPUs=16 Partition=cpu-epyc
[2022-07-20T14:49:44.787] sched: Allocate JobId=46580 NodeList=cpu14 #CPUs=16 Partition=cpu-epyc
[2022-07-20T14:59:51.726] sched: Allocate JobId=46581 NodeList=gpu04 #CPUs=16 Partition=gpu-k40c
[2022-07-20T15:04:00.131] sched: Allocate JobId=46585 NodeList=gpu04 #CPUs=16 Partition=gpu-k40c
[2022-07-20T15:18:27.888] sched: Allocate JobId=46592 NodeList=cpu12 #CPUs=16 Partition=cpu-epyc
[2022-07-20T15:26:13.600] sched: Allocate JobId=46594 NodeList=cpu12 #CPUs=16 Partition=cpu-epyc
[2022-07-20T15:26:54.657] sched: Allocate JobId=46595 NodeList=cpu12 #CPUs=16 Partition=cpu-epyc
[2022-07-20T15:27:35.773] sched: Allocate JobId=46596 NodeList=cpu12 #CPUs=16 Partition=cpu-epyc
[2022-07-20T15:52:29.555] sched: Allocate JobId=46597 NodeList=cpu14 #CPUs=16 Partition=cpu-epyc
[2022-07-20T17:14:48.090] sched: Allocate JobId=46598 NodeList=cpu14 #CPUs=16 Partition=cpu-epyc
[2022-07-20T18:15:05.404] sched: Allocate JobId=46600 NodeList=cpu14 #CPUs=16 Partition=cpu-epyc
[2022-07-20T18:24:16.882] sched: Allocate JobId=46601 NodeList=cpu14 #CPUs=16 Partition=cpu-epyc
[2022-07-20T18:42:33.514] sched: Allocate JobId=46602 NodeList=gpu04 #CPUs=16 Partition=gpu-k40c
[2022-07-20T20:46:17.536] sched: Allocate JobId=46603 NodeList=gpu04 #CPUs=16 Partition=gpu-k40c
[2022-07-20T21:29:46.874] sched: Allocate JobId=46582 NodeList=cpu09 #CPUs=16 Partition=cpu-opteron
[2022-07-20T21:29:46.875] sched: Allocate JobId=46583 NodeList=cpu09 #CPUs=16 Partition=cpu-opteron
[2022-07-20T21:29:46.876] sched: Allocate JobId=46584 NodeList=cpu09 #CPUs=16 Partition=cpu-opteron
[2022-07-20T21:29:46.877] sched: Allocate JobId=46586 NodeList=cpu09 #CPUs=16 Partition=cpu-opteron
[2022-07-20T21:31:40.480] sched: Allocate JobId=46604 NodeList=cpu14 #CPUs=16 Partition=cpu-epyc
[2022-07-20T21:37:11.368] sched: Allocate JobId=46588 NodeList=cpu09 #CPUs=16 Partition=cpu-opteron
[2022-07-20T21:37:11.381] sched: Allocate JobId=46570 NodeList=cpu09 #CPUs=16 Partition=cpu-opteron
[2022-07-20T22:58:51.080] sched: Allocate JobId=46605 NodeList=gpu04 #CPUs=16 Partition=gpu-k40c
[2022-07-21T00:31:40.937] sched: Allocate JobId=46606 NodeList=cpu14 #CPUs=16 Partition=cpu-epyc
[2022-07-21T05:56:15.343] sched: Allocate JobId=46607 NodeList=gpu04 #CPUs=16 Partition=gpu-k40c
[2022-07-21T08:51:24.008] sched: _slurm_rpc_allocate_resources JobId=46609 NodeList=cpu03 usec=15563
[2022-07-21T09:24:06.769] sched: Allocate JobId=46610 NodeList=cpu14 #CPUs=16 Partition=cpu-epyc
[2022-07-21T09:27:56.356] sched: Allocate JobId=46611 NodeList=cpu14 #CPUs=16 Partition=cpu-epyc
[2022-07-21T09:49:40.651] sched: Allocate JobId=46612 NodeList=gpu02 #CPUs=2 Partition=gpu-titan
[2022-07-21T12:15:13.425] sched: Allocate JobId=46608 NodeList=gpu04 #CPUs=16 Partition=gpu-k40c
[2022-07-21T13:02:30.942] sched: Allocate JobId=46613 NodeList=gpu02 #CPUs=2 Partition=gpu-titan
[2022-07-21T13:25:48.505] sched: _slurm_rpc_allocate_resources JobId=46614 NodeList=cpu03 usec=14044
[2022-07-21T14:02:27.295] sched: Allocate JobId=46615 NodeList=gpu02 #CPUs=2 Partition=gpu-titan
[2022-07-21T15:16:49.482] sched: Allocate JobId=46616 NodeList=cpu14 #CPUs=16 Partition=cpu-epyc
[2022-07-21T15:23:24.961] sched: Allocate JobId=46617 NodeList=cpu09 #CPUs=64 Partition=cpu-opteron
[2022-07-21T16:12:56.498] sched: Allocate JobId=46619 NodeList=gpu05 #CPUs=16 Partition=gpu-v100s
[2022-07-21T16:22:53.545] sched: Allocate JobId=46620 NodeList=gpu05 #CPUs=16 Partition=gpu-v100s
[2022-07-21T18:24:34.692] sched: Allocate JobId=46624 NodeList=cpu14 #CPUs=16 Partition=cpu-epyc
[2022-07-21T18:35:33.851] sched: Allocate JobId=46625 NodeList=cpu03 #CPUs=16 Partition=cpu-opteron
[2022-07-21T18:38:24.228] sched: Allocate JobId=46626 NodeList=cpu03 #CPUs=16 Partition=cpu-opteron
[2022-07-21T18:59:15.518] sched: Allocate JobId=46627 NodeList=gpu04 #CPUs=16 Partition=gpu-k40c
[2022-07-21T20:31:50.312] sched: Allocate JobId=46628 NodeList=cpu14 #CPUs=16 Partition=cpu-epyc
[2022-07-22T02:03:56.877] sched: Allocate JobId=46629 NodeList=gpu02 #CPUs=16 Partition=gpu-titan
[2022-07-22T03:11:43.918] sched: Allocate JobId=46630 NodeList=gpu02 #CPUs=2 Partition=gpu-titan
[2022-07-22T08:46:44.805] sched: Allocate JobId=46631 NodeList=gpu02 #CPUs=16 Partition=gpu-titan
[2022-07-22T09:35:16.834] sched: Allocate JobId=46618 NodeList=cpu13 #CPUs=48 Partition=cpu-epyc
[2022-07-22T09:46:33.076] sched: Allocate JobId=46632 NodeList=cpu12 #CPUs=16 Partition=cpu-epyc
[2022-07-22T09:56:00.105] sched: Allocate JobId=46633 NodeList=cpu03 #CPUs=16 Partition=cpu-opteron
[2022-07-22T12:53:11.090] sched: Allocate JobId=46635 NodeList=gpu01 #CPUs=4 Partition=gpu-k10
[2022-07-22T20:32:13.865] sched: Allocate JobId=46642 NodeList=cpu14 #CPUs=16 Partition=cpu-epyc
[2022-07-22T20:59:45.450] sched: Allocate JobId=46643 NodeList=cpu14 #CPUs=16 Partition=cpu-epyc
[2022-07-22T21:34:37.946] sched: Allocate JobId=46644 NodeList=cpu14 #CPUs=16 Partition=cpu-epyc
[2022-07-22T22:01:34.501] sched: Allocate JobId=46634 NodeList=gpu02 #CPUs=2 Partition=gpu-titan
[2022-07-22T22:07:44.425] sched: Allocate JobId=46671 NodeList=gpu02 #CPUs=14 Partition=gpu-titan
[2022-07-22T22:10:31.224] sched: Allocate JobId=46645 NodeList=cpu14 #CPUs=16 Partition=cpu-epyc
[2022-07-22T22:13:50.400] sched: Allocate JobId=46672 NodeList=gpu02 #CPUs=14 Partition=gpu-titan
[2022-07-22T22:13:56.985] sched: Allocate JobId=46673 NodeList=gpu02 #CPUs=14 Partition=gpu-titan
[2022-07-22T22:37:06.442] sched: Allocate JobId=46646 NodeList=cpu14 #CPUs=16 Partition=cpu-epyc
[2022-07-22T23:01:54.852] sched: Allocate JobId=46647 NodeList=cpu14 #CPUs=16 Partition=cpu-epyc
[2022-07-22T23:29:44.290] sched: Allocate JobId=46648 NodeList=cpu14 #CPUs=16 Partition=cpu-epyc
[2022-07-22T23:55:14.282] sched: Allocate JobId=46649 NodeList=cpu14 #CPUs=16 Partition=cpu-epyc
[2022-07-23T00:21:25.787] sched: Allocate JobId=46650 NodeList=cpu14 #CPUs=16 Partition=cpu-epyc
[2022-07-23T00:58:14.765] sched: Allocate JobId=46651 NodeList=cpu14 #CPUs=16 Partition=cpu-epyc
[2022-07-23T01:27:01.504] sched: Allocate JobId=46676 NodeList=gpu02 #CPUs=14 Partition=gpu-titan
[2022-07-23T01:38:38.104] sched: Allocate JobId=46652 NodeList=cpu14 #CPUs=16 Partition=cpu-epyc
[2022-07-23T01:48:30.844] sched: Allocate JobId=46679 NodeList=gpu01 #CPUs=16 Partition=gpu-k10
[2022-07-23T02:16:48.160] sched: Allocate JobId=46653 NodeList=cpu14 #CPUs=16 Partition=cpu-epyc
[2022-07-23T02:52:01.428] sched: Allocate JobId=46654 NodeList=cpu14 #CPUs=16 Partition=cpu-epyc
[2022-07-23T03:18:34.761] sched: Allocate JobId=46655 NodeList=cpu14 #CPUs=16 Partition=cpu-epyc
[2022-07-23T03:46:28.270] sched: Allocate JobId=46656 NodeList=cpu14 #CPUs=16 Partition=cpu-epyc
[2022-07-23T04:11:37.606] sched: Allocate JobId=46657 NodeList=cpu14 #CPUs=16 Partition=cpu-epyc
[2022-07-23T04:43:18.835] sched: Allocate JobId=46658 NodeList=cpu14 #CPUs=16 Partition=cpu-epyc
[2022-07-23T05:10:09.554] sched: Allocate JobId=46659 NodeList=cpu14 #CPUs=16 Partition=cpu-epyc
[2022-07-23T05:37:08.426] sched: Allocate JobId=46660 NodeList=cpu14 #CPUs=16 Partition=cpu-epyc
[2022-07-23T05:47:37.839] sched: Allocate JobId=46677 NodeList=gpu02 #CPUs=14 Partition=gpu-titan
[2022-07-23T06:04:37.841] sched: Allocate JobId=46661 NodeList=cpu14 #CPUs=16 Partition=cpu-epyc
[2022-07-23T06:31:28.145] sched: Allocate JobId=46662 NodeList=cpu14 #CPUs=16 Partition=cpu-epyc
[2022-07-23T07:05:12.511] sched: Allocate JobId=46663 NodeList=cpu14 #CPUs=16 Partition=cpu-epyc
[2022-07-23T07:30:32.984] sched: Allocate JobId=46664 NodeList=cpu14 #CPUs=16 Partition=cpu-epyc
[2022-07-23T07:31:35.505] sched: Allocate JobId=46621 NodeList=gpu05 #CPUs=16 Partition=gpu-v100s
[2022-07-23T08:11:49.340] sched: Allocate JobId=46678 NodeList=gpu02 #CPUs=14 Partition=gpu-titan
[2022-07-23T08:19:08.102] sched: Allocate JobId=46665 NodeList=cpu14 #CPUs=16 Partition=cpu-epyc
[2022-07-23T08:51:51.840] sched: Allocate JobId=46666 NodeList=cpu14 #CPUs=16 Partition=cpu-epyc
[2022-07-23T12:47:27.075] sched: Allocate JobId=46680 NodeList=gpu02 #CPUs=2 Partition=gpu-titan
[2022-07-23T20:20:40.695] sched: Allocate JobId=46675 NodeList=cpu03 #CPUs=16 Partition=cpu-opteron
[2022-07-23T21:48:29.738] sched: Allocate JobId=46667 NodeList=cpu14 #CPUs=16 Partition=cpu-epyc
[2022-07-24T00:50:05.376] sched: Allocate JobId=46681 NodeList=gpu04 #CPUs=16 Partition=gpu-k40c
[2022-07-24T00:55:08.860] sched: Allocate JobId=46682 NodeList=gpu04 #CPUs=16 Partition=gpu-k40c
[2022-07-24T01:35:28.365] sched: Allocate JobId=46668 NodeList=cpu13 #CPUs=16 Partition=cpu-epyc
[2022-07-24T01:35:28.366] sched: Allocate JobId=46669 NodeList=cpu13 #CPUs=16 Partition=cpu-epyc
[2022-07-24T01:35:28.380] sched: Allocate JobId=46674 NodeList=cpu13 #CPUs=16 Partition=cpu-epyc
[2022-07-24T01:41:22.647] sched: Allocate JobId=46683 NodeList=gpu02 #CPUs=8 Partition=gpu-titan
[2022-07-24T02:36:47.962] sched: Allocate JobId=46684 NodeList=gpu02 #CPUs=8 Partition=gpu-titan
[2022-07-24T07:18:43.359] sched: Allocate JobId=46685 NodeList=gpu02 #CPUs=8 Partition=gpu-titan
[2022-07-24T07:46:04.363] sched: Allocate JobId=46686 NodeList=gpu04 #CPUs=16 Partition=gpu-k40c
[2022-07-24T09:23:52.657] sched: Allocate JobId=46687 NodeList=gpu02 #CPUs=2 Partition=gpu-titan
[2022-07-24T10:34:51.623] sched: Allocate JobId=46688 NodeList=gpu04 #CPUs=16 Partition=gpu-k40c
[2022-07-24T10:49:55.269] sched: Allocate JobId=46670 NodeList=cpu14 #CPUs=16 Partition=cpu-epyc
[2022-07-24T11:04:29.794] sched: Allocate JobId=46689 NodeList=gpu02 #CPUs=2 Partition=gpu-titan
[2022-07-24T14:54:55.949] sched: Allocate JobId=46622 NodeList=gpu05 #CPUs=16 Partition=gpu-v100s
[2022-07-24T15:53:48.761] sched: Allocate JobId=46641 NodeList=cpu13 #CPUs=16 Partition=cpu-epyc
[2022-07-24T15:55:11.991] sched: Allocate JobId=46690 NodeList=gpu02 #CPUs=8 Partition=gpu-titan
[2022-07-24T17:09:36.883] sched: Allocate JobId=46691 NodeList=gpu04 #CPUs=16 Partition=gpu-k40c
[2022-07-25T08:47:47.622] sched: Allocate JobId=46692 NodeList=cpu13 #CPUs=48 Partition=cpu-epyc
[2022-07-25T08:58:50.095] sched: Allocate JobId=46623 NodeList=gpu05 #CPUs=16 Partition=gpu-v100s
[2022-07-25T13:19:42.245] sched: _slurm_rpc_allocate_resources JobId=46694 NodeList=(null) usec=907
[2022-07-25T14:15:14.699] sched: _slurm_rpc_allocate_resources JobId=46695 NodeList=(null) usec=983
[2022-07-25T14:20:06.259] sched: _slurm_rpc_allocate_resources JobId=46697 NodeList=(null) usec=893
[2022-07-25T14:57:26.203] sched: _slurm_rpc_allocate_resources JobId=46699 NodeList=(null) usec=863
[2022-07-25T17:50:22.087] sched: Allocate JobId=46705 NodeList=cpu14 #CPUs=16 Partition=cpu-epyc
[2022-07-25T20:07:41.774] sched: Allocate JobId=46710 NodeList=gpu02 #CPUs=8 Partition=gpu-titan
[2022-07-25T20:40:15.345] sched: Allocate JobId=46711 NodeList=gpu01 #CPUs=16 Partition=gpu-k10
[2022-07-25T20:41:20.422] sched: Allocate JobId=46712 NodeList=gpu01 #CPUs=16 Partition=gpu-k10
[2022-07-25T20:42:40.672] sched: Allocate JobId=46713 NodeList=gpu01 #CPUs=16 Partition=gpu-k10
[2022-07-25T20:58:15.501] sched/backfill: _start_job: Started JobId=46709 in cpu-epyc on cpu14
[2022-07-25T21:13:17.782] sched: Allocate JobId=46714 NodeList=gpu01 #CPUs=16 Partition=gpu-k10
[2022-07-25T21:39:58.627] sched: Allocate JobId=46715 NodeList=gpu01 #CPUs=16 Partition=gpu-k10
[2022-07-26T09:05:10.390] sched: Allocate JobId=46706 NodeList=cpu14 #CPUs=24 Partition=cpu-epyc
[2022-07-26T09:05:10.390] sched: Allocate JobId=46708 NodeList=cpu14 #CPUs=24 Partition=cpu-epyc
[2022-07-26T11:01:18.102] sched/backfill: _start_job: Started JobId=46700 in cpu-opteron on cpu03
[2022-07-26T11:16:18.146] sched/backfill: _start_job: Started JobId=46701 in cpu-opteron on cpu03
[2022-07-26T11:17:18.166] sched/backfill: _start_job: Started JobId=46721 in cpu-opteron on cpu03
[2022-07-26T11:19:39.939] sched: Allocate JobId=46718 NodeList=cpu14 #CPUs=32 Partition=cpu-epyc
[2022-07-26T11:20:56.979] sched: Allocate JobId=46720 NodeList=cpu14 #CPUs=24 Partition=cpu-epyc
[2022-07-26T11:20:56.980] sched: Allocate JobId=46696 NodeList=cpu14 #CPUs=24 Partition=cpu-epyc
[2022-07-26T11:54:44.601] sched: Allocate JobId=46722 NodeList=cpu14 #CPUs=16 Partition=cpu-epyc
[2022-07-26T13:51:48.253] sched: Allocate JobId=46725 NodeList=gpu04 #CPUs=16 Partition=gpu-k40c
[2022-07-26T14:55:28.976] sched: Allocate JobId=46728 NodeList=gpu01 #CPUs=16 Partition=gpu-k10
[2022-07-26T14:56:38.746] sched: Allocate JobId=46724 NodeList=cpu14 #CPUs=12 Partition=cpu-epyc
[2022-07-26T15:45:29.188] sched: Allocate JobId=46732 NodeList=cpu14 #CPUs=12 Partition=cpu-epyc
[2022-07-26T19:31:35.022] sched: Allocate JobId=46719 NodeList=gpu05 #CPUs=16 Partition=gpu-v100s
[2022-07-26T21:11:46.759] sched: Allocate JobId=46729 NodeList=gpu01 #CPUs=16 Partition=gpu-k10
[2022-07-26T21:43:58.663] sched: Allocate JobId=46693 NodeList=cpu01 #CPUs=32 Partition=cpu-opteron
[2022-07-26T21:43:58.678] sched: Allocate JobId=46698 NodeList=cpu01 #CPUs=24 Partition=cpu-opteron
[2022-07-26T21:46:08.391] sched: Allocate JobId=46702 NodeList=cpu01 #CPUs=24 Partition=cpu-opteron
[2022-07-26T21:51:58.180] sched: Allocate JobId=46703 NodeList=cpu08 #CPUs=32 Partition=cpu-opteron
[2022-07-26T21:51:58.181] sched: Allocate JobId=46704 NodeList=cpu08 #CPUs=32 Partition=cpu-opteron
[2022-07-26T22:16:31.200] sched: Allocate JobId=46733 NodeList=cpu12 #CPUs=24 Partition=cpu-epyc
[2022-07-26T22:58:38.330] sched: Allocate JobId=46734 NodeList=cpu14 #CPUs=16 Partition=cpu-epyc
[2022-07-27T01:08:54.858] sched: _slurm_rpc_allocate_resources JobId=46756 NodeList=(null) usec=935
[2022-07-27T01:09:19.319] sched: _slurm_rpc_allocate_resources JobId=46757 NodeList=(null) usec=672
[2022-07-27T01:10:17.736] sched: _slurm_rpc_allocate_resources JobId=46758 NodeList=(null) usec=777
[2022-07-27T01:10:18.206] sched: Allocate JobId=46758 NodeList=gpu05 #CPUs=16 Partition=gpu-v100s
[2022-07-27T01:14:43.668] sched: Allocate JobId=46759 NodeList=gpu05 #CPUs=8 Partition=gpu-v100s
[2022-07-27T01:20:00.283] sched: _slurm_rpc_allocate_resources JobId=46760 NodeList=(null) usec=789
[2022-07-27T01:20:00.284] sched: Allocate JobId=46760 NodeList=gpu05 #CPUs=16 Partition=gpu-v100s
[2022-07-27T01:44:51.914] sched: Allocate JobId=46730 NodeList=gpu01 #CPUs=16 Partition=gpu-k10
[2022-07-27T02:03:09.469] sched: Allocate JobId=46763 NodeList=gpu05 #CPUs=8 Partition=gpu-v100s
[2022-07-27T02:40:35.691] sched: Allocate JobId=46735 NodeList=cpu12 #CPUs=16 Partition=cpu-epyc
[2022-07-27T02:40:35.692] sched: Allocate JobId=46736 NodeList=cpu12 #CPUs=16 Partition=cpu-epyc
[2022-07-27T03:17:14.950] sched: Allocate JobId=46737 NodeList=cpu14 #CPUs=16 Partition=cpu-epyc
[2022-07-27T05:41:19.207] sched: Allocate JobId=46731 NodeList=cpu04 #CPUs=32 Partition=cpu-opteron
[2022-07-27T05:43:06.697] sched: Allocate JobId=46755 NodeList=cpu04 #CPUs=48 Partition=cpu-opteron
[2022-07-27T05:59:58.607] sched: Allocate JobId=46761 NodeList=gpu01 #CPUs=16 Partition=gpu-k10
[2022-07-27T06:50:02.982] sched: Allocate JobId=46738 NodeList=cpu15 #CPUs=16 Partition=cpu-epyc
[2022-07-27T07:03:34.045] sched: Allocate JobId=46739 NodeList=cpu14 #CPUs=16 Partition=cpu-epyc
[2022-07-27T07:36:33.612] sched: Allocate JobId=46740 NodeList=cpu12 #CPUs=16 Partition=cpu-epyc
[2022-07-27T07:43:55.060] sched: Allocate JobId=46741 NodeList=cpu12 #CPUs=16 Partition=cpu-epyc
[2022-07-27T10:57:38.375] sched: Allocate JobId=46742 NodeList=cpu15 #CPUs=16 Partition=cpu-epyc
[2022-07-27T11:03:15.463] sched: Allocate JobId=46743 NodeList=cpu14 #CPUs=16 Partition=cpu-epyc
[2022-07-27T11:21:05.070] sched: Allocate JobId=46744 NodeList=cpu14 #CPUs=16 Partition=cpu-epyc
[2022-07-27T12:15:54.629] sched: Allocate JobId=46745 NodeList=cpu12 #CPUs=16 Partition=cpu-epyc
[2022-07-27T12:41:27.784] sched: Allocate JobId=46746 NodeList=cpu12 #CPUs=16 Partition=cpu-epyc
[2022-07-27T13:42:24.470] sched: Allocate JobId=46782 NodeList=gpu01 #CPUs=16 Partition=gpu-k10
[2022-07-27T13:54:55.818] sched: Allocate JobId=46783 NodeList=gpu03 #CPUs=16 Partition=gpu-k10
[2022-07-27T14:48:21.647] sched/backfill: _start_job: Started JobId=46784 in cpu-opteron on cpu03
[2022-07-27T14:50:21.651] sched/backfill: _start_job: Started JobId=46785 in cpu-opteron on cpu04
[2022-07-27T14:53:21.656] sched/backfill: _start_job: Started JobId=46786 in cpu-opteron on cpu03
[2022-07-27T15:05:58.496] sched: Allocate JobId=46747 NodeList=cpu14 #CPUs=16 Partition=cpu-epyc
[2022-07-27T15:22:50.352] sched: Allocate JobId=46748 NodeList=cpu15 #CPUs=16 Partition=cpu-epyc
[2022-07-27T15:35:24.040] sched: Allocate JobId=46749 NodeList=cpu14 #CPUs=16 Partition=cpu-epyc
[2022-07-27T16:47:52.300] sched: Allocate JobId=46750 NodeList=cpu12 #CPUs=16 Partition=cpu-epyc
[2022-07-27T16:56:20.455] sched: Allocate JobId=46751 NodeList=cpu12 #CPUs=16 Partition=cpu-epyc
[2022-07-27T19:34:22.145] sched: Allocate JobId=46752 NodeList=cpu14 #CPUs=16 Partition=cpu-epyc
[2022-07-27T20:10:50.299] sched: Allocate JobId=46753 NodeList=cpu15 #CPUs=16 Partition=cpu-epyc
[2022-07-27T20:38:39.299] sched: Allocate JobId=46754 NodeList=cpu14 #CPUs=16 Partition=cpu-epyc
[2022-07-27T21:16:00.160] sched: Allocate JobId=46787 NodeList=gpu01 #CPUs=16 Partition=gpu-k10
[2022-07-27T21:18:32.503] sched: Allocate JobId=46788 NodeList=gpu01 #CPUs=16 Partition=gpu-k10
[2022-07-27T21:19:34.592] sched: Allocate JobId=46789 NodeList=gpu01 #CPUs=16 Partition=gpu-k10
[2022-07-27T21:20:46.692] sched: Allocate JobId=46790 NodeList=gpu01 #CPUs=16 Partition=gpu-k10
[2022-07-27T21:21:48.779] sched: Allocate JobId=46791 NodeList=gpu03 #CPUs=16 Partition=gpu-k10
[2022-07-27T21:24:44.127] sched: Allocate JobId=46792 NodeList=gpu03 #CPUs=16 Partition=gpu-k10
[2022-07-27T21:31:38.791] sched: Allocate JobId=46793 NodeList=gpu03 #CPUs=16 Partition=gpu-k10
[2022-07-27T21:34:22.092] sched: Allocate JobId=46794 NodeList=gpu03 #CPUs=16 Partition=gpu-k10
[2022-07-27T21:36:32.275] sched: Allocate JobId=46795 NodeList=gpu03 #CPUs=16 Partition=gpu-k10
[2022-07-27T21:38:40.539] sched: Allocate JobId=46796 NodeList=gpu03 #CPUs=16 Partition=gpu-k10
[2022-07-27T21:40:56.732] sched: Allocate JobId=46797 NodeList=gpu03 #CPUs=16 Partition=gpu-k10
[2022-07-27T21:44:04.662] sched: Allocate JobId=46765 NodeList=cpu01 #CPUs=32 Partition=cpu-opteron
[2022-07-27T21:52:05.920] sched: Allocate JobId=46766 NodeList=cpu08 #CPUs=64 Partition=cpu-opteron
[2022-07-27T22:16:54.604] sched: Allocate JobId=46798 NodeList=gpu03 #CPUs=16 Partition=gpu-k10
[2022-07-27T23:09:09.298] sched: Allocate JobId=46804 NodeList=cpu05 #CPUs=64 Partition=cpu-opteron
[2022-07-27T23:44:43.177] sched: Allocate JobId=46805 NodeList=cpu01 #CPUs=16 Partition=cpu-opteron
[2022-07-28T01:23:04.306] sched: Allocate JobId=46767 NodeList=cpu14 #CPUs=48 Partition=cpu-epyc
[2022-07-28T01:31:55.601] sched: Allocate JobId=46811 NodeList=gpu02 #CPUs=4 Partition=gpu-titan
[2022-07-28T01:34:27.907] sched: Allocate JobId=46813 NodeList=gpu02 #CPUs=8 Partition=gpu-titan
[2022-07-28T01:38:39.348] sched: Allocate JobId=46814 NodeList=gpu02 #CPUs=8 Partition=gpu-titan
[2022-07-28T02:50:11.205] sched: Allocate JobId=46815 NodeList=gpu02 #CPUs=8 Partition=gpu-titan
[2022-07-28T06:46:20.888] sched: Allocate JobId=46768 NodeList=cpu14 #CPUs=48 Partition=cpu-epyc
[2022-07-28T10:00:18.829] sched: Allocate JobId=46818 NodeList=gpu02 #CPUs=8 Partition=gpu-titan
[2022-07-28T10:01:35.898] sched: Allocate JobId=46769 NodeList=cpu15 #CPUs=48 Partition=cpu-epyc
[2022-07-28T10:43:30.932] sched: Allocate JobId=46822 NodeList=gpu01 #CPUs=4 Partition=gpu-k10
[2022-07-28T10:43:41.587] sched: Allocate JobId=46819 NodeList=gpu02 #CPUs=8 Partition=gpu-titan
[2022-07-28T10:51:02.072] sched: Allocate JobId=46820 NodeList=gpu02 #CPUs=16 Partition=gpu-titan
[2022-07-28T10:56:38.222] sched: Allocate JobId=46821 NodeList=gpu02 #CPUs=16 Partition=gpu-titan
[2022-07-28T11:06:59.310] sched: Allocate JobId=46823 NodeList=gpu02 #CPUs=8 Partition=gpu-titan
[2022-07-28T11:37:09.542] sched: Allocate JobId=46824 NodeList=gpu02 #CPUs=8 Partition=gpu-titan
[2022-07-28T11:39:32.813] sched: Allocate JobId=46825 NodeList=gpu02 #CPUs=8 Partition=gpu-titan
[2022-07-28T12:16:31.122] sched: Allocate JobId=46770 NodeList=cpu14 #CPUs=48 Partition=cpu-epyc
[2022-07-28T15:26:47.387] sched: Allocate JobId=46831 NodeList=gpu01 #CPUs=8 Partition=gpu-k10
[2022-07-28T15:32:24.261] sched/backfill: _start_job: Started JobId=46841 in cpu-epyc on cpu12
[2022-07-28T15:32:24.261] sched/backfill: _start_job: Started JobId=46842 in cpu-epyc on cpu12
[2022-07-28T15:38:11.627] sched: Allocate JobId=46771 NodeList=cpu15 #CPUs=48 Partition=cpu-epyc
[2022-07-28T15:38:52.295] sched: Allocate JobId=46833 NodeList=gpu01 #CPUs=8 Partition=gpu-k10
[2022-07-28T16:13:24.395] sched/backfill: _start_job: Started JobId=46843 in cpu-epyc on cpu12
[2022-07-28T16:33:24.461] sched/backfill: _start_job: Started JobId=46844 in cpu-epyc on cpu12
[2022-07-28T16:34:37.730] sched: Allocate JobId=46827 NodeList=gpu02 #CPUs=8 Partition=gpu-titan
[2022-07-28T16:34:37.731] sched: Allocate JobId=46828 NodeList=gpu02 #CPUs=8 Partition=gpu-titan
[2022-07-28T16:43:00.274] sched: Allocate JobId=46850 NodeList=gpu02 #CPUs=15 Partition=gpu-titan
[2022-07-28T16:46:07.543] sched: Allocate JobId=46851 NodeList=gpu02 #CPUs=16 Partition=gpu-titan
[2022-07-28T16:48:43.850] sched: Allocate JobId=46852 NodeList=gpu02 #CPUs=16 Partition=gpu-titan
[2022-07-28T16:58:24.531] sched/backfill: _start_job: Started JobId=46845 in cpu-epyc on cpu12
[2022-07-28T17:00:24.538] sched/backfill: _start_job: Started JobId=46846 in cpu-epyc on cpu12
[2022-07-28T17:13:37.826] sched: Allocate JobId=46772 NodeList=cpu14 #CPUs=48 Partition=cpu-epyc
[2022-07-28T17:24:24.598] sched/backfill: _start_job: Started JobId=46847 in cpu-epyc on cpu12
[2022-07-28T17:26:24.603] sched/backfill: _start_job: Started JobId=46848 in cpu-epyc on cpu12
[2022-07-28T18:23:56.423] sched: Allocate JobId=46808 NodeList=cpu11 #CPUs=24 Partition=cpu-opteron
[2022-07-28T18:23:56.424] sched: Allocate JobId=46809 NodeList=cpu11 #CPUs=24 Partition=cpu-opteron
[2022-07-28T18:38:57.098] sched: Allocate JobId=46854 NodeList=gpu01 #CPUs=8 Partition=gpu-k10
[2022-07-28T18:41:11.273] sched: Allocate JobId=46855 NodeList=gpu02 #CPUs=8 Partition=gpu-titan
[2022-07-28T18:44:57.741] sched: Allocate JobId=46857 NodeList=cpu12 #CPUs=8 Partition=cpu-epyc
[2022-07-28T18:50:51.380] sched: Allocate JobId=46858 NodeList=cpu12 #CPUs=8 Partition=cpu-epyc
[2022-07-28T18:58:14.196] sched: Allocate JobId=46859 NodeList=cpu12 #CPUs=8 Partition=cpu-epyc
[2022-07-28T19:04:50.838] sched: Allocate JobId=46860 NodeList=cpu12 #CPUs=8 Partition=cpu-epyc
[2022-07-28T19:12:27.729] sched: Allocate JobId=46861 NodeList=cpu12 #CPUs=8 Partition=cpu-epyc
[2022-07-28T19:15:57.104] sched: Allocate JobId=46862 NodeList=cpu12 #CPUs=8 Partition=cpu-epyc
[2022-07-28T19:21:29.651] sched: Allocate JobId=46863 NodeList=cpu12 #CPUs=8 Partition=cpu-epyc
[2022-07-28T19:30:17.560] sched: Allocate JobId=46864 NodeList=cpu12 #CPUs=8 Partition=cpu-epyc
[2022-07-28T19:31:55.695] sched: Allocate JobId=46865 NodeList=cpu12 #CPUs=8 Partition=cpu-epyc
[2022-07-28T20:04:21.202] sched: Allocate JobId=46866 NodeList=cpu12 #CPUs=8 Partition=cpu-epyc
[2022-07-28T20:30:24.928] sched/backfill: _start_job: Started JobId=46867 in cpu-epyc on cpu12
[2022-07-28T20:36:24.938] sched/backfill: _start_job: Started JobId=46869 in cpu-epyc on cpu12
[2022-07-28T20:42:47.769] sched: Allocate JobId=46773 NodeList=cpu15 #CPUs=48 Partition=cpu-epyc
[2022-07-28T20:42:47.782] sched: Allocate JobId=46774 NodeList=cpu12 #CPUs=32 Partition=cpu-epyc
[2022-07-28T20:50:55.314] sched: Allocate JobId=46871 NodeList=cpu11 #CPUs=8 Partition=cpu-opteron
[2022-07-28T21:12:17.058] sched: Allocate JobId=46810 NodeList=cpu07 #CPUs=24 Partition=cpu-opteron
[2022-07-28T21:17:34.593] sched: Allocate JobId=46872 NodeList=gpu02 #CPUs=8 Partition=gpu-titan
[2022-07-28T21:18:18.688] sched: Allocate JobId=46873 NodeList=cpu11 #CPUs=8 Partition=cpu-opteron
[2022-07-28T21:20:35.880] sched: Allocate JobId=46875 NodeList=cpu11 #CPUs=8 Partition=cpu-opteron
[2022-07-28T22:24:19.591] sched: Allocate JobId=46775 NodeList=cpu14 #CPUs=32 Partition=cpu-epyc
[2022-07-28T23:45:12.505] sched: Allocate JobId=46868 NodeList=cpu01 #CPUs=64 Partition=cpu-opteron
[2022-07-29T02:19:07.136] sched: Allocate JobId=46776 NodeList=cpu15 #CPUs=32 Partition=cpu-epyc
[2022-07-29T06:11:25.372] sched: Allocate JobId=46777 NodeList=cpu12 #CPUs=32 Partition=cpu-epyc
[2022-07-29T07:11:51.606] sched: Allocate JobId=46778 NodeList=cpu14 #CPUs=32 Partition=cpu-epyc
[2022-07-29T08:23:29.024] sched: Allocate JobId=46878 NodeList=cpu14 #CPUs=12 Partition=cpu-epyc
[2022-07-29T08:24:57.137] sched: Allocate JobId=46880 NodeList=cpu14 #CPUs=12 Partition=cpu-epyc
[2022-07-29T08:31:22.791] sched: Allocate JobId=46882 NodeList=cpu15 #CPUs=12 Partition=cpu-epyc
[2022-07-29T09:58:09.449] sched: Allocate JobId=46883 NodeList=cpu03 #CPUs=16 Partition=cpu-opteron
[2022-07-29T10:25:15.449] sched: Allocate JobId=46884 NodeList=cpu03 #CPUs=16 Partition=cpu-opteron
[2022-07-29T10:29:50.911] sched: Allocate JobId=46885 NodeList=gpu02 #CPUs=8 Partition=gpu-titan
[2022-07-29T11:43:56.767] sched: Allocate JobId=46886 NodeList=gpu02 #CPUs=8 Partition=gpu-titan
[2022-07-29T11:57:13.055] sched: Allocate JobId=46779 NodeList=cpu15 #CPUs=32 Partition=cpu-epyc
[2022-07-29T12:32:56.578] sched: Allocate JobId=46888 NodeList=cpu07 #CPUs=24 Partition=cpu-opteron
[2022-07-29T12:33:08.583] sched: Allocate JobId=46889 NodeList=cpu09 #CPUs=24 Partition=cpu-opteron
[2022-07-29T12:33:53.645] sched: Allocate JobId=46890 NodeList=cpu09 #CPUs=24 Partition=cpu-opteron
[2022-07-29T13:11:53.740] sched: Allocate JobId=46891 NodeList=cpu09 #CPUs=24 Partition=cpu-opteron
[2022-07-29T14:16:49.836] sched: Allocate JobId=46780 NodeList=cpu13 #CPUs=32 Partition=cpu-epyc
[2022-07-29T14:50:28.531] sched: Allocate JobId=46817 NodeList=cpu14 #CPUs=24 Partition=cpu-epyc
[2022-07-29T14:50:28.544] sched: Allocate JobId=46876 NodeList=cpu14 #CPUs=24 Partition=cpu-epyc
[2022-07-29T14:50:30.393] sched: Allocate JobId=46877 NodeList=cpu15 #CPUs=32 Partition=cpu-epyc
[2022-07-29T14:50:34.102] sched: Allocate JobId=46881 NodeList=cpu13 #CPUs=32 Partition=cpu-epyc
[2022-07-29T14:53:57.685] sched: Allocate JobId=46895 NodeList=cpu12 #CPUs=32 Partition=cpu-epyc
[2022-07-29T14:59:01.192] sched: Allocate JobId=46903 NodeList=cpu13 #CPUs=16 Partition=cpu-epyc
[2022-07-29T15:39:02.555] sched: Allocate JobId=46904 NodeList=cpu15 #CPUs=16 Partition=cpu-epyc
[2022-07-29T15:43:43.041] sched: Allocate JobId=46905 NodeList=cpu[03,07] #CPUs=32 Partition=cpu-opteron
[2022-07-29T15:46:23.248] sched: Allocate JobId=46906 NodeList=cpu03 #CPUs=16 Partition=cpu-opteron
[2022-07-29T15:59:44.691] sched: Allocate JobId=46907 NodeList=cpu15 #CPUs=16 Partition=cpu-epyc
[2022-07-29T16:19:38.830] sched: Allocate JobId=46909 NodeList=gpu01 #CPUs=16 Partition=gpu-k10
[2022-07-29T17:57:45.269] sched: Allocate JobId=46908 NodeList=cpu11 #CPUs=32 Partition=cpu-opteron
[2022-07-29T18:24:13.548] sched: Allocate JobId=46910 NodeList=cpu11 #CPUs=32 Partition=cpu-opteron
[2022-07-29T18:24:14.858] sched: Allocate JobId=46892 NodeList=cpu11 #CPUs=24 Partition=cpu-opteron
[2022-07-29T20:25:20.097] sched: Allocate JobId=46911 NodeList=cpu13 #CPUs=16 Partition=cpu-epyc
[2022-07-29T20:48:37.691] sched: Allocate JobId=46916 NodeList=cpu13 #CPUs=16 Partition=cpu-epyc
[2022-07-29T21:55:44.350] sched: Allocate JobId=46914 NodeList=cpu07 #CPUs=64 Partition=cpu-opteron
[2022-07-29T22:34:28.725] sched: Allocate JobId=46915 NodeList=cpu07 #CPUs=64 Partition=cpu-opteron
[2022-07-29T23:12:58.649] sched: Allocate JobId=46893 NodeList=cpu07 #CPUs=24 Partition=cpu-opteron
[2022-07-30T00:41:18.237] sched: Allocate JobId=46887 NodeList=gpu02 #CPUs=8 Partition=gpu-titan
[2022-07-30T00:43:43.528] sched: Allocate JobId=46917 NodeList=gpu02 #CPUs=8 Partition=gpu-titan
[2022-07-30T05:02:27.062] sched: Allocate JobId=46912 NodeList=cpu12 #CPUs=48 Partition=cpu-epyc
[2022-07-30T11:10:33.501] sched: Allocate JobId=46834 NodeList=gpu04 #CPUs=8 Partition=gpu-k40c
[2022-07-30T12:10:47.198] sched: Allocate JobId=46849 NodeList=gpu04 #CPUs=16 Partition=gpu-k40c
[2022-07-30T17:17:33.363] sched: Allocate JobId=46919 NodeList=gpu04 #CPUs=16 Partition=gpu-k40c
[2022-07-30T23:05:14.252] sched: Allocate JobId=46920 NodeList=cpu07 #CPUs=24 Partition=cpu-opteron
[2022-07-30T23:20:59.905] sched: Allocate JobId=46921 NodeList=cpu09 #CPUs=24 Partition=cpu-opteron
[2022-07-31T00:11:07.540] sched: Allocate JobId=46922 NodeList=cpu09 #CPUs=32 Partition=cpu-opteron
[2022-07-31T00:30:01.698] sched: Allocate JobId=46923 NodeList=cpu11 #CPUs=32 Partition=cpu-opteron
[2022-07-31T08:54:57.234] sched: Allocate JobId=46924 NodeList=cpu03 #CPUs=16 Partition=cpu-opteron
[2022-07-31T09:20:01.114] sched: Allocate JobId=46925 NodeList=cpu03 #CPUs=16 Partition=cpu-opteron
[2022-07-31T09:21:08.206] sched: Allocate JobId=46926 NodeList=cpu03 #CPUs=16 Partition=cpu-opteron
[2022-07-31T09:27:46.104] sched: Allocate JobId=46927 NodeList=cpu07 #CPUs=32 Partition=cpu-opteron
[2022-07-31T09:28:29.164] sched: Allocate JobId=46928 NodeList=cpu07 #CPUs=32 Partition=cpu-opteron
[2022-07-31T09:29:04.213] sched: Allocate JobId=46929 NodeList=cpu07 #CPUs=32 Partition=cpu-opteron
[2022-07-31T11:52:31.808] sched: Allocate JobId=46930 NodeList=cpu07 #CPUs=32 Partition=cpu-opteron
[2022-07-31T14:02:03.323] sched: Allocate JobId=46931 NodeList=cpu11 #CPUs=32 Partition=cpu-opteron
[2022-07-31T14:02:46.488] sched: Allocate JobId=46932 NodeList=cpu11 #CPUs=64 Partition=cpu-opteron
[2022-07-31T14:40:32.359] sched: Allocate JobId=46933 NodeList=gpu04 #CPUs=16 Partition=gpu-k40c
[2022-07-31T17:09:15.517] sched: Allocate JobId=46829 NodeList=gpu05 #CPUs=8 Partition=gpu-v100s
[2022-07-31T17:14:52.791] sched: Allocate JobId=46839 NodeList=gpu05 #CPUs=8 Partition=gpu-v100s
[2022-08-01T10:02:35.479] sched: Allocate JobId=46939 NodeList=gpu01 #CPUs=2 Partition=gpu-k10
[2022-08-01T10:09:04.237] sched: Allocate JobId=46940 NodeList=cpu07 #CPUs=1 Partition=cpu-opteron
[2022-08-01T11:17:15.487] sched: Allocate JobId=46950 NodeList=gpu01 #CPUs=8 Partition=gpu-k10
[2022-08-01T11:23:07.680] sched: Allocate JobId=46951 NodeList=gpu01 #CPUs=8 Partition=gpu-k10
[2022-08-01T11:37:48.724] sched: Allocate JobId=46955 NodeList=gpu02 #CPUs=8 Partition=gpu-titan
[2022-08-01T11:42:33.264] sched/backfill: _start_job: Started JobId=46957 in gpu-v100s on gpu05
[2022-08-01T11:42:47.569] sched: Allocate JobId=46956 NodeList=gpu02 #CPUs=8 Partition=gpu-titan
[2022-08-01T11:43:33.267] sched/backfill: _start_job: Started JobId=46958 in gpu-v100s on gpu05
[2022-08-01T11:50:27.865] sched: Allocate JobId=46949 NodeList=gpu04 #CPUs=8 Partition=gpu-k40c
[2022-08-01T11:57:50.389] sched: Allocate JobId=46953 NodeList=gpu04 #CPUs=8 Partition=gpu-k40c
[2022-08-01T12:03:37.411] sched: Allocate JobId=46954 NodeList=gpu04 #CPUs=8 Partition=gpu-k40c
[2022-08-01T12:10:02.409] sched: Allocate JobId=46952 NodeList=gpu04 #CPUs=16 Partition=gpu-k40c
[2022-08-01T12:44:16.135] sched: Allocate JobId=46959 NodeList=cpu07 #CPUs=8 Partition=cpu-opteron
[2022-08-01T12:47:33.353] sched/backfill: _start_job: Started JobId=46960 in cpu-opteron on cpu09
[2022-08-01T12:50:33.358] sched/backfill: _start_job: Started JobId=46961 in cpu-epyc on cpu15
[2022-08-01T12:50:33.359] sched/backfill: _start_job: Started JobId=46962 in cpu-epyc on cpu15
[2022-08-01T13:27:10.681] sched: Allocate JobId=46963 NodeList=cpu07 #CPUs=8 Partition=cpu-opteron
[2022-08-01T13:29:00.968] sched: Allocate JobId=46964 NodeList=cpu09 #CPUs=8 Partition=cpu-opteron
[2022-08-01T13:42:33.449] sched/backfill: _start_job: Started JobId=46966 in cpu-opteron on cpu07
[2022-08-01T13:47:54.025] sched: Allocate JobId=46967 NodeList=cpu07 #CPUs=8 Partition=cpu-opteron
[2022-08-01T13:55:28.757] sched: Allocate JobId=46968 NodeList=cpu09 #CPUs=8 Partition=cpu-opteron
[2022-08-01T16:11:33.693] sched/backfill: _start_job: Started JobId=46969 in cpu-opteron on cpu09
[2022-08-01T18:31:45.861] sched: Allocate JobId=46936 NodeList=cpu[03,11] #CPUs=128 Partition=cpu-opteron
[2022-08-01T18:31:45.877] sched: Allocate JobId=46970 NodeList=cpu07 #CPUs=16 Partition=cpu-opteron
[2022-08-01T18:31:45.877] sched: Allocate JobId=46971 NodeList=cpu07 #CPUs=16 Partition=cpu-opteron
[2022-08-01T19:28:55.497] sched: Allocate JobId=46972 NodeList=cpu03 #CPUs=16 Partition=cpu-opteron
[2022-08-01T19:28:55.497] sched: Allocate JobId=46973 NodeList=cpu03 #CPUs=16 Partition=cpu-opteron
[2022-08-01T19:28:55.498] sched: Allocate JobId=46974 NodeList=cpu03 #CPUs=16 Partition=cpu-opteron
[2022-08-01T19:28:55.499] sched: Allocate JobId=46975 NodeList=cpu03 #CPUs=16 Partition=cpu-opteron
[2022-08-01T19:28:55.500] sched: Allocate JobId=46976 NodeList=cpu11 #CPUs=16 Partition=cpu-opteron
[2022-08-01T19:28:55.501] sched: Allocate JobId=46977 NodeList=cpu11 #CPUs=16 Partition=cpu-opteron
[2022-08-01T19:28:55.502] sched: Allocate JobId=46978 NodeList=cpu11 #CPUs=16 Partition=cpu-opteron
[2022-08-01T19:28:55.502] sched: Allocate JobId=46979 NodeList=cpu11 #CPUs=16 Partition=cpu-opteron
[2022-08-02T01:05:19.140] sched: Allocate JobId=46980 NodeList=cpu11 #CPUs=16 Partition=cpu-opteron
[2022-08-02T01:29:02.430] sched: Allocate JobId=46981 NodeList=cpu07 #CPUs=16 Partition=cpu-opteron
[2022-08-02T02:13:06.505] sched: Allocate JobId=46982 NodeList=cpu03 #CPUs=16 Partition=cpu-opteron
[2022-08-02T02:16:35.531] sched/backfill: _start_job: Started JobId=46998 in cpu-epyc on cpu15
[2022-08-02T02:25:35.555] sched/backfill: _start_job: Started JobId=46999 in cpu-epyc on cpu15
[2022-08-02T02:26:56.272] sched: Allocate JobId=46983 NodeList=cpu11 #CPUs=16 Partition=cpu-opteron
[2022-08-02T02:28:35.566] sched/backfill: _start_job: Started JobId=47000 in cpu-epyc on cpu15
[2022-08-02T02:37:35.588] sched/backfill: _start_job: Started JobId=47001 in cpu-epyc on cpu15
[2022-08-02T02:40:03.526] sched: Allocate JobId=46984 NodeList=cpu07 #CPUs=16 Partition=cpu-opteron
[2022-08-02T02:46:47.948] sched: Allocate JobId=46985 NodeList=cpu03 #CPUs=16 Partition=cpu-opteron
[2022-08-02T03:32:16.939] sched: Allocate JobId=46986 NodeList=cpu03 #CPUs=16 Partition=cpu-opteron
[2022-08-02T03:49:08.193] sched: Allocate JobId=46987 NodeList=cpu11 #CPUs=16 Partition=cpu-opteron
[2022-08-02T04:30:28.214] sched: Allocate JobId=46988 NodeList=cpu03 #CPUs=16 Partition=cpu-opteron
[2022-08-02T07:59:02.313] sched: Allocate JobId=46989 NodeList=cpu11 #CPUs=16 Partition=cpu-opteron
[2022-08-02T08:09:35.551] sched: Allocate JobId=46990 NodeList=cpu03 #CPUs=16 Partition=cpu-opteron
[2022-08-02T08:16:06.382] sched: Allocate JobId=46991 NodeList=cpu07 #CPUs=16 Partition=cpu-opteron
[2022-08-02T09:16:14.733] sched: Allocate JobId=46994 NodeList=cpu11 #CPUs=16 Partition=cpu-opteron
[2022-08-02T09:21:36.434] sched/backfill: _start_job: Started JobId=46996 in cpu-opteron on cpu11
[2022-08-02T09:52:36.500] sched/backfill: _start_job: Started JobId=46995 in cpu-opteron on cpu07
[2022-08-02T09:59:36.514] sched/backfill: _start_job: Started JobId=47002 in cpu-opteron on cpu11
[2022-08-02T10:33:25.847] sched: Allocate JobId=46992 NodeList=cpu09 #CPUs=32 Partition=cpu-opteron
[2022-08-02T10:33:44.028] sched: Allocate JobId=46993 NodeList=cpu09 #CPUs=32 Partition=cpu-opteron
[2022-08-02T13:04:31.587] sched: Allocate JobId=47003 NodeList=cpu03 #CPUs=32 Partition=cpu-opteron
[2022-08-02T14:10:36.825] sched/backfill: _start_job: Started JobId=47004 in cpu-epyc on cpu15
[2022-08-02T14:11:16.786] sched: Allocate JobId=47005 NodeList=cpu03 #CPUs=32 Partition=cpu-opteron
[2022-08-02T14:19:27.685] sched: Allocate JobId=47007 NodeList=cpu[03,09] #CPUs=64 Partition=cpu-opteron
[2022-08-02T14:20:42.805] sched: Allocate JobId=47008 NodeList=cpu11 #CPUs=16 Partition=cpu-opteron
[2022-08-02T14:22:36.056] sched: Allocate JobId=47009 NodeList=cpu[03,09] #CPUs=64 Partition=cpu-opteron
[2022-08-02T14:25:20.331] sched: Allocate JobId=47011 NodeList=cpu[03,09] #CPUs=64 Partition=cpu-opteron
[2022-08-02T14:31:14.950] sched: Allocate JobId=47012 NodeList=cpu[03,09] #CPUs=64 Partition=cpu-opteron
[2022-08-02T14:35:05.389] sched: Allocate JobId=47013 NodeList=cpu[03,09] #CPUs=64 Partition=cpu-opteron
[2022-08-02T14:36:12.483] sched: Allocate JobId=47014 NodeList=cpu03 #CPUs=16 Partition=cpu-opteron
[2022-08-02T14:50:20.994] sched: Allocate JobId=47015 NodeList=cpu[03,09] #CPUs=8 Partition=cpu-opteron
[2022-08-02T14:51:55.123] sched: Allocate JobId=47016 NodeList=cpu[03,09] #CPUs=8 Partition=cpu-opteron
[2022-08-02T14:53:06.347] sched: Allocate JobId=47017 NodeList=cpu[03,09] #CPUs=8 Partition=cpu-opteron
[2022-08-02T14:53:25.401] sched: Allocate JobId=47018 NodeList=cpu[03,09] #CPUs=8 Partition=cpu-opteron
[2022-08-02T14:54:08.431] sched: Allocate JobId=47019 NodeList=cpu[03,09] #CPUs=8 Partition=cpu-opteron
[2022-08-02T14:54:59.503] sched: Allocate JobId=47020 NodeList=cpu[03,09] #CPUs=8 Partition=cpu-opteron
[2022-08-02T15:01:42.209] sched: Allocate JobId=47021 NodeList=cpu03 #CPUs=16 Partition=cpu-opteron
[2022-08-02T15:01:45.211] sched: Allocate JobId=47022 NodeList=cpu09 #CPUs=16 Partition=cpu-opteron
[2022-08-02T15:07:55.943] sched: Allocate JobId=47023 NodeList=cpu[03,09] #CPUs=8 Partition=cpu-opteron
[2022-08-02T15:09:08.038] sched: Allocate JobId=47024 NodeList=cpu[03,09] #CPUs=8 Partition=cpu-opteron
[2022-08-02T15:09:52.099] sched: Allocate JobId=47025 NodeList=cpu[03,09] #CPUs=8 Partition=cpu-opteron
[2022-08-02T15:10:54.209] sched: Allocate JobId=47027 NodeList=cpu11 #CPUs=32 Partition=cpu-opteron
[2022-08-02T15:12:48.508] sched: Allocate JobId=47028 NodeList=cpu[03,09] #CPUs=8 Partition=cpu-opteron
[2022-08-02T15:13:36.576] sched: Allocate JobId=47029 NodeList=cpu03 #CPUs=32 Partition=cpu-opteron
[2022-08-02T15:13:39.580] sched: Allocate JobId=47030 NodeList=cpu[09,11] #CPUs=8 Partition=cpu-opteron
[2022-08-02T15:17:21.891] sched: Allocate JobId=47031 NodeList=cpu03 #CPUs=32 Partition=cpu-opteron
[2022-08-02T15:20:05.260] sched: Allocate JobId=47032 NodeList=cpu[03,09] #CPUs=8 Partition=cpu-opteron
[2022-08-02T15:21:05.332] sched: Allocate JobId=47033 NodeList=cpu[03,09] #CPUs=8 Partition=cpu-opteron
[2022-08-02T15:22:48.556] sched: Allocate JobId=47034 NodeList=cpu[03,09] #CPUs=8 Partition=cpu-opteron
[2022-08-02T15:23:22.606] sched: Allocate JobId=47035 NodeList=cpu11 #CPUs=32 Partition=cpu-opteron
[2022-08-02T15:24:40.707] sched: Allocate JobId=47036 NodeList=cpu11 #CPUs=32 Partition=cpu-opteron
[2022-08-02T15:25:19.761] sched: Allocate JobId=47037 NodeList=cpu03 #CPUs=32 Partition=cpu-opteron
[2022-08-02T15:26:47.890] sched: Allocate JobId=47038 NodeList=cpu09 #CPUs=16 Partition=cpu-opteron
[2022-08-02T15:26:50.891] sched: Allocate JobId=47039 NodeList=cpu03 #CPUs=16 Partition=cpu-opteron
[2022-08-02T15:27:19.932] sched: Allocate JobId=47040 NodeList=cpu11 #CPUs=32 Partition=cpu-opteron
[2022-08-02T15:29:58.232] sched: Allocate JobId=47041 NodeList=cpu11 #CPUs=32 Partition=cpu-opteron
[2022-08-02T15:40:31.375] sched: Allocate JobId=47042 NodeList=cpu[03,07] #CPUs=8 Partition=cpu-opteron
[2022-08-02T15:43:51.764] sched: Allocate JobId=47043 NodeList=cpu03 #CPUs=16 Partition=cpu-opteron
[2022-08-02T15:44:52.850] sched: Allocate JobId=47044 NodeList=cpu[07,11] #CPUs=8 Partition=cpu-opteron
[2022-08-02T15:47:31.078] sched: Allocate JobId=47045 NodeList=cpu[07,11] #CPUs=8 Partition=cpu-opteron
[2022-08-02T15:48:30.253] sched: Allocate JobId=47046 NodeList=cpu[07,11] #CPUs=8 Partition=cpu-opteron
[2022-08-02T15:49:26.334] sched: Allocate JobId=47047 NodeList=cpu[07,11] #CPUs=8 Partition=cpu-opteron
[2022-08-02T15:52:04.557] sched: Allocate JobId=47048 NodeList=cpu[03,07] #CPUs=8 Partition=cpu-opteron
[2022-08-02T15:52:55.769] sched: Allocate JobId=47049 NodeList=cpu[03,07] #CPUs=8 Partition=cpu-opteron
[2022-08-02T15:54:11.876] sched: Allocate JobId=47050 NodeList=cpu[03,07] #CPUs=8 Partition=cpu-opteron
[2022-08-02T15:54:59.941] sched: Allocate JobId=47051 NodeList=cpu[03,07] #CPUs=8 Partition=cpu-opteron
[2022-08-02T15:56:10.038] sched: Allocate JobId=47052 NodeList=cpu[03,07] #CPUs=8 Partition=cpu-opteron
[2022-08-02T15:56:49.094] sched: Allocate JobId=47053 NodeList=cpu11 #CPUs=32 Partition=cpu-opteron
[2022-08-02T15:57:25.141] sched: Allocate JobId=47054 NodeList=cpu11 #CPUs=32 Partition=cpu-opteron
[2022-08-02T15:58:40.344] sched: Allocate JobId=47055 NodeList=cpu03 #CPUs=8 Partition=cpu-opteron
[2022-08-02T15:59:36.430] sched: Allocate JobId=47056 NodeList=cpu03 #CPUs=16 Partition=cpu-opteron
[2022-08-02T15:59:47.440] sched: Allocate JobId=47057 NodeList=cpu07 #CPUs=8 Partition=cpu-opteron
[2022-08-02T16:03:36.960] sched/backfill: _start_job: Started JobId=47058 in cpu-epyc on cpu15
[2022-08-02T16:11:23.664] sched: Allocate JobId=47059 NodeList=cpu[12-13] #CPUs=8 Partition=cpu-epyc
[2022-08-02T16:14:33.071] sched: Allocate JobId=47060 NodeList=cpu[12-13] #CPUs=8 Partition=cpu-epyc
[2022-08-02T16:15:36.975] sched/backfill: _start_job: Started JobId=47061 in cpu-epyc on cpu[12-13]
[2022-08-02T16:16:36.976] sched/backfill: _start_job: Started JobId=47062 in cpu-epyc on cpu[12-13]
[2022-08-02T16:18:19.523] sched: Allocate JobId=47063 NodeList=cpu[12-13] #CPUs=8 Partition=cpu-epyc
[2022-08-02T16:19:15.604] sched: Allocate JobId=47065 NodeList=cpu07 #CPUs=16 Partition=cpu-opteron
[2022-08-02T16:19:18.605] sched: Allocate JobId=47064 NodeList=cpu[12-13] #CPUs=8 Partition=cpu-epyc
[2022-08-02T16:21:36.984] sched/backfill: _start_job: Started JobId=47066 in cpu-epyc on cpu[12-13]
[2022-08-02T16:24:29.162] sched: Allocate JobId=47067 NodeList=cpu[12-13] #CPUs=8 Partition=cpu-epyc
[2022-08-02T16:25:36.993] sched/backfill: _start_job: Started JobId=47068 in cpu-epyc on cpu[12-13]
[2022-08-02T16:26:53.359] sched: Allocate JobId=47069 NodeList=cpu[12-13] #CPUs=8 Partition=cpu-epyc
[2022-08-02T16:28:15.558] sched: Allocate JobId=47070 NodeList=cpu[12-13] #CPUs=8 Partition=cpu-epyc
[2022-08-02T16:33:20.174] sched: Allocate JobId=47071 NodeList=cpu[12-13] #CPUs=8 Partition=cpu-epyc
[2022-08-02T16:40:40.071] sched: Allocate JobId=47072 NodeList=cpu03 #CPUs=16 Partition=cpu-opteron
[2022-08-02T16:40:43.071] sched: Allocate JobId=47073 NodeList=cpu07 #CPUs=16 Partition=cpu-opteron
[2022-08-02T16:40:53.087] sched: Allocate JobId=47074 NodeList=cpu11 #CPUs=32 Partition=cpu-opteron
[2022-08-02T16:44:20.553] sched: Allocate JobId=47075 NodeList=cpu[03,09] #CPUs=8 Partition=cpu-opteron
[2022-08-02T16:44:58.599] sched: Allocate JobId=47076 NodeList=cpu[03,09] #CPUs=8 Partition=cpu-opteron
[2022-08-02T16:45:17.627] sched: Allocate JobId=47077 NodeList=cpu[03,09] #CPUs=8 Partition=cpu-opteron
[2022-08-02T16:45:28.641] sched: Allocate JobId=47078 NodeList=cpu[03,09] #CPUs=8 Partition=cpu-opteron
[2022-08-02T16:45:54.678] sched: Allocate JobId=47079 NodeList=cpu[03,09] #CPUs=8 Partition=cpu-opteron
[2022-08-02T16:51:16.285] sched: Allocate JobId=47080 NodeList=cpu11 #CPUs=32 Partition=cpu-opteron
[2022-08-02T16:53:35.557] sched: Allocate JobId=47081 NodeList=cpu03 #CPUs=16 Partition=cpu-opteron
[2022-08-02T16:53:38.558] sched: Allocate JobId=47082 NodeList=cpu11 #CPUs=16 Partition=cpu-opteron
[2022-08-02T16:53:38.559] sched: Allocate JobId=47083 NodeList=cpu09 #CPUs=16 Partition=cpu-opteron
[2022-08-02T17:05:26.748] sched: Allocate JobId=47085 NodeList=cpu09 #CPUs=16 Partition=cpu-opteron
[2022-08-02T17:05:29.749] sched: Allocate JobId=47086 NodeList=cpu11 #CPUs=16 Partition=cpu-opteron
[2022-08-02T17:05:32.753] sched: Allocate JobId=47087 NodeList=cpu11 #CPUs=16 Partition=cpu-opteron
[2022-08-02T17:05:37.045] sched/backfill: _start_job: Started JobId=47084 in cpu-epyc on cpu[12-13]
[2022-08-02T17:08:57.231] sched: Allocate JobId=47090 NodeList=cpu[13,15] #CPUs=8 Partition=cpu-epyc
[2022-08-02T17:10:50.387] sched: Allocate JobId=47092 NodeList=cpu[12-13] #CPUs=8 Partition=cpu-epyc
[2022-08-02T17:13:04.780] sched: Allocate JobId=47093 NodeList=cpu[12-13] #CPUs=8 Partition=cpu-epyc
[2022-08-02T17:16:26.070] sched: Allocate JobId=47102 NodeList=cpu[12-13] #CPUs=8 Partition=cpu-epyc
[2022-08-02T17:17:52.126] sched: Allocate JobId=47088 NodeList=cpu03 #CPUs=16 Partition=cpu-opteron
[2022-08-02T17:19:37.072] sched/backfill: _start_job: Started JobId=47103 in cpu-epyc on cpu[12-13]
[2022-08-02T17:50:25.789] sched: Allocate JobId=47089 NodeList=cpu09 #CPUs=16 Partition=cpu-opteron
[2022-08-02T17:52:27.238] sched: Allocate JobId=47095 NodeList=cpu03 #CPUs=16 Partition=cpu-opteron
[2022-08-02T17:55:26.182] sched: Allocate JobId=47096 NodeList=cpu11 #CPUs=16 Partition=cpu-opteron
[2022-08-02T18:32:23.335] sched: Allocate JobId=47097 NodeList=cpu07 #CPUs=16 Partition=cpu-opteron
[2022-08-02T18:34:19.306] sched: Allocate JobId=47098 NodeList=cpu03 #CPUs=16 Partition=cpu-opteron
[2022-08-02T22:02:19.985] sched: Allocate JobId=47099 NodeList=cpu03 #CPUs=16 Partition=cpu-opteron
[2022-08-02T22:32:52.119] sched: Allocate JobId=47104 NodeList=cpu11 #CPUs=16 Partition=cpu-opteron
[2022-08-02T23:21:24.184] sched: Allocate JobId=47105 NodeList=cpu10 #CPUs=16 Partition=cpu-opteron
[2022-08-02T23:21:24.184] sched: Allocate JobId=47106 NodeList=cpu10 #CPUs=16 Partition=cpu-opteron
[2022-08-02T23:21:24.185] sched: Allocate JobId=47107 NodeList=cpu10 #CPUs=16 Partition=cpu-opteron
[2022-08-02T23:21:24.185] sched: Allocate JobId=47108 NodeList=cpu10 #CPUs=16 Partition=cpu-opteron
[2022-08-02T23:25:35.483] sched: Allocate JobId=47109 NodeList=cpu11 #CPUs=16 Partition=cpu-opteron
[2022-08-03T00:02:55.296] sched: Allocate JobId=47110 NodeList=cpu09 #CPUs=16 Partition=cpu-opteron
[2022-08-03T00:32:40.536] sched: Allocate JobId=47111 NodeList=cpu03 #CPUs=16 Partition=cpu-opteron
[2022-08-03T00:39:10.594] sched: Allocate JobId=47112 NodeList=cpu03 #CPUs=16 Partition=cpu-opteron
[2022-08-03T01:12:19.459] sched: Allocate JobId=47113 NodeList=cpu09 #CPUs=16 Partition=cpu-opteron
[2022-08-03T01:26:38.636] sched: Allocate JobId=47114 NodeList=cpu11 #CPUs=16 Partition=cpu-opteron
[2022-08-03T02:08:29.728] sched: Allocate JobId=47115 NodeList=cpu03 #CPUs=16 Partition=cpu-opteron
[2022-08-03T04:07:44.469] sched: Allocate JobId=47116 NodeList=cpu07 #CPUs=16 Partition=cpu-opteron
[2022-08-03T04:24:37.343] sched: Allocate JobId=47117 NodeList=cpu07 #CPUs=16 Partition=cpu-opteron
[2022-08-03T05:46:13.047] sched: Allocate JobId=47118 NodeList=cpu11 #CPUs=16 Partition=cpu-opteron
[2022-08-03T05:57:18.897] sched: Allocate JobId=47119 NodeList=cpu10 #CPUs=16 Partition=cpu-opteron
[2022-08-03T06:58:06.333] sched: Allocate JobId=47120 NodeList=cpu10 #CPUs=16 Partition=cpu-opteron
[2022-08-03T07:51:27.136] sched: Allocate JobId=47121 NodeList=cpu11 #CPUs=16 Partition=cpu-opteron
[2022-08-03T08:01:01.833] sched: Allocate JobId=47122 NodeList=cpu03 #CPUs=16 Partition=cpu-opteron
[2022-08-03T08:39:02.550] sched: Allocate JobId=46935 NodeList=cpu12 #CPUs=32 Partition=cpu-epyc
[2022-08-03T08:59:59.766] sched: Allocate JobId=47125 NodeList=cpu07 #CPUs=8 Partition=cpu-opteron
[2022-08-03T09:00:39.377] sched/backfill: _start_job: Started JobId=47101 in cpu-opteron on cpu[03,07]
[2022-08-03T09:02:58.423] sched: Allocate JobId=47126 NodeList=cpu[03,07] #CPUs=16 Partition=cpu-opteron
[2022-08-03T09:03:39.400] sched/backfill: _start_job: Started JobId=47124 in cpu-opteron on cpu03
[2022-08-03T09:40:53.566] sched: Allocate JobId=47127 NodeList=cpu[12-13] #CPUs=32 Partition=cpu-epyc
[2022-08-03T09:41:12.173] sched: Allocate JobId=47100 NodeList=cpu10 #CPUs=32 Partition=cpu-opteron
[2022-08-03T09:41:48.618] sched: Allocate JobId=47128 NodeList=cpu[12-13] #CPUs=64 Partition=cpu-epyc
[2022-08-03T09:42:49.928] sched: Allocate JobId=47129 NodeList=cpu[12-13] #CPUs=64 Partition=cpu-epyc
[2022-08-03T09:44:37.080] sched: Allocate JobId=47130 NodeList=cpu[12-13] #CPUs=64 Partition=cpu-epyc
[2022-08-03T09:45:39.477] sched/backfill: _start_job: Started JobId=47123 in cpu-opteron on cpu10
[2022-08-03T09:46:23.231] sched: Allocate JobId=47131 NodeList=cpu[12-13] #CPUs=64 Partition=cpu-epyc
[2022-08-03T09:48:44.796] sched: Allocate JobId=47132 NodeList=cpu[12-13] #CPUs=64 Partition=cpu-epyc
[2022-08-03T09:50:00.904] sched: Allocate JobId=47133 NodeList=cpu[12-13] #CPUs=64 Partition=cpu-epyc
[2022-08-03T09:51:50.060] sched: Allocate JobId=47134 NodeList=cpu[12-13] #CPUs=64 Partition=cpu-epyc
[2022-08-03T09:52:40.365] sched: Allocate JobId=47135 NodeList=cpu[12-13] #CPUs=32 Partition=cpu-epyc
[2022-08-03T09:54:08.531] sched: Allocate JobId=47136 NodeList=cpu[13,15] #CPUs=32 Partition=cpu-epyc
[2022-08-03T09:55:57.683] sched: Allocate JobId=47137 NodeList=cpu[12-13] #CPUs=32 Partition=cpu-epyc
[2022-08-03T09:57:40.000] sched: Allocate JobId=47138 NodeList=cpu[12-13] #CPUs=32 Partition=cpu-epyc
[2022-08-03T09:58:49.138] sched: Allocate JobId=47139 NodeList=cpu[12,15] #CPUs=32 Partition=cpu-epyc
[2022-08-03T10:00:01.235] sched: Allocate JobId=47140 NodeList=cpu[12-13] #CPUs=32 Partition=cpu-epyc
[2022-08-03T10:01:28.357] sched: Allocate JobId=47141 NodeList=cpu[12-13] #CPUs=32 Partition=cpu-epyc
[2022-08-03T10:03:13.952] sched: Allocate JobId=47142 NodeList=cpu[12-13] #CPUs=32 Partition=cpu-epyc
[2022-08-03T10:04:30.052] sched: Allocate JobId=47143 NodeList=cpu[12-13] #CPUs=32 Partition=cpu-epyc
[2022-08-03T10:04:45.072] sched: Allocate JobId=47144 NodeList=cpu[12-13] #CPUs=8 Partition=cpu-epyc
[2022-08-03T10:05:05.098] sched: Allocate JobId=47145 NodeList=cpu[12-13] #CPUs=8 Partition=cpu-epyc
[2022-08-03T10:05:42.151] sched: Allocate JobId=47146 NodeList=cpu[12-13] #CPUs=8 Partition=cpu-epyc
[2022-08-03T10:06:23.207] sched: Allocate JobId=47147 NodeList=cpu[12-13] #CPUs=8 Partition=cpu-epyc
[2022-08-03T10:06:49.244] sched: Allocate JobId=47148 NodeList=cpu[12-13] #CPUs=8 Partition=cpu-epyc
[2022-08-03T10:07:13.278] sched: Allocate JobId=47149 NodeList=cpu[12-13] #CPUs=8 Partition=cpu-epyc
[2022-08-03T10:21:39.530] sched/backfill: _start_job: Started JobId=47150 in cpu-epyc on cpu[12-13,15]
[2022-08-03T10:26:09.404] sched: Allocate JobId=47151 NodeList=cpu[12-13,15] #CPUs=48 Partition=cpu-epyc
[2022-08-03T10:28:05.674] sched: Allocate JobId=47152 NodeList=cpu[12-13,15] #CPUs=48 Partition=cpu-epyc
[2022-08-03T10:33:39.550] sched/backfill: _start_job: Started JobId=47153 in cpu-epyc on cpu[12-13,15]
[2022-08-03T10:37:02.571] sched: Allocate JobId=47154 NodeList=cpu[12-13,15] #CPUs=48 Partition=cpu-epyc
[2022-08-03T10:38:18.824] sched: Allocate JobId=47155 NodeList=cpu[12-13,15] #CPUs=48 Partition=cpu-epyc
[2022-08-03T10:39:05.888] sched: Allocate JobId=47156 NodeList=cpu[12-13] #CPUs=32 Partition=cpu-epyc
[2022-08-03T10:40:50.031] sched: Allocate JobId=47157 NodeList=cpu[12-13] #CPUs=32 Partition=cpu-epyc
[2022-08-03T10:42:20.153] sched: Allocate JobId=47158 NodeList=cpu[12-13] #CPUs=32 Partition=cpu-epyc
[2022-08-03T10:46:32.604] sched: Allocate JobId=47159 NodeList=cpu[12-13] #CPUs=32 Partition=cpu-epyc
[2022-08-03T10:54:16.533] sched: Allocate JobId=47160 NodeList=cpu[12-13] #CPUs=32 Partition=cpu-epyc
[2022-08-03T10:58:13.033] sched: Allocate JobId=47161 NodeList=cpu[12-13] #CPUs=32 Partition=cpu-epyc
[2022-08-03T10:59:59.178] sched: Allocate JobId=47162 NodeList=cpu[12-13] #CPUs=32 Partition=cpu-epyc
[2022-08-03T11:00:53.253] sched: Allocate JobId=47163 NodeList=cpu[12-13] #CPUs=16 Partition=cpu-epyc
[2022-08-03T11:03:59.589] sched: Allocate JobId=47164 NodeList=cpu[12-13] #CPUs=16 Partition=cpu-epyc
[2022-08-03T11:04:35.640] sched: Allocate JobId=47165 NodeList=cpu[12-13] #CPUs=16 Partition=cpu-epyc
[2022-08-03T11:08:54.131] sched: Allocate JobId=47166 NodeList=cpu[12-13] #CPUs=16 Partition=cpu-epyc
[2022-08-03T11:12:39.615] sched/backfill: _start_job: Started JobId=47167 in cpu-epyc on cpu15
[2022-08-03T11:12:39.616] sched/backfill: _start_job: Started JobId=47168 in cpu-epyc on cpu12
[2022-08-03T11:12:39.617] sched/backfill: _start_job: Started JobId=47169 in cpu-epyc on cpu13
[2022-08-03T11:20:48.713] sched: Allocate JobId=47211 NodeList=cpu[09-10] #CPUs=16 Partition=cpu-opteron
[2022-08-03T11:33:20.141] sched: Allocate JobId=47212 NodeList=cpu[09-10] #CPUs=16 Partition=cpu-opteron
[2022-08-03T11:34:14.212] sched: Allocate JobId=47213 NodeList=cpu[09-10] #CPUs=16 Partition=cpu-opteron
[2022-08-03T11:38:39.701] sched/backfill: _start_job: Started JobId=47170 in cpu-epyc on cpu15
[2022-08-03T11:40:39.708] sched/backfill: _start_job: Started JobId=47171 in cpu-epyc on cpu13
[2022-08-03T11:44:39.722] sched/backfill: _start_job: Started JobId=47172 in cpu-epyc on cpu12
[2022-08-03T11:53:05.431] sched: Allocate JobId=47214 NodeList=cpu[09-10] #CPUs=16 Partition=cpu-opteron
[2022-08-03T11:54:45.572] sched: Allocate JobId=47215 NodeList=cpu[03,07] #CPUs=32 Partition=cpu-opteron
[2022-08-03T12:06:39.800] sched/backfill: _start_job: Started JobId=47173 in cpu-epyc on cpu15
[2022-08-03T12:09:12.074] sched: Allocate JobId=47216 NodeList=cpu[03,07] #CPUs=32 Partition=cpu-opteron
[2022-08-03T12:26:39.868] sched/backfill: _start_job: Started JobId=47174 in cpu-epyc on cpu12
[2022-08-03T12:26:39.869] sched/backfill: _start_job: Started JobId=47175 in cpu-epyc on cpu13
[2022-08-03T12:35:39.897] sched/backfill: _start_job: Started JobId=47176 in cpu-epyc on cpu15
[2022-08-03T12:55:39.962] sched/backfill: _start_job: Started JobId=47177 in cpu-epyc on cpu12
[2022-08-03T13:02:39.986] sched/backfill: _start_job: Started JobId=47178 in cpu-epyc on cpu13
[2022-08-03T13:08:13.555] sched: Allocate JobId=47217 NodeList=cpu[09-10] #CPUs=8 Partition=cpu-opteron
[2022-08-03T13:08:33.580] sched: Allocate JobId=47218 NodeList=cpu[09-10] #CPUs=8 Partition=cpu-opteron
[2022-08-03T13:08:40.008] sched/backfill: _start_job: Started JobId=47179 in cpu-epyc on cpu15
[2022-08-03T13:23:12.261] sched: Allocate JobId=47219 NodeList=cpu03 #CPUs=1 Partition=cpu-opteron
[2022-08-03T13:23:20.256] sched: Allocate JobId=47220 NodeList=cpu03 #CPUs=1 Partition=cpu-opteron
[2022-08-03T13:23:27.267] sched: Allocate JobId=47221 NodeList=cpu03 #CPUs=1 Partition=cpu-opteron
[2022-08-03T13:23:34.276] sched: Allocate JobId=47222 NodeList=cpu03 #CPUs=1 Partition=cpu-opteron
[2022-08-03T13:23:46.292] sched: Allocate JobId=47223 NodeList=cpu03 #CPUs=1 Partition=cpu-opteron
[2022-08-03T13:23:52.300] sched: Allocate JobId=47224 NodeList=cpu03 #CPUs=1 Partition=cpu-opteron
[2022-08-03T13:23:58.308] sched: Allocate JobId=47225 NodeList=cpu03 #CPUs=1 Partition=cpu-opteron
[2022-08-03T13:24:06.319] sched: Allocate JobId=47226 NodeList=cpu03 #CPUs=1 Partition=cpu-opteron
[2022-08-03T13:24:13.329] sched: Allocate JobId=47227 NodeList=cpu03 #CPUs=1 Partition=cpu-opteron
[2022-08-03T13:24:23.340] sched: Allocate JobId=47228 NodeList=cpu03 #CPUs=1 Partition=cpu-opteron
[2022-08-03T13:24:33.351] sched: Allocate JobId=47229 NodeList=cpu03 #CPUs=1 Partition=cpu-opteron
[2022-08-03T13:28:40.073] sched/backfill: _start_job: Started JobId=47180 in cpu-epyc on cpu12
[2022-08-03T13:29:29.015] sched: Allocate JobId=46799 NodeList=gpu05 #CPUs=16 Partition=gpu-v100s
[2022-08-03T13:30:33.708] sched: Allocate JobId=46801 NodeList=gpu05 #CPUs=16 Partition=gpu-v100s
[2022-08-03T13:32:40.086] sched/backfill: _start_job: Started JobId=47181 in cpu-epyc on cpu13
[2022-08-03T13:36:49.607] sched: Allocate JobId=47231 NodeList=cpu03 #CPUs=8 Partition=cpu-opteron
[2022-08-03T13:37:36.743] sched: Allocate JobId=47232 NodeList=cpu03 #CPUs=8 Partition=cpu-opteron
[2022-08-03T13:40:40.114] sched/backfill: _start_job: Started JobId=47182 in cpu-epyc on cpu15
[2022-08-03T13:57:07.821] sched: Allocate JobId=47233 NodeList=cpu03 #CPUs=8 Partition=cpu-opteron
[2022-08-03T14:02:40.182] sched/backfill: _start_job: Started JobId=47183 in cpu-epyc on cpu13
[2022-08-03T14:14:40.220] sched/backfill: _start_job: Started JobId=47184 in cpu-epyc on cpu12
[2022-08-03T14:14:40.221] sched/backfill: _start_job: Started JobId=47185 in cpu-epyc on cpu15
[2022-08-03T14:15:52.852] sched: Allocate JobId=47234 NodeList=cpu03 #CPUs=8 Partition=cpu-opteron
[2022-08-03T14:17:20.976] sched: Allocate JobId=47235 NodeList=cpu03 #CPUs=8 Partition=cpu-opteron
[2022-08-03T14:20:49.367] sched: Allocate JobId=47236 NodeList=cpu03 #CPUs=8 Partition=cpu-opteron
[2022-08-03T14:25:06.086] sched: Allocate JobId=47237 NodeList=cpu03 #CPUs=8 Partition=cpu-opteron
[2022-08-03T14:31:40.271] sched/backfill: _start_job: Started JobId=47186 in cpu-epyc on cpu13
[2022-08-03T14:32:00.768] sched: Allocate JobId=47238 NodeList=cpu03 #CPUs=8 Partition=cpu-opteron
[2022-08-03T14:34:13.081] sched: Allocate JobId=47239 NodeList=cpu03 #CPUs=8 Partition=cpu-opteron
[2022-08-03T14:37:25.359] sched: Allocate JobId=47240 NodeList=cpu03 #CPUs=8 Partition=cpu-opteron
[2022-08-03T14:38:23.547] sched: Allocate JobId=47241 NodeList=cpu03 #CPUs=8 Partition=cpu-opteron
[2022-08-03T14:41:36.816] sched: Allocate JobId=47242 NodeList=cpu03 #CPUs=8 Partition=cpu-opteron
[2022-08-03T14:41:40.301] sched/backfill: _start_job: Started JobId=47187 in cpu-epyc on cpu15
[2022-08-03T14:41:53.853] sched: Allocate JobId=47243 NodeList=cpu03 #CPUs=8 Partition=cpu-opteron
[2022-08-03T14:45:46.310] sched: Allocate JobId=47244 NodeList=cpu03 #CPUs=16 Partition=cpu-opteron
[2022-08-03T14:45:49.301] sched: Allocate JobId=47245 NodeList=cpu07 #CPUs=16 Partition=cpu-opteron
[2022-08-03T14:55:40.356] sched/backfill: _start_job: Started JobId=47246 in cpu-opteron on cpu09
[2022-08-03T14:56:40.360] sched/backfill: _start_job: Started JobId=47247 in cpu-opteron on cpu11
[2022-08-03T14:57:15.521] sched: Allocate JobId=47248 NodeList=cpu03 #CPUs=8 Partition=cpu-opteron
[2022-08-03T14:59:37.085] sched: Allocate JobId=47249 NodeList=cpu03 #CPUs=16 Partition=cpu-opteron
[2022-08-03T14:59:47.847] sched: Allocate JobId=47250 NodeList=cpu07 #CPUs=8 Partition=cpu-opteron
[2022-08-03T15:01:40.377] sched/backfill: _start_job: Started JobId=47188 in cpu-epyc on cpu12
[2022-08-03T15:05:40.390] sched/backfill: _start_job: Started JobId=47189 in cpu-epyc on cpu13
[2022-08-03T15:05:40.390] sched/backfill: _start_job: Started JobId=47190 in cpu-epyc on cpu15
[2022-08-03T15:08:47.865] sched: Allocate JobId=47251 NodeList=cpu09 #CPUs=8 Partition=cpu-opteron
[2022-08-03T15:15:24.028] sched: Allocate JobId=47252 NodeList=cpu07 #CPUs=16 Partition=cpu-opteron
[2022-08-03T15:21:27.150] sched: Allocate JobId=47253 NodeList=cpu[09-10] #CPUs=16 Partition=cpu-opteron
[2022-08-03T15:22:06.200] sched: Allocate JobId=47254 NodeList=cpu07 #CPUs=16 Partition=cpu-opteron
[2022-08-03T15:25:19.589] sched: Allocate JobId=47255 NodeList=cpu[09-10] #CPUs=16 Partition=cpu-opteron
[2022-08-03T15:27:24.761] sched: Allocate JobId=47256 NodeList=cpu[09-10] #CPUs=16 Partition=cpu-opteron
[2022-08-03T15:28:52.999] sched: Allocate JobId=47257 NodeList=cpu07 #CPUs=16 Partition=cpu-opteron
[2022-08-03T15:31:00.174] sched: Allocate JobId=47258 NodeList=cpu[09-10] #CPUs=16 Partition=cpu-opteron
[2022-08-03T15:32:40.426] sched: Allocate JobId=47259 NodeList=cpu[09-10] #CPUs=16 Partition=cpu-opteron
[2022-08-03T15:33:40.468] sched/backfill: _start_job: Started JobId=47191 in cpu-epyc on cpu12
[2022-08-03T15:34:48.637] sched: Allocate JobId=47260 NodeList=cpu[09-10] #CPUs=16 Partition=cpu-opteron
[2022-08-03T15:35:06.663] sched: Allocate JobId=47261 NodeList=cpu[09-10] #CPUs=16 Partition=cpu-opteron
[2022-08-03T15:35:40.474] sched/backfill: _start_job: Started JobId=47192 in cpu-epyc on cpu15
[2022-08-03T15:39:06.090] sched: Allocate JobId=47262 NodeList=cpu03 #CPUs=8 Partition=cpu-opteron
[2022-08-03T15:39:22.113] sched: Allocate JobId=47263 NodeList=cpu03 #CPUs=8 Partition=cpu-opteron
[2022-08-03T15:42:17.353] sched: Allocate JobId=47264 NodeList=cpu03 #CPUs=4 Partition=cpu-opteron
[2022-08-03T15:42:25.367] sched: Allocate JobId=47266 NodeList=cpu03 #CPUs=8 Partition=cpu-opteron
[2022-08-03T15:42:25.371] sched: Allocate JobId=47265 NodeList=cpu03 #CPUs=16 Partition=cpu-opteron
[2022-08-03T15:42:28.369] sched: Allocate JobId=47267 NodeList=cpu07 #CPUs=16 Partition=cpu-opteron
[2022-08-03T15:43:41.579] sched: Allocate JobId=47268 NodeList=cpu03 #CPUs=4 Partition=cpu-opteron
[2022-08-03T15:44:56.682] sched: Allocate JobId=47269 NodeList=cpu[09-10] #CPUs=8 Partition=cpu-opteron
[2022-08-03T15:46:31.813] sched: Allocate JobId=47270 NodeList=cpu[09-10] #CPUs=8 Partition=cpu-opteron
[2022-08-03T15:46:41.826] sched: Allocate JobId=47271 NodeList=cpu03 #CPUs=8 Partition=cpu-opteron
[2022-08-03T15:47:33.918] sched: Allocate JobId=47272 NodeList=cpu03 #CPUs=16 Partition=cpu-opteron
[2022-08-03T15:49:15.131] sched: Allocate JobId=47273 NodeList=cpu[09-10] #CPUs=16 Partition=cpu-opteron
[2022-08-03T15:50:02.194] sched: Allocate JobId=47274 NodeList=cpu[09-10] #CPUs=16 Partition=cpu-opteron
[2022-08-03T15:50:57.270] sched: Allocate JobId=47275 NodeList=cpu07 #CPUs=8 Partition=cpu-opteron
[2022-08-03T15:51:20.300] sched: Allocate JobId=47276 NodeList=cpu10 #CPUs=16 Partition=cpu-opteron
[2022-08-03T15:52:01.360] sched: Allocate JobId=47278 NodeList=cpu07 #CPUs=8 Partition=cpu-opteron
[2022-08-03T15:52:57.586] sched: Allocate JobId=47279 NodeList=cpu07 #CPUs=8 Partition=cpu-opteron
[2022-08-03T15:53:16.604] sched: Allocate JobId=47280 NodeList=cpu[09-10] #CPUs=16 Partition=cpu-opteron
[2022-08-03T15:54:40.529] sched/backfill: _start_job: Started JobId=47193 in cpu-epyc on cpu13
[2022-08-03T15:55:18.775] sched: Allocate JobId=47282 NodeList=cpu[09-10] #CPUs=16 Partition=cpu-opteron
[2022-08-03T15:56:50.593] sched: Allocate JobId=47281 NodeList=cpu03 #CPUs=32 Partition=cpu-opteron
[2022-08-03T15:57:26.924] sched: Allocate JobId=47283 NodeList=cpu03 #CPUs=32 Partition=cpu-opteron
[2022-08-03T15:57:54.096] sched: Allocate JobId=47288 NodeList=cpu[09-10] #CPUs=16 Partition=cpu-opteron
[2022-08-03T15:58:01.272] sched: Allocate JobId=47284 NodeList=cpu03 #CPUs=32 Partition=cpu-opteron
[2022-08-03T15:58:14.836] sched: Allocate JobId=47286 NodeList=cpu03 #CPUs=32 Partition=cpu-opteron
[2022-08-03T15:58:19.892] sched: Allocate JobId=47287 NodeList=cpu03 #CPUs=32 Partition=cpu-opteron
[2022-08-03T15:58:35.687] sched: Allocate JobId=47277 NodeList=cpu03 #CPUs=16 Partition=cpu-opteron
[2022-08-03T15:58:35.687] sched: Allocate JobId=47285 NodeList=cpu03 #CPUs=16 Partition=cpu-opteron
[2022-08-03T16:00:43.332] sched: Allocate JobId=47293 NodeList=cpu[09-10] #CPUs=16 Partition=cpu-opteron
[2022-08-03T16:00:58.355] sched: Allocate JobId=47294 NodeList=cpu[09-10] #CPUs=16 Partition=cpu-opteron
[2022-08-03T16:02:38.567] sched: Allocate JobId=47296 NodeList=cpu07 #CPUs=8 Partition=cpu-opteron
[2022-08-03T16:03:40.565] sched/backfill: _start_job: Started JobId=47194 in cpu-epyc on cpu12
[2022-08-03T16:03:40.566] sched/backfill: _start_job: Started JobId=47195 in cpu-epyc on cpu15
